{
  "version": 8,
  "blockIdVersion": 8,
  "anchorX": -2,
  "anchorY": 27,
  "anchorZ": 0,
  "blocks": [
    {
      "x": -7,
      "y": 24,
      "z": -3,
      "name": "Rock_Stone"
    },
    {
      "x": -7,
      "y": 25,
      "z": -3,
      "name": "Rock_Stone"
    },
    {
      "x": -7,
      "y": 26,
      "z": -3,
      "name": "Rock_Stone"
    },
    {
      "x": -7,
      "y": 27,
      "z": -3,
      "name": "Rock_Stone"
    },
    {
      "x": -7,
      "y": 28,
      "z": -3,
      "name": "Rock_Stone"
    },
    {
      "x": -7,
      "y": 29,
      "z": -3,
      "name": "Rock_Stone_Mossy"
    },
    {
      "x": -7,
      "y": 30,
      "z": -3,
      "name": "Rock_Stone_Mossy"
    },
    {
      "x": -7,
      "y": 24,
      "z": -2,
      "name": "Rock_Stone"
    },
    {
      "x": -7,
      "y": 25,
      "z": -2,
      "name": "Rock_Stone"
    },
    {
      "x": -7,
      "y": 26,
      "z": -2,
      "name": "Rock_Stone"
    },
    {
      "x": -7,
      "y": 27,
      "z": -2,
      "name": "Rock_Stone"
    },
    {
      "x": -7,
      "y": 28,
      "z": -2,
      "name": "Rock_Stone_Mossy"
    },
    {
      "x": -7,
      "y": 29,
      "z": -2,
      "name": "Rock_Stone_Mossy"
    },
    {
      "x": -7,
      "y": 30,
      "z": -2,
      "name": "Soil_Dirt"
    },
    {
      "x": -7,
      "y": 31,
      "z": -2,
      "name": "Soil_Dirt"
    },
    {
      "x": -7,
      "y": 32,
      "z": -2,
      "name": "Soil_Dirt"
    },
    {
      "x": -7,
      "y": 33,
      "z": -2,
      "name": "Soil_Grass"
    },
    {
      "x": -7,
      "y": 22,
      "z": -1,
      "name": "Rock_Stone"
    },
    {
      "x": -7,
      "y": 23,
      "z": -1,
      "name": "Rock_Stone"
    },
    {
      "x": -7,
      "y": 24,
      "z": -1,
      "name": "Rock_Stone"
    },
    {
      "x": -7,
      "y": 25,
      "z": -1,
      "name": "Rock_Stone"
    },
    {
      "x": -7,
      "y": 26,
      "z": -1,
      "name": "Rock_Stone"
    },
    {
      "x": -7,
      "y": 27,
      "z": -1,
      "name": "Rock_Stone_Mossy"
    },
    {
      "x": -7,
      "y": 28,
      "z": -1,
      "name": "Rock_Stone_Mossy"
    },
    {
      "x": -7,
      "y": 29,
      "z": -1,
      "name": "Rock_Stone_Mossy"
    },
    {
      "x": -7,
      "y": 30,
      "z": -1,
      "name": "Soil_Dirt"
    },
    {
      "x": -7,
      "y": 31,
      "z": -1,
      "name": "Soil_Dirt"
    },
    {
      "x": -7,
      "y": 32,
      "z": -1,
      "name": "Soil_Dirt"
    },
    {
      "x": -7,
      "y": 33,
      "z": -1,
      "name": "Soil_Grass"
    },
    {
      "x": -7,
      "y": 22,
      "z": 0,
      "name": "Rock_Stone"
    },
    {
      "x": -7,
      "y": 23,
      "z": 0,
      "name": "Rock_Stone"
    },
    {
      "x": -7,
      "y": 24,
      "z": 0,
      "name": "Rock_Stone"
    },
    {
      "x": -7,
      "y": 25,
      "z": 0,
      "name": "Rock_Stone"
    },
    {
      "x": -7,
      "y": 26,
      "z": 0,
      "name": "Rock_Stone"
    },
    {
      "x": -7,
      "y": 27,
      "z": 0,
      "name": "Rock_Stone"
    },
    {
      "x": -7,
      "y": 28,
      "z": 0,
      "name": "Rock_Stone_Mossy"
    },
    {
      "x": -7,
      "y": 29,
      "z": 0,
      "name": "Rock_Stone"
    },
    {
      "x": -7,
      "y": 30,
      "z": 0,
      "name": "Soil_Dirt"
    },
    {
      "x": -7,
      "y": 31,
      "z": 0,
      "name": "Soil_Dirt"
    },
    {
      "x": -7,
      "y": 32,
      "z": 0,
      "name": "Soil_Dirt"
    },
    {
      "x": -7,
      "y": 33,
      "z": 0,
      "name": "Soil_Grass"
    },
    {
      "x": -7,
      "y": 34,
      "z": 0,
      "name": "Plant_Grass_Sharp_Tall"
    },
    {
      "x": -7,
      "y": 35,
      "z": 0,
      "name": "Plant_Grass_Sharp_Tall",
      "filler": 1024
    },
    {
      "x": -7,
      "y": 22,
      "z": 1,
      "name": "Rock_Stone"
    },
    {
      "x": -7,
      "y": 23,
      "z": 1,
      "name": "Rock_Stone"
    },
    {
      "x": -7,
      "y": 24,
      "z": 1,
      "name": "Rock_Stone"
    },
    {
      "x": -7,
      "y": 25,
      "z": 1,
      "name": "Rock_Stone"
    },
    {
      "x": -7,
      "y": 26,
      "z": 1,
      "name": "Rock_Stone"
    },
    {
      "x": -7,
      "y": 30,
      "z": 1,
      "name": "Rock_Stone"
    },
    {
      "x": -7,
      "y": 31,
      "z": 1,
      "name": "Soil_Dirt"
    },
    {
      "x": -7,
      "y": 32,
      "z": 1,
      "name": "Soil_Dirt"
    },
    {
      "x": -7,
      "y": 33,
      "z": 1,
      "name": "Soil_Grass"
    },
    {
      "x": -6,
      "y": 30,
      "z": -4,
      "name": "Rock_Stone"
    },
    {
      "x": -6,
      "y": 31,
      "z": -4,
      "name": "Soil_Dirt"
    },
    {
      "x": -6,
      "y": 32,
      "z": -4,
      "name": "Soil_Grass"
    },
    {
      "x": -6,
      "y": 24,
      "z": -3,
      "name": "Rock_Stone"
    },
    {
      "x": -6,
      "y": 25,
      "z": -3,
      "name": "Rock_Stone"
    },
    {
      "x": -6,
      "y": 26,
      "z": -3,
      "name": "Rock_Stone"
    },
    {
      "x": -6,
      "y": 27,
      "z": -3,
      "name": "Rock_Stone"
    },
    {
      "x": -6,
      "y": 28,
      "z": -3,
      "name": "Rock_Stone"
    },
    {
      "x": -6,
      "y": 29,
      "z": -3,
      "name": "Rock_Stone"
    },
    {
      "x": -6,
      "y": 30,
      "z": -3,
      "name": "Rock_Stone_Mossy"
    },
    {
      "x": -6,
      "y": 31,
      "z": -3,
      "name": "Soil_Dirt"
    },
    {
      "x": -6,
      "y": 32,
      "z": -3,
      "name": "Soil_Dirt"
    },
    {
      "x": -6,
      "y": 33,
      "z": -3,
      "name": "Soil_Grass"
    },
    {
      "x": -6,
      "y": 21,
      "z": -2,
      "name": "Rock_Stone"
    },
    {
      "x": -6,
      "y": 22,
      "z": -2,
      "name": "Rock_Stone"
    },
    {
      "x": -6,
      "y": 23,
      "z": -2,
      "name": "Rock_Stone"
    },
    {
      "x": -6,
      "y": 24,
      "z": -2,
      "name": "Rock_Stone"
    },
    {
      "x": -6,
      "y": 25,
      "z": -2,
      "name": "Rock_Stone"
    },
    {
      "x": -6,
      "y": 26,
      "z": -2,
      "name": "Rock_Stone"
    },
    {
      "x": -6,
      "y": 27,
      "z": -2,
      "name": "Rock_Stone"
    },
    {
      "x": -6,
      "y": 28,
      "z": -2,
      "name": "Rock_Stone"
    },
    {
      "x": -6,
      "y": 29,
      "z": -2,
      "name": "Rock_Stone_Mossy"
    },
    {
      "x": -6,
      "y": 30,
      "z": -2,
      "name": "Soil_Dirt"
    },
    {
      "x": -6,
      "y": 31,
      "z": -2,
      "name": "Soil_Dirt"
    },
    {
      "x": -6,
      "y": 32,
      "z": -2,
      "name": "Soil_Dirt"
    },
    {
      "x": -6,
      "y": 33,
      "z": -2,
      "name": "Soil_Grass"
    },
    {
      "x": -6,
      "y": 34,
      "z": -2,
      "name": "Plant_Grass_Sharp"
    },
    {
      "x": -6,
      "y": 41,
      "z": -2,
      "name": "Soil_Dirt"
    },
    {
      "x": -6,
      "y": 42,
      "z": -2,
      "name": "Soil_Dirt"
    },
    {
      "x": -6,
      "y": 43,
      "z": -2,
      "name": "Soil_Grass"
    },
    {
      "x": -6,
      "y": 20,
      "z": -1,
      "name": "Rock_Stone"
    },
    {
      "x": -6,
      "y": 21,
      "z": -1,
      "name": "Rock_Stone"
    },
    {
      "x": -6,
      "y": 22,
      "z": -1,
      "name": "Rock_Stone"
    },
    {
      "x": -6,
      "y": 23,
      "z": -1,
      "name": "Rock_Stone"
    },
    {
      "x": -6,
      "y": 24,
      "z": -1,
      "name": "Rock_Stone"
    },
    {
      "x": -6,
      "y": 25,
      "z": -1,
      "name": "Rock_Stone"
    },
    {
      "x": -6,
      "y": 26,
      "z": -1,
      "name": "Rock_Stone"
    },
    {
      "x": -6,
      "y": 27,
      "z": -1,
      "name": "Rock_Stone"
    },
    {
      "x": -6,
      "y": 28,
      "z": -1,
      "name": "Rock_Stone_Mossy"
    },
    {
      "x": -6,
      "y": 29,
      "z": -1,
      "name": "Rock_Stone"
    },
    {
      "x": -6,
      "y": 30,
      "z": -1,
      "name": "Soil_Dirt"
    },
    {
      "x": -6,
      "y": 31,
      "z": -1,
      "name": "Soil_Dirt"
    },
    {
      "x": -6,
      "y": 32,
      "z": -1,
      "name": "Soil_Dirt"
    },
    {
      "x": -6,
      "y": 33,
      "z": -1,
      "name": "Soil_Grass"
    },
    {
      "x": -6,
      "y": 34,
      "z": -1,
      "name": "Plant_Grass_Sharp_Tall"
    },
    {
      "x": -6,
      "y": 35,
      "z": -1,
      "name": "Plant_Grass_Sharp_Tall",
      "filler": 1024
    },
    {
      "x": -6,
      "y": 39,
      "z": -1,
      "name": "Rock_Stone"
    },
    {
      "x": -6,
      "y": 40,
      "z": -1,
      "name": "Soil_Dirt"
    },
    {
      "x": -6,
      "y": 41,
      "z": -1,
      "name": "Soil_Dirt"
    },
    {
      "x": -6,
      "y": 42,
      "z": -1,
      "name": "Soil_Dirt"
    },
    {
      "x": -6,
      "y": 43,
      "z": -1,
      "name": "Soil_Grass"
    },
    {
      "x": -6,
      "y": 20,
      "z": 0,
      "name": "Rock_Stone"
    },
    {
      "x": -6,
      "y": 21,
      "z": 0,
      "name": "Rock_Stone"
    },
    {
      "x": -6,
      "y": 22,
      "z": 0,
      "name": "Rock_Stone"
    },
    {
      "x": -6,
      "y": 23,
      "z": 0,
      "name": "Rock_Stone"
    },
    {
      "x": -6,
      "y": 24,
      "z": 0,
      "name": "Rock_Stone"
    },
    {
      "x": -6,
      "y": 25,
      "z": 0,
      "name": "Rock_Stone"
    },
    {
      "x": -6,
      "y": 26,
      "z": 0,
      "name": "Rock_Stone"
    },
    {
      "x": -6,
      "y": 27,
      "z": 0,
      "name": "Rock_Stone"
    },
    {
      "x": -6,
      "y": 28,
      "z": 0,
      "name": "Rock_Stone"
    },
    {
      "x": -6,
      "y": 29,
      "z": 0,
      "name": "Rock_Stone"
    },
    {
      "x": -6,
      "y": 30,
      "z": 0,
      "name": "Soil_Dirt"
    },
    {
      "x": -6,
      "y": 31,
      "z": 0,
      "name": "Soil_Dirt"
    },
    {
      "x": -6,
      "y": 32,
      "z": 0,
      "name": "Soil_Dirt"
    },
    {
      "x": -6,
      "y": 33,
      "z": 0,
      "name": "Soil_Grass"
    },
    {
      "x": -6,
      "y": 39,
      "z": 0,
      "name": "Rock_Stone"
    },
    {
      "x": -6,
      "y": 40,
      "z": 0,
      "name": "Soil_Dirt"
    },
    {
      "x": -6,
      "y": 41,
      "z": 0,
      "name": "Soil_Dirt"
    },
    {
      "x": -6,
      "y": 42,
      "z": 0,
      "name": "Soil_Dirt"
    },
    {
      "x": -6,
      "y": 43,
      "z": 0,
      "name": "Soil_Grass"
    },
    {
      "x": -6,
      "y": 44,
      "z": 0,
      "name": "Plant_Grass_Sharp"
    },
    {
      "x": -6,
      "y": 20,
      "z": 1,
      "name": "Rock_Stone"
    },
    {
      "x": -6,
      "y": 21,
      "z": 1,
      "name": "Rock_Stone"
    },
    {
      "x": -6,
      "y": 22,
      "z": 1,
      "name": "Rock_Stone"
    },
    {
      "x": -6,
      "y": 23,
      "z": 1,
      "name": "Rock_Stone"
    },
    {
      "x": -6,
      "y": 24,
      "z": 1,
      "name": "Rock_Stone"
    },
    {
      "x": -6,
      "y": 25,
      "z": 1,
      "name": "Rock_Stone"
    },
    {
      "x": -6,
      "y": 26,
      "z": 1,
      "name": "Rock_Stone"
    },
    {
      "x": -6,
      "y": 27,
      "z": 1,
      "name": "Rock_Stone"
    },
    {
      "x": -6,
      "y": 28,
      "z": 1,
      "name": "Rock_Stone"
    },
    {
      "x": -6,
      "y": 29,
      "z": 1,
      "name": "Rock_Stone"
    },
    {
      "x": -6,
      "y": 30,
      "z": 1,
      "name": "Rock_Stone"
    },
    {
      "x": -6,
      "y": 31,
      "z": 1,
      "name": "Soil_Dirt"
    },
    {
      "x": -6,
      "y": 32,
      "z": 1,
      "name": "Soil_Dirt"
    },
    {
      "x": -6,
      "y": 33,
      "z": 1,
      "name": "Soil_Grass"
    },
    {
      "x": -6,
      "y": 42,
      "z": 1,
      "name": "Soil_Dirt"
    },
    {
      "x": -6,
      "y": 43,
      "z": 1,
      "name": "Soil_Grass"
    },
    {
      "x": -6,
      "y": 54,
      "z": 1,
      "name": "Plant_Leaves_Aspen"
    },
    {
      "x": -6,
      "y": 21,
      "z": 2,
      "name": "Rock_Stone"
    },
    {
      "x": -6,
      "y": 22,
      "z": 2,
      "name": "Rock_Stone"
    },
    {
      "x": -6,
      "y": 23,
      "z": 2,
      "name": "Rock_Stone"
    },
    {
      "x": -6,
      "y": 24,
      "z": 2,
      "name": "Rock_Stone"
    },
    {
      "x": -6,
      "y": 25,
      "z": 2,
      "name": "Rock_Stone"
    },
    {
      "x": -6,
      "y": 26,
      "z": 2,
      "name": "Rock_Stone"
    },
    {
      "x": -6,
      "y": 27,
      "z": 2,
      "name": "Rock_Stone"
    },
    {
      "x": -6,
      "y": 32,
      "z": 2,
      "name": "Soil_Dirt"
    },
    {
      "x": -6,
      "y": 33,
      "z": 2,
      "name": "Soil_Dirt"
    },
    {
      "x": -6,
      "y": 34,
      "z": 2,
      "name": "Soil_Grass"
    },
    {
      "x": -6,
      "y": 33,
      "z": 3,
      "name": "Soil_Dirt"
    },
    {
      "x": -6,
      "y": 34,
      "z": 3,
      "name": "Soil_Grass"
    },
    {
      "x": -5,
      "y": 28,
      "z": -4,
      "name": "Rock_Stone"
    },
    {
      "x": -5,
      "y": 29,
      "z": -4,
      "name": "Rock_Stone"
    },
    {
      "x": -5,
      "y": 30,
      "z": -4,
      "name": "Rock_Stone"
    },
    {
      "x": -5,
      "y": 31,
      "z": -4,
      "name": "Soil_Dirt"
    },
    {
      "x": -5,
      "y": 32,
      "z": -4,
      "name": "Soil_Dirt"
    },
    {
      "x": -5,
      "y": 33,
      "z": -4,
      "name": "Soil_Grass"
    },
    {
      "x": -5,
      "y": 22,
      "z": -3,
      "name": "Rock_Stone"
    },
    {
      "x": -5,
      "y": 23,
      "z": -3,
      "name": "Rock_Stone"
    },
    {
      "x": -5,
      "y": 24,
      "z": -3,
      "name": "Rock_Stone"
    },
    {
      "x": -5,
      "y": 25,
      "z": -3,
      "name": "Rock_Stone"
    },
    {
      "x": -5,
      "y": 26,
      "z": -3,
      "name": "Rock_Stone"
    },
    {
      "x": -5,
      "y": 27,
      "z": -3,
      "name": "Rock_Stone"
    },
    {
      "x": -5,
      "y": 28,
      "z": -3,
      "name": "Rock_Stone"
    },
    {
      "x": -5,
      "y": 29,
      "z": -3,
      "name": "Rock_Stone"
    },
    {
      "x": -5,
      "y": 30,
      "z": -3,
      "name": "Rock_Stone"
    },
    {
      "x": -5,
      "y": 31,
      "z": -3,
      "name": "Soil_Dirt"
    },
    {
      "x": -5,
      "y": 32,
      "z": -3,
      "name": "Soil_Dirt"
    },
    {
      "x": -5,
      "y": 33,
      "z": -3,
      "name": "Soil_Grass"
    },
    {
      "x": -5,
      "y": 40,
      "z": -3,
      "name": "Soil_Dirt"
    },
    {
      "x": -5,
      "y": 41,
      "z": -3,
      "name": "Soil_Dirt"
    },
    {
      "x": -5,
      "y": 42,
      "z": -3,
      "name": "Soil_Dirt"
    },
    {
      "x": -5,
      "y": 43,
      "z": -3,
      "name": "Soil_Grass"
    },
    {
      "x": -5,
      "y": 20,
      "z": -2,
      "name": "Rock_Stone"
    },
    {
      "x": -5,
      "y": 21,
      "z": -2,
      "name": "Rock_Stone"
    },
    {
      "x": -5,
      "y": 22,
      "z": -2,
      "name": "Rock_Stone"
    },
    {
      "x": -5,
      "y": 23,
      "z": -2,
      "name": "Rock_Stone"
    },
    {
      "x": -5,
      "y": 24,
      "z": -2,
      "name": "Rock_Stone"
    },
    {
      "x": -5,
      "y": 25,
      "z": -2,
      "name": "Rock_Stone"
    },
    {
      "x": -5,
      "y": 26,
      "z": -2,
      "name": "Rock_Stone"
    },
    {
      "x": -5,
      "y": 27,
      "z": -2,
      "name": "Rock_Stone"
    },
    {
      "x": -5,
      "y": 28,
      "z": -2,
      "name": "Rock_Stone"
    },
    {
      "x": -5,
      "y": 29,
      "z": -2,
      "name": "Rock_Stone"
    },
    {
      "x": -5,
      "y": 30,
      "z": -2,
      "name": "Rock_Stone"
    },
    {
      "x": -5,
      "y": 31,
      "z": -2,
      "name": "Soil_Dirt"
    },
    {
      "x": -5,
      "y": 32,
      "z": -2,
      "name": "Soil_Dirt"
    },
    {
      "x": -5,
      "y": 33,
      "z": -2,
      "name": "Soil_Grass"
    },
    {
      "x": -5,
      "y": 34,
      "z": -2,
      "name": "Plant_Grass_Sharp"
    },
    {
      "x": -5,
      "y": 38,
      "z": -2,
      "name": "Rock_Stone_Mossy"
    },
    {
      "x": -5,
      "y": 39,
      "z": -2,
      "name": "Rock_Stone_Mossy"
    },
    {
      "x": -5,
      "y": 40,
      "z": -2,
      "name": "Soil_Dirt"
    },
    {
      "x": -5,
      "y": 41,
      "z": -2,
      "name": "Soil_Dirt"
    },
    {
      "x": -5,
      "y": 42,
      "z": -2,
      "name": "Soil_Dirt"
    },
    {
      "x": -5,
      "y": 43,
      "z": -2,
      "name": "Soil_Grass"
    },
    {
      "x": -5,
      "y": 20,
      "z": -1,
      "name": "Rock_Stone"
    },
    {
      "x": -5,
      "y": 21,
      "z": -1,
      "name": "Rock_Stone"
    },
    {
      "x": -5,
      "y": 22,
      "z": -1,
      "name": "Rock_Stone"
    },
    {
      "x": -5,
      "y": 23,
      "z": -1,
      "name": "Rock_Stone"
    },
    {
      "x": -5,
      "y": 24,
      "z": -1,
      "name": "Rock_Stone"
    },
    {
      "x": -5,
      "y": 25,
      "z": -1,
      "name": "Rock_Stone"
    },
    {
      "x": -5,
      "y": 26,
      "z": -1,
      "name": "Rock_Stone"
    },
    {
      "x": -5,
      "y": 27,
      "z": -1,
      "name": "Rock_Stone"
    },
    {
      "x": -5,
      "y": 28,
      "z": -1,
      "name": "Rock_Stone"
    },
    {
      "x": -5,
      "y": 29,
      "z": -1,
      "name": "Rock_Stone"
    },
    {
      "x": -5,
      "y": 30,
      "z": -1,
      "name": "Rock_Stone"
    },
    {
      "x": -5,
      "y": 31,
      "z": -1,
      "name": "Soil_Dirt"
    },
    {
      "x": -5,
      "y": 32,
      "z": -1,
      "name": "Soil_Dirt"
    },
    {
      "x": -5,
      "y": 33,
      "z": -1,
      "name": "Soil_Grass"
    },
    {
      "x": -5,
      "y": 34,
      "z": -1,
      "name": "Plant_Grass_Sharp_Tall"
    },
    {
      "x": -5,
      "y": 35,
      "z": -1,
      "name": "Plant_Grass_Sharp_Tall",
      "filler": 1024
    },
    {
      "x": -5,
      "y": 36,
      "z": -1,
      "name": "Rock_Stone"
    },
    {
      "x": -5,
      "y": 37,
      "z": -1,
      "name": "Rock_Stone"
    },
    {
      "x": -5,
      "y": 38,
      "z": -1,
      "name": "Rock_Stone"
    },
    {
      "x": -5,
      "y": 39,
      "z": -1,
      "name": "Rock_Stone_Mossy"
    },
    {
      "x": -5,
      "y": 40,
      "z": -1,
      "name": "Soil_Dirt"
    },
    {
      "x": -5,
      "y": 41,
      "z": -1,
      "name": "Soil_Dirt"
    },
    {
      "x": -5,
      "y": 42,
      "z": -1,
      "name": "Soil_Dirt"
    },
    {
      "x": -5,
      "y": 43,
      "z": -1,
      "name": "Soil_Grass"
    },
    {
      "x": -5,
      "y": 44,
      "z": -1,
      "name": "Plant_Grass_Sharp_Tall"
    },
    {
      "x": -5,
      "y": 45,
      "z": -1,
      "name": "Plant_Grass_Sharp_Tall",
      "filler": 1024
    },
    {
      "x": -5,
      "y": 53,
      "z": -1,
      "name": "Plant_Leaves_Aspen"
    },
    {
      "x": -5,
      "y": 19,
      "z": 0,
      "name": "Rock_Stone"
    },
    {
      "x": -5,
      "y": 20,
      "z": 0,
      "name": "Rock_Stone"
    },
    {
      "x": -5,
      "y": 21,
      "z": 0,
      "name": "Rock_Stone"
    },
    {
      "x": -5,
      "y": 22,
      "z": 0,
      "name": "Rock_Stone"
    },
    {
      "x": -5,
      "y": 23,
      "z": 0,
      "name": "Rock_Stone"
    },
    {
      "x": -5,
      "y": 24,
      "z": 0,
      "name": "Rock_Stone"
    },
    {
      "x": -5,
      "y": 25,
      "z": 0,
      "name": "Rock_Stone"
    },
    {
      "x": -5,
      "y": 26,
      "z": 0,
      "name": "Rock_Stone"
    },
    {
      "x": -5,
      "y": 27,
      "z": 0,
      "name": "Rock_Stone"
    },
    {
      "x": -5,
      "y": 28,
      "z": 0,
      "name": "Rock_Stone"
    },
    {
      "x": -5,
      "y": 29,
      "z": 0,
      "name": "Rock_Stone"
    },
    {
      "x": -5,
      "y": 30,
      "z": 0,
      "name": "Rock_Stone"
    },
    {
      "x": -5,
      "y": 31,
      "z": 0,
      "name": "Soil_Dirt"
    },
    {
      "x": -5,
      "y": 32,
      "z": 0,
      "name": "Soil_Dirt"
    },
    {
      "x": -5,
      "y": 33,
      "z": 0,
      "name": "Rock_Stone"
    },
    {
      "x": -5,
      "y": 34,
      "z": 0,
      "name": "Soil_Grass"
    },
    {
      "x": -5,
      "y": 37,
      "z": 0,
      "name": "Rock_Stone"
    },
    {
      "x": -5,
      "y": 38,
      "z": 0,
      "name": "Rock_Stone"
    },
    {
      "x": -5,
      "y": 39,
      "z": 0,
      "name": "Rock_Stone"
    },
    {
      "x": -5,
      "y": 40,
      "z": 0,
      "name": "Soil_Dirt"
    },
    {
      "x": -5,
      "y": 41,
      "z": 0,
      "name": "Soil_Dirt"
    },
    {
      "x": -5,
      "y": 42,
      "z": 0,
      "name": "Soil_Dirt"
    },
    {
      "x": -5,
      "y": 43,
      "z": 0,
      "name": "Soil_Grass"
    },
    {
      "x": -5,
      "y": 44,
      "z": 0,
      "name": "Plant_Grass_Sharp"
    },
    {
      "x": -5,
      "y": 53,
      "z": 0,
      "name": "Plant_Leaves_Aspen"
    },
    {
      "x": -5,
      "y": 54,
      "z": 0,
      "name": "Plant_Leaves_Aspen"
    },
    {
      "x": -5,
      "y": 55,
      "z": 0,
      "name": "Plant_Leaves_Aspen"
    },
    {
      "x": -5,
      "y": 56,
      "z": 0,
      "name": "Plant_Leaves_Aspen"
    },
    {
      "x": -5,
      "y": 20,
      "z": 1,
      "name": "Rock_Stone"
    },
    {
      "x": -5,
      "y": 21,
      "z": 1,
      "name": "Rock_Stone"
    },
    {
      "x": -5,
      "y": 22,
      "z": 1,
      "name": "Rock_Stone"
    },
    {
      "x": -5,
      "y": 23,
      "z": 1,
      "name": "Rock_Stone"
    },
    {
      "x": -5,
      "y": 24,
      "z": 1,
      "name": "Rock_Stone"
    },
    {
      "x": -5,
      "y": 25,
      "z": 1,
      "name": "Rock_Stone"
    },
    {
      "x": -5,
      "y": 26,
      "z": 1,
      "name": "Rock_Stone"
    },
    {
      "x": -5,
      "y": 27,
      "z": 1,
      "name": "Rock_Stone"
    },
    {
      "x": -5,
      "y": 28,
      "z": 1,
      "name": "Rock_Stone"
    },
    {
      "x": -5,
      "y": 29,
      "z": 1,
      "name": "Rock_Stone"
    },
    {
      "x": -5,
      "y": 30,
      "z": 1,
      "name": "Rock_Stone"
    },
    {
      "x": -5,
      "y": 31,
      "z": 1,
      "name": "Soil_Dirt"
    },
    {
      "x": -5,
      "y": 32,
      "z": 1,
      "name": "Soil_Dirt"
    },
    {
      "x": -5,
      "y": 33,
      "z": 1,
      "name": "Soil_Dirt"
    },
    {
      "x": -5,
      "y": 34,
      "z": 1,
      "name": "Soil_Grass"
    },
    {
      "x": -5,
      "y": 35,
      "z": 1,
      "name": "Plant_Grass_Sharp"
    },
    {
      "x": -5,
      "y": 40,
      "z": 1,
      "name": "Soil_Dirt"
    },
    {
      "x": -5,
      "y": 41,
      "z": 1,
      "name": "Soil_Dirt"
    },
    {
      "x": -5,
      "y": 42,
      "z": 1,
      "name": "Soil_Dirt"
    },
    {
      "x": -5,
      "y": 43,
      "z": 1,
      "name": "Soil_Grass"
    },
    {
      "x": -5,
      "y": 44,
      "z": 1,
      "name": "Plant_Grass_Sharp"
    },
    {
      "x": -5,
      "y": 52,
      "z": 1,
      "name": "Plant_Leaves_Aspen"
    },
    {
      "x": -5,
      "y": 53,
      "z": 1,
      "name": "Plant_Leaves_Aspen"
    },
    {
      "x": -5,
      "y": 54,
      "z": 1,
      "name": "Plant_Leaves_Aspen"
    },
    {
      "x": -5,
      "y": 55,
      "z": 1,
      "name": "Plant_Leaves_Aspen"
    },
    {
      "x": -5,
      "y": 56,
      "z": 1,
      "name": "Plant_Leaves_Aspen"
    },
    {
      "x": -5,
      "y": 57,
      "z": 1,
      "name": "Plant_Leaves_Aspen"
    },
    {
      "x": -5,
      "y": 20,
      "z": 2,
      "name": "Rock_Stone"
    },
    {
      "x": -5,
      "y": 21,
      "z": 2,
      "name": "Rock_Stone"
    },
    {
      "x": -5,
      "y": 22,
      "z": 2,
      "name": "Rock_Stone"
    },
    {
      "x": -5,
      "y": 23,
      "z": 2,
      "name": "Rock_Stone"
    },
    {
      "x": -5,
      "y": 24,
      "z": 2,
      "name": "Rock_Stone"
    },
    {
      "x": -5,
      "y": 25,
      "z": 2,
      "name": "Rock_Stone"
    },
    {
      "x": -5,
      "y": 26,
      "z": 2,
      "name": "Rock_Stone"
    },
    {
      "x": -5,
      "y": 27,
      "z": 2,
      "name": "Rock_Stone"
    },
    {
      "x": -5,
      "y": 28,
      "z": 2,
      "name": "Rock_Stone"
    },
    {
      "x": -5,
      "y": 29,
      "z": 2,
      "name": "Rock_Stone"
    },
    {
      "x": -5,
      "y": 30,
      "z": 2,
      "name": "Soil_Dirt"
    },
    {
      "x": -5,
      "y": 31,
      "z": 2,
      "name": "Soil_Dirt"
    },
    {
      "x": -5,
      "y": 32,
      "z": 2,
      "name": "Soil_Dirt"
    },
    {
      "x": -5,
      "y": 33,
      "z": 2,
      "name": "Soil_Dirt"
    },
    {
      "x": -5,
      "y": 34,
      "z": 2,
      "name": "Soil_Grass"
    },
    {
      "x": -5,
      "y": 35,
      "z": 2,
      "name": "Plant_Grass_Sharp"
    },
    {
      "x": -5,
      "y": 52,
      "z": 2,
      "name": "Plant_Leaves_Aspen"
    },
    {
      "x": -5,
      "y": 53,
      "z": 2,
      "name": "Plant_Leaves_Aspen"
    },
    {
      "x": -5,
      "y": 22,
      "z": 3,
      "name": "Rock_Stone"
    },
    {
      "x": -5,
      "y": 23,
      "z": 3,
      "name": "Rock_Stone"
    },
    {
      "x": -5,
      "y": 24,
      "z": 3,
      "name": "Rock_Stone"
    },
    {
      "x": -5,
      "y": 25,
      "z": 3,
      "name": "Rock_Stone"
    },
    {
      "x": -5,
      "y": 26,
      "z": 3,
      "name": "Rock_Stone"
    },
    {
      "x": -5,
      "y": 30,
      "z": 3,
      "name": "Soil_Dirt"
    },
    {
      "x": -5,
      "y": 31,
      "z": 3,
      "name": "Soil_Dirt"
    },
    {
      "x": -5,
      "y": 32,
      "z": 3,
      "name": "Soil_Dirt"
    },
    {
      "x": -5,
      "y": 33,
      "z": 3,
      "name": "Soil_Dirt"
    },
    {
      "x": -5,
      "y": 34,
      "z": 3,
      "name": "Soil_Grass"
    },
    {
      "x": -5,
      "y": 52,
      "z": 3,
      "name": "Plant_Leaves_Aspen"
    },
    {
      "x": -4,
      "y": 32,
      "z": -4,
      "name": "Soil_Dirt"
    },
    {
      "x": -4,
      "y": 33,
      "z": -4,
      "name": "Soil_Grass"
    },
    {
      "x": -4,
      "y": 22,
      "z": -3,
      "name": "Rock_Stone"
    },
    {
      "x": -4,
      "y": 23,
      "z": -3,
      "name": "Rock_Stone"
    },
    {
      "x": -4,
      "y": 24,
      "z": -3,
      "name": "Rock_Stone"
    },
    {
      "x": -4,
      "y": 25,
      "z": -3,
      "name": "Rock_Stone"
    },
    {
      "x": -4,
      "y": 26,
      "z": -3,
      "name": "Rock_Stone"
    },
    {
      "x": -4,
      "y": 27,
      "z": -3,
      "name": "Rock_Stone"
    },
    {
      "x": -4,
      "y": 28,
      "z": -3,
      "name": "Rock_Stone"
    },
    {
      "x": -4,
      "y": 29,
      "z": -3,
      "name": "Rock_Stone"
    },
    {
      "x": -4,
      "y": 30,
      "z": -3,
      "name": "Rock_Stone"
    },
    {
      "x": -4,
      "y": 31,
      "z": -3,
      "name": "Rock_Stone"
    },
    {
      "x": -4,
      "y": 32,
      "z": -3,
      "name": "Soil_Dirt"
    },
    {
      "x": -4,
      "y": 33,
      "z": -3,
      "name": "Soil_Grass"
    },
    {
      "x": -4,
      "y": 40,
      "z": -3,
      "name": "Soil_Dirt"
    },
    {
      "x": -4,
      "y": 41,
      "z": -3,
      "name": "Soil_Dirt"
    },
    {
      "x": -4,
      "y": 42,
      "z": -3,
      "name": "Soil_Dirt"
    },
    {
      "x": -4,
      "y": 43,
      "z": -3,
      "name": "Soil_Grass"
    },
    {
      "x": -4,
      "y": 44,
      "z": -3,
      "name": "Plant_Grass_Sharp"
    },
    {
      "x": -4,
      "y": 20,
      "z": -2,
      "name": "Rock_Stone"
    },
    {
      "x": -4,
      "y": 21,
      "z": -2,
      "name": "Rock_Stone"
    },
    {
      "x": -4,
      "y": 22,
      "z": -2,
      "name": "Rock_Stone"
    },
    {
      "x": -4,
      "y": 23,
      "z": -2,
      "name": "Rock_Stone"
    },
    {
      "x": -4,
      "y": 24,
      "z": -2,
      "name": "Rock_Stone"
    },
    {
      "x": -4,
      "y": 25,
      "z": -2,
      "name": "Rock_Stone"
    },
    {
      "x": -4,
      "y": 26,
      "z": -2,
      "name": "Rock_Stone"
    },
    {
      "x": -4,
      "y": 27,
      "z": -2,
      "name": "Rock_Stone"
    },
    {
      "x": -4,
      "y": 28,
      "z": -2,
      "name": "Rock_Stone"
    },
    {
      "x": -4,
      "y": 29,
      "z": -2,
      "name": "Rock_Stone"
    },
    {
      "x": -4,
      "y": 30,
      "z": -2,
      "name": "Rock_Stone"
    },
    {
      "x": -4,
      "y": 31,
      "z": -2,
      "name": "Rock_Stone"
    },
    {
      "x": -4,
      "y": 32,
      "z": -2,
      "name": "Rock_Stone"
    },
    {
      "x": -4,
      "y": 33,
      "z": -2,
      "name": "Rock_Stone"
    },
    {
      "x": -4,
      "y": 34,
      "z": -2,
      "name": "Rock_Stone"
    },
    {
      "x": -4,
      "y": 35,
      "z": -2,
      "name": "Rock_Stone"
    },
    {
      "x": -4,
      "y": 36,
      "z": -2,
      "name": "Rock_Stone"
    },
    {
      "x": -4,
      "y": 37,
      "z": -2,
      "name": "Rock_Stone"
    },
    {
      "x": -4,
      "y": 38,
      "z": -2,
      "name": "Rock_Stone"
    },
    {
      "x": -4,
      "y": 39,
      "z": -2,
      "name": "Soil_Dirt"
    },
    {
      "x": -4,
      "y": 40,
      "z": -2,
      "name": "Soil_Dirt"
    },
    {
      "x": -4,
      "y": 41,
      "z": -2,
      "name": "Soil_Dirt"
    },
    {
      "x": -4,
      "y": 42,
      "z": -2,
      "name": "Soil_Dirt"
    },
    {
      "x": -4,
      "y": 43,
      "z": -2,
      "name": "Rock_Stone"
    },
    {
      "x": -4,
      "y": 44,
      "z": -2,
      "name": "Rock_Stone"
    },
    {
      "x": -4,
      "y": 45,
      "z": -2,
      "name": "Soil_Dirt"
    },
    {
      "x": -4,
      "y": 46,
      "z": -2,
      "name": "Soil_Grass"
    },
    {
      "x": -4,
      "y": 53,
      "z": -2,
      "name": "Plant_Leaves_Aspen"
    },
    {
      "x": -4,
      "y": 54,
      "z": -2,
      "name": "Plant_Leaves_Aspen"
    },
    {
      "x": -4,
      "y": 55,
      "z": -2,
      "name": "Plant_Leaves_Aspen"
    },
    {
      "x": -4,
      "y": 19,
      "z": -1,
      "name": "Rock_Stone"
    },
    {
      "x": -4,
      "y": 20,
      "z": -1,
      "name": "Rock_Stone"
    },
    {
      "x": -4,
      "y": 21,
      "z": -1,
      "name": "Rock_Stone"
    },
    {
      "x": -4,
      "y": 22,
      "z": -1,
      "name": "Rock_Stone"
    },
    {
      "x": -4,
      "y": 23,
      "z": -1,
      "name": "Rock_Stone"
    },
    {
      "x": -4,
      "y": 24,
      "z": -1,
      "name": "Rock_Stone"
    },
    {
      "x": -4,
      "y": 25,
      "z": -1,
      "name": "Rock_Stone"
    },
    {
      "x": -4,
      "y": 26,
      "z": -1,
      "name": "Rock_Stone"
    },
    {
      "x": -4,
      "y": 27,
      "z": -1,
      "name": "Rock_Stone"
    },
    {
      "x": -4,
      "y": 28,
      "z": -1,
      "name": "Rock_Stone"
    },
    {
      "x": -4,
      "y": 29,
      "z": -1,
      "name": "Rock_Stone"
    },
    {
      "x": -4,
      "y": 30,
      "z": -1,
      "name": "Rock_Stone"
    },
    {
      "x": -4,
      "y": 31,
      "z": -1,
      "name": "Rock_Stone"
    },
    {
      "x": -4,
      "y": 32,
      "z": -1,
      "name": "Rock_Stone"
    },
    {
      "x": -4,
      "y": 33,
      "z": -1,
      "name": "Rock_Stone"
    },
    {
      "x": -4,
      "y": 34,
      "z": -1,
      "name": "Rock_Stone"
    },
    {
      "x": -4,
      "y": 35,
      "z": -1,
      "name": "Rock_Stone"
    },
    {
      "x": -4,
      "y": 36,
      "z": -1,
      "name": "Rock_Stone"
    },
    {
      "x": -4,
      "y": 37,
      "z": -1,
      "name": "Rock_Stone"
    },
    {
      "x": -4,
      "y": 38,
      "z": -1,
      "name": "Rock_Stone"
    },
    {
      "x": -4,
      "y": 39,
      "z": -1,
      "name": "Rock_Stone"
    },
    {
      "x": -4,
      "y": 40,
      "z": -1,
      "name": "Soil_Dirt"
    },
    {
      "x": -4,
      "y": 41,
      "z": -1,
      "name": "Soil_Dirt"
    },
    {
      "x": -4,
      "y": 42,
      "z": -1,
      "name": "Rock_Stone"
    },
    {
      "x": -4,
      "y": 43,
      "z": -1,
      "name": "Rock_Stone"
    },
    {
      "x": -4,
      "y": 44,
      "z": -1,
      "name": "Soil_Dirt"
    },
    {
      "x": -4,
      "y": 45,
      "z": -1,
      "name": "Soil_Dirt"
    },
    {
      "x": -4,
      "y": 46,
      "z": -1,
      "name": "Soil_Dirt"
    },
    {
      "x": -4,
      "y": 47,
      "z": -1,
      "name": "Soil_Grass"
    },
    {
      "x": -4,
      "y": 56,
      "z": -1,
      "name": "Plant_Leaves_Aspen"
    },
    {
      "x": -4,
      "y": 19,
      "z": 0,
      "name": "Rock_Stone"
    },
    {
      "x": -4,
      "y": 20,
      "z": 0,
      "name": "Rock_Stone"
    },
    {
      "x": -4,
      "y": 21,
      "z": 0,
      "name": "Rock_Stone"
    },
    {
      "x": -4,
      "y": 22,
      "z": 0,
      "name": "Rock_Stone"
    },
    {
      "x": -4,
      "y": 23,
      "z": 0,
      "name": "Rock_Stone"
    },
    {
      "x": -4,
      "y": 24,
      "z": 0,
      "name": "Rock_Stone"
    },
    {
      "x": -4,
      "y": 25,
      "z": 0,
      "name": "Rock_Stone"
    },
    {
      "x": -4,
      "y": 26,
      "z": 0,
      "name": "Rock_Stone"
    },
    {
      "x": -4,
      "y": 27,
      "z": 0,
      "name": "Rock_Stone"
    },
    {
      "x": -4,
      "y": 28,
      "z": 0,
      "name": "Rock_Stone"
    },
    {
      "x": -4,
      "y": 29,
      "z": 0,
      "name": "Rock_Stone"
    },
    {
      "x": -4,
      "y": 30,
      "z": 0,
      "name": "Rock_Stone"
    },
    {
      "x": -4,
      "y": 31,
      "z": 0,
      "name": "Rock_Stone"
    },
    {
      "x": -4,
      "y": 32,
      "z": 0,
      "name": "Rock_Stone"
    },
    {
      "x": -4,
      "y": 33,
      "z": 0,
      "name": "Rock_Stone"
    },
    {
      "x": -4,
      "y": 34,
      "z": 0,
      "name": "Rock_Stone"
    },
    {
      "x": -4,
      "y": 35,
      "z": 0,
      "name": "Rock_Stone"
    },
    {
      "x": -4,
      "y": 36,
      "z": 0,
      "name": "Rock_Stone"
    },
    {
      "x": -4,
      "y": 37,
      "z": 0,
      "name": "Rock_Stone"
    },
    {
      "x": -4,
      "y": 38,
      "z": 0,
      "name": "Rock_Stone"
    },
    {
      "x": -4,
      "y": 39,
      "z": 0,
      "name": "Rock_Stone"
    },
    {
      "x": -4,
      "y": 40,
      "z": 0,
      "name": "Rock_Stone"
    },
    {
      "x": -4,
      "y": 41,
      "z": 0,
      "name": "Soil_Dirt"
    },
    {
      "x": -4,
      "y": 42,
      "z": 0,
      "name": "Rock_Stone"
    },
    {
      "x": -4,
      "y": 43,
      "z": 0,
      "name": "Rock_Stone"
    },
    {
      "x": -4,
      "y": 44,
      "z": 0,
      "name": "Soil_Dirt"
    },
    {
      "x": -4,
      "y": 45,
      "z": 0,
      "name": "Soil_Dirt"
    },
    {
      "x": -4,
      "y": 46,
      "z": 0,
      "name": "Soil_Dirt"
    },
    {
      "x": -4,
      "y": 47,
      "z": 0,
      "name": "Soil_Grass"
    },
    {
      "x": -4,
      "y": 56,
      "z": 0,
      "name": "Plant_Leaves_Aspen"
    },
    {
      "x": -4,
      "y": 57,
      "z": 0,
      "name": "Plant_Leaves_Aspen"
    },
    {
      "x": -4,
      "y": 58,
      "z": 0,
      "name": "Plant_Leaves_Aspen"
    },
    {
      "x": -4,
      "y": 59,
      "z": 0,
      "name": "Plant_Leaves_Aspen"
    },
    {
      "x": -4,
      "y": 19,
      "z": 1,
      "name": "Rock_Stone"
    },
    {
      "x": -4,
      "y": 20,
      "z": 1,
      "name": "Rock_Stone"
    },
    {
      "x": -4,
      "y": 21,
      "z": 1,
      "name": "Rock_Stone"
    },
    {
      "x": -4,
      "y": 22,
      "z": 1,
      "name": "Rock_Stone"
    },
    {
      "x": -4,
      "y": 23,
      "z": 1,
      "name": "Rock_Stone"
    },
    {
      "x": -4,
      "y": 24,
      "z": 1,
      "name": "Rock_Stone"
    },
    {
      "x": -4,
      "y": 25,
      "z": 1,
      "name": "Rock_Stone"
    },
    {
      "x": -4,
      "y": 26,
      "z": 1,
      "name": "Rock_Stone"
    },
    {
      "x": -4,
      "y": 27,
      "z": 1,
      "name": "Rock_Stone"
    },
    {
      "x": -4,
      "y": 28,
      "z": 1,
      "name": "Rock_Stone"
    },
    {
      "x": -4,
      "y": 29,
      "z": 1,
      "name": "Rock_Stone"
    },
    {
      "x": -4,
      "y": 30,
      "z": 1,
      "name": "Rock_Stone"
    },
    {
      "x": -4,
      "y": 31,
      "z": 1,
      "name": "Soil_Dirt"
    },
    {
      "x": -4,
      "y": 32,
      "z": 1,
      "name": "Rock_Stone"
    },
    {
      "x": -4,
      "y": 33,
      "z": 1,
      "name": "Soil_Dirt"
    },
    {
      "x": -4,
      "y": 34,
      "z": 1,
      "name": "Rock_Stone"
    },
    {
      "x": -4,
      "y": 35,
      "z": 1,
      "name": "Rock_Stone"
    },
    {
      "x": -4,
      "y": 36,
      "z": 1,
      "name": "Rock_Stone"
    },
    {
      "x": -4,
      "y": 37,
      "z": 1,
      "name": "Rock_Stone"
    },
    {
      "x": -4,
      "y": 38,
      "z": 1,
      "name": "Rock_Stone"
    },
    {
      "x": -4,
      "y": 39,
      "z": 1,
      "name": "Rock_Stone"
    },
    {
      "x": -4,
      "y": 40,
      "z": 1,
      "name": "Soil_Dirt"
    },
    {
      "x": -4,
      "y": 41,
      "z": 1,
      "name": "Soil_Dirt"
    },
    {
      "x": -4,
      "y": 42,
      "z": 1,
      "name": "Soil_Dirt"
    },
    {
      "x": -4,
      "y": 43,
      "z": 1,
      "name": "Soil_Grass"
    },
    {
      "x": -4,
      "y": 51,
      "z": 1,
      "name": "Plant_Leaves_Aspen"
    },
    {
      "x": -4,
      "y": 52,
      "z": 1,
      "name": "Plant_Leaves_Aspen"
    },
    {
      "x": -4,
      "y": 53,
      "z": 1,
      "name": "Wood_Aspen_Branch_Corner",
      "rotation": 3
    },
    {
      "x": -4,
      "y": 54,
      "z": 1,
      "name": "Wood_Aspen_Branch_Long"
    },
    {
      "x": -4,
      "y": 55,
      "z": 1,
      "name": "Wood_Aspen_Branch_Long"
    },
    {
      "x": -4,
      "y": 57,
      "z": 1,
      "name": "Plant_Leaves_Aspen"
    },
    {
      "x": -4,
      "y": 58,
      "z": 1,
      "name": "Plant_Leaves_Aspen"
    },
    {
      "x": -4,
      "y": 59,
      "z": 1,
      "name": "Plant_Leaves_Aspen"
    },
    {
      "x": -4,
      "y": 20,
      "z": 2,
      "name": "Rock_Stone"
    },
    {
      "x": -4,
      "y": 21,
      "z": 2,
      "name": "Rock_Stone"
    },
    {
      "x": -4,
      "y": 22,
      "z": 2,
      "name": "Rock_Stone"
    },
    {
      "x": -4,
      "y": 23,
      "z": 2,
      "name": "Rock_Stone"
    },
    {
      "x": -4,
      "y": 24,
      "z": 2,
      "name": "Rock_Stone"
    },
    {
      "x": -4,
      "y": 25,
      "z": 2,
      "name": "Rock_Stone"
    },
    {
      "x": -4,
      "y": 26,
      "z": 2,
      "name": "Rock_Stone"
    },
    {
      "x": -4,
      "y": 27,
      "z": 2,
      "name": "Rock_Stone"
    },
    {
      "x": -4,
      "y": 28,
      "z": 2,
      "name": "Rock_Stone"
    },
    {
      "x": -4,
      "y": 29,
      "z": 2,
      "name": "Rock_Stone"
    },
    {
      "x": -4,
      "y": 30,
      "z": 2,
      "name": "Soil_Dirt"
    },
    {
      "x": -4,
      "y": 31,
      "z": 2,
      "name": "Soil_Dirt"
    },
    {
      "x": -4,
      "y": 32,
      "z": 2,
      "name": "Soil_Dirt"
    },
    {
      "x": -4,
      "y": 33,
      "z": 2,
      "name": "Soil_Dirt"
    },
    {
      "x": -4,
      "y": 34,
      "z": 2,
      "name": "Soil_Grass"
    },
    {
      "x": -4,
      "y": 35,
      "z": 2,
      "name": "Plant_Grass_Sharp"
    },
    {
      "x": -4,
      "y": 41,
      "z": 2,
      "name": "Soil_Dirt"
    },
    {
      "x": -4,
      "y": 42,
      "z": 2,
      "name": "Soil_Dirt"
    },
    {
      "x": -4,
      "y": 43,
      "z": 2,
      "name": "Soil_Grass"
    },
    {
      "x": -4,
      "y": 55,
      "z": 2,
      "name": "Plant_Leaves_Aspen"
    },
    {
      "x": -4,
      "y": 56,
      "z": 2,
      "name": "Plant_Leaves_Aspen"
    },
    {
      "x": -4,
      "y": 57,
      "z": 2,
      "name": "Plant_Leaves_Aspen"
    },
    {
      "x": -4,
      "y": 20,
      "z": 3,
      "name": "Rock_Stone"
    },
    {
      "x": -4,
      "y": 21,
      "z": 3,
      "name": "Rock_Stone"
    },
    {
      "x": -4,
      "y": 22,
      "z": 3,
      "name": "Rock_Stone"
    },
    {
      "x": -4,
      "y": 23,
      "z": 3,
      "name": "Rock_Stone"
    },
    {
      "x": -4,
      "y": 24,
      "z": 3,
      "name": "Rock_Stone"
    },
    {
      "x": -4,
      "y": 25,
      "z": 3,
      "name": "Rock_Stone"
    },
    {
      "x": -4,
      "y": 26,
      "z": 3,
      "name": "Rock_Stone"
    },
    {
      "x": -4,
      "y": 28,
      "z": 3,
      "name": "Rock_Stone"
    },
    {
      "x": -4,
      "y": 29,
      "z": 3,
      "name": "Rock_Stone"
    },
    {
      "x": -4,
      "y": 30,
      "z": 3,
      "name": "Soil_Dirt"
    },
    {
      "x": -4,
      "y": 31,
      "z": 3,
      "name": "Soil_Dirt"
    },
    {
      "x": -4,
      "y": 32,
      "z": 3,
      "name": "Soil_Dirt"
    },
    {
      "x": -4,
      "y": 33,
      "z": 3,
      "name": "Soil_Dirt"
    },
    {
      "x": -4,
      "y": 34,
      "z": 3,
      "name": "Soil_Grass"
    },
    {
      "x": -4,
      "y": 51,
      "z": 3,
      "name": "Plant_Leaves_Aspen"
    },
    {
      "x": -4,
      "y": 52,
      "z": 3,
      "name": "Plant_Leaves_Aspen"
    },
    {
      "x": -4,
      "y": 53,
      "z": 3,
      "name": "Plant_Leaves_Aspen"
    },
    {
      "x": -4,
      "y": 54,
      "z": 3,
      "name": "Plant_Leaves_Aspen"
    },
    {
      "x": -4,
      "y": 55,
      "z": 3,
      "name": "Plant_Leaves_Aspen"
    },
    {
      "x": -4,
      "y": 52,
      "z": 4,
      "name": "Plant_Leaves_Aspen"
    },
    {
      "x": -4,
      "y": 53,
      "z": 4,
      "name": "Plant_Leaves_Aspen"
    },
    {
      "x": -4,
      "y": 53,
      "z": 5,
      "name": "Plant_Leaves_Aspen"
    },
    {
      "x": -3,
      "y": 20,
      "z": -3,
      "name": "Rock_Stone"
    },
    {
      "x": -3,
      "y": 21,
      "z": -3,
      "name": "Rock_Stone"
    },
    {
      "x": -3,
      "y": 22,
      "z": -3,
      "name": "Rock_Stone"
    },
    {
      "x": -3,
      "y": 23,
      "z": -3,
      "name": "Rock_Stone"
    },
    {
      "x": -3,
      "y": 24,
      "z": -3,
      "name": "Rock_Stone"
    },
    {
      "x": -3,
      "y": 25,
      "z": -3,
      "name": "Rock_Stone"
    },
    {
      "x": -3,
      "y": 26,
      "z": -3,
      "name": "Rock_Stone"
    },
    {
      "x": -3,
      "y": 27,
      "z": -3,
      "name": "Rock_Stone"
    },
    {
      "x": -3,
      "y": 28,
      "z": -3,
      "name": "Rock_Stone"
    },
    {
      "x": -3,
      "y": 29,
      "z": -3,
      "name": "Rock_Stone"
    },
    {
      "x": -3,
      "y": 30,
      "z": -3,
      "name": "Rock_Stone"
    },
    {
      "x": -3,
      "y": 31,
      "z": -3,
      "name": "Rock_Stone"
    },
    {
      "x": -3,
      "y": 32,
      "z": -3,
      "name": "Rock_Stone"
    },
    {
      "x": -3,
      "y": 33,
      "z": -3,
      "name": "Rock_Stone"
    },
    {
      "x": -3,
      "y": 34,
      "z": -3,
      "name": "Rock_Stone"
    },
    {
      "x": -3,
      "y": 35,
      "z": -3,
      "name": "Rock_Stone_Mossy"
    },
    {
      "x": -3,
      "y": 36,
      "z": -3,
      "name": "Rock_Stone_Mossy"
    },
    {
      "x": -3,
      "y": 37,
      "z": -3,
      "name": "Rock_Stone_Mossy"
    },
    {
      "x": -3,
      "y": 38,
      "z": -3,
      "name": "Rock_Stone_Mossy"
    },
    {
      "x": -3,
      "y": 39,
      "z": -3,
      "name": "Soil_Dirt"
    },
    {
      "x": -3,
      "y": 40,
      "z": -3,
      "name": "Soil_Dirt"
    },
    {
      "x": -3,
      "y": 41,
      "z": -3,
      "name": "Soil_Dirt"
    },
    {
      "x": -3,
      "y": 42,
      "z": -3,
      "name": "Soil_Dirt"
    },
    {
      "x": -3,
      "y": 43,
      "z": -3,
      "name": "Soil_Grass"
    },
    {
      "x": -3,
      "y": 44,
      "z": -3,
      "name": "Plant_Grass_Sharp"
    },
    {
      "x": -3,
      "y": 53,
      "z": -3,
      "name": "Plant_Leaves_Aspen"
    },
    {
      "x": -3,
      "y": 54,
      "z": -3,
      "name": "Plant_Leaves_Aspen"
    },
    {
      "x": -3,
      "y": 18,
      "z": -2,
      "name": "Rock_Stone"
    },
    {
      "x": -3,
      "y": 19,
      "z": -2,
      "name": "Rock_Stone"
    },
    {
      "x": -3,
      "y": 20,
      "z": -2,
      "name": "Rock_Stone"
    },
    {
      "x": -3,
      "y": 21,
      "z": -2,
      "name": "Rock_Stone"
    },
    {
      "x": -3,
      "y": 22,
      "z": -2,
      "name": "Rock_Stone"
    },
    {
      "x": -3,
      "y": 23,
      "z": -2,
      "name": "Rock_Stone"
    },
    {
      "x": -3,
      "y": 24,
      "z": -2,
      "name": "Rock_Stone"
    },
    {
      "x": -3,
      "y": 25,
      "z": -2,
      "name": "Rock_Stone"
    },
    {
      "x": -3,
      "y": 26,
      "z": -2,
      "name": "Rock_Stone"
    },
    {
      "x": -3,
      "y": 27,
      "z": -2,
      "name": "Rock_Stone"
    },
    {
      "x": -3,
      "y": 28,
      "z": -2,
      "name": "Rock_Stone"
    },
    {
      "x": -3,
      "y": 29,
      "z": -2,
      "name": "Rock_Stone"
    },
    {
      "x": -3,
      "y": 30,
      "z": -2,
      "name": "Rock_Stone"
    },
    {
      "x": -3,
      "y": 31,
      "z": -2,
      "name": "Rock_Stone"
    },
    {
      "x": -3,
      "y": 32,
      "z": -2,
      "name": "Rock_Stone"
    },
    {
      "x": -3,
      "y": 33,
      "z": -2,
      "name": "Rock_Stone"
    },
    {
      "x": -3,
      "y": 34,
      "z": -2,
      "name": "Rock_Stone"
    },
    {
      "x": -3,
      "y": 35,
      "z": -2,
      "name": "Rock_Stone"
    },
    {
      "x": -3,
      "y": 36,
      "z": -2,
      "name": "Rock_Stone_Mossy"
    },
    {
      "x": -3,
      "y": 37,
      "z": -2,
      "name": "Rock_Stone"
    },
    {
      "x": -3,
      "y": 38,
      "z": -2,
      "name": "Rock_Stone"
    },
    {
      "x": -3,
      "y": 39,
      "z": -2,
      "name": "Soil_Dirt"
    },
    {
      "x": -3,
      "y": 40,
      "z": -2,
      "name": "Soil_Dirt"
    },
    {
      "x": -3,
      "y": 41,
      "z": -2,
      "name": "Soil_Dirt"
    },
    {
      "x": -3,
      "y": 42,
      "z": -2,
      "name": "Soil_Dirt"
    },
    {
      "x": -3,
      "y": 43,
      "z": -2,
      "name": "Rock_Stone"
    },
    {
      "x": -3,
      "y": 44,
      "z": -2,
      "name": "Rock_Stone"
    },
    {
      "x": -3,
      "y": 45,
      "z": -2,
      "name": "Soil_Dirt"
    },
    {
      "x": -3,
      "y": 46,
      "z": -2,
      "name": "Soil_Dirt"
    },
    {
      "x": -3,
      "y": 47,
      "z": -2,
      "name": "Soil_Grass"
    },
    {
      "x": -3,
      "y": 52,
      "z": -2,
      "name": "Plant_Leaves_Aspen"
    },
    {
      "x": -3,
      "y": 53,
      "z": -2,
      "name": "Plant_Leaves_Aspen"
    },
    {
      "x": -3,
      "y": 56,
      "z": -2,
      "name": "Plant_Leaves_Aspen"
    },
    {
      "x": -3,
      "y": 18,
      "z": -1,
      "name": "Rock_Stone"
    },
    {
      "x": -3,
      "y": 19,
      "z": -1,
      "name": "Rock_Stone"
    },
    {
      "x": -3,
      "y": 20,
      "z": -1,
      "name": "Rock_Stone"
    },
    {
      "x": -3,
      "y": 21,
      "z": -1,
      "name": "Rock_Stone"
    },
    {
      "x": -3,
      "y": 22,
      "z": -1,
      "name": "Rock_Stone"
    },
    {
      "x": -3,
      "y": 23,
      "z": -1,
      "name": "Rock_Stone"
    },
    {
      "x": -3,
      "y": 24,
      "z": -1,
      "name": "Rock_Stone"
    },
    {
      "x": -3,
      "y": 25,
      "z": -1,
      "name": "Rock_Stone"
    },
    {
      "x": -3,
      "y": 26,
      "z": -1,
      "name": "Rock_Stone"
    },
    {
      "x": -3,
      "y": 27,
      "z": -1,
      "name": "Rock_Stone"
    },
    {
      "x": -3,
      "y": 28,
      "z": -1,
      "name": "Rock_Stone"
    },
    {
      "x": -3,
      "y": 29,
      "z": -1,
      "name": "Rock_Stone"
    },
    {
      "x": -3,
      "y": 30,
      "z": -1,
      "name": "Rock_Stone"
    },
    {
      "x": -3,
      "y": 31,
      "z": -1,
      "name": "Rock_Stone"
    },
    {
      "x": -3,
      "y": 32,
      "z": -1,
      "name": "Rock_Stone"
    },
    {
      "x": -3,
      "y": 33,
      "z": -1,
      "name": "Rock_Stone"
    },
    {
      "x": -3,
      "y": 34,
      "z": -1,
      "name": "Rock_Stone"
    },
    {
      "x": -3,
      "y": 35,
      "z": -1,
      "name": "Rock_Stone"
    },
    {
      "x": -3,
      "y": 36,
      "z": -1,
      "name": "Rock_Stone"
    },
    {
      "x": -3,
      "y": 37,
      "z": -1,
      "name": "Rock_Stone"
    },
    {
      "x": -3,
      "y": 38,
      "z": -1,
      "name": "Rock_Stone"
    },
    {
      "x": -3,
      "y": 39,
      "z": -1,
      "name": "Rock_Stone"
    },
    {
      "x": -3,
      "y": 40,
      "z": -1,
      "name": "Soil_Dirt"
    },
    {
      "x": -3,
      "y": 41,
      "z": -1,
      "name": "Soil_Dirt"
    },
    {
      "x": -3,
      "y": 42,
      "z": -1,
      "name": "Rock_Stone"
    },
    {
      "x": -3,
      "y": 43,
      "z": -1,
      "name": "Rock_Stone"
    },
    {
      "x": -3,
      "y": 44,
      "z": -1,
      "name": "Soil_Dirt"
    },
    {
      "x": -3,
      "y": 45,
      "z": -1,
      "name": "Soil_Dirt"
    },
    {
      "x": -3,
      "y": 46,
      "z": -1,
      "name": "Soil_Dirt"
    },
    {
      "x": -3,
      "y": 47,
      "z": -1,
      "name": "Soil_Grass"
    },
    {
      "x": -3,
      "y": 57,
      "z": -1,
      "name": "Plant_Leaves_Aspen"
    },
    {
      "x": -3,
      "y": 18,
      "z": 0,
      "name": "Rock_Stone"
    },
    {
      "x": -3,
      "y": 19,
      "z": 0,
      "name": "Rock_Stone"
    },
    {
      "x": -3,
      "y": 20,
      "z": 0,
      "name": "Rock_Stone"
    },
    {
      "x": -3,
      "y": 21,
      "z": 0,
      "name": "Rock_Stone"
    },
    {
      "x": -3,
      "y": 22,
      "z": 0,
      "name": "Rock_Stone"
    },
    {
      "x": -3,
      "y": 23,
      "z": 0,
      "name": "Rock_Stone"
    },
    {
      "x": -3,
      "y": 24,
      "z": 0,
      "name": "Rock_Stone"
    },
    {
      "x": -3,
      "y": 25,
      "z": 0,
      "name": "Rock_Stone"
    },
    {
      "x": -3,
      "y": 26,
      "z": 0,
      "name": "Rock_Stone"
    },
    {
      "x": -3,
      "y": 27,
      "z": 0,
      "name": "Rock_Stone"
    },
    {
      "x": -3,
      "y": 28,
      "z": 0,
      "name": "Rock_Stone"
    },
    {
      "x": -3,
      "y": 29,
      "z": 0,
      "name": "Rock_Stone"
    },
    {
      "x": -3,
      "y": 30,
      "z": 0,
      "name": "Rock_Stone"
    },
    {
      "x": -3,
      "y": 31,
      "z": 0,
      "name": "Rock_Stone"
    },
    {
      "x": -3,
      "y": 32,
      "z": 0,
      "name": "Rock_Stone"
    },
    {
      "x": -3,
      "y": 33,
      "z": 0,
      "name": "Rock_Stone"
    },
    {
      "x": -3,
      "y": 34,
      "z": 0,
      "name": "Rock_Stone"
    },
    {
      "x": -3,
      "y": 35,
      "z": 0,
      "name": "Rock_Stone"
    },
    {
      "x": -3,
      "y": 36,
      "z": 0,
      "name": "Rock_Stone"
    },
    {
      "x": -3,
      "y": 37,
      "z": 0,
      "name": "Rock_Stone"
    },
    {
      "x": -3,
      "y": 38,
      "z": 0,
      "name": "Rock_Stone"
    },
    {
      "x": -3,
      "y": 39,
      "z": 0,
      "name": "Rock_Stone"
    },
    {
      "x": -3,
      "y": 40,
      "z": 0,
      "name": "Rock_Stone"
    },
    {
      "x": -3,
      "y": 41,
      "z": 0,
      "name": "Soil_Dirt"
    },
    {
      "x": -3,
      "y": 42,
      "z": 0,
      "name": "Rock_Stone"
    },
    {
      "x": -3,
      "y": 43,
      "z": 0,
      "name": "Rock_Stone"
    },
    {
      "x": -3,
      "y": 44,
      "z": 0,
      "name": "Soil_Dirt"
    },
    {
      "x": -3,
      "y": 45,
      "z": 0,
      "name": "Soil_Dirt"
    },
    {
      "x": -3,
      "y": 46,
      "z": 0,
      "name": "Soil_Dirt"
    },
    {
      "x": -3,
      "y": 47,
      "z": 0,
      "name": "Soil_Grass"
    },
    {
      "x": -3,
      "y": 53,
      "z": 0,
      "name": "Wood_Aspen_Branch_Corner",
      "rotation": 2
    },
    {
      "x": -3,
      "y": 54,
      "z": 0,
      "name": "Wood_Aspen_Branch_Long"
    },
    {
      "x": -3,
      "y": 55,
      "z": 0,
      "name": "Wood_Aspen_Branch_Long"
    },
    {
      "x": -3,
      "y": 56,
      "z": 0,
      "name": "Plant_Leaves_Aspen"
    },
    {
      "x": -3,
      "y": 57,
      "z": 0,
      "name": "Plant_Leaves_Aspen"
    },
    {
      "x": -3,
      "y": 58,
      "z": 0,
      "name": "Plant_Leaves_Aspen"
    },
    {
      "x": -3,
      "y": 59,
      "z": 0,
      "name": "Plant_Leaves_Aspen"
    },
    {
      "x": -3,
      "y": 19,
      "z": 1,
      "name": "Rock_Stone"
    },
    {
      "x": -3,
      "y": 20,
      "z": 1,
      "name": "Rock_Stone"
    },
    {
      "x": -3,
      "y": 21,
      "z": 1,
      "name": "Rock_Stone"
    },
    {
      "x": -3,
      "y": 22,
      "z": 1,
      "name": "Rock_Stone"
    },
    {
      "x": -3,
      "y": 23,
      "z": 1,
      "name": "Rock_Stone"
    },
    {
      "x": -3,
      "y": 24,
      "z": 1,
      "name": "Rock_Stone"
    },
    {
      "x": -3,
      "y": 25,
      "z": 1,
      "name": "Rock_Stone"
    },
    {
      "x": -3,
      "y": 26,
      "z": 1,
      "name": "Rock_Stone"
    },
    {
      "x": -3,
      "y": 27,
      "z": 1,
      "name": "Rock_Stone"
    },
    {
      "x": -3,
      "y": 28,
      "z": 1,
      "name": "Rock_Stone"
    },
    {
      "x": -3,
      "y": 29,
      "z": 1,
      "name": "Rock_Stone"
    },
    {
      "x": -3,
      "y": 30,
      "z": 1,
      "name": "Rock_Stone"
    },
    {
      "x": -3,
      "y": 31,
      "z": 1,
      "name": "Rock_Stone"
    },
    {
      "x": -3,
      "y": 32,
      "z": 1,
      "name": "Soil_Dirt"
    },
    {
      "x": -3,
      "y": 33,
      "z": 1,
      "name": "Rock_Stone"
    },
    {
      "x": -3,
      "y": 34,
      "z": 1,
      "name": "Rock_Stone"
    },
    {
      "x": -3,
      "y": 35,
      "z": 1,
      "name": "Rock_Stone"
    },
    {
      "x": -3,
      "y": 36,
      "z": 1,
      "name": "Rock_Stone"
    },
    {
      "x": -3,
      "y": 37,
      "z": 1,
      "name": "Rock_Stone"
    },
    {
      "x": -3,
      "y": 38,
      "z": 1,
      "name": "Rock_Stone"
    },
    {
      "x": -3,
      "y": 39,
      "z": 1,
      "name": "Rock_Stone"
    },
    {
      "x": -3,
      "y": 40,
      "z": 1,
      "name": "Soil_Dirt"
    },
    {
      "x": -3,
      "y": 41,
      "z": 1,
      "name": "Soil_Dirt"
    },
    {
      "x": -3,
      "y": 42,
      "z": 1,
      "name": "Soil_Dirt"
    },
    {
      "x": -3,
      "y": 43,
      "z": 1,
      "name": "Rock_Stone"
    },
    {
      "x": -3,
      "y": 44,
      "z": 1,
      "name": "Soil_Dirt"
    },
    {
      "x": -3,
      "y": 45,
      "z": 1,
      "name": "Soil_Dirt"
    },
    {
      "x": -3,
      "y": 46,
      "z": 1,
      "name": "Soil_Dirt"
    },
    {
      "x": -3,
      "y": 47,
      "z": 1,
      "name": "Soil_Grass"
    },
    {
      "x": -3,
      "y": 53,
      "z": 1,
      "name": "Wood_Aspen_Trunk_Full"
    },
    {
      "x": -3,
      "y": 54,
      "z": 1,
      "name": "Wood_Aspen_Branch_Long"
    },
    {
      "x": -3,
      "y": 55,
      "z": 1,
      "name": "Wood_Aspen_Branch_Long"
    },
    {
      "x": -3,
      "y": 56,
      "z": 1,
      "name": "Wood_Aspen_Branch_Long"
    },
    {
      "x": -3,
      "y": 57,
      "z": 1,
      "name": "Wood_Aspen_Branch_Long"
    },
    {
      "x": -3,
      "y": 58,
      "z": 1,
      "name": "Plant_Leaves_Aspen"
    },
    {
      "x": -3,
      "y": 59,
      "z": 1,
      "name": "Plant_Leaves_Aspen"
    },
    {
      "x": -3,
      "y": 60,
      "z": 1,
      "name": "Plant_Leaves_Aspen"
    },
    {
      "x": -3,
      "y": 61,
      "z": 1,
      "name": "Plant_Leaves_Aspen"
    },
    {
      "x": -3,
      "y": 19,
      "z": 2,
      "name": "Rock_Stone"
    },
    {
      "x": -3,
      "y": 20,
      "z": 2,
      "name": "Rock_Stone"
    },
    {
      "x": -3,
      "y": 21,
      "z": 2,
      "name": "Rock_Stone"
    },
    {
      "x": -3,
      "y": 22,
      "z": 2,
      "name": "Rock_Stone"
    },
    {
      "x": -3,
      "y": 23,
      "z": 2,
      "name": "Rock_Stone"
    },
    {
      "x": -3,
      "y": 24,
      "z": 2,
      "name": "Rock_Stone"
    },
    {
      "x": -3,
      "y": 25,
      "z": 2,
      "name": "Rock_Stone"
    },
    {
      "x": -3,
      "y": 26,
      "z": 2,
      "name": "Rock_Stone"
    },
    {
      "x": -3,
      "y": 27,
      "z": 2,
      "name": "Rock_Stone"
    },
    {
      "x": -3,
      "y": 28,
      "z": 2,
      "name": "Rock_Stone"
    },
    {
      "x": -3,
      "y": 29,
      "z": 2,
      "name": "Rock_Stone"
    },
    {
      "x": -3,
      "y": 30,
      "z": 2,
      "name": "Rock_Stone"
    },
    {
      "x": -3,
      "y": 31,
      "z": 2,
      "name": "Soil_Dirt"
    },
    {
      "x": -3,
      "y": 32,
      "z": 2,
      "name": "Soil_Dirt"
    },
    {
      "x": -3,
      "y": 33,
      "z": 2,
      "name": "Soil_Dirt"
    },
    {
      "x": -3,
      "y": 34,
      "z": 2,
      "name": "Rock_Stone"
    },
    {
      "x": -3,
      "y": 35,
      "z": 2,
      "name": "Soil_Grass"
    },
    {
      "x": -3,
      "y": 38,
      "z": 2,
      "name": "Rock_Stone"
    },
    {
      "x": -3,
      "y": 39,
      "z": 2,
      "name": "Rock_Stone"
    },
    {
      "x": -3,
      "y": 40,
      "z": 2,
      "name": "Soil_Dirt"
    },
    {
      "x": -3,
      "y": 41,
      "z": 2,
      "name": "Soil_Dirt"
    },
    {
      "x": -3,
      "y": 42,
      "z": 2,
      "name": "Soil_Dirt"
    },
    {
      "x": -3,
      "y": 43,
      "z": 2,
      "name": "Soil_Dirt"
    },
    {
      "x": -3,
      "y": 44,
      "z": 2,
      "name": "Soil_Grass"
    },
    {
      "x": -3,
      "y": 58,
      "z": 2,
      "name": "Plant_Leaves_Aspen"
    },
    {
      "x": -3,
      "y": 59,
      "z": 2,
      "name": "Plant_Leaves_Aspen"
    },
    {
      "x": -3,
      "y": 60,
      "z": 2,
      "name": "Plant_Leaves_Aspen"
    },
    {
      "x": -3,
      "y": 19,
      "z": 3,
      "name": "Rock_Stone"
    },
    {
      "x": -3,
      "y": 20,
      "z": 3,
      "name": "Rock_Stone"
    },
    {
      "x": -3,
      "y": 21,
      "z": 3,
      "name": "Rock_Stone"
    },
    {
      "x": -3,
      "y": 22,
      "z": 3,
      "name": "Rock_Stone"
    },
    {
      "x": -3,
      "y": 23,
      "z": 3,
      "name": "Rock_Stone"
    },
    {
      "x": -3,
      "y": 24,
      "z": 3,
      "name": "Rock_Stone"
    },
    {
      "x": -3,
      "y": 25,
      "z": 3,
      "name": "Rock_Stone"
    },
    {
      "x": -3,
      "y": 26,
      "z": 3,
      "name": "Rock_Stone"
    },
    {
      "x": -3,
      "y": 28,
      "z": 3,
      "name": "Rock_Stone"
    },
    {
      "x": -3,
      "y": 29,
      "z": 3,
      "name": "Rock_Stone_Mossy"
    },
    {
      "x": -3,
      "y": 30,
      "z": 3,
      "name": "Rock_Stone"
    },
    {
      "x": -3,
      "y": 31,
      "z": 3,
      "name": "Soil_Dirt"
    },
    {
      "x": -3,
      "y": 32,
      "z": 3,
      "name": "Soil_Dirt"
    },
    {
      "x": -3,
      "y": 33,
      "z": 3,
      "name": "Soil_Dirt"
    },
    {
      "x": -3,
      "y": 34,
      "z": 3,
      "name": "Soil_Grass"
    },
    {
      "x": -3,
      "y": 42,
      "z": 3,
      "name": "Soil_Dirt"
    },
    {
      "x": -3,
      "y": 43,
      "z": 3,
      "name": "Soil_Dirt"
    },
    {
      "x": -3,
      "y": 44,
      "z": 3,
      "name": "Soil_Grass"
    },
    {
      "x": -3,
      "y": 53,
      "z": 4,
      "name": "Plant_Leaves_Aspen"
    },
    {
      "x": -3,
      "y": 54,
      "z": 4,
      "name": "Plant_Leaves_Aspen"
    },
    {
      "x": -3,
      "y": 55,
      "z": 4,
      "name": "Plant_Leaves_Aspen"
    },
    {
      "x": -3,
      "y": 56,
      "z": 4,
      "name": "Plant_Leaves_Aspen"
    },
    {
      "x": -2,
      "y": 33,
      "z": -5,
      "name": "Soil_Dirt"
    },
    {
      "x": -2,
      "y": 34,
      "z": -5,
      "name": "Soil_Dirt"
    },
    {
      "x": -2,
      "y": 35,
      "z": -5,
      "name": "Soil_Grass"
    },
    {
      "x": -2,
      "y": 25,
      "z": -4,
      "name": "Rock_Stone"
    },
    {
      "x": -2,
      "y": 26,
      "z": -4,
      "name": "Rock_Stone"
    },
    {
      "x": -2,
      "y": 27,
      "z": -4,
      "name": "Rock_Stone"
    },
    {
      "x": -2,
      "y": 28,
      "z": -4,
      "name": "Rock_Stone"
    },
    {
      "x": -2,
      "y": 29,
      "z": -4,
      "name": "Rock_Stone"
    },
    {
      "x": -2,
      "y": 30,
      "z": -4,
      "name": "Rock_Stone"
    },
    {
      "x": -2,
      "y": 31,
      "z": -4,
      "name": "Rock_Stone"
    },
    {
      "x": -2,
      "y": 32,
      "z": -4,
      "name": "Soil_Dirt"
    },
    {
      "x": -2,
      "y": 33,
      "z": -4,
      "name": "Soil_Dirt"
    },
    {
      "x": -2,
      "y": 34,
      "z": -4,
      "name": "Soil_Dirt"
    },
    {
      "x": -2,
      "y": 35,
      "z": -4,
      "name": "Soil_Grass"
    },
    {
      "x": -2,
      "y": 53,
      "z": -4,
      "name": "Plant_Leaves_Aspen"
    },
    {
      "x": -2,
      "y": 20,
      "z": -3,
      "name": "Rock_Stone"
    },
    {
      "x": -2,
      "y": 21,
      "z": -3,
      "name": "Rock_Stone"
    },
    {
      "x": -2,
      "y": 22,
      "z": -3,
      "name": "Rock_Stone"
    },
    {
      "x": -2,
      "y": 23,
      "z": -3,
      "name": "Rock_Stone"
    },
    {
      "x": -2,
      "y": 24,
      "z": -3,
      "name": "Rock_Stone"
    },
    {
      "x": -2,
      "y": 25,
      "z": -3,
      "name": "Rock_Stone"
    },
    {
      "x": -2,
      "y": 26,
      "z": -3,
      "name": "Rock_Stone"
    },
    {
      "x": -2,
      "y": 27,
      "z": -3,
      "name": "Rock_Stone"
    },
    {
      "x": -2,
      "y": 28,
      "z": -3,
      "name": "Rock_Stone"
    },
    {
      "x": -2,
      "y": 29,
      "z": -3,
      "name": "Rock_Stone"
    },
    {
      "x": -2,
      "y": 30,
      "z": -3,
      "name": "Rock_Stone"
    },
    {
      "x": -2,
      "y": 31,
      "z": -3,
      "name": "Rock_Stone"
    },
    {
      "x": -2,
      "y": 32,
      "z": -3,
      "name": "Rock_Stone"
    },
    {
      "x": -2,
      "y": 33,
      "z": -3,
      "name": "Soil_Dirt"
    },
    {
      "x": -2,
      "y": 34,
      "z": -3,
      "name": "Rock_Stone"
    },
    {
      "x": -2,
      "y": 35,
      "z": -3,
      "name": "Rock_Stone"
    },
    {
      "x": -2,
      "y": 36,
      "z": -3,
      "name": "Rock_Stone_Mossy"
    },
    {
      "x": -2,
      "y": 37,
      "z": -3,
      "name": "Rock_Stone"
    },
    {
      "x": -2,
      "y": 38,
      "z": -3,
      "name": "Soil_Dirt"
    },
    {
      "x": -2,
      "y": 39,
      "z": -3,
      "name": "Soil_Dirt"
    },
    {
      "x": -2,
      "y": 40,
      "z": -3,
      "name": "Soil_Dirt"
    },
    {
      "x": -2,
      "y": 41,
      "z": -3,
      "name": "Soil_Dirt"
    },
    {
      "x": -2,
      "y": 42,
      "z": -3,
      "name": "Soil_Grass"
    },
    {
      "x": -2,
      "y": 53,
      "z": -3,
      "name": "Plant_Leaves_Aspen"
    },
    {
      "x": -2,
      "y": 55,
      "z": -3,
      "name": "Plant_Leaves_Aspen"
    },
    {
      "x": -2,
      "y": 18,
      "z": -2,
      "name": "Rock_Stone"
    },
    {
      "x": -2,
      "y": 19,
      "z": -2,
      "name": "Rock_Stone"
    },
    {
      "x": -2,
      "y": 20,
      "z": -2,
      "name": "Rock_Stone"
    },
    {
      "x": -2,
      "y": 21,
      "z": -2,
      "name": "Rock_Stone"
    },
    {
      "x": -2,
      "y": 22,
      "z": -2,
      "name": "Rock_Stone"
    },
    {
      "x": -2,
      "y": 23,
      "z": -2,
      "name": "Rock_Stone"
    },
    {
      "x": -2,
      "y": 24,
      "z": -2,
      "name": "Rock_Stone"
    },
    {
      "x": -2,
      "y": 25,
      "z": -2,
      "name": "Rock_Stone"
    },
    {
      "x": -2,
      "y": 26,
      "z": -2,
      "name": "Rock_Stone"
    },
    {
      "x": -2,
      "y": 27,
      "z": -2,
      "name": "Rock_Stone"
    },
    {
      "x": -2,
      "y": 28,
      "z": -2,
      "name": "Rock_Stone"
    },
    {
      "x": -2,
      "y": 29,
      "z": -2,
      "name": "Rock_Stone"
    },
    {
      "x": -2,
      "y": 30,
      "z": -2,
      "name": "Rock_Stone"
    },
    {
      "x": -2,
      "y": 31,
      "z": -2,
      "name": "Rock_Stone"
    },
    {
      "x": -2,
      "y": 32,
      "z": -2,
      "name": "Rock_Stone"
    },
    {
      "x": -2,
      "y": 33,
      "z": -2,
      "name": "Rock_Stone"
    },
    {
      "x": -2,
      "y": 34,
      "z": -2,
      "name": "Rock_Stone"
    },
    {
      "x": -2,
      "y": 35,
      "z": -2,
      "name": "Rock_Stone"
    },
    {
      "x": -2,
      "y": 36,
      "z": -2,
      "name": "Rock_Stone"
    },
    {
      "x": -2,
      "y": 37,
      "z": -2,
      "name": "Rock_Stone"
    },
    {
      "x": -2,
      "y": 38,
      "z": -2,
      "name": "Soil_Dirt"
    },
    {
      "x": -2,
      "y": 39,
      "z": -2,
      "name": "Soil_Dirt"
    },
    {
      "x": -2,
      "y": 40,
      "z": -2,
      "name": "Soil_Dirt"
    },
    {
      "x": -2,
      "y": 41,
      "z": -2,
      "name": "Soil_Dirt"
    },
    {
      "x": -2,
      "y": 42,
      "z": -2,
      "name": "Rock_Stone"
    },
    {
      "x": -2,
      "y": 43,
      "z": -2,
      "name": "Soil_Dirt"
    },
    {
      "x": -2,
      "y": 44,
      "z": -2,
      "name": "Soil_Dirt"
    },
    {
      "x": -2,
      "y": 45,
      "z": -2,
      "name": "Soil_Dirt"
    },
    {
      "x": -2,
      "y": 46,
      "z": -2,
      "name": "Soil_Dirt"
    },
    {
      "x": -2,
      "y": 47,
      "z": -2,
      "name": "Soil_Grass"
    },
    {
      "x": -2,
      "y": 55,
      "z": -2,
      "name": "Plant_Leaves_Aspen"
    },
    {
      "x": -2,
      "y": 56,
      "z": -2,
      "name": "Plant_Leaves_Aspen"
    },
    {
      "x": -2,
      "y": 57,
      "z": -2,
      "name": "Plant_Leaves_Aspen"
    },
    {
      "x": -2,
      "y": 58,
      "z": -2,
      "name": "Plant_Leaves_Aspen"
    },
    {
      "x": -2,
      "y": 17,
      "z": -1,
      "name": "Rock_Stone"
    },
    {
      "x": -2,
      "y": 18,
      "z": -1,
      "name": "Rock_Stone"
    },
    {
      "x": -2,
      "y": 19,
      "z": -1,
      "name": "Rock_Stone"
    },
    {
      "x": -2,
      "y": 20,
      "z": -1,
      "name": "Rock_Stone"
    },
    {
      "x": -2,
      "y": 21,
      "z": -1,
      "name": "Rock_Stone"
    },
    {
      "x": -2,
      "y": 22,
      "z": -1,
      "name": "Rock_Stone"
    },
    {
      "x": -2,
      "y": 23,
      "z": -1,
      "name": "Rock_Stone"
    },
    {
      "x": -2,
      "y": 24,
      "z": -1,
      "name": "Rock_Stone"
    },
    {
      "x": -2,
      "y": 25,
      "z": -1,
      "name": "Rock_Stone"
    },
    {
      "x": -2,
      "y": 26,
      "z": -1,
      "name": "Rock_Stone"
    },
    {
      "x": -2,
      "y": 27,
      "z": -1,
      "name": "Rock_Stone"
    },
    {
      "x": -2,
      "y": 28,
      "z": -1,
      "name": "Rock_Stone"
    },
    {
      "x": -2,
      "y": 29,
      "z": -1,
      "name": "Rock_Stone"
    },
    {
      "x": -2,
      "y": 30,
      "z": -1,
      "name": "Rock_Stone"
    },
    {
      "x": -2,
      "y": 31,
      "z": -1,
      "name": "Rock_Stone"
    },
    {
      "x": -2,
      "y": 32,
      "z": -1,
      "name": "Rock_Stone"
    },
    {
      "x": -2,
      "y": 33,
      "z": -1,
      "name": "Rock_Stone"
    },
    {
      "x": -2,
      "y": 34,
      "z": -1,
      "name": "Rock_Stone"
    },
    {
      "x": -2,
      "y": 35,
      "z": -1,
      "name": "Rock_Stone"
    },
    {
      "x": -2,
      "y": 36,
      "z": -1,
      "name": "Rock_Stone"
    },
    {
      "x": -2,
      "y": 37,
      "z": -1,
      "name": "Rock_Stone"
    },
    {
      "x": -2,
      "y": 38,
      "z": -1,
      "name": "Rock_Stone"
    },
    {
      "x": -2,
      "y": 39,
      "z": -1,
      "name": "Soil_Dirt"
    },
    {
      "x": -2,
      "y": 40,
      "z": -1,
      "name": "Soil_Dirt"
    },
    {
      "x": -2,
      "y": 41,
      "z": -1,
      "name": "Rock_Stone"
    },
    {
      "x": -2,
      "y": 42,
      "z": -1,
      "name": "Rock_Stone"
    },
    {
      "x": -2,
      "y": 43,
      "z": -1,
      "name": "Soil_Dirt"
    },
    {
      "x": -2,
      "y": 44,
      "z": -1,
      "name": "Soil_Dirt"
    },
    {
      "x": -2,
      "y": 45,
      "z": -1,
      "name": "Soil_Dirt"
    },
    {
      "x": -2,
      "y": 46,
      "z": -1,
      "name": "Soil_Dirt"
    },
    {
      "x": -2,
      "y": 47,
      "z": -1,
      "name": "Soil_Grass"
    },
    {
      "x": -2,
      "y": 59,
      "z": -1,
      "name": "Plant_Leaves_Aspen"
    },
    {
      "x": -2,
      "y": 60,
      "z": -1,
      "name": "Plant_Leaves_Aspen"
    },
    {
      "x": -2,
      "y": 17,
      "z": 0,
      "name": "Rock_Stone"
    },
    {
      "x": -2,
      "y": 18,
      "z": 0,
      "name": "Rock_Stone"
    },
    {
      "x": -2,
      "y": 19,
      "z": 0,
      "name": "Rock_Stone"
    },
    {
      "x": -2,
      "y": 20,
      "z": 0,
      "name": "Rock_Stone"
    },
    {
      "x": -2,
      "y": 21,
      "z": 0,
      "name": "Rock_Stone"
    },
    {
      "x": -2,
      "y": 22,
      "z": 0,
      "name": "Rock_Stone"
    },
    {
      "x": -2,
      "y": 23,
      "z": 0,
      "name": "Rock_Stone"
    },
    {
      "x": -2,
      "y": 24,
      "z": 0,
      "name": "Rock_Stone"
    },
    {
      "x": -2,
      "y": 25,
      "z": 0,
      "name": "Rock_Stone"
    },
    {
      "x": -2,
      "y": 26,
      "z": 0,
      "name": "Rock_Stone"
    },
    {
      "x": -2,
      "y": 27,
      "z": 0,
      "name": "Rock_Stone_Mossy"
    },
    {
      "x": -2,
      "y": 28,
      "z": 0,
      "name": "Rock_Stone"
    },
    {
      "x": -2,
      "y": 29,
      "z": 0,
      "name": "Rock_Stone"
    },
    {
      "x": -2,
      "y": 30,
      "z": 0,
      "name": "Rock_Stone"
    },
    {
      "x": -2,
      "y": 31,
      "z": 0,
      "name": "Rock_Stone"
    },
    {
      "x": -2,
      "y": 32,
      "z": 0,
      "name": "Rock_Stone"
    },
    {
      "x": -2,
      "y": 33,
      "z": 0,
      "name": "Rock_Stone"
    },
    {
      "x": -2,
      "y": 34,
      "z": 0,
      "name": "Rock_Stone"
    },
    {
      "x": -2,
      "y": 35,
      "z": 0,
      "name": "Rock_Stone"
    },
    {
      "x": -2,
      "y": 36,
      "z": 0,
      "name": "Rock_Stone"
    },
    {
      "x": -2,
      "y": 37,
      "z": 0,
      "name": "Rock_Stone"
    },
    {
      "x": -2,
      "y": 38,
      "z": 0,
      "name": "Rock_Stone"
    },
    {
      "x": -2,
      "y": 39,
      "z": 0,
      "name": "Rock_Stone"
    },
    {
      "x": -2,
      "y": 40,
      "z": 0,
      "name": "Rock_Stone"
    },
    {
      "x": -2,
      "y": 41,
      "z": 0,
      "name": "Rock_Stone"
    },
    {
      "x": -2,
      "y": 42,
      "z": 0,
      "name": "Rock_Stone"
    },
    {
      "x": -2,
      "y": 43,
      "z": 0,
      "name": "Soil_Dirt"
    },
    {
      "x": -2,
      "y": 44,
      "z": 0,
      "name": "Rock_Stone"
    },
    {
      "x": -2,
      "y": 45,
      "z": 0,
      "name": "Soil_Dirt"
    },
    {
      "x": -2,
      "y": 46,
      "z": 0,
      "name": "Soil_Dirt"
    },
    {
      "x": -2,
      "y": 47,
      "z": 0,
      "name": "Soil_Grass"
    },
    {
      "x": -2,
      "y": 56,
      "z": 0,
      "name": "Wood_Aspen_Branch_Corner",
      "rotation": 3
    },
    {
      "x": -2,
      "y": 57,
      "z": 0,
      "name": "Wood_Aspen_Branch_Long"
    },
    {
      "x": -2,
      "y": 58,
      "z": 0,
      "name": "Wood_Aspen_Branch_Long"
    },
    {
      "x": -2,
      "y": 61,
      "z": 0,
      "name": "Plant_Leaves_Aspen"
    },
    {
      "x": -2,
      "y": 17,
      "z": 1,
      "name": "Rock_Stone"
    },
    {
      "x": -2,
      "y": 18,
      "z": 1,
      "name": "Rock_Stone"
    },
    {
      "x": -2,
      "y": 19,
      "z": 1,
      "name": "Rock_Stone"
    },
    {
      "x": -2,
      "y": 20,
      "z": 1,
      "name": "Rock_Stone"
    },
    {
      "x": -2,
      "y": 21,
      "z": 1,
      "name": "Rock_Stone"
    },
    {
      "x": -2,
      "y": 22,
      "z": 1,
      "name": "Rock_Stone"
    },
    {
      "x": -2,
      "y": 23,
      "z": 1,
      "name": "Rock_Stone"
    },
    {
      "x": -2,
      "y": 24,
      "z": 1,
      "name": "Rock_Stone"
    },
    {
      "x": -2,
      "y": 25,
      "z": 1,
      "name": "Rock_Stone"
    },
    {
      "x": -2,
      "y": 26,
      "z": 1,
      "name": "Rock_Stone"
    },
    {
      "x": -2,
      "y": 27,
      "z": 1,
      "name": "Rock_Stone_Mossy"
    },
    {
      "x": -2,
      "y": 28,
      "z": 1,
      "name": "Rock_Stone"
    },
    {
      "x": -2,
      "y": 29,
      "z": 1,
      "name": "Rock_Stone"
    },
    {
      "x": -2,
      "y": 30,
      "z": 1,
      "name": "Rock_Stone"
    },
    {
      "x": -2,
      "y": 31,
      "z": 1,
      "name": "Rock_Stone"
    },
    {
      "x": -2,
      "y": 32,
      "z": 1,
      "name": "Soil_Dirt"
    },
    {
      "x": -2,
      "y": 33,
      "z": 1,
      "name": "Rock_Stone"
    },
    {
      "x": -2,
      "y": 34,
      "z": 1,
      "name": "Rock_Stone"
    },
    {
      "x": -2,
      "y": 35,
      "z": 1,
      "name": "Rock_Stone"
    },
    {
      "x": -2,
      "y": 36,
      "z": 1,
      "name": "Rock_Stone"
    },
    {
      "x": -2,
      "y": 37,
      "z": 1,
      "name": "Rock_Stone"
    },
    {
      "x": -2,
      "y": 38,
      "z": 1,
      "name": "Rock_Stone"
    },
    {
      "x": -2,
      "y": 39,
      "z": 1,
      "name": "Rock_Stone"
    },
    {
      "x": -2,
      "y": 40,
      "z": 1,
      "name": "Rock_Stone"
    },
    {
      "x": -2,
      "y": 41,
      "z": 1,
      "name": "Soil_Dirt"
    },
    {
      "x": -2,
      "y": 42,
      "z": 1,
      "name": "Soil_Dirt"
    },
    {
      "x": -2,
      "y": 43,
      "z": 1,
      "name": "Rock_Stone"
    },
    {
      "x": -2,
      "y": 44,
      "z": 1,
      "name": "Rock_Stone"
    },
    {
      "x": -2,
      "y": 45,
      "z": 1,
      "name": "Soil_Dirt"
    },
    {
      "x": -2,
      "y": 46,
      "z": 1,
      "name": "Soil_Dirt"
    },
    {
      "x": -2,
      "y": 47,
      "z": 1,
      "name": "Wood_Aspen_Branch_Short",
      "rotation": 3
    },
    {
      "x": -2,
      "y": 53,
      "z": 1,
      "name": "Wood_Aspen_Trunk_Full"
    },
    {
      "x": -2,
      "y": 60,
      "z": 1,
      "name": "Plant_Leaves_Aspen"
    },
    {
      "x": -2,
      "y": 61,
      "z": 1,
      "name": "Plant_Leaves_Aspen"
    },
    {
      "x": -2,
      "y": 62,
      "z": 1,
      "name": "Plant_Leaves_Aspen"
    },
    {
      "x": -2,
      "y": 19,
      "z": 2,
      "name": "Rock_Stone"
    },
    {
      "x": -2,
      "y": 20,
      "z": 2,
      "name": "Rock_Stone"
    },
    {
      "x": -2,
      "y": 21,
      "z": 2,
      "name": "Rock_Stone"
    },
    {
      "x": -2,
      "y": 22,
      "z": 2,
      "name": "Rock_Stone"
    },
    {
      "x": -2,
      "y": 23,
      "z": 2,
      "name": "Rock_Stone"
    },
    {
      "x": -2,
      "y": 24,
      "z": 2,
      "name": "Rock_Stone"
    },
    {
      "x": -2,
      "y": 25,
      "z": 2,
      "name": "Rock_Stone"
    },
    {
      "x": -2,
      "y": 26,
      "z": 2,
      "name": "Rock_Stone"
    },
    {
      "x": -2,
      "y": 27,
      "z": 2,
      "name": "Rock_Stone"
    },
    {
      "x": -2,
      "y": 28,
      "z": 2,
      "name": "Rock_Stone_Mossy"
    },
    {
      "x": -2,
      "y": 29,
      "z": 2,
      "name": "Rock_Stone_Mossy"
    },
    {
      "x": -2,
      "y": 30,
      "z": 2,
      "name": "Rock_Stone"
    },
    {
      "x": -2,
      "y": 31,
      "z": 2,
      "name": "Soil_Dirt"
    },
    {
      "x": -2,
      "y": 32,
      "z": 2,
      "name": "Soil_Dirt"
    },
    {
      "x": -2,
      "y": 33,
      "z": 2,
      "name": "Soil_Dirt"
    },
    {
      "x": -2,
      "y": 34,
      "z": 2,
      "name": "Rock_Stone"
    },
    {
      "x": -2,
      "y": 35,
      "z": 2,
      "name": "Rock_Stone"
    },
    {
      "x": -2,
      "y": 36,
      "z": 2,
      "name": "Rock_Stone"
    },
    {
      "x": -2,
      "y": 37,
      "z": 2,
      "name": "Rock_Stone"
    },
    {
      "x": -2,
      "y": 38,
      "z": 2,
      "name": "Rock_Stone"
    },
    {
      "x": -2,
      "y": 39,
      "z": 2,
      "name": "Rock_Stone"
    },
    {
      "x": -2,
      "y": 40,
      "z": 2,
      "name": "Rock_Stone"
    },
    {
      "x": -2,
      "y": 41,
      "z": 2,
      "name": "Soil_Dirt"
    },
    {
      "x": -2,
      "y": 42,
      "z": 2,
      "name": "Soil_Dirt"
    },
    {
      "x": -2,
      "y": 43,
      "z": 2,
      "name": "Soil_Dirt"
    },
    {
      "x": -2,
      "y": 44,
      "z": 2,
      "name": "Soil_Grass"
    },
    {
      "x": -2,
      "y": 45,
      "z": 2,
      "name": "Plant_Grass_Sharp"
    },
    {
      "x": -2,
      "y": 60,
      "z": 2,
      "name": "Plant_Leaves_Aspen"
    },
    {
      "x": -2,
      "y": 61,
      "z": 2,
      "name": "Plant_Leaves_Aspen"
    },
    {
      "x": -2,
      "y": 62,
      "z": 2,
      "name": "Plant_Leaves_Aspen"
    },
    {
      "x": -2,
      "y": 19,
      "z": 3,
      "name": "Rock_Stone"
    },
    {
      "x": -2,
      "y": 20,
      "z": 3,
      "name": "Rock_Stone"
    },
    {
      "x": -2,
      "y": 21,
      "z": 3,
      "name": "Rock_Stone"
    },
    {
      "x": -2,
      "y": 22,
      "z": 3,
      "name": "Rock_Stone"
    },
    {
      "x": -2,
      "y": 23,
      "z": 3,
      "name": "Rock_Stone"
    },
    {
      "x": -2,
      "y": 24,
      "z": 3,
      "name": "Rock_Stone"
    },
    {
      "x": -2,
      "y": 25,
      "z": 3,
      "name": "Rock_Stone"
    },
    {
      "x": -2,
      "y": 29,
      "z": 3,
      "name": "Rock_Stone_Mossy"
    },
    {
      "x": -2,
      "y": 30,
      "z": 3,
      "name": "Rock_Stone_Mossy"
    },
    {
      "x": -2,
      "y": 31,
      "z": 3,
      "name": "Soil_Dirt"
    },
    {
      "x": -2,
      "y": 32,
      "z": 3,
      "name": "Soil_Dirt"
    },
    {
      "x": -2,
      "y": 33,
      "z": 3,
      "name": "Soil_Dirt"
    },
    {
      "x": -2,
      "y": 34,
      "z": 3,
      "name": "Soil_Grass"
    },
    {
      "x": -2,
      "y": 40,
      "z": 3,
      "name": "Rock_Stone"
    },
    {
      "x": -2,
      "y": 41,
      "z": 3,
      "name": "Soil_Dirt"
    },
    {
      "x": -2,
      "y": 42,
      "z": 3,
      "name": "Soil_Dirt"
    },
    {
      "x": -2,
      "y": 43,
      "z": 3,
      "name": "Soil_Dirt"
    },
    {
      "x": -2,
      "y": 44,
      "z": 3,
      "name": "Soil_Grass"
    },
    {
      "x": -2,
      "y": 45,
      "z": 3,
      "name": "Plant_Grass_Sharp"
    },
    {
      "x": -2,
      "y": 52,
      "z": 3,
      "name": "Wood_Aspen_Branch_Corner",
      "rotation": 3
    },
    {
      "x": -2,
      "y": 53,
      "z": 3,
      "name": "Wood_Aspen_Branch_Long"
    },
    {
      "x": -2,
      "y": 54,
      "z": 3,
      "name": "Plant_Leaves_Aspen"
    },
    {
      "x": -2,
      "y": 57,
      "z": 3,
      "name": "Plant_Leaves_Aspen"
    },
    {
      "x": -2,
      "y": 58,
      "z": 3,
      "name": "Plant_Leaves_Aspen"
    },
    {
      "x": -2,
      "y": 59,
      "z": 3,
      "name": "Plant_Leaves_Aspen"
    },
    {
      "x": -2,
      "y": 60,
      "z": 3,
      "name": "Plant_Leaves_Aspen"
    },
    {
      "x": -2,
      "y": 53,
      "z": 4,
      "name": "Plant_Leaves_Aspen"
    },
    {
      "x": -2,
      "y": 56,
      "z": 4,
      "name": "Plant_Leaves_Aspen"
    },
    {
      "x": -2,
      "y": 57,
      "z": 4,
      "name": "Plant_Leaves_Aspen"
    },
    {
      "x": -2,
      "y": 58,
      "z": 4,
      "name": "Plant_Leaves_Aspen"
    },
    {
      "x": -2,
      "y": 52,
      "z": 5,
      "name": "Plant_Leaves_Aspen"
    },
    {
      "x": -2,
      "y": 53,
      "z": 5,
      "name": "Plant_Leaves_Aspen"
    },
    {
      "x": -2,
      "y": 54,
      "z": 5,
      "name": "Plant_Leaves_Aspen"
    },
    {
      "x": -1,
      "y": 31,
      "z": -5,
      "name": "Rock_Stone"
    },
    {
      "x": -1,
      "y": 32,
      "z": -5,
      "name": "Soil_Dirt"
    },
    {
      "x": -1,
      "y": 33,
      "z": -5,
      "name": "Soil_Dirt"
    },
    {
      "x": -1,
      "y": 34,
      "z": -5,
      "name": "Soil_Dirt"
    },
    {
      "x": -1,
      "y": 35,
      "z": -5,
      "name": "Soil_Grass"
    },
    {
      "x": -1,
      "y": 23,
      "z": -4,
      "name": "Rock_Stone"
    },
    {
      "x": -1,
      "y": 24,
      "z": -4,
      "name": "Rock_Stone"
    },
    {
      "x": -1,
      "y": 25,
      "z": -4,
      "name": "Rock_Stone"
    },
    {
      "x": -1,
      "y": 26,
      "z": -4,
      "name": "Rock_Stone"
    },
    {
      "x": -1,
      "y": 27,
      "z": -4,
      "name": "Rock_Stone_Mossy"
    },
    {
      "x": -1,
      "y": 28,
      "z": -4,
      "name": "Rock_Stone"
    },
    {
      "x": -1,
      "y": 29,
      "z": -4,
      "name": "Rock_Stone"
    },
    {
      "x": -1,
      "y": 30,
      "z": -4,
      "name": "Rock_Stone"
    },
    {
      "x": -1,
      "y": 31,
      "z": -4,
      "name": "Rock_Stone"
    },
    {
      "x": -1,
      "y": 32,
      "z": -4,
      "name": "Soil_Dirt"
    },
    {
      "x": -1,
      "y": 33,
      "z": -4,
      "name": "Soil_Dirt"
    },
    {
      "x": -1,
      "y": 34,
      "z": -4,
      "name": "Soil_Dirt"
    },
    {
      "x": -1,
      "y": 35,
      "z": -4,
      "name": "Soil_Grass"
    },
    {
      "x": -1,
      "y": 36,
      "z": -4,
      "name": "Plant_Grass_Sharp"
    },
    {
      "x": -1,
      "y": 56,
      "z": -4,
      "name": "Plant_Leaves_Aspen"
    },
    {
      "x": -1,
      "y": 21,
      "z": -3,
      "name": "Rock_Stone"
    },
    {
      "x": -1,
      "y": 22,
      "z": -3,
      "name": "Rock_Stone"
    },
    {
      "x": -1,
      "y": 23,
      "z": -3,
      "name": "Rock_Stone"
    },
    {
      "x": -1,
      "y": 24,
      "z": -3,
      "name": "Rock_Stone"
    },
    {
      "x": -1,
      "y": 25,
      "z": -3,
      "name": "Rock_Stone"
    },
    {
      "x": -1,
      "y": 26,
      "z": -3,
      "name": "Rock_Stone"
    },
    {
      "x": -1,
      "y": 27,
      "z": -3,
      "name": "Rock_Stone"
    },
    {
      "x": -1,
      "y": 28,
      "z": -3,
      "name": "Rock_Stone"
    },
    {
      "x": -1,
      "y": 29,
      "z": -3,
      "name": "Rock_Stone"
    },
    {
      "x": -1,
      "y": 30,
      "z": -3,
      "name": "Rock_Stone"
    },
    {
      "x": -1,
      "y": 31,
      "z": -3,
      "name": "Rock_Stone"
    },
    {
      "x": -1,
      "y": 32,
      "z": -3,
      "name": "Rock_Stone"
    },
    {
      "x": -1,
      "y": 33,
      "z": -3,
      "name": "Soil_Dirt"
    },
    {
      "x": -1,
      "y": 34,
      "z": -3,
      "name": "Soil_Dirt"
    },
    {
      "x": -1,
      "y": 35,
      "z": -3,
      "name": "Rock_Stone"
    },
    {
      "x": -1,
      "y": 36,
      "z": -3,
      "name": "Rock_Stone"
    },
    {
      "x": -1,
      "y": 37,
      "z": -3,
      "name": "Rock_Stone"
    },
    {
      "x": -1,
      "y": 38,
      "z": -3,
      "name": "Soil_Dirt"
    },
    {
      "x": -1,
      "y": 39,
      "z": -3,
      "name": "Soil_Dirt"
    },
    {
      "x": -1,
      "y": 40,
      "z": -3,
      "name": "Soil_Grass"
    },
    {
      "x": -1,
      "y": 52,
      "z": -3,
      "name": "Plant_Leaves_Aspen"
    },
    {
      "x": -1,
      "y": 53,
      "z": -3,
      "name": "Plant_Leaves_Aspen"
    },
    {
      "x": -1,
      "y": 54,
      "z": -3,
      "name": "Plant_Leaves_Aspen"
    },
    {
      "x": -1,
      "y": 55,
      "z": -3,
      "name": "Plant_Leaves_Aspen"
    },
    {
      "x": -1,
      "y": 56,
      "z": -3,
      "name": "Plant_Leaves_Aspen"
    },
    {
      "x": -1,
      "y": 57,
      "z": -3,
      "name": "Plant_Leaves_Aspen"
    },
    {
      "x": -1,
      "y": 59,
      "z": -3,
      "name": "Plant_Leaves_Aspen"
    },
    {
      "x": -1,
      "y": 17,
      "z": -2,
      "name": "Rock_Stone"
    },
    {
      "x": -1,
      "y": 18,
      "z": -2,
      "name": "Rock_Stone"
    },
    {
      "x": -1,
      "y": 19,
      "z": -2,
      "name": "Rock_Stone"
    },
    {
      "x": -1,
      "y": 20,
      "z": -2,
      "name": "Rock_Stone"
    },
    {
      "x": -1,
      "y": 21,
      "z": -2,
      "name": "Rock_Stone"
    },
    {
      "x": -1,
      "y": 22,
      "z": -2,
      "name": "Rock_Stone"
    },
    {
      "x": -1,
      "y": 23,
      "z": -2,
      "name": "Rock_Stone"
    },
    {
      "x": -1,
      "y": 24,
      "z": -2,
      "name": "Rock_Stone"
    },
    {
      "x": -1,
      "y": 25,
      "z": -2,
      "name": "Rock_Stone"
    },
    {
      "x": -1,
      "y": 26,
      "z": -2,
      "name": "Rock_Stone"
    },
    {
      "x": -1,
      "y": 27,
      "z": -2,
      "name": "Rock_Stone"
    },
    {
      "x": -1,
      "y": 28,
      "z": -2,
      "name": "Rock_Stone"
    },
    {
      "x": -1,
      "y": 29,
      "z": -2,
      "name": "Rock_Stone"
    },
    {
      "x": -1,
      "y": 30,
      "z": -2,
      "name": "Rock_Stone"
    },
    {
      "x": -1,
      "y": 31,
      "z": -2,
      "name": "Rock_Stone"
    },
    {
      "x": -1,
      "y": 32,
      "z": -2,
      "name": "Rock_Stone"
    },
    {
      "x": -1,
      "y": 33,
      "z": -2,
      "name": "Rock_Stone"
    },
    {
      "x": -1,
      "y": 34,
      "z": -2,
      "name": "Rock_Stone"
    },
    {
      "x": -1,
      "y": 35,
      "z": -2,
      "name": "Rock_Stone"
    },
    {
      "x": -1,
      "y": 36,
      "z": -2,
      "name": "Rock_Stone"
    },
    {
      "x": -1,
      "y": 37,
      "z": -2,
      "name": "Rock_Stone"
    },
    {
      "x": -1,
      "y": 38,
      "z": -2,
      "name": "Soil_Dirt"
    },
    {
      "x": -1,
      "y": 39,
      "z": -2,
      "name": "Soil_Dirt"
    },
    {
      "x": -1,
      "y": 40,
      "z": -2,
      "name": "Soil_Dirt"
    },
    {
      "x": -1,
      "y": 41,
      "z": -2,
      "name": "Rock_Stone"
    },
    {
      "x": -1,
      "y": 42,
      "z": -2,
      "name": "Soil_Dirt"
    },
    {
      "x": -1,
      "y": 43,
      "z": -2,
      "name": "Soil_Dirt"
    },
    {
      "x": -1,
      "y": 44,
      "z": -2,
      "name": "Soil_Dirt"
    },
    {
      "x": -1,
      "y": 45,
      "z": -2,
      "name": "Soil_Grass"
    },
    {
      "x": -1,
      "y": 51,
      "z": -2,
      "name": "Plant_Leaves_Aspen"
    },
    {
      "x": -1,
      "y": 52,
      "z": -2,
      "name": "Plant_Leaves_Aspen"
    },
    {
      "x": -1,
      "y": 53,
      "z": -2,
      "name": "Plant_Leaves_Aspen"
    },
    {
      "x": -1,
      "y": 54,
      "z": -2,
      "name": "Plant_Leaves_Aspen"
    },
    {
      "x": -1,
      "y": 55,
      "z": -2,
      "name": "Plant_Leaves_Aspen"
    },
    {
      "x": -1,
      "y": 56,
      "z": -2,
      "name": "Plant_Leaves_Aspen"
    },
    {
      "x": -1,
      "y": 57,
      "z": -2,
      "name": "Plant_Leaves_Aspen"
    },
    {
      "x": -1,
      "y": 58,
      "z": -2,
      "name": "Plant_Leaves_Aspen"
    },
    {
      "x": -1,
      "y": 59,
      "z": -2,
      "name": "Plant_Leaves_Aspen"
    },
    {
      "x": -1,
      "y": 60,
      "z": -2,
      "name": "Plant_Leaves_Aspen"
    },
    {
      "x": -1,
      "y": 17,
      "z": -1,
      "name": "Rock_Stone"
    },
    {
      "x": -1,
      "y": 18,
      "z": -1,
      "name": "Rock_Stone"
    },
    {
      "x": -1,
      "y": 19,
      "z": -1,
      "name": "Rock_Stone"
    },
    {
      "x": -1,
      "y": 20,
      "z": -1,
      "name": "Rock_Stone"
    },
    {
      "x": -1,
      "y": 21,
      "z": -1,
      "name": "Rock_Stone"
    },
    {
      "x": -1,
      "y": 22,
      "z": -1,
      "name": "Rock_Stone"
    },
    {
      "x": -1,
      "y": 23,
      "z": -1,
      "name": "Rock_Stone"
    },
    {
      "x": -1,
      "y": 24,
      "z": -1,
      "name": "Rock_Stone"
    },
    {
      "x": -1,
      "y": 25,
      "z": -1,
      "name": "Rock_Stone"
    },
    {
      "x": -1,
      "y": 26,
      "z": -1,
      "name": "Rock_Stone"
    },
    {
      "x": -1,
      "y": 27,
      "z": -1,
      "name": "Rock_Stone"
    },
    {
      "x": -1,
      "y": 28,
      "z": -1,
      "name": "Rock_Stone"
    },
    {
      "x": -1,
      "y": 29,
      "z": -1,
      "name": "Rock_Stone"
    },
    {
      "x": -1,
      "y": 30,
      "z": -1,
      "name": "Rock_Stone"
    },
    {
      "x": -1,
      "y": 31,
      "z": -1,
      "name": "Rock_Stone"
    },
    {
      "x": -1,
      "y": 32,
      "z": -1,
      "name": "Rock_Stone"
    },
    {
      "x": -1,
      "y": 33,
      "z": -1,
      "name": "Rock_Stone"
    },
    {
      "x": -1,
      "y": 34,
      "z": -1,
      "name": "Rock_Stone"
    },
    {
      "x": -1,
      "y": 35,
      "z": -1,
      "name": "Rock_Stone"
    },
    {
      "x": -1,
      "y": 36,
      "z": -1,
      "name": "Rock_Stone"
    },
    {
      "x": -1,
      "y": 37,
      "z": -1,
      "name": "Rock_Stone"
    },
    {
      "x": -1,
      "y": 38,
      "z": -1,
      "name": "Rock_Stone"
    },
    {
      "x": -1,
      "y": 39,
      "z": -1,
      "name": "Soil_Dirt"
    },
    {
      "x": -1,
      "y": 40,
      "z": -1,
      "name": "Soil_Dirt"
    },
    {
      "x": -1,
      "y": 41,
      "z": -1,
      "name": "Rock_Stone"
    },
    {
      "x": -1,
      "y": 42,
      "z": -1,
      "name": "Soil_Dirt"
    },
    {
      "x": -1,
      "y": 43,
      "z": -1,
      "name": "Soil_Dirt"
    },
    {
      "x": -1,
      "y": 44,
      "z": -1,
      "name": "Soil_Dirt"
    },
    {
      "x": -1,
      "y": 45,
      "z": -1,
      "name": "Soil_Dirt"
    },
    {
      "x": -1,
      "y": 46,
      "z": -1,
      "name": "Soil_Dirt"
    },
    {
      "x": -1,
      "y": 47,
      "z": -1,
      "name": "Soil_Grass"
    },
    {
      "x": -1,
      "y": 54,
      "z": -1,
      "name": "Wood_Aspen_Branch_Long",
      "rotation": 4
    },
    {
      "x": -1,
      "y": 57,
      "z": -1,
      "name": "Wood_Aspen_Branch_Corner",
      "rotation": 2
    },
    {
      "x": -1,
      "y": 58,
      "z": -1,
      "name": "Wood_Aspen_Branch_Long"
    },
    {
      "x": -1,
      "y": 59,
      "z": -1,
      "name": "Plant_Leaves_Aspen"
    },
    {
      "x": -1,
      "y": 60,
      "z": -1,
      "name": "Plant_Leaves_Aspen"
    },
    {
      "x": -1,
      "y": 61,
      "z": -1,
      "name": "Plant_Leaves_Aspen"
    },
    {
      "x": -1,
      "y": 62,
      "z": -1,
      "name": "Plant_Leaves_Aspen"
    },
    {
      "x": -1,
      "y": 17,
      "z": 0,
      "name": "Rock_Stone"
    },
    {
      "x": -1,
      "y": 18,
      "z": 0,
      "name": "Rock_Stone"
    },
    {
      "x": -1,
      "y": 19,
      "z": 0,
      "name": "Rock_Stone"
    },
    {
      "x": -1,
      "y": 20,
      "z": 0,
      "name": "Rock_Stone"
    },
    {
      "x": -1,
      "y": 21,
      "z": 0,
      "name": "Rock_Stone"
    },
    {
      "x": -1,
      "y": 22,
      "z": 0,
      "name": "Rock_Stone"
    },
    {
      "x": -1,
      "y": 23,
      "z": 0,
      "name": "Rock_Stone"
    },
    {
      "x": -1,
      "y": 24,
      "z": 0,
      "name": "Rock_Stone"
    },
    {
      "x": -1,
      "y": 25,
      "z": 0,
      "name": "Rock_Stone"
    },
    {
      "x": -1,
      "y": 26,
      "z": 0,
      "name": "Rock_Stone"
    },
    {
      "x": -1,
      "y": 27,
      "z": 0,
      "name": "Rock_Stone"
    },
    {
      "x": -1,
      "y": 28,
      "z": 0,
      "name": "Rock_Stone"
    },
    {
      "x": -1,
      "y": 29,
      "z": 0,
      "name": "Rock_Stone"
    },
    {
      "x": -1,
      "y": 30,
      "z": 0,
      "name": "Rock_Stone"
    },
    {
      "x": -1,
      "y": 31,
      "z": 0,
      "name": "Rock_Stone"
    },
    {
      "x": -1,
      "y": 32,
      "z": 0,
      "name": "Rock_Stone"
    },
    {
      "x": -1,
      "y": 33,
      "z": 0,
      "name": "Rock_Stone"
    },
    {
      "x": -1,
      "y": 34,
      "z": 0,
      "name": "Rock_Stone"
    },
    {
      "x": -1,
      "y": 35,
      "z": 0,
      "name": "Rock_Stone"
    },
    {
      "x": -1,
      "y": 36,
      "z": 0,
      "name": "Rock_Stone"
    },
    {
      "x": -1,
      "y": 37,
      "z": 0,
      "name": "Rock_Stone"
    },
    {
      "x": -1,
      "y": 38,
      "z": 0,
      "name": "Rock_Stone"
    },
    {
      "x": -1,
      "y": 39,
      "z": 0,
      "name": "Rock_Stone"
    },
    {
      "x": -1,
      "y": 40,
      "z": 0,
      "name": "Rock_Stone"
    },
    {
      "x": -1,
      "y": 41,
      "z": 0,
      "name": "Rock_Stone"
    },
    {
      "x": -1,
      "y": 42,
      "z": 0,
      "name": "Soil_Dirt"
    },
    {
      "x": -1,
      "y": 43,
      "z": 0,
      "name": "Soil_Dirt"
    },
    {
      "x": -1,
      "y": 44,
      "z": 0,
      "name": "Soil_Dirt"
    },
    {
      "x": -1,
      "y": 45,
      "z": 0,
      "name": "Soil_Dirt"
    },
    {
      "x": -1,
      "y": 46,
      "z": 0,
      "name": "Soil_Dirt"
    },
    {
      "x": -1,
      "y": 47,
      "z": 0,
      "name": "Soil_Grass"
    },
    {
      "x": -1,
      "y": 54,
      "z": 0,
      "name": "Wood_Aspen_Trunk_Full"
    },
    {
      "x": -1,
      "y": 55,
      "z": 0,
      "name": "Wood_Aspen_Trunk"
    },
    {
      "x": -1,
      "y": 56,
      "z": 0,
      "name": "Wood_Aspen_Trunk"
    },
    {
      "x": -1,
      "y": 57,
      "z": 0,
      "name": "Wood_Aspen_Trunk_Full"
    },
    {
      "x": -1,
      "y": 58,
      "z": 0,
      "name": "Wood_Aspen_Branch_Long"
    },
    {
      "x": -1,
      "y": 59,
      "z": 0,
      "name": "Wood_Aspen_Branch_Long"
    },
    {
      "x": -1,
      "y": 60,
      "z": 0,
      "name": "Wood_Aspen_Branch_Long"
    },
    {
      "x": -1,
      "y": 61,
      "z": 0,
      "name": "Plant_Leaves_Aspen"
    },
    {
      "x": -1,
      "y": 62,
      "z": 0,
      "name": "Plant_Leaves_Aspen"
    },
    {
      "x": -1,
      "y": 63,
      "z": 0,
      "name": "Plant_Leaves_Aspen"
    },
    {
      "x": -1,
      "y": 17,
      "z": 1,
      "name": "Rock_Stone"
    },
    {
      "x": -1,
      "y": 18,
      "z": 1,
      "name": "Rock_Stone_Mossy"
    },
    {
      "x": -1,
      "y": 19,
      "z": 1,
      "name": "Rock_Stone"
    },
    {
      "x": -1,
      "y": 20,
      "z": 1,
      "name": "Rock_Stone"
    },
    {
      "x": -1,
      "y": 21,
      "z": 1,
      "name": "Rock_Stone"
    },
    {
      "x": -1,
      "y": 22,
      "z": 1,
      "name": "Rock_Stone"
    },
    {
      "x": -1,
      "y": 23,
      "z": 1,
      "name": "Rock_Stone"
    },
    {
      "x": -1,
      "y": 24,
      "z": 1,
      "name": "Rock_Stone"
    },
    {
      "x": -1,
      "y": 25,
      "z": 1,
      "name": "Rock_Stone"
    },
    {
      "x": -1,
      "y": 26,
      "z": 1,
      "name": "Rock_Stone_Mossy"
    },
    {
      "x": -1,
      "y": 27,
      "z": 1,
      "name": "Rock_Stone_Mossy"
    },
    {
      "x": -1,
      "y": 28,
      "z": 1,
      "name": "Rock_Stone_Mossy"
    },
    {
      "x": -1,
      "y": 29,
      "z": 1,
      "name": "Rock_Stone"
    },
    {
      "x": -1,
      "y": 30,
      "z": 1,
      "name": "Rock_Stone_Mossy"
    },
    {
      "x": -1,
      "y": 31,
      "z": 1,
      "name": "Rock_Stone"
    },
    {
      "x": -1,
      "y": 32,
      "z": 1,
      "name": "Soil_Dirt"
    },
    {
      "x": -1,
      "y": 33,
      "z": 1,
      "name": "Rock_Stone"
    },
    {
      "x": -1,
      "y": 34,
      "z": 1,
      "name": "Rock_Stone"
    },
    {
      "x": -1,
      "y": 35,
      "z": 1,
      "name": "Rock_Stone"
    },
    {
      "x": -1,
      "y": 36,
      "z": 1,
      "name": "Rock_Stone"
    },
    {
      "x": -1,
      "y": 37,
      "z": 1,
      "name": "Rock_Stone"
    },
    {
      "x": -1,
      "y": 38,
      "z": 1,
      "name": "Rock_Stone"
    },
    {
      "x": -1,
      "y": 39,
      "z": 1,
      "name": "Rock_Stone"
    },
    {
      "x": -1,
      "y": 40,
      "z": 1,
      "name": "Wood_Aspen_Trunk"
    },
    {
      "x": -1,
      "y": 41,
      "z": 1,
      "name": "Wood_Aspen_Trunk"
    },
    {
      "x": -1,
      "y": 42,
      "z": 1,
      "name": "Wood_Aspen_Trunk"
    },
    {
      "x": -1,
      "y": 43,
      "z": 1,
      "name": "Wood_Aspen_Trunk"
    },
    {
      "x": -1,
      "y": 44,
      "z": 1,
      "name": "Wood_Aspen_Trunk"
    },
    {
      "x": -1,
      "y": 45,
      "z": 1,
      "name": "Wood_Aspen_Trunk"
    },
    {
      "x": -1,
      "y": 46,
      "z": 1,
      "name": "Wood_Aspen_Trunk"
    },
    {
      "x": -1,
      "y": 47,
      "z": 1,
      "name": "Wood_Aspen_Trunk"
    },
    {
      "x": -1,
      "y": 48,
      "z": 1,
      "name": "Wood_Aspen_Trunk"
    },
    {
      "x": -1,
      "y": 49,
      "z": 1,
      "name": "Wood_Aspen_Trunk"
    },
    {
      "x": -1,
      "y": 50,
      "z": 1,
      "name": "Wood_Aspen_Trunk"
    },
    {
      "x": -1,
      "y": 51,
      "z": 1,
      "name": "Wood_Aspen_Trunk"
    },
    {
      "x": -1,
      "y": 52,
      "z": 1,
      "name": "Wood_Aspen_Trunk"
    },
    {
      "x": -1,
      "y": 53,
      "z": 1,
      "name": "Wood_Aspen_Trunk"
    },
    {
      "x": -1,
      "y": 54,
      "z": 1,
      "name": "Wood_Aspen_Trunk_Full"
    },
    {
      "x": -1,
      "y": 61,
      "z": 1,
      "name": "Plant_Leaves_Aspen"
    },
    {
      "x": -1,
      "y": 62,
      "z": 1,
      "name": "Plant_Leaves_Aspen"
    },
    {
      "x": -1,
      "y": 63,
      "z": 1,
      "name": "Plant_Leaves_Aspen"
    },
    {
      "x": -1,
      "y": 19,
      "z": 2,
      "name": "Rock_Stone"
    },
    {
      "x": -1,
      "y": 20,
      "z": 2,
      "name": "Rock_Stone"
    },
    {
      "x": -1,
      "y": 21,
      "z": 2,
      "name": "Rock_Stone"
    },
    {
      "x": -1,
      "y": 22,
      "z": 2,
      "name": "Rock_Stone"
    },
    {
      "x": -1,
      "y": 23,
      "z": 2,
      "name": "Rock_Stone"
    },
    {
      "x": -1,
      "y": 24,
      "z": 2,
