{
  "version": 8,
  "blockIdVersion": 8,
  "anchorX": -3,
  "anchorY": 27,
  "anchorZ": -1,
  "blocks": [
    {
      "x": -8,
      "y": 24,
      "z": -3,
      "name": "Rock_Stone"
    },
    {
      "x": -8,
      "y": 25,
      "z": -3,
      "name": "Rock_Stone"
    },
    {
      "x": -8,
      "y": 26,
      "z": -3,
      "name": "Rock_Stone"
    },
    {
      "x": -8,
      "y": 27,
      "z": -3,
      "name": "Rock_Stone"
    },
    {
      "x": -8,
      "y": 23,
      "z": -2,
      "name": "Rock_Stone"
    },
    {
      "x": -8,
      "y": 24,
      "z": -2,
      "name": "Rock_Stone"
    },
    {
      "x": -8,
      "y": 25,
      "z": -2,
      "name": "Rock_Stone"
    },
    {
      "x": -8,
      "y": 26,
      "z": -2,
      "name": "Rock_Stone"
    },
    {
      "x": -8,
      "y": 27,
      "z": -2,
      "name": "Rock_Stone"
    },
    {
      "x": -8,
      "y": 28,
      "z": -2,
      "name": "Rock_Stone"
    },
    {
      "x": -8,
      "y": 29,
      "z": -2,
      "name": "Soil_Dirt"
    },
    {
      "x": -8,
      "y": 30,
      "z": -2,
      "name": "Soil_Dirt"
    },
    {
      "x": -8,
      "y": 31,
      "z": -2,
      "name": "Soil_Grass"
    },
    {
      "x": -8,
      "y": 23,
      "z": -1,
      "name": "Rock_Stone"
    },
    {
      "x": -8,
      "y": 24,
      "z": -1,
      "name": "Rock_Stone"
    },
    {
      "x": -8,
      "y": 25,
      "z": -1,
      "name": "Rock_Stone"
    },
    {
      "x": -8,
      "y": 26,
      "z": -1,
      "name": "Rock_Stone"
    },
    {
      "x": -8,
      "y": 27,
      "z": -1,
      "name": "Rock_Stone"
    },
    {
      "x": -8,
      "y": 28,
      "z": -1,
      "name": "Rock_Stone_Mossy"
    },
    {
      "x": -8,
      "y": 29,
      "z": -1,
      "name": "Rock_Stone_Mossy"
    },
    {
      "x": -8,
      "y": 30,
      "z": -1,
      "name": "Soil_Dirt"
    },
    {
      "x": -8,
      "y": 31,
      "z": -1,
      "name": "Soil_Grass"
    },
    {
      "x": -8,
      "y": 23,
      "z": 0,
      "name": "Rock_Stone"
    },
    {
      "x": -8,
      "y": 24,
      "z": 0,
      "name": "Rock_Stone"
    },
    {
      "x": -8,
      "y": 25,
      "z": 0,
      "name": "Rock_Stone"
    },
    {
      "x": -8,
      "y": 26,
      "z": 0,
      "name": "Rock_Stone"
    },
    {
      "x": -8,
      "y": 27,
      "z": 0,
      "name": "Rock_Stone"
    },
    {
      "x": -8,
      "y": 28,
      "z": 0,
      "name": "Rock_Stone_Mossy"
    },
    {
      "x": -8,
      "y": 29,
      "z": 0,
      "name": "Rock_Stone_Mossy"
    },
    {
      "x": -8,
      "y": 30,
      "z": 0,
      "name": "Rock_Stone_Mossy"
    },
    {
      "x": -8,
      "y": 31,
      "z": 0,
      "name": "Soil_Dirt"
    },
    {
      "x": -8,
      "y": 32,
      "z": 0,
      "name": "Soil_Dirt"
    },
    {
      "x": -8,
      "y": 33,
      "z": 0,
      "name": "Soil_Grass"
    },
    {
      "x": -8,
      "y": 24,
      "z": 1,
      "name": "Rock_Stone"
    },
    {
      "x": -8,
      "y": 25,
      "z": 1,
      "name": "Rock_Stone"
    },
    {
      "x": -8,
      "y": 26,
      "z": 1,
      "name": "Rock_Stone"
    },
    {
      "x": -8,
      "y": 27,
      "z": 1,
      "name": "Rock_Stone_Mossy"
    },
    {
      "x": -8,
      "y": 28,
      "z": 1,
      "name": "Rock_Stone_Mossy"
    },
    {
      "x": -8,
      "y": 29,
      "z": 1,
      "name": "Rock_Stone_Mossy"
    },
    {
      "x": -8,
      "y": 30,
      "z": 1,
      "name": "Rock_Stone_Mossy"
    },
    {
      "x": -8,
      "y": 31,
      "z": 1,
      "name": "Soil_Dirt"
    },
    {
      "x": -8,
      "y": 32,
      "z": 1,
      "name": "Soil_Dirt"
    },
    {
      "x": -8,
      "y": 33,
      "z": 1,
      "name": "Soil_Grass"
    },
    {
      "x": -8,
      "y": 29,
      "z": 2,
      "name": "Rock_Stone"
    },
    {
      "x": -8,
      "y": 30,
      "z": 2,
      "name": "Rock_Stone_Mossy"
    },
    {
      "x": -8,
      "y": 31,
      "z": 2,
      "name": "Rock_Stone_Mossy"
    },
    {
      "x": -8,
      "y": 32,
      "z": 2,
      "name": "Soil_Dirt"
    },
    {
      "x": -8,
      "y": 33,
      "z": 2,
      "name": "Soil_Grass"
    },
    {
      "x": -8,
      "y": 34,
      "z": 2,
      "name": "Plant_Grass_Sharp"
    },
    {
      "x": -8,
      "y": 26,
      "z": 3,
      "name": "Soil_Dirt"
    },
    {
      "x": -8,
      "y": 27,
      "z": 3,
      "name": "Soil_Grass"
    },
    {
      "x": -8,
      "y": 31,
      "z": 3,
      "name": "Rock_Stone"
    },
    {
      "x": -8,
      "y": 32,
      "z": 3,
      "name": "Soil_Dirt"
    },
    {
      "x": -8,
      "y": 33,
      "z": 3,
      "name": "Soil_Grass"
    },
    {
      "x": -8,
      "y": 25,
      "z": 4,
      "name": "Soil_Dirt"
    },
    {
      "x": -8,
      "y": 26,
      "z": 4,
      "name": "Soil_Dirt"
    },
    {
      "x": -8,
      "y": 27,
      "z": 4,
      "name": "Soil_Grass"
    },
    {
      "x": -8,
      "y": 25,
      "z": 5,
      "name": "Soil_Dirt"
    },
    {
      "x": -8,
      "y": 26,
      "z": 5,
      "name": "Soil_Dirt"
    },
    {
      "x": -8,
      "y": 27,
      "z": 5,
      "name": "Soil_Grass"
    },
    {
      "x": -8,
      "y": 28,
      "z": 5,
      "name": "Plant_Grass_Sharp"
    },
    {
      "x": -7,
      "y": 23,
      "z": -4,
      "name": "Rock_Stone"
    },
    {
      "x": -7,
      "y": 24,
      "z": -4,
      "name": "Rock_Stone"
    },
    {
      "x": -7,
      "y": 25,
      "z": -4,
      "name": "Rock_Stone"
    },
    {
      "x": -7,
      "y": 26,
      "z": -4,
      "name": "Rock_Stone"
    },
    {
      "x": -7,
      "y": 27,
      "z": -4,
      "name": "Rock_Stone"
    },
    {
      "x": -7,
      "y": 28,
      "z": -4,
      "name": "Rock_Stone"
    },
    {
      "x": -7,
      "y": 29,
      "z": -4,
      "name": "Soil_Dirt"
    },
    {
      "x": -7,
      "y": 30,
      "z": -4,
      "name": "Soil_Grass"
    },
    {
      "x": -7,
      "y": 23,
      "z": -3,
      "name": "Rock_Stone"
    },
    {
      "x": -7,
      "y": 24,
      "z": -3,
      "name": "Rock_Stone"
    },
    {
      "x": -7,
      "y": 25,
      "z": -3,
      "name": "Rock_Stone"
    },
    {
      "x": -7,
      "y": 26,
      "z": -3,
      "name": "Rock_Stone"
    },
    {
      "x": -7,
      "y": 27,
      "z": -3,
      "name": "Rock_Stone"
    },
    {
      "x": -7,
      "y": 28,
      "z": -3,
      "name": "Rock_Stone"
    },
    {
      "x": -7,
      "y": 29,
      "z": -3,
      "name": "Soil_Dirt"
    },
    {
      "x": -7,
      "y": 30,
      "z": -3,
      "name": "Soil_Dirt"
    },
    {
      "x": -7,
      "y": 31,
      "z": -3,
      "name": "Soil_Dirt"
    },
    {
      "x": -7,
      "y": 32,
      "z": -3,
      "name": "Soil_Grass"
    },
    {
      "x": -7,
      "y": 23,
      "z": -2,
      "name": "Rock_Stone"
    },
    {
      "x": -7,
      "y": 24,
      "z": -2,
      "name": "Rock_Stone"
    },
    {
      "x": -7,
      "y": 25,
      "z": -2,
      "name": "Rock_Stone"
    },
    {
      "x": -7,
      "y": 26,
      "z": -2,
      "name": "Rock_Stone"
    },
    {
      "x": -7,
      "y": 27,
      "z": -2,
      "name": "Rock_Stone"
    },
    {
      "x": -7,
      "y": 28,
      "z": -2,
      "name": "Rock_Stone"
    },
    {
      "x": -7,
      "y": 29,
      "z": -2,
      "name": "Soil_Dirt"
    },
    {
      "x": -7,
      "y": 30,
      "z": -2,
      "name": "Soil_Dirt"
    },
    {
      "x": -7,
      "y": 31,
      "z": -2,
      "name": "Soil_Dirt"
    },
    {
      "x": -7,
      "y": 32,
      "z": -2,
      "name": "Soil_Grass"
    },
    {
      "x": -7,
      "y": 22,
      "z": -1,
      "name": "Rock_Stone"
    },
    {
      "x": -7,
      "y": 23,
      "z": -1,
      "name": "Rock_Stone"
    },
    {
      "x": -7,
      "y": 24,
      "z": -1,
      "name": "Rock_Stone"
    },
    {
      "x": -7,
      "y": 25,
      "z": -1,
      "name": "Rock_Stone"
    },
    {
      "x": -7,
      "y": 26,
      "z": -1,
      "name": "Rock_Stone"
    },
    {
      "x": -7,
      "y": 27,
      "z": -1,
      "name": "Rock_Stone"
    },
    {
      "x": -7,
      "y": 28,
      "z": -1,
      "name": "Rock_Stone"
    },
    {
      "x": -7,
      "y": 29,
      "z": -1,
      "name": "Rock_Stone_Mossy"
    },
    {
      "x": -7,
      "y": 30,
      "z": -1,
      "name": "Soil_Dirt"
    },
    {
      "x": -7,
      "y": 31,
      "z": -1,
      "name": "Soil_Dirt"
    },
    {
      "x": -7,
      "y": 32,
      "z": -1,
      "name": "Soil_Dirt"
    },
    {
      "x": -7,
      "y": 33,
      "z": -1,
      "name": "Soil_Grass"
    },
    {
      "x": -7,
      "y": 21,
      "z": 0,
      "name": "Rock_Stone"
    },
    {
      "x": -7,
      "y": 22,
      "z": 0,
      "name": "Rock_Stone"
    },
    {
      "x": -7,
      "y": 23,
      "z": 0,
      "name": "Rock_Stone_Mossy"
    },
    {
      "x": -7,
      "y": 24,
      "z": 0,
      "name": "Rock_Stone"
    },
    {
      "x": -7,
      "y": 25,
      "z": 0,
      "name": "Rock_Stone"
    },
    {
      "x": -7,
      "y": 26,
      "z": 0,
      "name": "Rock_Stone"
    },
    {
      "x": -7,
      "y": 27,
      "z": 0,
      "name": "Rock_Stone"
    },
    {
      "x": -7,
      "y": 28,
      "z": 0,
      "name": "Rock_Stone"
    },
    {
      "x": -7,
      "y": 29,
      "z": 0,
      "name": "Rock_Stone"
    },
    {
      "x": -7,
      "y": 30,
      "z": 0,
      "name": "Rock_Stone"
    },
    {
      "x": -7,
      "y": 31,
      "z": 0,
      "name": "Soil_Dirt"
    },
    {
      "x": -7,
      "y": 32,
      "z": 0,
      "name": "Soil_Dirt"
    },
    {
      "x": -7,
      "y": 33,
      "z": 0,
      "name": "Soil_Grass"
    },
    {
      "x": -7,
      "y": 21,
      "z": 1,
      "name": "Rock_Stone"
    },
    {
      "x": -7,
      "y": 22,
      "z": 1,
      "name": "Rock_Stone_Mossy"
    },
    {
      "x": -7,
      "y": 23,
      "z": 1,
      "name": "Rock_Stone_Mossy"
    },
    {
      "x": -7,
      "y": 24,
      "z": 1,
      "name": "Rock_Stone_Mossy"
    },
    {
      "x": -7,
      "y": 25,
      "z": 1,
      "name": "Rock_Stone"
    },
    {
      "x": -7,
      "y": 26,
      "z": 1,
      "name": "Rock_Stone"
    },
    {
      "x": -7,
      "y": 27,
      "z": 1,
      "name": "Rock_Stone"
    },
    {
      "x": -7,
      "y": 28,
      "z": 1,
      "name": "Rock_Stone_Mossy"
    },
    {
      "x": -7,
      "y": 29,
      "z": 1,
      "name": "Rock_Stone"
    },
    {
      "x": -7,
      "y": 30,
      "z": 1,
      "name": "Rock_Stone_Mossy"
    },
    {
      "x": -7,
      "y": 31,
      "z": 1,
      "name": "Soil_Dirt"
    },
    {
      "x": -7,
      "y": 32,
      "z": 1,
      "name": "Soil_Dirt"
    },
    {
      "x": -7,
      "y": 33,
      "z": 1,
      "name": "Soil_Grass"
    },
    {
      "x": -7,
      "y": 34,
      "z": 1,
      "name": "Plant_Grass_Sharp_Tall"
    },
    {
      "x": -7,
      "y": 35,
      "z": 1,
      "name": "Plant_Grass_Sharp_Tall",
      "filler": 1024
    },
    {
      "x": -7,
      "y": 23,
      "z": 2,
      "name": "Rock_Stone_Mossy"
    },
    {
      "x": -7,
      "y": 24,
      "z": 2,
      "name": "Rock_Stone_Mossy"
    },
    {
      "x": -7,
      "y": 25,
      "z": 2,
      "name": "Rock_Stone"
    },
    {
      "x": -7,
      "y": 26,
      "z": 2,
      "name": "Rock_Stone"
    },
    {
      "x": -7,
      "y": 27,
      "z": 2,
      "name": "Rock_Stone"
    },
    {
      "x": -7,
      "y": 28,
      "z": 2,
      "name": "Rock_Stone"
    },
    {
      "x": -7,
      "y": 29,
      "z": 2,
      "name": "Rock_Stone"
    },
    {
      "x": -7,
      "y": 30,
      "z": 2,
      "name": "Rock_Stone"
    },
    {
      "x": -7,
      "y": 31,
      "z": 2,
      "name": "Rock_Stone"
    },
    {
      "x": -7,
      "y": 32,
      "z": 2,
      "name": "Soil_Dirt"
    },
    {
      "x": -7,
      "y": 33,
      "z": 2,
      "name": "Soil_Grass"
    },
    {
      "x": -7,
      "y": 34,
      "z": 2,
      "name": "Plant_Grass_Sharp"
    },
    {
      "x": -7,
      "y": 24,
      "z": 3,
      "name": "Rock_Stone_Mossy"
    },
    {
      "x": -7,
      "y": 25,
      "z": 3,
      "name": "Rock_Stone_Mossy"
    },
    {
      "x": -7,
      "y": 26,
      "z": 3,
      "name": "Soil_Dirt"
    },
    {
      "x": -7,
      "y": 27,
      "z": 3,
      "name": "Rock_Stone"
    },
    {
      "x": -7,
      "y": 28,
      "z": 3,
      "name": "Rock_Stone"
    },
    {
      "x": -7,
      "y": 29,
      "z": 3,
      "name": "Rock_Stone"
    },
    {
      "x": -7,
      "y": 30,
      "z": 3,
      "name": "Rock_Stone"
    },
    {
      "x": -7,
      "y": 31,
      "z": 3,
      "name": "Soil_Dirt"
    },
    {
      "x": -7,
      "y": 32,
      "z": 3,
      "name": "Soil_Dirt"
    },
    {
      "x": -7,
      "y": 33,
      "z": 3,
      "name": "Soil_Grass"
    },
    {
      "x": -7,
      "y": 24,
      "z": 4,
      "name": "Rock_Stone_Mossy"
    },
    {
      "x": -7,
      "y": 25,
      "z": 4,
      "name": "Soil_Dirt"
    },
    {
      "x": -7,
      "y": 26,
      "z": 4,
      "name": "Soil_Dirt"
    },
    {
      "x": -7,
      "y": 27,
      "z": 4,
      "name": "Soil_Grass"
    },
    {
      "x": -7,
      "y": 28,
      "z": 4,
      "name": "Plant_Grass_Sharp"
    },
    {
      "x": -7,
      "y": 30,
      "z": 4,
      "name": "Rock_Stone"
    },
    {
      "x": -7,
      "y": 31,
      "z": 4,
      "name": "Soil_Dirt"
    },
    {
      "x": -7,
      "y": 32,
      "z": 4,
      "name": "Soil_Dirt"
    },
    {
      "x": -7,
      "y": 33,
      "z": 4,
      "name": "Soil_Grass"
    },
    {
      "x": -7,
      "y": 25,
      "z": 5,
      "name": "Soil_Dirt"
    },
    {
      "x": -7,
      "y": 26,
      "z": 5,
      "name": "Soil_Dirt"
    },
    {
      "x": -7,
      "y": 27,
      "z": 5,
      "name": "Soil_Grass"
    },
    {
      "x": -6,
      "y": 28,
      "z": -5,
      "name": "Rock_Stone"
    },
    {
      "x": -6,
      "y": 29,
      "z": -5,
      "name": "Soil_Dirt"
    },
    {
      "x": -6,
      "y": 30,
      "z": -5,
      "name": "Soil_Dirt"
    },
    {
      "x": -6,
      "y": 31,
      "z": -5,
      "name": "Soil_Grass"
    },
    {
      "x": -6,
      "y": 23,
      "z": -4,
      "name": "Rock_Stone"
    },
    {
      "x": -6,
      "y": 24,
      "z": -4,
      "name": "Rock_Stone"
    },
    {
      "x": -6,
      "y": 25,
      "z": -4,
      "name": "Rock_Stone"
    },
    {
      "x": -6,
      "y": 26,
      "z": -4,
      "name": "Rock_Stone"
    },
    {
      "x": -6,
      "y": 27,
      "z": -4,
      "name": "Rock_Stone"
    },
    {
      "x": -6,
      "y": 28,
      "z": -4,
      "name": "Rock_Stone"
    },
    {
      "x": -6,
      "y": 29,
      "z": -4,
      "name": "Soil_Dirt"
    },
    {
      "x": -6,
      "y": 30,
      "z": -4,
      "name": "Soil_Dirt"
    },
    {
      "x": -6,
      "y": 31,
      "z": -4,
      "name": "Soil_Dirt"
    },
    {
      "x": -6,
      "y": 32,
      "z": -4,
      "name": "Soil_Grass"
    },
    {
      "x": -6,
      "y": 22,
      "z": -3,
      "name": "Rock_Stone"
    },
    {
      "x": -6,
      "y": 23,
      "z": -3,
      "name": "Rock_Stone"
    },
    {
      "x": -6,
      "y": 24,
      "z": -3,
      "name": "Rock_Stone"
    },
    {
      "x": -6,
      "y": 25,
      "z": -3,
      "name": "Rock_Stone"
    },
    {
      "x": -6,
      "y": 26,
      "z": -3,
      "name": "Rock_Stone"
    },
    {
      "x": -6,
      "y": 27,
      "z": -3,
      "name": "Rock_Stone"
    },
    {
      "x": -6,
      "y": 28,
      "z": -3,
      "name": "Rock_Stone"
    },
    {
      "x": -6,
      "y": 29,
      "z": -3,
      "name": "Soil_Dirt"
    },
    {
      "x": -6,
      "y": 30,
      "z": -3,
      "name": "Soil_Dirt"
    },
    {
      "x": -6,
      "y": 31,
      "z": -3,
      "name": "Soil_Dirt"
    },
    {
      "x": -6,
      "y": 32,
      "z": -3,
      "name": "Soil_Grass"
    },
    {
      "x": -6,
      "y": 21,
      "z": -2,
      "name": "Rock_Stone_Mossy"
    },
    {
      "x": -6,
      "y": 22,
      "z": -2,
      "name": "Rock_Stone_Mossy"
    },
    {
      "x": -6,
      "y": 23,
      "z": -2,
      "name": "Rock_Stone"
    },
    {
      "x": -6,
      "y": 24,
      "z": -2,
      "name": "Rock_Stone"
    },
    {
      "x": -6,
      "y": 25,
      "z": -2,
      "name": "Rock_Stone"
    },
    {
      "x": -6,
      "y": 26,
      "z": -2,
      "name": "Rock_Stone"
    },
    {
      "x": -6,
      "y": 27,
      "z": -2,
      "name": "Rock_Stone"
    },
    {
      "x": -6,
      "y": 28,
      "z": -2,
      "name": "Rock_Stone"
    },
    {
      "x": -6,
      "y": 29,
      "z": -2,
      "name": "Soil_Dirt"
    },
    {
      "x": -6,
      "y": 30,
      "z": -2,
      "name": "Soil_Dirt"
    },
    {
      "x": -6,
      "y": 31,
      "z": -2,
      "name": "Soil_Dirt"
    },
    {
      "x": -6,
      "y": 32,
      "z": -2,
      "name": "Soil_Grass"
    },
    {
      "x": -6,
      "y": 33,
      "z": -2,
      "name": "Plant_Grass_Sharp"
    },
    {
      "x": -6,
      "y": 21,
      "z": -1,
      "name": "Rock_Stone_Mossy"
    },
    {
      "x": -6,
      "y": 22,
      "z": -1,
      "name": "Rock_Stone"
    },
    {
      "x": -6,
      "y": 23,
      "z": -1,
      "name": "Rock_Stone"
    },
    {
      "x": -6,
      "y": 24,
      "z": -1,
      "name": "Rock_Stone"
    },
    {
      "x": -6,
      "y": 25,
      "z": -1,
      "name": "Rock_Stone"
    },
    {
      "x": -6,
      "y": 26,
      "z": -1,
      "name": "Rock_Stone"
    },
    {
      "x": -6,
      "y": 27,
      "z": -1,
      "name": "Rock_Stone"
    },
    {
      "x": -6,
      "y": 28,
      "z": -1,
      "name": "Rock_Stone"
    },
    {
      "x": -6,
      "y": 29,
      "z": -1,
      "name": "Rock_Stone"
    },
    {
      "x": -6,
      "y": 30,
      "z": -1,
      "name": "Soil_Dirt"
    },
    {
      "x": -6,
      "y": 31,
      "z": -1,
      "name": "Soil_Dirt"
    },
    {
      "x": -6,
      "y": 32,
      "z": -1,
      "name": "Soil_Dirt"
    },
    {
      "x": -6,
      "y": 33,
      "z": -1,
      "name": "Soil_Grass"
    },
    {
      "x": -6,
      "y": 21,
      "z": 0,
      "name": "Rock_Stone"
    },
    {
      "x": -6,
      "y": 22,
      "z": 0,
      "name": "Rock_Stone"
    },
    {
      "x": -6,
      "y": 23,
      "z": 0,
      "name": "Rock_Stone"
    },
    {
      "x": -6,
      "y": 24,
      "z": 0,
      "name": "Rock_Stone"
    },
    {
      "x": -6,
      "y": 25,
      "z": 0,
      "name": "Rock_Stone"
    },
    {
      "x": -6,
      "y": 26,
      "z": 0,
      "name": "Rock_Stone"
    },
    {
      "x": -6,
      "y": 27,
      "z": 0,
      "name": "Rock_Stone"
    },
    {
      "x": -6,
      "y": 28,
      "z": 0,
      "name": "Rock_Stone"
    },
    {
      "x": -6,
      "y": 29,
      "z": 0,
      "name": "Rock_Stone"
    },
    {
      "x": -6,
      "y": 30,
      "z": 0,
      "name": "Rock_Stone"
    },
    {
      "x": -6,
      "y": 31,
      "z": 0,
      "name": "Rock_Stone"
    },
    {
      "x": -6,
      "y": 32,
      "z": 0,
      "name": "Soil_Dirt"
    },
    {
      "x": -6,
      "y": 33,
      "z": 0,
      "name": "Soil_Grass"
    },
    {
      "x": -6,
      "y": 21,
      "z": 1,
      "name": "Rock_Stone"
    },
    {
      "x": -6,
      "y": 22,
      "z": 1,
      "name": "Rock_Stone"
    },
    {
      "x": -6,
      "y": 23,
      "z": 1,
      "name": "Rock_Stone_Mossy"
    },
    {
      "x": -6,
      "y": 24,
      "z": 1,
      "name": "Rock_Stone"
    },
    {
      "x": -6,
      "y": 25,
      "z": 1,
      "name": "Rock_Stone"
    },
    {
      "x": -6,
      "y": 26,
      "z": 1,
      "name": "Rock_Stone"
    },
    {
      "x": -6,
      "y": 27,
      "z": 1,
      "name": "Rock_Stone"
    },
    {
      "x": -6,
      "y": 28,
      "z": 1,
      "name": "Rock_Stone"
    },
    {
      "x": -6,
      "y": 29,
      "z": 1,
      "name": "Rock_Stone"
    },
    {
      "x": -6,
      "y": 30,
      "z": 1,
      "name": "Rock_Stone"
    },
    {
      "x": -6,
      "y": 31,
      "z": 1,
      "name": "Rock_Stone"
    },
    {
      "x": -6,
      "y": 32,
      "z": 1,
      "name": "Soil_Dirt"
    },
    {
      "x": -6,
      "y": 33,
      "z": 1,
      "name": "Soil_Grass"
    },
    {
      "x": -6,
      "y": 34,
      "z": 1,
      "name": "Plant_Bush"
    },
    {
      "x": -6,
      "y": 21,
      "z": 2,
      "name": "Rock_Stone"
    },
    {
      "x": -6,
      "y": 22,
      "z": 2,
      "name": "Rock_Stone"
    },
    {
      "x": -6,
      "y": 23,
      "z": 2,
      "name": "Rock_Stone"
    },
    {
      "x": -6,
      "y": 24,
      "z": 2,
      "name": "Rock_Stone"
    },
    {
      "x": -6,
      "y": 25,
      "z": 2,
      "name": "Rock_Stone"
    },
    {
      "x": -6,
      "y": 26,
      "z": 2,
      "name": "Rock_Stone"
    },
    {
      "x": -6,
      "y": 27,
      "z": 2,
      "name": "Rock_Stone"
    },
    {
      "x": -6,
      "y": 28,
      "z": 2,
      "name": "Rock_Stone"
    },
    {
      "x": -6,
      "y": 29,
      "z": 2,
      "name": "Rock_Stone"
    },
    {
      "x": -6,
      "y": 30,
      "z": 2,
      "name": "Rock_Stone"
    },
    {
      "x": -6,
      "y": 31,
      "z": 2,
      "name": "Rock_Stone"
    },
    {
      "x": -6,
      "y": 32,
      "z": 2,
      "name": "Soil_Dirt"
    },
    {
      "x": -6,
      "y": 33,
      "z": 2,
      "name": "Soil_Grass"
    },
    {
      "x": -6,
      "y": 34,
      "z": 2,
      "name": "Plant_Grass_Sharp"
    },
    {
      "x": -6,
      "y": 22,
      "z": 3,
      "name": "Rock_Stone"
    },
    {
      "x": -6,
      "y": 23,
      "z": 3,
      "name": "Rock_Stone"
    },
    {
      "x": -6,
      "y": 24,
      "z": 3,
      "name": "Rock_Stone_Mossy"
    },
    {
      "x": -6,
      "y": 25,
      "z": 3,
      "name": "Rock_Stone"
    },
    {
      "x": -6,
      "y": 26,
      "z": 3,
      "name": "Rock_Stone"
    },
    {
      "x": -6,
      "y": 27,
      "z": 3,
      "name": "Rock_Stone"
    },
    {
      "x": -6,
      "y": 28,
      "z": 3,
      "name": "Rock_Stone"
    },
    {
      "x": -6,
      "y": 29,
      "z": 3,
      "name": "Rock_Stone"
    },
    {
      "x": -6,
      "y": 30,
      "z": 3,
      "name": "Rock_Stone"
    },
    {
      "x": -6,
      "y": 31,
      "z": 3,
      "name": "Soil_Dirt"
    },
    {
      "x": -6,
      "y": 32,
      "z": 3,
      "name": "Soil_Dirt"
    },
    {
      "x": -6,
      "y": 33,
      "z": 3,
      "name": "Soil_Grass"
    },
    {
      "x": -6,
      "y": 34,
      "z": 3,
      "name": "Plant_Grass_Sharp"
    },
    {
      "x": -6,
      "y": 22,
      "z": 4,
      "name": "Rock_Stone"
    },
    {
      "x": -6,
      "y": 23,
      "z": 4,
      "name": "Rock_Stone"
    },
    {
      "x": -6,
      "y": 24,
      "z": 4,
      "name": "Rock_Stone"
    },
    {
      "x": -6,
      "y": 25,
      "z": 4,
      "name": "Soil_Dirt"
    },
    {
      "x": -6,
      "y": 26,
      "z": 4,
      "name": "Soil_Dirt"
    },
    {
      "x": -6,
      "y": 27,
      "z": 4,
      "name": "Rock_Stone"
    },
    {
      "x": -6,
      "y": 28,
      "z": 4,
      "name": "Rock_Stone"
    },
    {
      "x": -6,
      "y": 29,
      "z": 4,
      "name": "Rock_Stone"
    },
    {
      "x": -6,
      "y": 30,
      "z": 4,
      "name": "Rock_Stone"
    },
    {
      "x": -6,
      "y": 31,
      "z": 4,
      "name": "Soil_Dirt"
    },
    {
      "x": -6,
      "y": 32,
      "z": 4,
      "name": "Soil_Dirt"
    },
    {
      "x": -6,
      "y": 33,
      "z": 4,
      "name": "Soil_Grass"
    },
    {
      "x": -6,
      "y": 22,
      "z": 5,
      "name": "Rock_Stone"
    },
    {
      "x": -6,
      "y": 23,
      "z": 5,
      "name": "Rock_Stone"
    },
    {
      "x": -6,
      "y": 24,
      "z": 5,
      "name": "Soil_Dirt"
    },
    {
      "x": -6,
      "y": 25,
      "z": 5,
      "name": "Soil_Dirt"
    },
    {
      "x": -6,
      "y": 26,
      "z": 5,
      "name": "Soil_Dirt"
    },
    {
      "x": -6,
      "y": 27,
      "z": 5,
      "name": "Soil_Grass"
    },
    {
      "x": -6,
      "y": 28,
      "z": 5,
      "name": "Plant_Grass_Sharp"
    },
    {
      "x": -6,
      "y": 23,
      "z": 6,
      "name": "Rock_Stone"
    },
    {
      "x": -6,
      "y": 24,
      "z": 6,
      "name": "Soil_Dirt"
    },
    {
      "x": -6,
      "y": 25,
      "z": 6,
      "name": "Soil_Dirt"
    },
    {
      "x": -6,
      "y": 26,
      "z": 6,
      "name": "Soil_Dirt"
    },
    {
      "x": -6,
      "y": 27,
      "z": 6,
      "name": "Soil_Grass"
    },
    {
      "x": -6,
      "y": 28,
      "z": 6,
      "name": "Plant_Grass_Sharp"
    },
    {
      "x": -6,
      "y": 25,
      "z": 7,
      "name": "Soil_Dirt"
    },
    {
      "x": -6,
      "y": 26,
      "z": 7,
      "name": "Soil_Dirt"
    },
    {
      "x": -6,
      "y": 27,
      "z": 7,
      "name": "Soil_Grass"
    },
    {
      "x": -5,
      "y": 30,
      "z": -6,
      "name": "Soil_Dirt"
    },
    {
      "x": -5,
      "y": 31,
      "z": -6,
      "name": "Soil_Grass"
    },
    {
      "x": -5,
      "y": 24,
      "z": -5,
      "name": "Rock_Stone"
    },
    {
      "x": -5,
      "y": 25,
      "z": -5,
      "name": "Rock_Stone"
    },
    {
      "x": -5,
      "y": 26,
      "z": -5,
      "name": "Rock_Stone"
    },
    {
      "x": -5,
      "y": 27,
      "z": -5,
      "name": "Rock_Stone"
    },
    {
      "x": -5,
      "y": 28,
      "z": -5,
      "name": "Rock_Stone"
    },
    {
      "x": -5,
      "y": 29,
      "z": -5,
      "name": "Rock_Stone"
    },
    {
      "x": -5,
      "y": 30,
      "z": -5,
      "name": "Soil_Dirt"
    },
    {
      "x": -5,
      "y": 31,
      "z": -5,
      "name": "Soil_Grass"
    },
    {
      "x": -5,
      "y": 22,
      "z": -4,
      "name": "Rock_Stone"
    },
    {
      "x": -5,
      "y": 23,
      "z": -4,
      "name": "Rock_Stone"
    },
    {
      "x": -5,
      "y": 24,
      "z": -4,
      "name": "Rock_Stone"
    },
    {
      "x": -5,
      "y": 25,
      "z": -4,
      "name": "Rock_Stone"
    },
    {
      "x": -5,
      "y": 26,
      "z": -4,
      "name": "Rock_Stone"
    },
    {
      "x": -5,
      "y": 27,
      "z": -4,
      "name": "Rock_Stone"
    },
    {
      "x": -5,
      "y": 28,
      "z": -4,
      "name": "Rock_Stone"
    },
    {
      "x": -5,
      "y": 29,
      "z": -4,
      "name": "Rock_Stone"
    },
    {
      "x": -5,
      "y": 30,
      "z": -4,
      "name": "Soil_Dirt"
    },
    {
      "x": -5,
      "y": 31,
      "z": -4,
      "name": "Soil_Dirt"
    },
    {
      "x": -5,
      "y": 32,
      "z": -4,
      "name": "Soil_Grass"
    },
    {
      "x": -5,
      "y": 33,
      "z": -4,
      "name": "Plant_Grass_Sharp"
    },
    {
      "x": -5,
      "y": 21,
      "z": -3,
      "name": "Rock_Stone"
    },
    {
      "x": -5,
      "y": 22,
      "z": -3,
      "name": "Rock_Stone"
    },
    {
      "x": -5,
      "y": 23,
      "z": -3,
      "name": "Rock_Stone"
    },
    {
      "x": -5,
      "y": 24,
      "z": -3,
      "name": "Rock_Stone"
    },
    {
      "x": -5,
      "y": 25,
      "z": -3,
      "name": "Rock_Stone"
    },
    {
      "x": -5,
      "y": 26,
      "z": -3,
      "name": "Rock_Stone"
    },
    {
      "x": -5,
      "y": 27,
      "z": -3,
      "name": "Rock_Stone"
    },
    {
      "x": -5,
      "y": 28,
      "z": -3,
      "name": "Rock_Stone"
    },
    {
      "x": -5,
      "y": 29,
      "z": -3,
      "name": "Rock_Stone"
    },
    {
      "x": -5,
      "y": 30,
      "z": -3,
      "name": "Soil_Dirt"
    },
    {
      "x": -5,
      "y": 31,
      "z": -3,
      "name": "Soil_Dirt"
    },
    {
      "x": -5,
      "y": 32,
      "z": -3,
      "name": "Soil_Grass"
    },
    {
      "x": -5,
      "y": 33,
      "z": -3,
      "name": "Plant_Grass_Sharp"
    },
    {
      "x": -5,
      "y": 21,
      "z": -2,
      "name": "Rock_Stone_Mossy"
    },
    {
      "x": -5,
      "y": 22,
      "z": -2,
      "name": "Rock_Stone"
    },
    {
      "x": -5,
      "y": 23,
      "z": -2,
      "name": "Rock_Stone"
    },
    {
      "x": -5,
      "y": 24,
      "z": -2,
      "name": "Rock_Stone"
    },
    {
      "x": -5,
      "y": 25,
      "z": -2,
      "name": "Rock_Stone"
    },
    {
      "x": -5,
      "y": 26,
      "z": -2,
      "name": "Rock_Stone"
    },
    {
      "x": -5,
      "y": 27,
      "z": -2,
      "name": "Rock_Stone"
    },
    {
      "x": -5,
      "y": 28,
      "z": -2,
      "name": "Rock_Stone"
    },
    {
      "x": -5,
      "y": 29,
      "z": -2,
      "name": "Rock_Stone"
    },
    {
      "x": -5,
      "y": 30,
      "z": -2,
      "name": "Soil_Dirt"
    },
    {
      "x": -5,
      "y": 31,
      "z": -2,
      "name": "Soil_Dirt"
    },
    {
      "x": -5,
      "y": 32,
      "z": -2,
      "name": "Soil_Dirt"
    },
    {
      "x": -5,
      "y": 33,
      "z": -2,
      "name": "Soil_Grass"
    },
    {
      "x": -5,
      "y": 20,
      "z": -1,
      "name": "Rock_Stone"
    },
    {
      "x": -5,
      "y": 21,
      "z": -1,
      "name": "Rock_Stone"
    },
    {
      "x": -5,
      "y": 22,
      "z": -1,
      "name": "Rock_Stone"
    },
    {
      "x": -5,
      "y": 23,
      "z": -1,
      "name": "Rock_Stone"
    },
    {
      "x": -5,
      "y": 24,
      "z": -1,
      "name": "Rock_Stone"
    },
    {
      "x": -5,
      "y": 25,
      "z": -1,
      "name": "Rock_Stone"
    },
    {
      "x": -5,
      "y": 26,
      "z": -1,
      "name": "Rock_Stone"
    },
    {
      "x": -5,
      "y": 27,
      "z": -1,
      "name": "Rock_Stone"
    },
    {
      "x": -5,
      "y": 28,
      "z": -1,
      "name": "Rock_Stone"
    },
    {
      "x": -5,
      "y": 29,
      "z": -1,
      "name": "Rock_Stone"
    },
    {
      "x": -5,
      "y": 30,
      "z": -1,
      "name": "Rock_Stone"
    },
    {
      "x": -5,
      "y": 31,
      "z": -1,
      "name": "Rock_Stone"
    },
    {
      "x": -5,
      "y": 32,
      "z": -1,
      "name": "Soil_Dirt"
    },
    {
      "x": -5,
      "y": 33,
      "z": -1,
      "name": "Soil_Grass"
    },
    {
      "x": -5,
      "y": 20,
      "z": 0,
      "name": "Rock_Stone"
    },
    {
      "x": -5,
      "y": 21,
      "z": 0,
      "name": "Rock_Stone"
    },
    {
      "x": -5,
      "y": 22,
      "z": 0,
      "name": "Rock_Stone"
    },
    {
      "x": -5,
      "y": 23,
      "z": 0,
      "name": "Rock_Stone"
    },
    {
      "x": -5,
      "y": 24,
      "z": 0,
      "name": "Rock_Stone"
    },
    {
      "x": -5,
      "y": 25,
      "z": 0,
      "name": "Rock_Stone"
    },
    {
      "x": -5,
      "y": 26,
      "z": 0,
      "name": "Rock_Stone"
    },
    {
      "x": -5,
      "y": 27,
      "z": 0,
      "name": "Rock_Stone"
    },
    {
      "x": -5,
      "y": 28,
      "z": 0,
      "name": "Rock_Stone"
    },
    {
      "x": -5,
      "y": 29,
      "z": 0,
      "name": "Rock_Stone"
    },
    {
      "x": -5,
      "y": 30,
      "z": 0,
      "name": "Rock_Stone"
    },
    {
      "x": -5,
      "y": 31,
      "z": 0,
      "name": "Rock_Stone"
    },
    {
      "x": -5,
      "y": 32,
      "z": 0,
      "name": "Rock_Stone"
    },
    {
      "x": -5,
      "y": 33,
      "z": 0,
      "name": "Soil_Grass"
    },
    {
      "x": -5,
      "y": 34,
      "z": 0,
      "name": "Plant_Bush"
    },
    {
      "x": -5,
      "y": 20,
      "z": 1,
      "name": "Rock_Stone"
    },
    {
      "x": -5,
      "y": 21,
      "z": 1,
      "name": "Rock_Stone"
    },
    {
      "x": -5,
      "y": 22,
      "z": 1,
      "name": "Rock_Stone"
    },
    {
      "x": -5,
      "y": 23,
      "z": 1,
      "name": "Rock_Stone"
    },
    {
      "x": -5,
      "y": 24,
      "z": 1,
      "name": "Rock_Stone"
    },
    {
      "x": -5,
      "y": 25,
      "z": 1,
      "name": "Rock_Stone"
    },
    {
      "x": -5,
      "y": 26,
      "z": 1,
      "name": "Rock_Stone"
    },
    {
      "x": -5,
      "y": 27,
      "z": 1,
      "name": "Rock_Stone"
    },
    {
      "x": -5,
      "y": 28,
      "z": 1,
      "name": "Rock_Stone"
    },
    {
      "x": -5,
      "y": 29,
      "z": 1,
      "name": "Rock_Stone"
    },
    {
      "x": -5,
      "y": 30,
      "z": 1,
      "name": "Rock_Stone"
    },
    {
      "x": -5,
      "y": 31,
      "z": 1,
      "name": "Rock_Stone"
    },
    {
      "x": -5,
      "y": 32,
      "z": 1,
      "name": "Rock_Stone"
    },
    {
      "x": -5,
      "y": 33,
      "z": 1,
      "name": "Soil_Grass"
    },
    {
      "x": -5,
      "y": 34,
      "z": 1,
      "name": "Plant_Grass_Sharp"
    },
    {
      "x": -5,
      "y": 21,
      "z": 2,
      "name": "Rock_Stone"
    },
    {
      "x": -5,
      "y": 22,
      "z": 2,
      "name": "Rock_Stone"
    },
    {
      "x": -5,
      "y": 23,
      "z": 2,
      "name": "Rock_Stone"
    },
    {
      "x": -5,
      "y": 24,
      "z": 2,
      "name": "Rock_Stone"
    },
    {
      "x": -5,
      "y": 25,
      "z": 2,
      "name": "Rock_Stone"
    },
    {
      "x": -5,
      "y": 26,
      "z": 2,
      "name": "Rock_Stone"
    },
    {
      "x": -5,
      "y": 27,
      "z": 2,
      "name": "Rock_Stone"
    },
    {
      "x": -5,
      "y": 28,
      "z": 2,
      "name": "Rock_Stone"
    },
    {
      "x": -5,
      "y": 29,
      "z": 2,
      "name": "Rock_Stone"
    },
    {
      "x": -5,
      "y": 30,
      "z": 2,
      "name": "Rock_Stone"
    },
    {
      "x": -5,
      "y": 31,
      "z": 2,
      "name": "Rock_Stone"
    },
    {
      "x": -5,
      "y": 32,
      "z": 2,
      "name": "Soil_Dirt"
    },
    {
      "x": -5,
      "y": 33,
      "z": 2,
      "name": "Soil_Grass"
    },
    {
      "x": -5,
      "y": 34,
      "z": 2,
      "name": "*Plant_Crop_Berry_Block_State_Definitions_StageFinal",
      "components": {
        "Components": {
          "FarmingBlock": {}
        }
      }
    },
    {
      "x": -5,
      "y": 21,
      "z": 3,
      "name": "Rock_Stone"
    },
    {
      "x": -5,
      "y": 22,
      "z": 3,
      "name": "Rock_Stone"
    },
    {
      "x": -5,
      "y": 23,
      "z": 3,
      "name": "Rock_Stone"
    },
    {
      "x": -5,
      "y": 24,
      "z": 3,
      "name": "Rock_Stone"
    },
    {
      "x": -5,
      "y": 25,
      "z": 3,
      "name": "Rock_Stone"
    },
    {
      "x": -5,
      "y": 26,
      "z": 3,
      "name": "Rock_Stone"
    },
    {
      "x": -5,
      "y": 27,
      "z": 3,
      "name": "Rock_Stone"
    },
    {
      "x": -5,
      "y": 28,
      "z": 3,
      "name": "Rock_Stone"
    },
    {
      "x": -5,
      "y": 29,
      "z": 3,
      "name": "Rock_Stone"
    },
    {
      "x": -5,
      "y": 30,
      "z": 3,
      "name": "Rock_Stone"
    },
    {
      "x": -5,
      "y": 31,
      "z": 3,
      "name": "Soil_Dirt"
    },
    {
      "x": -5,
      "y": 32,
      "z": 3,
      "name": "Soil_Dirt"
    },
    {
      "x": -5,
      "y": 33,
      "z": 3,
      "name": "Soil_Grass"
    },
    {
      "x": -5,
      "y": 34,
      "z": 3,
      "name": "Plant_Grass_Sharp"
    },
    {
      "x": -5,
      "y": 21,
      "z": 4,
      "name": "Rock_Stone"
    },
    {
      "x": -5,
      "y": 22,
      "z": 4,
      "name": "Rock_Stone"
    },
    {
      "x": -5,
      "y": 23,
      "z": 4,
      "name": "Rock_Stone"
    },
    {
      "x": -5,
      "y": 24,
      "z": 4,
      "name": "Rock_Stone"
    },
    {
      "x": -5,
      "y": 25,
      "z": 4,
      "name": "Soil_Dirt"
    },
    {
      "x": -5,
      "y": 26,
      "z": 4,
      "name": "Rock_Stone"
    },
    {
      "x": -5,
      "y": 27,
      "z": 4,
      "name": "Rock_Stone"
    },
    {
      "x": -5,
      "y": 28,
      "z": 4,
      "name": "Rock_Stone"
    },
    {
      "x": -5,
      "y": 29,
      "z": 4,
      "name": "Rock_Stone"
    },
    {
      "x": -5,
      "y": 30,
      "z": 4,
      "name": "Rock_Stone"
    },
    {
      "x": -5,
      "y": 31,
      "z": 4,
      "name": "Soil_Dirt"
    },
    {
      "x": -5,
      "y": 32,
      "z": 4,
      "name": "Soil_Dirt"
    },
    {
      "x": -5,
      "y": 33,
      "z": 4,
      "name": "Soil_Grass"
    },
    {
      "x": -5,
      "y": 21,
      "z": 5,
      "name": "Rock_Stone"
    },
    {
      "x": -5,
      "y": 22,
      "z": 5,
      "name": "Rock_Stone"
    },
    {
      "x": -5,
      "y": 23,
      "z": 5,
      "name": "Rock_Stone"
    },
    {
      "x": -5,
      "y": 24,
      "z": 5,
      "name": "Soil_Dirt"
    },
    {
      "x": -5,
      "y": 25,
      "z": 5,
      "name": "Soil_Dirt"
    },
    {
      "x": -5,
      "y": 26,
      "z": 5,
      "name": "Soil_Dirt"
    },
    {
      "x": -5,
      "y": 27,
      "z": 5,
      "name": "Soil_Grass"
    },
    {
      "x": -5,
      "y": 21,
      "z": 6,
      "name": "Rock_Stone"
    },
    {
      "x": -5,
      "y": 22,
      "z": 6,
      "name": "Rock_Stone"
    },
    {
      "x": -5,
      "y": 23,
      "z": 6,
      "name": "Rock_Stone"
    },
    {
      "x": -5,
      "y": 24,
      "z": 6,
      "name": "Soil_Dirt"
    },
    {
      "x": -5,
      "y": 25,
      "z": 6,
      "name": "Soil_Dirt"
    },
    {
      "x": -5,
      "y": 26,
      "z": 6,
      "name": "Soil_Dirt"
    },
    {
      "x": -5,
      "y": 27,
      "z": 6,
      "name": "Soil_Grass"
    },
    {
      "x": -5,
      "y": 23,
      "z": 7,
      "name": "Rock_Stone"
    },
    {
      "x": -5,
      "y": 24,
      "z": 7,
      "name": "Soil_Dirt"
    },
    {
      "x": -5,
      "y": 25,
      "z": 7,
      "name": "Soil_Dirt"
    },
    {
      "x": -5,
      "y": 26,
      "z": 7,
      "name": "Soil_Dirt"
    },
    {
      "x": -5,
      "y": 27,
      "z": 7,
      "name": "Soil_Grass"
    },
    {
      "x": -5,
      "y": 27,
      "z": 8,
      "name": "Soil_Grass"
    },
    {
      "x": -4,
      "y": 28,
      "z": -7,
      "name": "Rock_Stone"
    },
    {
      "x": -4,
      "y": 29,
      "z": -7,
      "name": "Rock_Stone"
    },
    {
      "x": -4,
      "y": 30,
      "z": -7,
      "name": "Soil_Dirt"
    },
    {
      "x": -4,
      "y": 31,
      "z": -7,
      "name": "Soil_Grass"
    },
    {
      "x": -4,
      "y": 26,
      "z": -6,
      "name": "Rock_Stone"
    },
    {
      "x": -4,
      "y": 27,
      "z": -6,
      "name": "Rock_Stone"
    },
    {
      "x": -4,
      "y": 28,
      "z": -6,
      "name": "Rock_Stone"
    },
    {
      "x": -4,
      "y": 29,
      "z": -6,
      "name": "Rock_Stone"
    },
    {
      "x": -4,
      "y": 30,
      "z": -6,
      "name": "Soil_Dirt"
    },
    {
      "x": -4,
      "y": 31,
      "z": -6,
      "name": "Soil_Grass"
    },
    {
      "x": -4,
      "y": 23,
      "z": -5,
      "name": "Rock_Stone"
    },
    {
      "x": -4,
      "y": 24,
      "z": -5,
      "name": "Rock_Stone"
    },
    {
      "x": -4,
      "y": 25,
      "z": -5,
      "name": "Rock_Stone"
    },
    {
      "x": -4,
      "y": 26,
      "z": -5,
      "name": "Rock_Stone"
    },
    {
      "x": -4,
      "y": 27,
      "z": -5,
      "name": "Rock_Stone"
    },
    {
      "x": -4,
      "y": 28,
      "z": -5,
      "name": "Rock_Stone"
    },
    {
      "x": -4,
      "y": 29,
      "z": -5,
      "name": "Rock_Stone"
    },
    {
      "x": -4,
      "y": 30,
      "z": -5,
      "name": "Soil_Dirt"
    },
    {
      "x": -4,
      "y": 31,
      "z": -5,
      "name": "Soil_Grass"
    },
    {
      "x": -4,
      "y": 22,
      "z": -4,
      "name": "Rock_Stone"
    },
    {
      "x": -4,
      "y": 23,
      "z": -4,
      "name": "Rock_Stone"
    },
    {
      "x": -4,
      "y": 24,
      "z": -4,
      "name": "Rock_Stone"
    },
    {
      "x": -4,
      "y": 25,
      "z": -4,
      "name": "Rock_Stone"
    },
    {
      "x": -4,
      "y": 26,
      "z": -4,
      "name": "Rock_Stone"
    },
    {
      "x": -4,
      "y": 27,
      "z": -4,
      "name": "Rock_Stone"
    },
    {
      "x": -4,
      "y": 28,
      "z": -4,
      "name": "Rock_Stone"
    },
    {
      "x": -4,
      "y": 29,
      "z": -4,
      "name": "Rock_Stone"
    },
    {
      "x": -4,
      "y": 30,
      "z": -4,
      "name": "Rock_Stone"
    },
    {
      "x": -4,
      "y": 31,
      "z": -4,
      "name": "Soil_Dirt"
    },
    {
      "x": -4,
      "y": 32,
      "z": -4,
      "name": "Soil_Grass"
    },
    {
      "x": -4,
      "y": 33,
      "z": -4,
      "name": "Plant_Grass_Sharp"
    },
    {
      "x": -4,
      "y": 21,
      "z": -3,
      "name": "Rock_Stone"
    },
    {
      "x": -4,
      "y": 22,
      "z": -3,
      "name": "Rock_Stone"
    },
    {
      "x": -4,
      "y": 23,
      "z": -3,
      "name": "Rock_Stone"
    },
    {
      "x": -4,
      "y": 24,
      "z": -3,
      "name": "Rock_Stone"
    },
    {
      "x": -4,
      "y": 25,
      "z": -3,
      "name": "Rock_Stone"
    },
    {
      "x": -4,
      "y": 26,
      "z": -3,
      "name": "Rock_Stone"
    },
    {
      "x": -4,
      "y": 27,
      "z": -3,
      "name": "Rock_Stone"
    },
    {
      "x": -4,
      "y": 28,
      "z": -3,
      "name": "Rock_Stone"
    },
    {
      "x": -4,
      "y": 29,
      "z": -3,
      "name": "Rock_Stone"
    },
    {
      "x": -4,
      "y": 30,
      "z": -3,
      "name": "Rock_Stone"
    },
    {
      "x": -4,
      "y": 31,
      "z": -3,
      "name": "Soil_Dirt"
    },
    {
      "x": -4,
      "y": 32,
      "z": -3,
      "name": "Soil_Grass"
    },
    {
      "x": -4,
      "y": 33,
      "z": -3,
      "name": "Plant_Grass_Sharp_Tall"
    },
    {
      "x": -4,
      "y": 34,
      "z": -3,
      "name": "Plant_Grass_Sharp_Tall",
      "filler": 1024
    },
    {
      "x": -4,
      "y": 20,
      "z": -2,
      "name": "Rock_Stone"
    },
    {
      "x": -4,
      "y": 21,
      "z": -2,
      "name": "Rock_Stone"
    },
    {
      "x": -4,
      "y": 22,
      "z": -2,
      "name": "Rock_Stone"
    },
    {
      "x": -4,
      "y": 23,
      "z": -2,
      "name": "Rock_Stone"
    },
    {
      "x": -4,
      "y": 24,
      "z": -2,
      "name": "Rock_Stone"
    },
    {
      "x": -4,
      "y": 25,
      "z": -2,
      "name": "Rock_Stone"
    },
    {
      "x": -4,
      "y": 26,
      "z": -2,
      "name": "Rock_Stone"
    },
    {
      "x": -4,
      "y": 27,
      "z": -2,
      "name": "Rock_Stone"
    },
    {
      "x": -4,
      "y": 28,
      "z": -2,
      "name": "Rock_Stone"
    },
    {
      "x": -4,
      "y": 29,
      "z": -2,
      "name": "Rock_Stone"
    },
    {
      "x": -4,
      "y": 30,
      "z": -2,
      "name": "Rock_Stone"
    },
    {
      "x": -4,
      "y": 31,
      "z": -2,
      "name": "Soil_Dirt"
    },
    {
      "x": -4,
      "y": 32,
      "z": -2,
      "name": "Soil_Dirt"
    },
    {
      "x": -4,
      "y": 33,
      "z": -2,
      "name": "Soil_Grass"
    },
    {
      "x": -4,
      "y": 20,
      "z": -1,
      "name": "Rock_Stone"
    },
    {
      "x": -4,
      "y": 21,
      "z": -1,
      "name": "Rock_Stone"
    },
    {
      "x": -4,
      "y": 22,
      "z": -1,
      "name": "Rock_Stone"
    },
    {
      "x": -4,
      "y": 23,
      "z": -1,
      "name": "Rock_Stone"
    },
    {
      "x": -4,
      "y": 24,
      "z": -1,
      "name": "Rock_Stone"
    },
    {
      "x": -4,
      "y": 25,
      "z": -1,
      "name": "Rock_Stone"
    },
    {
      "x": -4,
      "y": 26,
      "z": -1,
      "name": "Rock_Stone"
    },
    {
      "x": -4,
      "y": 27,
      "z": -1,
      "name": "Rock_Stone"
    },
    {
      "x": -4,
      "y": 28,
      "z": -1,
      "name": "Rock_Stone"
    },
    {
      "x": -4,
      "y": 29,
      "z": -1,
      "name": "Rock_Stone"
    },
    {
      "x": -4,
      "y": 30,
      "z": -1,
      "name": "Rock_Stone"
    },
    {
      "x": -4,
      "y": 31,
      "z": -1,
      "name": "Rock_Stone"
    },
    {
      "x": -4,
      "y": 32,
      "z": -1,
      "name": "Soil_Dirt"
    },
    {
      "x": -4,
      "y": 33,
      "z": -1,
      "name": "Soil_Grass"
    },
    {
      "x": -4,
      "y": 20,
      "z": 0,
      "name": "Rock_Stone"
    },
    {
      "x": -4,
      "y": 21,
      "z": 0,
      "name": "Rock_Stone"
    },
    {
      "x": -4,
      "y": 22,
      "z": 0,
      "name": "Rock_Stone"
    },
    {
      "x": -4,
      "y": 23,
      "z": 0,
      "name": "Rock_Stone"
    },
    {
      "x": -4,
      "y": 24,
      "z": 0,
      "name": "Rock_Stone"
    },
    {
      "x": -4,
      "y": 25,
      "z": 0,
      "name": "Rock_Stone"
    },
    {
      "x": -4,
      "y": 26,
      "z": 0,
      "name": "Rock_Stone"
    },
    {
      "x": -4,
      "y": 27,
      "z": 0,
      "name": "Rock_Stone"
    },
    {
      "x": -4,
      "y": 28,
      "z": 0,
      "name": "Rock_Stone"
    },
    {
      "x": -4,
      "y": 29,
      "z": 0,
      "name": "Rock_Stone"
    },
    {
      "x": -4,
      "y": 30,
      "z": 0,
      "name": "Rock_Stone"
    },
    {
      "x": -4,
      "y": 31,
      "z": 0,
      "name": "Rock_Stone"
    },
    {
      "x": -4,
      "y": 32,
      "z": 0,
      "name": "Soil_Dirt"
    },
    {
      "x": -4,
      "y": 33,
      "z": 0,
      "name": "Soil_Grass"
    },
    {
      "x": -4,
      "y": 34,
      "z": 0,
      "name": "Plant_Grass_Sharp"
    },
    {
      "x": -4,
      "y": 20,
      "z": 1,
      "name": "Rock_Stone"
    },
    {
      "x": -4,
      "y": 21,
      "z": 1,
      "name": "Rock_Stone"
    },
    {
      "x": -4,
      "y": 22,
      "z": 1,
      "name": "Rock_Stone"
    },
    {
      "x": -4,
      "y": 23,
      "z": 1,
      "name": "Rock_Stone"
    },
    {
      "x": -4,
      "y": 24,
      "z": 1,
      "name": "Rock_Stone"
    },
    {
      "x": -4,
      "y": 25,
      "z": 1,
      "name": "Rock_Stone"
    },
    {
      "x": -4,
      "y": 26,
      "z": 1,
      "name": "Rock_Stone"
    },
    {
      "x": -4,
      "y": 27,
      "z": 1,
      "name": "Rock_Stone"
    },
    {
      "x": -4,
      "y": 28,
      "z": 1,
      "name": "Rock_Stone"
    },
    {
      "x": -4,
      "y": 29,
      "z": 1,
      "name": "Rock_Stone"
    },
    {
      "x": -4,
      "y": 30,
      "z": 1,
      "name": "Rock_Stone"
    },
    {
      "x": -4,
      "y": 31,
      "z": 1,
      "name": "Rock_Stone"
    },
    {
      "x": -4,
      "y": 32,
      "z": 1,
      "name": "Soil_Dirt"
    },
    {
      "x": -4,
      "y": 33,
      "z": 1,
      "name": "Soil_Grass"
    },
    {
      "x": -4,
      "y": 34,
      "z": 1,
      "name": "Plant_Grass_Sharp"
    },
    {
      "x": -4,
      "y": 20,
      "z": 2,
      "name": "Rock_Stone"
    },
    {
      "x": -4,
      "y": 21,
      "z": 2,
      "name": "Rock_Stone"
    },
    {
      "x": -4,
      "y": 22,
      "z": 2,
      "name": "Rock_Stone"
    },
    {
      "x": -4,
      "y": 23,
      "z": 2,
      "name": "Rock_Stone"
    },
    {
      "x": -4,
      "y": 24,
      "z": 2,
      "name": "Rock_Stone"
    },
    {
      "x": -4,
      "y": 25,
      "z": 2,
      "name": "Rock_Stone"
    },
    {
      "x": -4,
      "y": 26,
      "z": 2,
      "name": "Rock_Stone"
    },
    {
      "x": -4,
      "y": 27,
      "z": 2,
      "name": "Rock_Stone"
    },
    {
      "x": -4,
      "y": 28,
      "z": 2,
      "name": "Rock_Stone"
    },
    {
      "x": -4,
      "y": 29,
      "z": 2,
      "name": "Rock_Stone"
    },
    {
      "x": -4,
      "y": 30,
      "z": 2,
      "name": "Rock_Stone"
    },
    {
      "x": -4,
      "y": 31,
      "z": 2,
      "name": "Rock_Stone"
    },
    {
      "x": -4,
      "y": 32,
      "z": 2,
      "name": "Soil_Dirt"
    },
    {
      "x": -4,
      "y": 33,
      "z": 2,
      "name": "Soil_Grass"
    },
    {
      "x": -4,
      "y": 21,
      "z": 3,
      "name": "Rock_Stone"
    },
    {
      "x": -4,
      "y": 22,
      "z": 3,
      "name": "Rock_Stone"
    },
    {
      "x": -4,
      "y": 23,
      "z": 3,
      "name": "Rock_Stone"
    },
    {
      "x": -4,
      "y": 24,
      "z": 3,
      "name": "Rock_Stone"
    },
    {
      "x": -4,
      "y": 25,
      "z": 3,
      "name": "Rock_Stone"
    },
    {
      "x": -4,
      "y": 26,
      "z": 3,
      "name": "Rock_Stone"
    },
    {
      "x": -4,
      "y": 27,
      "z": 3,
      "name": "Rock_Stone"
    },
    {
      "x": -4,
      "y": 28,
      "z": 3,
      "name": "Rock_Stone"
    },
    {
      "x": -4,
      "y": 29,
      "z": 3,
      "name": "Rock_Stone"
    },
    {
      "x": -4,
      "y": 30,
      "z": 3,
      "name": "Rock_Stone"
    },
    {
      "x": -4,
      "y": 31,
      "z": 3,
      "name": "Rock_Stone"
    },
    {
      "x": -4,
      "y": 32,
      "z": 3,
      "name": "Soil_Dirt"
    },
    {
      "x": -4,
      "y": 33,
      "z": 3,
      "name": "Soil_Grass"
    },
    {
      "x": -4,
      "y": 40,
      "z": 3,
      "name": "Plant_Leaves_Aspen"
    },
    {
      "x": -4,
      "y": 21,
      "z": 4,
      "name": "Rock_Stone"
    },
    {
      "x": -4,
      "y": 22,
      "z": 4,
      "name": "Rock_Stone"
    },
    {
      "x": -4,
      "y": 23,
      "z": 4,
      "name": "Rock_Stone"
    },
    {
      "x": -4,
      "y": 24,
      "z": 4,
      "name": "Rock_Stone"
    },
    {
      "x": -4,
      "y": 25,
      "z": 4,
      "name": "Rock_Stone"
    },
    {
      "x": -4,
      "y": 26,
      "z": 4,
      "name": "Rock_Stone"
    },
    {
      "x": -4,
      "y": 27,
      "z": 4,
      "name": "Rock_Stone"
    },
    {
      "x": -4,
      "y": 28,
      "z": 4,
      "name": "Soil_Grass"
    },
    {
      "x": -4,
      "y": 32,
      "z": 4,
      "name": "Soil_Dirt"
    },
    {
      "x": -4,
      "y": 33,
      "z": 4,
      "name": "Soil_Grass"
    },
    {
      "x": -4,
      "y": 21,
      "z": 5,
      "name": "Rock_Stone"
    },
    {
      "x": -4,
      "y": 22,
      "z": 5,
      "name": "Rock_Stone"
    },
    {
      "x": -4,
      "y": 23,
      "z": 5,
      "name": "Rock_Stone"
    },
    {
      "x": -4,
      "y": 24,
      "z": 5,
      "name": "Rock_Stone"
    },
    {
      "x": -4,
      "y": 25,
      "z": 5,
      "name": "Soil_Dirt"
    },
    {
      "x": -4,
      "y": 26,
      "z": 5,
      "name": "Rock_Stone"
    },
    {
      "x": -4,
      "y": 27,
      "z": 5,
      "name": "Rock_Stone"
    },
    {
      "x": -4,
      "y": 28,
      "z": 5,
      "name": "Soil_Grass"
    },
    {
      "x": -4,
      "y": 21,
      "z": 6,
      "name": "Rock_Stone"
    },
    {
      "x": -4,
      "y": 22,
      "z": 6,
      "name": "Rock_Stone"
    },
    {
      "x": -4,
      "y": 23,
      "z": 6,
      "name": "Rock_Stone"
    },
    {
      "x": -4,
      "y": 24,
      "z": 6,
      "name": "Soil_Dirt"
    },
    {
      "x": -4,
      "y": 25,
      "z": 6,
      "name": "Soil_Dirt"
    },
    {
      "x": -4,
      "y": 26,
      "z": 6,
      "name": "Soil_Dirt"
    },
    {
      "x": -4,
      "y": 27,
      "z": 6,
      "name": "Soil_Dirt"
    },
    {
      "x": -4,
      "y": 28,
      "z": 6,
      "name": "Soil_Grass"
    },
    {
      "x": -4,
      "y": 29,
      "z": 6,
      "name": "*Plant_Crop_Berry_Block_State_Definitions_StageFinal",
      "components": {
        "Components": {
          "FarmingBlock": {}
        }
      }
    },
    {
      "x": -4,
      "y": 22,
      "z": 7,
      "name": "Rock_Stone"
    },
    {
      "x": -4,
      "y": 23,
      "z": 7,
      "name": "Rock_Stone"
    },
    {
      "x": -4,
      "y": 24,
      "z": 7,
      "name": "Soil_Dirt"
    },
    {
      "x": -4,
      "y": 25,
      "z": 7,
      "name": "Soil_Dirt"
    },
    {
      "x": -4,
      "y": 26,
      "z": 7,
      "name": "Soil_Dirt"
    },
    {
      "x": -4,
      "y": 27,
      "z": 7,
      "name": "Soil_Grass"
    },
    {
      "x": -4,
      "y": 28,
      "z": 7,
      "name": "Plant_Bush"
    },
    {
      "x": -4,
      "y": 24,
      "z": 8,
      "name": "Soil_Dirt"
    },
    {
      "x": -4,
      "y": 25,
      "z": 8,
      "name": "Soil_Dirt"
    },
    {
      "x": -4,
      "y": 26,
      "z": 8,
      "name": "Soil_Dirt"
    },
    {
      "x": -4,
      "y": 27,
      "z": 8,
      "name": "Soil_Grass"
    },
    {
      "x": -3,
      "y": 27,
      "z": -7,
      "name": "Rock_Stone"
    },
    {
      "x": -3,
      "y": 28,
      "z": -7,
      "name": "Rock_Stone"
    },
    {
      "x": -3,
      "y": 29,
      "z": -7,
      "name": "Rock_Stone"
    },
    {
      "x": -3,
      "y": 30,
      "z": -7,
      "name": "Soil_Dirt"
    },
    {
      "x": -3,
      "y": 31,
      "z": -7,
      "name": "Soil_Grass"
    },
    {
      "x": -3,
      "y": 24,
      "z": -6,
      "name": "Rock_Stone"
    },
    {
      "x": -3,
      "y": 25,
      "z": -6,
      "name": "Rock_Stone"
    },
    {
      "x": -3,
      "y": 26,
      "z": -6,
      "name": "Rock_Stone"
    },
    {
      "x": -3,
      "y": 27,
      "z": -6,
      "name": "Rock_Stone"
    },
    {
      "x": -3,
      "y": 28,
      "z": -6,
      "name": "Rock_Stone"
    },
    {
      "x": -3,
      "y": 29,
      "z": -6,
      "name": "Rock_Stone"
    },
    {
      "x": -3,
      "y": 30,
      "z": -6,
      "name": "Soil_Dirt"
    },
    {
      "x": -3,
      "y": 31,
      "z": -6,
      "name": "Soil_Grass"
    },
    {
      "x": -3,
      "y": 23,
      "z": -5,
      "name": "Rock_Stone"
    },
    {
      "x": -3,
      "y": 24,
      "z": -5,
      "name": "Rock_Stone"
    },
    {
      "x": -3,
      "y": 25,
      "z": -5,
      "name": "Rock_Stone"
    },
    {
      "x": -3,
      "y": 26,
      "z": -5,
      "name": "Rock_Stone"
    },
    {
      "x": -3,
      "y": 27,
      "z": -5,
      "name": "Rock_Stone"
    },
    {
      "x": -3,
      "y": 28,
      "z": -5,
      "name": "Rock_Stone"
    },
    {
      "x": -3,
      "y": 29,
      "z": -5,
      "name": "Rock_Stone"
    },
    {
      "x": -3,
      "y": 30,
      "z": -5,
      "name": "Soil_Dirt"
    },
    {
      "x": -3,
      "y": 31,
      "z": -5,
      "name": "Soil_Grass"
    },
    {
      "x": -3,
      "y": 21,
      "z": -4,
      "name": "Rock_Stone"
    },
    {
      "x": -3,
      "y": 22,
      "z": -4,
      "name": "Rock_Stone"
    },
    {
      "x": -3,
      "y": 23,
      "z": -4,
      "name": "Rock_Stone"
    },
    {
      "x": -3,
      "y": 24,
      "z": -4,
      "name": "Rock_Stone"
    },
    {
      "x": -3,
      "y": 25,
      "z": -4,
      "name": "Rock_Stone"
    },
    {
      "x": -3,
      "y": 26,
      "z": -4,
      "name": "Rock_Stone"
    },
    {
      "x": -3,
      "y": 27,
      "z": -4,
      "name": "Rock_Stone"
    },
    {
      "x": -3,
      "y": 28,
      "z": -4,
      "name": "Rock_Stone"
    },
    {
      "x": -3,
      "y": 29,
      "z": -4,
      "name": "Rock_Stone"
    },
    {
      "x": -3,
      "y": 30,
      "z": -4,
      "name": "Rock_Stone"
    },
    {
      "x": -3,
      "y": 31,
      "z": -4,
      "name": "Soil_Dirt"
    },
    {
      "x": -3,
      "y": 32,
      "z": -4,
      "name": "Soil_Grass"
    },
    {
      "x": -3,
      "y": 21,
      "z": -3,
      "name": "Rock_Stone"
    },
    {
      "x": -3,
      "y": 22,
      "z": -3,
      "name": "Rock_Stone"
    },
    {
      "x": -3,
      "y": 23,
      "z": -3,
      "name": "Rock_Stone"
    },
    {
      "x": -3,
      "y": 24,
      "z": -3,
      "name": "Rock_Stone"
    },
    {
      "x": -3,
      "y": 25,
      "z": -3,
      "name": "Rock_Stone"
    },
    {
      "x": -3,
      "y": 26,
      "z": -3,
      "name": "Rock_Stone"
    },
    {
      "x": -3,
      "y": 27,
      "z": -3,
      "name": "Rock_Stone"
    },
    {
      "x": -3,
      "y": 28,
      "z": -3,
      "name": "Rock_Stone"
    },
    {
      "x": -3,
      "y": 29,
      "z": -3,
      "name": "Rock_Stone"
    },
    {
      "x": -3,
      "y": 30,
      "z": -3,
      "name": "Rock_Stone"
    },
    {
      "x": -3,
      "y": 31,
      "z": -3,
      "name": "Soil_Dirt"
    },
    {
      "x": -3,
      "y": 32,
      "z": -3,
      "name": "Soil_Grass"
    },
    {
      "x": -3,
      "y": 33,
      "z": -3,
      "name": "Plant_Grass_Sharp_Tall"
    },
    {
      "x": -3,
      "y": 34,
      "z": -3,
      "name": "Plant_Grass_Sharp_Tall",
      "filler": 1024
    },
    {
      "x": -3,
      "y": 20,
      "z": -2,
      "name": "Rock_Stone"
    },
    {
      "x": -3,
      "y": 21,
      "z": -2,
      "name": "Rock_Stone"
    },
    {
      "x": -3,
      "y": 22,
      "z": -2,
      "name": "Rock_Stone"
    },
    {
      "x": -3,
      "y": 23,
      "z": -2,
      "name": "Rock_Stone"
    },
    {
      "x": -3,
      "y": 24,
      "z": -2,
      "name": "Rock_Stone"
    },
    {
      "x": -3,
      "y": 25,
      "z": -2,
      "name": "Rock_Stone"
    },
    {
      "x": -3,
      "y": 26,
      "z": -2,
      "name": "Rock_Stone"
    },
    {
      "x": -3,
      "y": 27,
      "z": -2,
      "name": "Rock_Stone"
    },
    {
      "x": -3,
      "y": 28,
      "z": -2,
      "name": "Rock_Stone"
    },
    {
      "x": -3,
      "y": 29,
      "z": -2,
      "name": "Rock_Stone"
    },
    {
      "x": -3,
      "y": 30,
      "z": -2,
      "name": "Rock_Stone"
    },
    {
      "x": -3,
      "y": 31,
      "z": -2,
      "name": "Soil_Dirt"
    },
    {
      "x": -3,
      "y": 32,
      "z": -2,
      "name": "Soil_Grass"
    },
    {
      "x": -3,
      "y": 33,
      "z": -2,
      "name": "Plant_Grass_Sharp_Tall"
    },
    {
      "x": -3,
      "y": 34,
      "z": -2,
      "name": "Plant_Grass_Sharp_Tall",
      "filler": 1024
    },
    {
      "x": -3,
      "y": 20,
      "z": -1,
      "name": "Rock_Stone"
    },
    {
      "x": -3,
      "y": 21,
      "z": -1,
      "name": "Rock_Stone"
    },
    {
      "x": -3,
      "y": 22,
      "z": -1,
      "name": "Rock_Stone"
    },
    {
      "x": -3,
      "y": 23,
      "z": -1,
      "name": "Rock_Stone"
    },
    {
      "x": -3,
      "y": 24,
      "z": -1,
      "name": "Rock_Stone"
    },
    {
      "x": -3,
      "y": 25,
      "z": -1,
      "name": "Rock_Stone"
    },
    {
      "x": -3,
      "y": 26,
      "z": -1,
      "name": "Rock_Stone"
    },
    {
      "x": -3,
      "y": 27,
      "z": -1,
      "name": "Rock_Stone"
    },
    {
      "x": -3,
      "y": 28,
      "z": -1,
      "name": "Rock_Stone"
    },
    {
      "x": -3,
      "y": 29,
      "z": -1,
      "name": "Rock_Stone"
    },
    {
      "x": -3,
      "y": 30,
      "z": -1,
      "name": "Rock_Stone"
    },
    {
      "x": -3,
      "y": 31,
      "z": -1,
      "name": "Soil_Dirt"
    },
    {
      "x": -3,
      "y": 32,
      "z": -1,
      "name": "Soil_Dirt"
    },
    {
      "x": -3,
      "y": 33,
      "z": -1,
      "name": "Soil_Grass"
    },
    {
      "x": -3,
      "y": 20,
      "z": 0,
      "name": "Rock_Stone"
    },
    {
      "x": -3,
      "y": 21,
      "z": 0,
      "name": "Rock_Stone"
    },
    {
      "x": -3,
      "y": 22,
      "z": 0,
      "name": "Rock_Stone"
    },
    {
      "x": -3,
      "y": 23,
      "z": 0,
      "name": "Rock_Stone"
    },
    {
      "x": -3,
      "y": 24,
      "z": 0,
      "name": "Rock_Stone"
    },
    {
      "x": -3,
      "y": 25,
      "z": 0,
      "name": "Rock_Stone"
    },
    {
      "x": -3,
      "y": 26,
      "z": 0,
      "name": "Rock_Stone"
    },
    {
      "x": -3,
      "y": 27,
      "z": 0,
      "name": "Rock_Stone"
    },
    {
      "x": -3,
      "y": 28,
      "z": 0,
      "name": "Rock_Stone"
    },
    {
      "x": -3,
      "y": 29,
      "z": 0,
      "name": "Soil_Dirt"
    },
    {
      "x": -3,
      "y": 30,
      "z": 0,
      "name": "Rock_Stone"
    },
    {
      "x": -3,
      "y": 31,
      "z": 0,
      "name": "Rock_Stone"
    },
    {
      "x": -3,
      "y": 32,
      "z": 0,
      "name": "Soil_Dirt"
    },
    {
      "x": -3,
      "y": 33,
      "z": 0,
      "name": "Soil_Grass"
    },
    {
      "x": -3,
      "y": 20,
      "z": 1,
      "name": "Rock_Stone"
    },
    {
      "x": -3,
      "y": 21,
      "z": 1,
      "name": "Rock_Stone"
    },
    {
      "x": -3,
      "y": 22,
      "z": 1,
      "name": "Rock_Stone"
    },
    {
      "x": -3,
      "y": 23,
      "z": 1,
      "name": "Rock_Stone"
    },
    {
      "x": -3,
      "y": 24,
      "z": 1,
      "name": "Rock_Stone"
    },
    {
      "x": -3,
      "y": 25,
      "z": 1,
      "name": "Rock_Stone"
    },
    {
      "x": -3,
      "y": 26,
      "z": 1,
      "name": "Rock_Stone"
    },
    {
      "x": -3,
      "y": 27,
      "z": 1,
      "name": "Rock_Stone"
    },
    {
      "x": -3,
      "y": 28,
      "z": 1,
      "name": "Rock_Stone"
    },
    {
      "x": -3,
      "y": 29,
      "z": 1,
      "name": "Rock_Stone"
    },
    {
      "x": -3,
      "y": 30,
      "z": 1,
      "name": "Rock_Stone"
    },
    {
      "x": -3,
      "y": 31,
      "z": 1,
      "name": "Rock_Stone"
    },
    {
      "x": -3,
      "y": 32,
      "z": 1,
      "name": "Soil_Dirt"
    },
    {
      "x": -3,
      "y": 33,
      "z": 1,
      "name": "Soil_Grass"
    },
    {
      "x": -3,
      "y": 39,
      "z": 1,
      "name": "Plant_Leaves_Aspen"
    },
    {
      "x": -3,
      "y": 20,
      "z": 2,
      "name": "Rock_Stone"
    },
    {
      "x": -3,
      "y": 21,
      "z": 2,
      "name": "Rock_Stone"
    },
    {
      "x": -3,
      "y": 22,
      "z": 2,
      "name": "Rock_Stone"
    },
    {
      "x": -3,
      "y": 23,
      "z": 2,
      "name": "Rock_Stone"
    },
    {
      "x": -3,
      "y": 24,
      "z": 2,
      "name": "Rock_Stone"
    },
    {
      "x": -3,
      "y": 25,
      "z": 2,
      "name": "Rock_Stone"
    },
    {
      "x": -3,
      "y": 26,
      "z": 2,
      "name": "Rock_Stone"
    },
    {
      "x": -3,
      "y": 27,
      "z": 2,
      "name": "Rock_Stone"
    },
    {
      "x": -3,
      "y": 28,
      "z": 2,
      "name": "Rock_Stone"
    },
    {
      "x": -3,
      "y": 29,
      "z": 2,
      "name": "Rock_Stone"
    },
    {
      "x": -3,
      "y": 30,
      "z": 2,
      "name": "Rock_Stone"
    },
    {
      "x": -3,
      "y": 31,
      "z": 2,
      "name": "Rock_Stone"
    },
    {
      "x": -3,
      "y": 32,
      "z": 2,
      "name": "Soil_Dirt"
    },
    {
      "x": -3,
      "y": 33,
      "z": 2,
      "name": "Soil_Grass"
    },
    {
      "x": -3,
      "y": 34,
      "z": 2,
      "name": "Plant_Grass_Sharp"
    },
    {
      "x": -3,
      "y": 39,
      "z": 2,
      "name": "Plant_Leaves_Aspen"
    },
    {
      "x": -3,
      "y": 40,
      "z": 2,
      "name": "Plant_Leaves_Aspen"
    },
    {
      "x": -3,
      "y": 41,
      "z": 2,
      "name": "Plant_Leaves_Aspen"
    },
    {
      "x": -3,
      "y": 42,
      "z": 2,
      "name": "Plant_Leaves_Aspen"
    },
    {
      "x": -3,
      "y": 21,
      "z": 3,
      "name": "Rock_Stone"
    },
    {
      "x": -3,
      "y": 22,
      "z": 3,
      "name": "Rock_Stone"
    },
    {
      "x": -3,
      "y": 23,
      "z": 3,
      "name": "Rock_Stone"
    },
    {
      "x": -3,
      "y": 24,
      "z": 3,
      "name": "Rock_Stone"
    },
    {
      "x": -3,
      "y": 25,
      "z": 3,
      "name": "Rock_Stone"
    },
    {
      "x": -3,
      "y": 26,
      "z": 3,
      "name": "Rock_Stone"
    },
    {
      "x": -3,
      "y": 27,
      "z": 3,
      "name": "Rock_Stone"
    },
    {
      "x": -3,
      "y": 28,
      "z": 3,
      "name": "Rock_Stone"
    },
    {
      "x": -3,
      "y": 29,
      "z": 3,
      "name": "Rock_Stone"
    },
    {
      "x": -3,
      "y": 30,
      "z": 3,
      "name": "Rock_Stone"
    },
    {
      "x": -3,
      "y": 31,
      "z": 3,
      "name": "Rock_Stone"
    },
    {
      "x": -3,
      "y": 32,
      "z": 3,
      "name": "Rock_Stone"
    },
    {
      "x": -3,
      "y": 38,
      "z": 3,
      "name": "Plant_Leaves_Aspen"
    },
    {
      "x": -3,
      "y": 39,
      "z": 3,
      "name": "Plant_Leaves_Aspen"
    },
    {
      "x": -3,
      "y": 40,
      "z": 3,
      "name": "Plant_Leaves_Aspen"
    },
    {
      "x": -3,
      "y": 41,
      "z": 3,
      "name": "Plant_Leaves_Aspen"
    },
    {
      "x": -3,
      "y": 42,
      "z": 3,
      "name": "Plant_Leaves_Aspen"
    },
    {
      "x": -3,
      "y": 43,
      "z": 3,
      "name": "Plant_Leaves_Aspen"
    },
    {
      "x": -3,
      "y": 21,
      "z": 4,
      "name": "Rock_Stone"
    },
    {
      "x": -3,
      "y": 22,
      "z": 4,
      "name": "Rock_Stone"
    },
    {
      "x": -3,
      "y": 23,
      "z": 4,
      "name": "Rock_Stone"
    },
    {
      "x": -3,
      "y": 24,
      "z": 4,
      "name": "Rock_Stone"
    },
    {
      "x": -3,
      "y": 25,
      "z": 4,
      "name": "Rock_Stone"
    },
    {
      "x": -3,
      "y": 26,
      "z": 4,
      "name": "Rock_Stone"
    },
    {
      "x": -3,
      "y": 27,
      "z": 4,
      "name": "Rock_Stone"
    },
    {
      "x": -3,
      "y": 28,
      "z": 4,
      "name": "Soil_Grass"
    },
    {
      "x": -3,
      "y": 38,
      "z": 4,
      "name": "Plant_Leaves_Aspen"
    },
    {
      "x": -3,
      "y": 39,
      "z": 4,
      "name": "Plant_Leaves_Aspen"
    },
    {
      "x": -3,
      "y": 21,
      "z": 5,
      "name": "Rock_Stone"
    },
    {
      "x": -3,
      "y": 22,
      "z": 5,
      "name": "Rock_Stone"
    },
    {
      "x": -3,
      "y": 23,
      "z": 5,
      "name": "Rock_Stone"
    },
    {
      "x": -3,
      "y": 24,
      "z": 5,
      "name": "Rock_Stone"
    },
    {
      "x": -3,
      "y": 25,
      "z": 5,
      "name": "Rock_Stone"
    },
    {
      "x": -3,
      "y": 26,
      "z": 5,
      "name": "Rock_Stone"
    },
    {
      "x": -3,
      "y": 27,
      "z": 5,
      "name": "Rock_Stone"
    },
    {
      "x": -3,
      "y": 28,
      "z": 5,
      "name": "Soil_Grass"
    },
    {
      "x": -3,
      "y": 38,
      "z": 5,
      "name": "Plant_Leaves_Aspen"
    },
    {
      "x": -3,
      "y": 21,
      "z": 6,
      "name": "Rock_Stone"
    },
    {
      "x": -3,
      "y": 22,
      "z": 6,
      "name": "Rock_Stone"
    },
    {
      "x": -3,
      "y": 23,
      "z": 6,
      "name": "Rock_Stone"
    },
    {
      "x": -3,
      "y": 24,
      "z": 6,
      "name": "Rock_Stone"
    },
    {
      "x": -3,
      "y": 25,
      "z": 6,
      "name": "Soil_Dirt"
    },
    {
      "x": -3,
      "y": 26,
      "z": 6,
      "name": "Rock_Stone"
    },
    {
      "x": -3,
      "y": 27,
      "z": 6,
      "name": "Soil_Dirt"
    },
    {
      "x": -3,
      "y": 28,
      "z": 6,
      "name": "Soil_Grass"
    },
    {
      "x": -3,
      "y": 29,
      "z": 6,
      "name": "*Plant_Crop_Berry_Block_State_Definitions_StageFinal",
      "components": {
        "Components": {
          "FarmingBlock": {}
        }
      }
    },
    {
      "x": -3,
      "y": 22,
      "z": 7,
      "name": "Rock_Stone"
    },
    {
      "x": -3,
      "y": 23,
      "z": 7,
      "name": "Rock_Stone"
    },
    {
      "x": -3,
      "y": 24,
      "z": 7,
      "name": "Rock_Stone"
    },
    {
      "x": -3,
      "y": 25,
      "z": 7,
      "name": "Soil_Dirt"
    },
    {
      "x": -3,
      "y": 26,
      "z": 7,
      "name": "Soil_Dirt"
    },
    {
      "x": -3,
      "y": 27,
      "z": 7,
      "name": "Soil_Grass"
    },
    {
      "x": -3,
      "y": 23,
      "z": 8,
      "name": "Rock_Stone"
    },
    {
      "x": -3,
      "y": 24,
      "z": 8,
      "name": "Rock_Stone"
    },
    {
      "x": -3,
      "y": 25,
      "z": 8,
      "name": "Soil_Dirt"
    },
    {
      "x": -3,
      "y": 26,
      "z": 8,
      "name": "Soil_Dirt"
    },
    {
      "x": -3,
      "y": 27,
      "z": 8,
      "name": "Soil_Grass"
    },
    {
      "x": -2,
      "y": 29,
      "z": -7,
      "name": "Soil_Dirt"
    },
    {
      "x": -2,
      "y": 30,
      "z": -7,
      "name": "Soil_Dirt"
    },
    {
      "x": -2,
      "y": 31,
      "z": -7,
      "name": "Soil_Grass"
    },
    {
      "x": -2,
      "y": 24,
      "z": -6,
      "name": "Rock_Stone"
    },
    {
      "x": -2,
      "y": 25,
      "z": -6,
      "name": "Rock_Stone"
    },
    {
      "x": -2,
      "y": 26,
      "z": -6,
      "name": "Rock_Stone"
    },
    {
      "x": -2,
      "y": 27,
      "z": -6,
      "name": "Rock_Stone"
    },
    {
      "x": -2,
      "y": 28,
      "z": -6,
      "name": "Rock_Stone_Mossy"
    },
    {
      "x": -2,
      "y": 29,
      "z": -6,
      "name": "Soil_Dirt"
    },
    {
      "x": -2,
      "y": 30,
      "z": -6,
      "name": "Soil_Dirt"
    },
    {
      "x": -2,
      "y": 31,
      "z": -6,
      "name": "Soil_Grass"
    },
    {
      "x": -2,
      "y": 23,
      "z": -5,
      "name": "Rock_Stone"
    },
    {
      "x": -2,
      "y": 24,
      "z": -5,
      "name": "Rock_Stone"
    },
    {
      "x": -2,
      "y": 25,
      "z": -5,
      "name": "Rock_Stone"
    },
    {
      "x": -2,
      "y": 26,
      "z": -5,
      "name": "Rock_Stone"
    },
    {
      "x": -2,
      "y": 27,
      "z": -5,
      "name": "Rock_Stone"
    },
    {
      "x": -2,
      "y": 28,
      "z": -5,
      "name": "Rock_Stone"
    },
    {
      "x": -2,
      "y": 29,
      "z": -5,
      "name": "Soil_Dirt"
    },
    {
      "x": -2,
      "y": 30,
      "z": -5,
      "name": "Soil_Dirt"
    },
    {
      "x": -2,
      "y": 31,
      "z": -5,
      "name": "Soil_Grass"
    },
    {
      "x": -2,
      "y": 22,
      "z": -4,
      "name": "Rock_Stone"
    },
    {
      "x": -2,
      "y": 23,
      "z": -4,
      "name": "Rock_Stone"
    },
    {
      "x": -2,
      "y": 24,
      "z": -4,
      "name": "Rock_Stone"
    },
    {
      "x": -2,
      "y": 25,
      "z": -4,
      "name": "Rock_Stone"
    },
    {
      "x": -2,
      "y": 26,
      "z": -4,
      "name": "Rock_Stone"
    },
    {
      "x": -2,
      "y": 27,
      "z": -4,
      "name": "Rock_Stone"
    },
    {
      "x": -2,
      "y": 28,
      "z": -4,
      "name": "Rock_Stone"
    },
    {
      "x": -2,
      "y": 29,
      "z": -4,
      "name": "Rock_Stone"
    },
    {
      "x": -2,
      "y": 30,
      "z": -4,
      "name": "Soil_Dirt"
    },
    {
      "x": -2,
      "y": 31,
      "z": -4,
      "name": "Soil_Grass"
    },
    {
      "x": -2,
      "y": 32,
      "z": -4,
      "name": "Plant_Grass_Sharp"
    },
    {
      "x": -2,
      "y": 21,
      "z": -3,
      "name": "Rock_Stone"
    },
    {
      "x": -2,
      "y": 22,
      "z": -3,
      "name": "Rock_Stone"
    },
    {
      "x": -2,
      "y": 23,
      "z": -3,
      "name": "Rock_Stone"
    },
    {
      "x": -2,
      "y": 24,
      "z": -3,
      "name": "Rock_Stone"
    },
    {
      "x": -2,
      "y": 25,
      "z": -3,
      "name": "Rock_Stone"
    },
    {
      "x": -2,
      "y": 26,
      "z": -3,
      "name": "Rock_Stone"
    },
    {
      "x": -2,
      "y": 27,
      "z": -3,
      "name": "Rock_Stone"
    },
    {
      "x": -2,
      "y": 28,
      "z": -3,
      "name": "Rock_Stone"
    },
    {
      "x": -2,
      "y": 29,
      "z": -3,
      "name": "Rock_Stone"
    },
    {
      "x": -2,
      "y": 30,
      "z": -3,
      "name": "Soil_Dirt"
    },
    {
      "x": -2,
      "y": 31,
      "z": -3,
      "name": "Soil_Dirt"
    },
    {
      "x": -2,
      "y": 32,
      "z": -3,
      "name": "Soil_Grass"
    },
    {
      "x": -2,
      "y": 20,
      "z": -2,
      "name": "Rock_Stone"
    },
    {
      "x": -2,
      "y": 21,
      "z": -2,
      "name": "Rock_Stone"
    },
    {
      "x": -2,
      "y": 22,
      "z": -2,
      "name": "Rock_Stone"
    },
    {
      "x": -2,
      "y": 23,
      "z": -2,
      "name": "Rock_Stone"
    },
    {
      "x": -2,
      "y": 24,
      "z": -2,
      "name": "Rock_Stone"
    },
    {
      "x": -2,
      "y": 25,
      "z": -2,
      "name": "Rock_Stone"
    },
    {
      "x": -2,
      "y": 26,
      "z": -2,
      "name": "Rock_Stone"
    },
    {
      "x": -2,
      "y": 27,
      "z": -2,
      "name": "Rock_Stone"
    },
    {
      "x": -2,
      "y": 28,
      "z": -2,
      "name": "Rock_Stone"
    },
    {
      "x": -2,
      "y": 29,
      "z": -2,
      "name": "Rock_Stone"
    },
    {
      "x": -2,
      "y": 30,
      "z": -2,
      "name": "Soil_Dirt"
    },
    {
      "x": -2,
      "y": 31,
      "z": -2,
      "name": "Soil_Dirt"
    },
    {
      "x": -2,
      "y": 32,
      "z": -2,
      "name": "Soil_Grass"
    },
    {
      "x": -2,
      "y": 20,
      "z": -1,
      "name": "Rock_Stone"
    },
    {
      "x": -2,
      "y": 21,
      "z": -1,
      "name": "Rock_Stone"
    },
    {
      "x": -2,
      "y": 22,
      "z": -1,
      "name": "Rock_Stone"
    },
    {
      "x": -2,
      "y": 23,
      "z": -1,
      "name": "Rock_Stone"
    },
    {
      "x": -2,
      "y": 24,
      "z": -1,
      "name": "Rock_Stone"
    },
    {
      "x": -2,
      "y": 25,
      "z": -1,
      "name": "Rock_Stone"
    },
    {
      "x": -2,
      "y": 26,
      "z": -1,
      "name": "Rock_Stone"
    },
    {
      "x": -2,
      "y": 27,
      "z": -1,
      "name": "Rock_Stone"
    },
    {
      "x": -2,
      "y": 28,
      "z": -1,
      "name": "Rock_Stone"
    },
    {
      "x": -2,
      "y": 29,
      "z": -1,
      "name": "Soil_Dirt"
    },
    {
      "x": -2,
      "y": 30,
      "z": -1,
      "name": "Soil_Dirt"
    },
    {
      "x": -2,
      "y": 31,
      "z": -1,
      "name": "Soil_Grass"
    },
    {
      "x": -2,
      "y": 20,
      "z": 0,
      "name": "Rock_Stone"
    },
    {
      "x": -2,
      "y": 21,
      "z": 0,
      "name": "Rock_Stone"
    },
    {
      "x": -2,
      "y": 22,
      "z": 0,
      "name": "Rock_Stone"
    },
    {
      "x": -2,
      "y": 23,
      "z": 0,
      "name": "Rock_Stone"
    },
    {
      "x": -2,
      "y": 24,
      "z": 0,
      "name": "Rock_Stone"
    },
    {
      "x": -2,
      "y": 25,
      "z": 0,
      "name": "Rock_Stone"
    },
    {
      "x": -2,
      "y": 26,
      "z": 0,
      "name": "Rock_Stone"
    },
    {
      "x": -2,
      "y": 27,
      "z": 0,
      "name": "Rock_Stone"
    },
    {
      "x": -2,
      "y": 28,
      "z": 0,
      "name": "Soil_Dirt"
    },
    {
      "x": -2,
      "y": 29,
      "z": 0,
      "name": "Soil_Dirt"
    },
    {
      "x": -2,
      "y": 30,
      "z": 0,
      "name": "Soil_Dirt"
    },
    {
      "x": -2,
      "y": 31,
      "z": 0,
      "name": "Soil_Grass"
    },
    {
      "x": -2,
      "y": 39,
      "z": 0,
      "name": "Plant_Leaves_Aspen"
    },
    {
      "x": -2,
      "y": 40,
      "z": 0,
      "name": "Plant_Leaves_Aspen"
    },
    {
      "x": -2,
      "y": 41,
      "z": 0,
      "name": "Plant_Leaves_Aspen"
    },
    {
      "x": -2,
      "y": 20,
      "z": 1,
      "name": "Rock_Stone"
    },
    {
      "x": -2,
      "y": 21,
      "z": 1,
      "name": "Rock_Stone"
    },
    {
      "x": -2,
      "y": 22,
      "z": 1,
      "name": "Rock_Stone"
    },
    {
      "x": -2,
      "y": 23,
      "z": 1,
      "name": "Rock_Stone"
    },
    {
      "x": -2,
      "y": 24,
      "z": 1,
      "name": "Rock_Stone"
    },
    {
      "x": -2,
      "y": 25,
      "z": 1,
      "name": "Rock_Stone"
    },
    {
      "x": -2,
      "y": 26,
      "z": 1,
      "name": "Rock_Stone"
    },
    {
      "x": -2,
      "y": 27,
      "z": 1,
      "name": "Rock_Stone"
    },
    {
      "x": -2,
      "y": 28,
      "z": 1,
      "name": "Soil_Dirt"
    },
    {
      "x": -2,
      "y": 29,
      "z": 1,
      "name": "Rock_Stone"
    },
    {
      "x": -2,
      "y": 30,
      "z": 1,
      "name": "Rock_Stone"
    },
    {
      "x": -2,
      "y": 31,
      "z": 1,
      "name": "Rock_Stone"
    },
    {
      "x": -2,
      "y": 32,
      "z": 1,
      "name": "Soil_Dirt"
    },
    {
      "x": -2,
      "y": 33,
      "z": 1,
      "name": "Soil_Grass"
    },
    {
      "x": -2,
      "y": 42,
      "z": 1,
      "name": "Plant_Leaves_Aspen"
    },
    {
      "x": -2,
      "y": 20,
      "z": 2,
      "name": "Rock_Stone"
    },
    {
      "x": -2,
      "y": 21,
      "z": 2,
      "name": "Rock_Stone"
    },
    {
      "x": -2,
      "y": 22,
      "z": 2,
      "name": "Rock_Stone"
    },
    {
      "x": -2,
      "y": 23,
      "z": 2,
      "name": "Rock_Stone"
    },
    {
      "x": -2,
      "y": 24,
      "z": 2,
      "name": "Rock_Stone"
    },
    {
      "x": -2,
      "y": 25,
      "z": 2,
      "name": "Rock_Stone"
    },
    {
      "x": -2,
      "y": 26,
      "z": 2,
      "name": "Rock_Stone"
    },
    {
      "x": -2,
      "y": 27,
      "z": 2,
      "name": "Rock_Stone"
    },
    {
      "x": -2,
      "y": 28,
      "z": 2,
      "name": "Soil_Dirt"
    },
    {
      "x": -2,
      "y": 29,
      "z": 2,
      "name": "Rock_Stone"
    },
    {
      "x": -2,
      "y": 30,
      "z": 2,
      "name": "Rock_Stone"
    },
    {
      "x": -2,
      "y": 31,
      "z": 2,
      "name": "Rock_Stone"
    },
    {
      "x": -2,
      "y": 32,
      "z": 2,
      "name": "Soil_Dirt"
    },
    {
      "x": -2,
      "y": 33,
      "z": 2,
      "name": "Soil_Grass"
    },
    {
      "x": -2,
      "y": 42,
      "z": 2,
      "name": "Plant_Leaves_Aspen"
    },
    {
      "x": -2,
      "y": 43,
      "z": 2,
      "name": "Plant_Leaves_Aspen"
    },
    {
      "x": -2,
      "y": 44,
      "z": 2,
      "name": "Plant_Leaves_Aspen"
    },
    {
      "x": -2,
      "y": 45,
      "z": 2,
      "name": "Plant_Leaves_Aspen"
    },
    {
      "x": -2,
      "y": 21,
      "z": 3,
      "name": "Rock_Stone"
    },
    {
      "x": -2,
      "y": 22,
      "z": 3,
      "name": "Rock_Stone"
    },
    {
      "x": -2,
      "y": 23,
      "z": 3,
      "name": "Rock_Stone"
    },
    {
      "x": -2,
      "y": 24,
      "z": 3,
      "name": "Rock_Stone"
    },
    {
      "x": -2,
      "y": 25,
      "z": 3,
      "name": "Rock_Stone"
    },
    {
      "x": -2,
      "y": 26,
      "z": 3,
      "name": "Rock_Stone"
    },
    {
      "x": -2,
      "y": 27,
      "z": 3,
      "name": "Rock_Stone"
    },
    {
      "x": -2,
      "y": 28,
      "z": 3,
      "name": "Soil_Dirt"
    },
    {
      "x": -2,
      "y": 29,
      "z": 3,
      "name": "Soil_Dirt"
    },
    {
      "x": -2,
      "y": 30,
      "z": 3,
      "name": "Rock_Stone"
    },
    {
      "x": -2,
      "y": 31,
      "z": 3,
      "name": "Rock_Stone"
    },
    {
      "x": -2,
      "y": 37,
      "z": 3,
      "name": "Plant_Leaves_Aspen"
    },
    {
      "x": -2,
      "y": 38,
      "z": 3,
      "name": "Plant_Leaves_Aspen"
    },
    {
      "x": -2,
      "y": 39,
      "z": 3,
      "name": "Wood_Aspen_Branch_Corner",
      "rotation": 3
    },
    {
      "x": -2,
      "y": 40,
      "z": 3,
      "name": "Wood_Aspen_Branch_Long"
    },
    {
      "x": -2,
      "y": 41,
      "z": 3,
      "name": "Wood_Aspen_Branch_Long"
    },
    {
      "x": -2,
      "y": 43,
      "z": 3,
      "name": "Plant_Leaves_Aspen"
    },
    {
      "x": -2,
      "y": 44,
      "z": 3,
      "name": "Plant_Leaves_Aspen"
    },
    {
      "x": -2,
      "y": 45,
      "z": 3,
      "name": "Plant_Leaves_Aspen"
    },
    {
      "x": -2,
      "y": 21,
      "z": 4,
      "name": "Rock_Stone"
    },
    {
      "x": -2,
      "y": 22,
      "z": 4,
      "name": "Rock_Stone"
    },
    {
      "x": -2,
      "y": 23,
      "z": 4,
      "name": "Rock_Stone"
    },
    {
      "x": -2,
      "y": 24,
      "z": 4,
      "name": "Rock_Stone"
    },
    {
      "x": -2,
      "y": 25,
      "z": 4,
      "name": "Rock_Stone"
    },
    {
      "x": -2,
      "y": 26,
      "z": 4,
      "name": "Rock_Stone"
    },
    {
      "x": -2,
      "y": 27,
      "z": 4,
      "name": "Soil_Dirt"
    },
    {
      "x": -2,
      "y": 28,
      "z": 4,
      "name": "Soil_Dirt"
    },
    {
      "x": -2,
      "y": 29,
      "z": 4,
      "name": "Soil_Grass"
    },
    {
      "x": -2,
      "y": 41,
      "z": 4,
      "name": "Plant_Leaves_Aspen"
    },
    {
      "x": -2,
      "y": 42,
      "z": 4,
      "name": "Plant_Leaves_Aspen"
    },
    {
      "x": -2,
      "y": 43,
      "z": 4,
      "name": "Plant_Leaves_Aspen"
    },
    {
      "x": -2,
      "y": 21,
      "z": 5,
      "name": "Rock_Stone"
    },
    {
      "x": -2,
      "y": 22,
      "z": 5,
      "name": "Rock_Stone"
    },
    {
      "x": -2,
      "y": 23,
      "z": 5,
      "name": "Rock_Stone"
    },
    {
      "x": -2,
      "y": 24,
      "z": 5,
      "name": "Rock_Stone"
    },
    {
      "x": -2,
      "y": 25,
      "z": 5,
      "name": "Rock_Stone"
    },
    {
      "x": -2,
      "y": 26,
      "z": 5,
      "name": "Rock_Stone"
    },
    {
      "x": -2,
      "y": 27,
      "z": 5,
      "name": "Soil_Dirt"
    },
    {
      "x": -2,
      "y": 28,
      "z": 5,
      "name": "Soil_Grass"
    },
    {
      "x": -2,
      "y": 37,
      "z": 5,
      "name": "Plant_Leaves_Aspen"
    },
    {
      "x": -2,
      "y": 38,
      "z": 5,
      "name": "Plant_Leaves_Aspen"
    },
    {
      "x": -2,
      "y": 39,
      "z": 5,
      "name": "Plant_Leaves_Aspen"
    },
    {
      "x": -2,
      "y": 40,
      "z": 5,
      "name": "Plant_Leaves_Aspen"
    },
    {
      "x": -2,
      "y": 41,
      "z": 5,
      "name": "Plant_Leaves_Aspen"
    },
    {
      "x": -2,
      "y": 21,
      "z": 6,
      "name": "Rock_Stone"
    },
    {
      "x": -2,
      "y": 22,
      "z": 6,
      "name": "Rock_Stone"
    },
    {
      "x": -2,
      "y": 23,
      "z": 6,
      "name": "Rock_Stone"
    },
    {
      "x": -2,
      "y": 24,
      "z": 6,
      "name": "Rock_Stone"
    },
    {
      "x": -2,
      "y": 25,
      "z": 6,
      "name": "Rock_Stone"
    },
    {
      "x": -2,
      "y": 26,
      "z": 6,
      "name": "Rock_Stone"
    },
    {
      "x": -2,
      "y": 27,
      "z": 6,
      "name": "Soil_Dirt"
    },
    {
      "x": -2,
      "y": 28,
      "z": 6,
      "name": "Soil_Grass"
    },
    {
      "x": -2,
      "y": 29,
      "z": 6,
      "name": "Plant_Grass_Sharp"
    },
    {
      "x": -2,
      "y": 38,
      "z": 6,
      "name": "Plant_Leaves_Aspen"
    },
    {
      "x": -2,
      "y": 39,
      "z": 6,
      "name": "Plant_Leaves_Aspen"
    },
    {
      "x": -2,
      "y": 22,
      "z": 7,
      "name": "Rock_Stone"
    },
    {
      "x": -2,
      "y": 23,
      "z": 7,
      "name": "Rock_Stone"
    },
    {
      "x": -2,
      "y": 24,
      "z": 7,
      "name": "Rock_Stone"
    },
    {
      "x": -2,
      "y": 25,
      "z": 7,
      "name": "Rock_Stone"
    },
    {
      "x": -2,
      "y": 26,
      "z": 7,
      "name": "Soil_Dirt"
    },
    {
      "x": -2,
      "y": 27,
      "z": 7,
      "name": "Soil_Dirt"
    },
    {
      "x": -2,
      "y": 28,
      "z": 7,
      "name": "Soil_Grass"
    },
    {
      "x": -2,
      "y": 29,
      "z": 7,
      "name": "Plant_Grass_Sharp"
    },
    {
      "x": -2,
      "y": 39,
      "z": 7,
      "name": "Plant_Leaves_Aspen"
    },
    {
      "x": -2,
      "y": 23,
      "z": 8,
      "name": "Rock_Stone"
    },
    {
      "x": -2,
      "y": 24,
      "z": 8,
      "name": "Rock_Stone"
    },
    {
      "x": -2,
      "y": 25,
      "z": 8,
      "name": "Rock_Stone"
    },
    {
      "x": -2,
      "y": 26,
      "z": 8,
      "name": "Soil_Dirt"
    },
    {
      "x": -2,
      "y": 27,
      "z": 8,
      "name": "Soil_Grass"
    },
    {
      "x": -1,
      "y": 24,
      "z": -6,
      "name": "Rock_Stone"
    },
    {
      "x": -1,
      "y": 25,
      "z": -6,
      "name": "Rock_Stone"
    },
    {
      "x": -1,
      "y": 26,
      "z": -6,
      "name": "Rock_Stone"
    },
    {
      "x": -1,
      "y": 27,
      "z": -6,
      "name": "Rock_Stone_Mossy"
    },
    {
      "x": -1,
      "y": 28,
      "z": -6,
      "name": "Rock_Stone_Mossy"
    },
    {
      "x": -1,
      "y": 29,
      "z": -6,
      "name": "Soil_Dirt"
    },
    {
      "x": -1,
      "y": 30,
      "z": -6,
      "name": "Soil_Dirt"
    },
    {
      "x": -1,
      "y": 31,
      "z": -6,
      "name": "Soil_Grass"
    },
    {
      "x": -1,
      "y": 24,
      "z": -5,
      "name": "Rock_Stone"
    },
    {
      "x": -1,
      "y": 25,
      "z": -5,
      "name": "Rock_Stone"
    },
    {
      "x": -1,
      "y": 26,
      "z": -5,
      "name": "Rock_Stone"
    },
    {
      "x": -1,
      "y": 27,
      "z": -5,
      "name": "Rock_Stone"
    },
    {
      "x": -1,
      "y": 28,
      "z": -5,
      "name": "Rock_Stone_Mossy"
    },
    {
      "x": -1,
      "y": 29,
      "z": -5,
      "name": "Soil_Dirt"
    },
    {
      "x": -1,
      "y": 30,
      "z": -5,
      "name": "Soil_Dirt"
    },
    {
      "x": -1,
      "y": 31,
      "z": -5,
      "name": "Soil_Grass"
    },
    {
      "x": -1,
      "y": 23,
      "z": -4,
      "name": "Rock_Stone"
    },
    {
      "x": -1,
      "y": 24,
      "z": -4,
      "name": "Rock_Stone"
    },
    {
      "x": -1,
      "y": 25,
      "z": -4,
      "name": "Rock_Stone"
    },
    {
      "x": -1,
      "y": 26,
      "z": -4,
      "name": "Rock_Stone"
    },
    {
      "x": -1,
      "y": 27,
      "z": -4,
      "name": "Rock_Stone"
    },
    {
      "x": -1,
      "y": 28,
      "z": -4,
      "name": "Rock_Stone"
    },
    {
      "x": -1,
      "y": 29,
      "z": -4,
      "name": "Rock_Stone"
    },
    {
      "x": -1,
      "y": 30,
      "z": -4,
      "name": "Soil_Dirt"
    },
    {
      "x": -1,
      "y": 31,
      "z": -4,
      "name": "Soil_Grass"
    },
    {
      "x": -1,
      "y": 32,
      "z": -4,
      "name": "Plant_Grass_Sharp"
    },
    {
      "x": -1,
      "y": 21,
      "z": -3,
      "name": "Rock_Stone"
    },
    {
      "x": -1,
      "y": 22,
      "z": -3,
      "name": "Rock_Stone"
    },
    {
      "x": -1,
      "y": 23,
      "z": -3,
      "name": "Rock_Stone_Mossy"
    },
    {
      "x": -1,
      "y": 24,
      "z": -3,
      "name": "Rock_Stone"
    },
    {
      "x": -1,
      "y": 25,
      "z": -3,
      "name": "Rock_Stone"
    },
    {
      "x": -1,
      "y": 26,
      "z": -3,
      "name": "Rock_Stone"
    },
    {
      "x": -1,
      "y": 27,
      "z": -3,
      "name": "Rock_Stone"
    },
    {
      "x": -1,
      "y": 28,
      "z": -3,
      "name": "Rock_Stone"
    },
    {
      "x": -1,
      "y": 29,
      "z": -3,
      "name": "Rock_Stone"
    },
    {
      "x": -1,
      "y": 30,
      "z": -3,
      "name": "Soil_Dirt"
    },
    {
      "x": -1,
      "y": 31,
      "z": -3,
      "name": "Soil_Grass"
    },
    {
      "x": -1,
      "y": 32,
      "z": -3,
      "name": "Plant_Grass_Sharp"
    },
    {
      "x": -1,
      "y": 21,
      "z": -2,
      "name": "Rock_Stone"
    },
    {
      "x": -1,
      "y": 22,
      "z": -2,
      "name": "Rock_Stone"
    },
    {
      "x": -1,
      "y": 23,
      "z": -2,
      "name": "Rock_Stone"
    },
    {
      "x": -1,
      "y": 24,
      "z": -2,
      "name": "Rock_Stone"
    },
    {
      "x": -1,
      "y": 25,
      "z": -2,
      "name": "Rock_Stone"
    },
    {
      "x": -1,
      "y": 26,
      "z": -2,
      "name": "Rock_Stone"
    },
    {
      "x": -1,
      "y": 27,
      "z": -2,
      "name": "Rock_Stone"
    },
    {
      "x": -1,
      "y": 28,
      "z": -2,
      "name": "Rock_Stone"
    },
    {
      "x": -1,
      "y": 29,
      "z": -2,
      "name": "Rock_Stone"
    },
    {
      "x": -1,
      "y": 30,
      "z": -2,
      "name": "Soil_Dirt"
    },
    {
      "x": -1,
      "y": 31,
      "z": -2,
      "name": "Soil_Grass"
    },
    {
      "x": -1,
      "y": 20,
      "z": -1,
      "name": "Rock_Stone"
    },
    {
      "x": -1,
      "y": 21,
      "z": -1,
      "name": "Rock_Stone"
    },
    {
      "x": -1,
      "y": 22,
      "z": -1,
      "name": "Rock_Stone"
    },
    {
      "x": -1,
      "y": 23,
      "z": -1,
      "name": "Rock_Stone"
    },
    {
      "x": -1,
      "y": 24,
      "z": -1,
      "name": "Rock_Stone"
    },
    {
      "x": -1,
      "y": 25,
      "z": -1,
      "name": "Rock_Stone"
    },
    {
      "x": -1,
      "y": 26,
      "z": -1,
      "name": "Rock_Stone"
    },
    {
      "x": -1,
      "y": 27,
      "z": -1,
      "name": "Rock_Stone"
    },
    {
      "x": -1,
      "y": 28,
      "z": -1,
      "name": "Rock_Stone"
    },
    {
      "x": -1,
      "y": 29,
      "z": -1,
      "name": "Soil_Dirt"
    },
    {
      "x": -1,
      "y": 30,
      "z": -1,
      "name": "Soil_Dirt"
    },
    {
      "x": -1,
      "y": 31,
      "z": -1,
      "name": "Soil_Grass"
    },
    {
      "x": -1,
      "y": 39,
      "z": -1,
      "name": "Plant_Leaves_Aspen"
    },
    {
      "x": -1,
      "y": 40,
      "z": -1,
      "name": "Plant_Leaves_Aspen"
    },
    {
      "x": -1,
      "y": 20,
      "z": 0,
      "name": "Rock_Stone"
    },
    {
      "x": -1,
      "y": 21,
      "z": 0,
      "name": "Rock_Stone"
    },
    {
      "x": -1,
      "y": 22,
      "z": 0,
      "name": "Rock_Stone"
    },
    {
      "x": -1,
      "y": 23,
      "z": 0,
      "name": "Rock_Stone"
    },
    {
      "x": -1,
      "y": 24,
      "z": 0,
      "name": "Rock_Stone"
    },
    {
      "x": -1,
      "y": 25,
      "z": 0,
      "name": "Rock_Stone"
    },
    {
      "x": -1,
      "y": 26,
      "z": 0,
      "name": "Rock_Stone"
    },
    {
      "x": -1,
      "y": 27,
      "z": 0,
      "name": "Rock_Stone"
    },
    {
      "x": -1,
      "y": 28,
      "z": 0,
      "name": "Soil_Dirt"
    },
    {
      "x": -1,
      "y": 29,
      "z": 0,
      "name": "Soil_Dirt"
    },
    {
      "x": -1,
      "y": 30,
      "z": 0,
      "name": "Soil_Grass"
    },
    {
      "x": -1,
      "y": 38,
      "z": 0,
      "name": "Plant_Leaves_Aspen"
    },
    {
      "x": -1,
      "y": 39,
      "z": 0,
      "name": "Plant_Leaves_Aspen"
    },
    {
      "x": -1,
      "y": 42,
      "z": 0,
      "name": "Plant_Leaves_Aspen"
    },
    {
      "x": -1,
      "y": 20,
      "z": 1,
      "name": "Rock_Stone"
    },
    {
      "x": -1,
      "y": 21,
      "z": 1,
      "name": "Rock_Stone"
    },
    {
      "x": -1,
      "y": 22,
      "z": 1,
      "name": "Rock_Stone"
    },
    {
      "x": -1,
      "y": 23,
      "z": 1,
      "name": "Rock_Stone"
    },
    {
      "x": -1,
      "y": 24,
      "z": 1,
      "name": "Rock_Stone"
    },
    {
      "x": -1,
      "y": 25,
      "z": 1,
      "name": "Rock_Stone"
    },
    {
      "x": -1,
      "y": 26,
      "z": 1,
      "name": "Rock_Stone"
    },
    {
      "x": -1,
      "y": 27,
      "z": 1,
      "name": "Rock_Stone"
    },
    {
      "x": -1,
      "y": 28,
      "z": 1,
      "name": "Soil_Dirt"
    },
    {
      "x": -1,
      "y": 29,
      "z": 1,
      "name": "Soil_Grass"
    },
    {
      "x": -1,
      "y": 43,
      "z": 1,
      "name": "Plant_Leaves_Aspen"
    },
    {
      "x": -1,
      "y": 21,
      "z": 2,
      "name": "Rock_Stone"
    },
    {
      "x": -1,
      "y": 22,
      "z": 2,
      "name": "Rock_Stone"
    },
    {
      "x": -1,
      "y": 23,
      "z": 2,
      "name": "Rock_Stone"
    },
    {
      "x": -1,
      "y": 24,
      "z": 2,
      "name": "Rock_Stone"
    },
    {
      "x": -1,
      "y": 25,
      "z": 2,
      "name": "Rock_Stone"
    },
    {
      "x": -1,
      "y": 26,
      "z": 2,
      "name": "Rock_Stone"
    },
    {
      "x": -1,
      "y": 27,
      "z": 2,
      "name": "Rock_Stone"
    },
    {
      "x": -1,
      "y": 28,
      "z": 2,
      "name": "Soil_Dirt"
    },
    {
      "x": -1,
      "y": 29,
      "z": 2,
      "name": "Soil_Grass"
    },
    {
      "x": -1,
      "y": 39,
      "z": 2,
      "name": "Wood_Aspen_Branch_Corner",
      "rotation": 2
    },
    {
      "x": -1,
      "y": 40,
      "z": 2,
      "name": "Wood_Aspen_Branch_Long"
    },
    {
      "x": -1,
      "y": 41,
      "z": 2,
      "name": "Wood_Aspen_Branch_Long"
    },
    {
      "x": -1,
      "y": 42,
      "z": 2,
      "name": "Plant_Leaves_Aspen"
    },
    {
      "x": -1,
      "y": 43,
      "z": 2,
      "name": "Plant_Leaves_Aspen"
    },
    {
      "x": -1,
      "y": 44,
      "z": 2,
      "name": "Plant_Leaves_Aspen"
    },
    {
      "x": -1,
      "y": 45,
      "z": 2,
      "name": "Plant_Leaves_Aspen"
    },
    {
      "x": -1,
      "y": 21,
      "z": 3,
      "name": "Rock_Stone"
    },
    {
      "x": -1,
      "y": 22,
      "z": 3,
      "name": "Rock_Stone"
    },
    {
      "x": -1,
      "y": 23,
      "z": 3,
      "name": "Rock_Stone"
    },
    {
      "x": -1,
      "y": 24,
      "z": 3,
      "name": "Rock_Stone"
    },
    {
      "x": -1,
      "y": 25,
      "z": 3,
      "name": "Rock_Stone"
    },
    {
      "x": -1,
      "y": 26,
      "z": 3,
      "name": "Rock_Stone"
    },
    {
      "x": -1,
      "y": 27,
      "z": 3,
      "name": "Rock_Stone"
    },
    {
      "x": -1,
      "y": 28,
      "z": 3,
      "name": "Soil_Dirt"
    },
    {
      "x": -1,
      "y": 29,
      "z": 3,
      "name": "Soil_Grass"
    },
    {
      "x": -1,
      "y": 30,
      "z": 3,
      "name": "Plant_Grass_Sharp"
    },
    {
      "x": -1,
      "y": 39,
      "z": 3,
      "name": "Wood_Aspen_Trunk_Full"
    },
    {
      "x": -1,
      "y": 40,
      "z": 3,
      "name": "Wood_Aspen_Branch_Long"
    },
    {
      "x": -1,
      "y": 41,
      "z": 3,
      "name": "Wood_Aspen_Branch_Long"
    },
    {
      "x": -1,
      "y": 42,
      "z": 3,
      "name": "Wood_Aspen_Branch_Long"
    },
    {
      "x": -1,
      "y": 43,
      "z": 3,
      "name": "Wood_Aspen_Branch_Long"
    },
    {
      "x": -1,
      "y": 44,
      "z": 3,
      "name": "Plant_Leaves_Aspen"
    },
    {
      "x": -1,
      "y": 45,
      "z": 3,
      "name": "Plant_Leaves_Aspen"
    },
    {
      "x": -1,
      "y": 46,
      "z": 3,
      "name": "Plant_Leaves_Aspen"
    },
    {
      "x": -1,
      "y": 47,
      "z": 3,
      "name": "Plant_Leaves_Aspen"
    },
    {
      "x": -1,
      "y": 21,
      "z": 4,
      "name": "Rock_Stone"
    },
    {
      "x": -1,
      "y": 22,
      "z": 4,
      "name": "Rock_Stone"
    },
    {
      "x": -1,
      "y": 23,
      "z": 4,
      "name": "Rock_Stone"
    },
    {
      "x": -1,
      "y": 24,
      "z": 4,
      "name": "Rock_Stone"
    },
    {
      "x": -1,
      "y": 25,
      "z": 4,
      "name": "Rock_Stone"
    },
    {
      "x": -1,
      "y": 26,
      "z": 4,
      "name": "Rock_Stone"
    },
    {
      "x": -1,
      "y": 27,
      "z": 4,
      "name": "Soil_Dirt"
    },
    {
      "x": -1,
      "y": 28,
      "z": 4,
      "name": "Soil_Dirt"
    },
    {
      "x": -1,
      "y": 29,
      "z": 4,
      "name": "Soil_Grass"
    },
    {
      "x": -1,
      "y": 30,
      "z": 4,
      "name": "Plant_Grass_Sharp"
    },
    {
      "x": -1,
      "y": 44,
      "z": 4,
      "name": "Plant_Leaves_Aspen"
    },
    {
      "x": -1,
      "y": 45,
      "z": 4,
      "name": "Plant_Leaves_Aspen"
    },
    {
      "x": -1,
      "y": 46,
      "z": 4,
      "name": "Plant_Leaves_Aspen"
    },
    {
      "x": -1,
      "y": 21,
      "z": 5,
      "name": "Rock_Stone"
    },
    {
      "x": -1,
      "y": 22,
      "z": 5,
      "name": "Rock_Stone"
    },
    {
      "x": -1,
      "y": 23,
      "z": 5,
      "name": "Rock_Stone"
    },
    {
      "x": -1,
      "y": 24,
      "z": 5,
      "name": "Rock_Stone"
    },
    {
      "x": -1,
      "y": 25,
      "z": 5,
      "name": "Rock_Stone"
    },
    {
      "x": -1,
      "y": 26,
      "z": 5,
      "name": "Rock_Stone"
    },
    {
      "x": -1,
      "y": 27,
      "z": 5,
      "name": "Soil_Dirt"
    },
    {
      "x": -1,
      "y": 28,
      "z": 5,
      "name": "Soil_Grass"
    },
    {
      "x": -1,
      "y": 21,
      "z": 6,
      "name": "Rock_Stone"
    },
    {
      "x": -1,
      "y": 22,
      "z": 6,
      "name": "Rock_Stone"
    },
    {
      "x": -1,
      "y": 23,
      "z": 6,
      "name": "Rock_Stone"
    },
    {
      "x": -1,
      "y": 24,
      "z": 6,
      "name": "Rock_Stone"
    },
    {
      "x": -1,
      "y": 25,
      "z": 6,
      "name": "Rock_Stone"
    },
    {
      "x": -1,
      "y": 26,
      "z": 6,
      "name": "Rock_Stone"
    },
    {
      "x": -1,
      "y": 27,
      "z": 6,
      "name": "Soil_Dirt"
    },
    {
      "x": -1,
      "y": 28,
      "z": 6,
      "name": "Soil_Grass"
    },
    {
      "x": -1,
      "y": 39,
      "z": 6,
      "name": "Plant_Leaves_Aspen"
    },
    {
      "x": -1,
      "y": 40,
      "z": 6,
      "name": "Plant_Leaves_Aspen"
    },
    {
      "x": -1,
      "y": 41,
      "z": 6,
      "name": "Plant_Leaves_Aspen"
    },
    {
      "x": -1,
      "y": 42,
      "z": 6,
      "name": "Plant_Leaves_Aspen"
    },
    {
      "x": -1,
      "y": 22,
      "z": 7,
      "name": "Rock_Stone"
    },
    {
      "x": -1,
      "y": 23,
      "z": 7,
      "name": "Rock_Stone"
    },
    {
      "x": -1,
      "y": 24,
      "z": 7,
      "name": "Rock_Stone"
    },
    {
      "x": -1,
      "y": 25,
      "z": 7,
      "name": "Rock_Stone"
    },
    {
      "x": -1,
      "y": 26,
      "z": 7,
      "name": "Soil_Dirt"
    },
    {
      "x": -1,
      "y": 27,
      "z": 7,
      "name": "Soil_Dirt"
    },
    {
      "x": -1,
      "y": 28,
      "z": 7,
      "name": "Soil_Grass"
    },
    {
      "x": -1,
      "y": 29,
      "z": 7,
      "name": "Plant_Grass_Sharp"
    },
    {
      "x": -1,
      "y": 24,
      "z": 8,
      "name": "Rock_Stone"
    },
    {
      "x": -1,
      "y": 25,
      "z": 8,
      "name": "Rock_Stone"
    },
    {
      "x": -1,
      "y": 26,
      "z": 8,
      "name": "Soil_Dirt"
    },
    {
      "x": -1,
      "y": 27,
      "z": 8,
      "name": "Soil_Grass"
    },
    {
      "x": 0,
      "y": 26,
      "z": -6,
      "name": "Rock_Stone"
    },
    {
      "x": 0,
      "y": 27,
      "z": -6,
      "name": "Rock_Stone"
    },
    {
      "x": 0,
      "y": 28,
      "z": -6,
      "name": "Rock_Stone_Mossy"
    },
    {
      "x": 0,
      "y": 29,
      "z": -6,
      "name": "Soil_Dirt"
    },
    {
      "x": 0,
      "y": 30,
      "z": -6,
      "name": "Soil_Dirt"
    },
    {
      "x": 0,
      "y": 31,
      "z": -6,
      "name": "Soil_Grass"
    },
    {
      "x": 0,
      "y": 24,
      "z": -5,
      "name": "Rock_Stone"
    },
    {
      "x": 0,
      "y": 25,
      "z": -5,
      "name": "Rock_Stone_Mossy"
    },
    {
      "x": 0,
      "y": 26,
      "z": -5,
      "name": "Rock_Stone"
    },
    {
      "x": 0,
      "y": 27,
      "z": -5,
      "name": "Rock_Stone"
    },
    {
      "x": 0,
      "y": 28,
      "z": -5,
      "name": "Rock_Stone"
    },
    {
      "x": 0,
      "y": 29,
      "z": -5,
      "name": "Soil_Dirt"
    },
    {
      "x": 0,
      "y": 30,
      "z": -5,
      "name": "Soil_Dirt"
    },
    {
      "x": 0,
      "y": 31,
