{
  "version": 8,
  "blockIdVersion": 8,
  "anchorX": -2,
  "anchorY": 27,
  "anchorZ": 3,
  "blocks": [
    {
      "x": -8,
      "y": 32,
      "z": 1,
      "name": "Soil_Dirt"
    },
    {
      "x": -8,
      "y": 33,
      "z": 1,
      "name": "Soil_Grass"
    },
    {
      "x": -8,
      "y": 31,
      "z": 2,
      "name": "Soil_Dirt"
    },
    {
      "x": -8,
      "y": 32,
      "z": 2,
      "name": "Soil_Dirt"
    },
    {
      "x": -8,
      "y": 33,
      "z": 2,
      "name": "Soil_Grass"
    },
    {
      "x": -8,
      "y": 29,
      "z": 3,
      "name": "Rock_Stone"
    },
    {
      "x": -8,
      "y": 30,
      "z": 3,
      "name": "Soil_Dirt"
    },
    {
      "x": -8,
      "y": 31,
      "z": 3,
      "name": "Soil_Dirt"
    },
    {
      "x": -8,
      "y": 32,
      "z": 3,
      "name": "Soil_Dirt"
    },
    {
      "x": -8,
      "y": 33,
      "z": 3,
      "name": "Soil_Grass"
    },
    {
      "x": -8,
      "y": 38,
      "z": 3,
      "name": "Rock_Stone"
    },
    {
      "x": -8,
      "y": 39,
      "z": 3,
      "name": "Soil_Dirt"
    },
    {
      "x": -8,
      "y": 40,
      "z": 3,
      "name": "Soil_Dirt"
    },
    {
      "x": -8,
      "y": 41,
      "z": 3,
      "name": "Soil_Dirt"
    },
    {
      "x": -8,
      "y": 42,
      "z": 3,
      "name": "Soil_Dirt"
    },
    {
      "x": -8,
      "y": 43,
      "z": 3,
      "name": "Soil_Grass"
    },
    {
      "x": -8,
      "y": 29,
      "z": 4,
      "name": "Rock_Stone"
    },
    {
      "x": -8,
      "y": 30,
      "z": 4,
      "name": "Soil_Dirt"
    },
    {
      "x": -8,
      "y": 31,
      "z": 4,
      "name": "Soil_Dirt"
    },
    {
      "x": -8,
      "y": 32,
      "z": 4,
      "name": "Soil_Dirt"
    },
    {
      "x": -8,
      "y": 33,
      "z": 4,
      "name": "Soil_Grass"
    },
    {
      "x": -8,
      "y": 36,
      "z": 4,
      "name": "Rock_Stone"
    },
    {
      "x": -8,
      "y": 37,
      "z": 4,
      "name": "Rock_Stone"
    },
    {
      "x": -8,
      "y": 38,
      "z": 4,
      "name": "Rock_Stone"
    },
    {
      "x": -8,
      "y": 39,
      "z": 4,
      "name": "Rock_Stone"
    },
    {
      "x": -8,
      "y": 40,
      "z": 4,
      "name": "Soil_Dirt"
    },
    {
      "x": -8,
      "y": 41,
      "z": 4,
      "name": "Soil_Dirt"
    },
    {
      "x": -8,
      "y": 42,
      "z": 4,
      "name": "Soil_Dirt"
    },
    {
      "x": -8,
      "y": 43,
      "z": 4,
      "name": "Soil_Grass"
    },
    {
      "x": -8,
      "y": 30,
      "z": 5,
      "name": "Rock_Stone"
    },
    {
      "x": -8,
      "y": 31,
      "z": 5,
      "name": "Soil_Dirt"
    },
    {
      "x": -8,
      "y": 32,
      "z": 5,
      "name": "Soil_Grass"
    },
    {
      "x": -8,
      "y": 39,
      "z": 5,
      "name": "Rock_Stone"
    },
    {
      "x": -8,
      "y": 40,
      "z": 5,
      "name": "Rock_Stone"
    },
    {
      "x": -8,
      "y": 41,
      "z": 5,
      "name": "Soil_Dirt"
    },
    {
      "x": -8,
      "y": 42,
      "z": 5,
      "name": "Soil_Dirt"
    },
    {
      "x": -8,
      "y": 43,
      "z": 5,
      "name": "Soil_Grass"
    },
    {
      "x": -8,
      "y": 44,
      "z": 5,
      "name": "Plant_Grass_Sharp_Tall"
    },
    {
      "x": -8,
      "y": 45,
      "z": 5,
      "name": "Plant_Grass_Sharp_Tall",
      "filler": 1024
    },
    {
      "x": -8,
      "y": 31,
      "z": 6,
      "name": "Soil_Dirt"
    },
    {
      "x": -8,
      "y": 32,
      "z": 6,
      "name": "Soil_Grass"
    },
    {
      "x": -8,
      "y": 31,
      "z": 7,
      "name": "Soil_Dirt"
    },
    {
      "x": -8,
      "y": 32,
      "z": 7,
      "name": "Soil_Grass"
    },
    {
      "x": -7,
      "y": 26,
      "z": 0,
      "name": "Rock_Stone_Mossy"
    },
    {
      "x": -7,
      "y": 27,
      "z": 0,
      "name": "Rock_Stone_Mossy"
    },
    {
      "x": -7,
      "y": 28,
      "z": 0,
      "name": "Rock_Stone_Mossy"
    },
    {
      "x": -7,
      "y": 25,
      "z": 1,
      "name": "Rock_Stone"
    },
    {
      "x": -7,
      "y": 26,
      "z": 1,
      "name": "Rock_Stone"
    },
    {
      "x": -7,
      "y": 27,
      "z": 1,
      "name": "Rock_Stone_Mossy"
    },
    {
      "x": -7,
      "y": 28,
      "z": 1,
      "name": "Rock_Stone_Mossy"
    },
    {
      "x": -7,
      "y": 29,
      "z": 1,
      "name": "Rock_Stone_Mossy"
    },
    {
      "x": -7,
      "y": 30,
      "z": 1,
      "name": "Rock_Stone_Mossy"
    },
    {
      "x": -7,
      "y": 31,
      "z": 1,
      "name": "Rock_Stone_Mossy"
    },
    {
      "x": -7,
      "y": 32,
      "z": 1,
      "name": "Rock_Stone_Mossy"
    },
    {
      "x": -7,
      "y": 33,
      "z": 1,
      "name": "Rock_Stone"
    },
    {
      "x": -7,
      "y": 34,
      "z": 1,
      "name": "Rock_Stone"
    },
    {
      "x": -7,
      "y": 35,
      "z": 1,
      "name": "Rock_Stone"
    },
    {
      "x": -7,
      "y": 36,
      "z": 1,
      "name": "Soil_Dirt"
    },
    {
      "x": -7,
      "y": 37,
      "z": 1,
      "name": "Soil_Dirt"
    },
    {
      "x": -7,
      "y": 38,
      "z": 1,
      "name": "Soil_Dirt"
    },
    {
      "x": -7,
      "y": 39,
      "z": 1,
      "name": "Soil_Grass"
    },
    {
      "x": -7,
      "y": 22,
      "z": 2,
      "name": "Rock_Stone"
    },
    {
      "x": -7,
      "y": 23,
      "z": 2,
      "name": "Rock_Stone"
    },
    {
      "x": -7,
      "y": 24,
      "z": 2,
      "name": "Rock_Stone"
    },
    {
      "x": -7,
      "y": 25,
      "z": 2,
      "name": "Rock_Stone"
    },
    {
      "x": -7,
      "y": 26,
      "z": 2,
      "name": "Rock_Stone"
    },
    {
      "x": -7,
      "y": 27,
      "z": 2,
      "name": "Rock_Stone_Mossy"
    },
    {
      "x": -7,
      "y": 28,
      "z": 2,
      "name": "Rock_Stone_Mossy"
    },
    {
      "x": -7,
      "y": 29,
      "z": 2,
      "name": "Rock_Stone_Mossy"
    },
    {
      "x": -7,
      "y": 30,
      "z": 2,
      "name": "Soil_Dirt"
    },
    {
      "x": -7,
      "y": 31,
      "z": 2,
      "name": "Rock_Stone_Mossy"
    },
    {
      "x": -7,
      "y": 32,
      "z": 2,
      "name": "Rock_Stone"
    },
    {
      "x": -7,
      "y": 33,
      "z": 2,
      "name": "Soil_Dirt"
    },
    {
      "x": -7,
      "y": 34,
      "z": 2,
      "name": "Rock_Stone"
    },
    {
      "x": -7,
      "y": 35,
      "z": 2,
      "name": "Rock_Stone"
    },
    {
      "x": -7,
      "y": 36,
      "z": 2,
      "name": "Rock_Stone"
    },
    {
      "x": -7,
      "y": 37,
      "z": 2,
      "name": "Soil_Dirt"
    },
    {
      "x": -7,
      "y": 38,
      "z": 2,
      "name": "Soil_Dirt"
    },
    {
      "x": -7,
      "y": 39,
      "z": 2,
      "name": "Soil_Dirt"
    },
    {
      "x": -7,
      "y": 40,
      "z": 2,
      "name": "Soil_Dirt"
    },
    {
      "x": -7,
      "y": 41,
      "z": 2,
      "name": "Soil_Dirt"
    },
    {
      "x": -7,
      "y": 42,
      "z": 2,
      "name": "Soil_Grass"
    },
    {
      "x": -7,
      "y": 22,
      "z": 3,
      "name": "Rock_Stone"
    },
    {
      "x": -7,
      "y": 23,
      "z": 3,
      "name": "Rock_Stone"
    },
    {
      "x": -7,
      "y": 24,
      "z": 3,
      "name": "Rock_Stone"
    },
    {
      "x": -7,
      "y": 25,
      "z": 3,
      "name": "Rock_Stone"
    },
    {
      "x": -7,
      "y": 26,
      "z": 3,
      "name": "Rock_Stone"
    },
    {
      "x": -7,
      "y": 27,
      "z": 3,
      "name": "Rock_Stone"
    },
    {
      "x": -7,
      "y": 28,
      "z": 3,
      "name": "Rock_Stone_Mossy"
    },
    {
      "x": -7,
      "y": 29,
      "z": 3,
      "name": "Rock_Stone_Mossy"
    },
    {
      "x": -7,
      "y": 30,
      "z": 3,
      "name": "Soil_Dirt"
    },
    {
      "x": -7,
      "y": 31,
      "z": 3,
      "name": "Soil_Dirt"
    },
    {
      "x": -7,
      "y": 32,
      "z": 3,
      "name": "Soil_Dirt"
    },
    {
      "x": -7,
      "y": 33,
      "z": 3,
      "name": "Soil_Dirt"
    },
    {
      "x": -7,
      "y": 34,
      "z": 3,
      "name": "Rock_Stone"
    },
    {
      "x": -7,
      "y": 35,
      "z": 3,
      "name": "Rock_Stone"
    },
    {
      "x": -7,
      "y": 36,
      "z": 3,
      "name": "Rock_Stone"
    },
    {
      "x": -7,
      "y": 37,
      "z": 3,
      "name": "Rock_Stone"
    },
    {
      "x": -7,
      "y": 38,
      "z": 3,
      "name": "Rock_Stone"
    },
    {
      "x": -7,
      "y": 39,
      "z": 3,
      "name": "Soil_Dirt"
    },
    {
      "x": -7,
      "y": 40,
      "z": 3,
      "name": "Soil_Dirt"
    },
    {
      "x": -7,
      "y": 41,
      "z": 3,
      "name": "Soil_Dirt"
    },
    {
      "x": -7,
      "y": 42,
      "z": 3,
      "name": "Soil_Dirt"
    },
    {
      "x": -7,
      "y": 43,
      "z": 3,
      "name": "Soil_Grass"
    },
    {
      "x": -7,
      "y": 23,
      "z": 4,
      "name": "Rock_Stone"
    },
    {
      "x": -7,
      "y": 24,
      "z": 4,
      "name": "Rock_Stone"
    },
    {
      "x": -7,
      "y": 25,
      "z": 4,
      "name": "Rock_Stone"
    },
    {
      "x": -7,
      "y": 26,
      "z": 4,
      "name": "Rock_Stone"
    },
    {
      "x": -7,
      "y": 27,
      "z": 4,
      "name": "Rock_Stone"
    },
    {
      "x": -7,
      "y": 28,
      "z": 4,
      "name": "Rock_Stone"
    },
    {
      "x": -7,
      "y": 29,
      "z": 4,
      "name": "Rock_Stone"
    },
    {
      "x": -7,
      "y": 30,
      "z": 4,
      "name": "Soil_Dirt"
    },
    {
      "x": -7,
      "y": 31,
      "z": 4,
      "name": "Soil_Dirt"
    },
    {
      "x": -7,
      "y": 32,
      "z": 4,
      "name": "Soil_Dirt"
    },
    {
      "x": -7,
      "y": 33,
      "z": 4,
      "name": "Soil_Grass"
    },
    {
      "x": -7,
      "y": 36,
      "z": 4,
      "name": "Rock_Stone"
    },
    {
      "x": -7,
      "y": 37,
      "z": 4,
      "name": "Rock_Stone"
    },
    {
      "x": -7,
      "y": 38,
      "z": 4,
      "name": "Rock_Stone"
    },
    {
      "x": -7,
      "y": 39,
      "z": 4,
      "name": "Rock_Stone"
    },
    {
      "x": -7,
      "y": 40,
      "z": 4,
      "name": "Soil_Dirt"
    },
    {
      "x": -7,
      "y": 41,
      "z": 4,
      "name": "Soil_Dirt"
    },
    {
      "x": -7,
      "y": 42,
      "z": 4,
      "name": "Soil_Dirt"
    },
    {
      "x": -7,
      "y": 43,
      "z": 4,
      "name": "Soil_Grass"
    },
    {
      "x": -7,
      "y": 28,
      "z": 5,
      "name": "Rock_Stone"
    },
    {
      "x": -7,
      "y": 29,
      "z": 5,
      "name": "Rock_Stone"
    },
    {
      "x": -7,
      "y": 30,
      "z": 5,
      "name": "Rock_Stone"
    },
    {
      "x": -7,
      "y": 31,
      "z": 5,
      "name": "Soil_Dirt"
    },
    {
      "x": -7,
      "y": 32,
      "z": 5,
      "name": "Soil_Grass"
    },
    {
      "x": -7,
      "y": 33,
      "z": 5,
      "name": "Plant_Bush"
    },
    {
      "x": -7,
      "y": 38,
      "z": 5,
      "name": "Rock_Stone"
    },
    {
      "x": -7,
      "y": 39,
      "z": 5,
      "name": "Rock_Stone"
    },
    {
      "x": -7,
      "y": 40,
      "z": 5,
      "name": "Rock_Stone"
    },
    {
      "x": -7,
      "y": 41,
      "z": 5,
      "name": "Soil_Dirt"
    },
    {
      "x": -7,
      "y": 42,
      "z": 5,
      "name": "Soil_Dirt"
    },
    {
      "x": -7,
      "y": 43,
      "z": 5,
      "name": "Soil_Grass"
    },
    {
      "x": -7,
      "y": 44,
      "z": 5,
      "name": "Plant_Grass_Sharp"
    },
    {
      "x": -7,
      "y": 30,
      "z": 6,
      "name": "Rock_Stone"
    },
    {
      "x": -7,
      "y": 31,
      "z": 6,
      "name": "Soil_Dirt"
    },
    {
      "x": -7,
      "y": 32,
      "z": 6,
      "name": "Soil_Grass"
    },
    {
      "x": -7,
      "y": 33,
      "z": 6,
      "name": "Plant_Grass_Sharp"
    },
    {
      "x": -7,
      "y": 41,
      "z": 6,
      "name": "Soil_Dirt"
    },
    {
      "x": -7,
      "y": 42,
      "z": 6,
      "name": "Soil_Dirt"
    },
    {
      "x": -7,
      "y": 43,
      "z": 6,
      "name": "Soil_Grass"
    },
    {
      "x": -7,
      "y": 44,
      "z": 6,
      "name": "Plant_Grass_Sharp_Tall"
    },
    {
      "x": -7,
      "y": 45,
      "z": 6,
      "name": "Plant_Grass_Sharp_Tall",
      "filler": 1024
    },
    {
      "x": -7,
      "y": 31,
      "z": 7,
      "name": "Soil_Dirt"
    },
    {
      "x": -7,
      "y": 32,
      "z": 7,
      "name": "Soil_Grass"
    },
    {
      "x": -7,
      "y": 31,
      "z": 8,
      "name": "Soil_Dirt"
    },
    {
      "x": -7,
      "y": 32,
      "z": 8,
      "name": "Soil_Grass"
    },
    {
      "x": -6,
      "y": 27,
      "z": -2,
      "name": "Rock_Stone"
    },
    {
      "x": -6,
      "y": 28,
      "z": -2,
      "name": "Rock_Stone"
    },
    {
      "x": -6,
      "y": 29,
      "z": -2,
      "name": "Rock_Stone"
    },
    {
      "x": -6,
      "y": 30,
      "z": -2,
      "name": "Rock_Stone"
    },
    {
      "x": -6,
      "y": 31,
      "z": -2,
      "name": "Rock_Stone"
    },
    {
      "x": -6,
      "y": 25,
      "z": -1,
      "name": "Rock_Stone"
    },
    {
      "x": -6,
      "y": 26,
      "z": -1,
      "name": "Rock_Stone"
    },
    {
      "x": -6,
      "y": 27,
      "z": -1,
      "name": "Rock_Stone"
    },
    {
      "x": -6,
      "y": 28,
      "z": -1,
      "name": "Rock_Stone"
    },
    {
      "x": -6,
      "y": 29,
      "z": -1,
      "name": "Rock_Stone"
    },
    {
      "x": -6,
      "y": 30,
      "z": -1,
      "name": "Rock_Stone"
    },
    {
      "x": -6,
      "y": 31,
      "z": -1,
      "name": "Rock_Stone"
    },
    {
      "x": -6,
      "y": 32,
      "z": -1,
      "name": "Rock_Stone"
    },
    {
      "x": -6,
      "y": 33,
      "z": -1,
      "name": "Soil_Dirt"
    },
    {
      "x": -6,
      "y": 34,
      "z": -1,
      "name": "Soil_Dirt"
    },
    {
      "x": -6,
      "y": 35,
      "z": -1,
      "name": "Soil_Grass"
    },
    {
      "x": -6,
      "y": 53,
      "z": -1,
      "name": "Plant_Leaves_Aspen"
    },
    {
      "x": -6,
      "y": 24,
      "z": 0,
      "name": "Rock_Stone"
    },
    {
      "x": -6,
      "y": 25,
      "z": 0,
      "name": "Rock_Stone"
    },
    {
      "x": -6,
      "y": 26,
      "z": 0,
      "name": "Rock_Stone"
    },
    {
      "x": -6,
      "y": 27,
      "z": 0,
      "name": "Rock_Stone_Mossy"
    },
    {
      "x": -6,
      "y": 28,
      "z": 0,
      "name": "Rock_Stone_Mossy"
    },
    {
      "x": -6,
      "y": 29,
      "z": 0,
      "name": "Rock_Stone"
    },
    {
      "x": -6,
      "y": 30,
      "z": 0,
      "name": "Rock_Stone"
    },
    {
      "x": -6,
      "y": 31,
      "z": 0,
      "name": "Rock_Stone"
    },
    {
      "x": -6,
      "y": 32,
      "z": 0,
      "name": "Rock_Stone"
    },
    {
      "x": -6,
      "y": 33,
      "z": 0,
      "name": "Rock_Stone"
    },
    {
      "x": -6,
      "y": 34,
      "z": 0,
      "name": "Soil_Dirt"
    },
    {
      "x": -6,
      "y": 35,
      "z": 0,
      "name": "Soil_Dirt"
    },
    {
      "x": -6,
      "y": 36,
      "z": 0,
      "name": "Soil_Dirt"
    },
    {
      "x": -6,
      "y": 37,
      "z": 0,
      "name": "Soil_Dirt"
    },
    {
      "x": -6,
      "y": 38,
      "z": 0,
      "name": "Soil_Grass"
    },
    {
      "x": -6,
      "y": 20,
      "z": 1,
      "name": "Rock_Stone"
    },
    {
      "x": -6,
      "y": 21,
      "z": 1,
      "name": "Rock_Stone"
    },
    {
      "x": -6,
      "y": 22,
      "z": 1,
      "name": "Rock_Stone"
    },
    {
      "x": -6,
      "y": 23,
      "z": 1,
      "name": "Rock_Stone"
    },
    {
      "x": -6,
      "y": 24,
      "z": 1,
      "name": "Rock_Stone"
    },
    {
      "x": -6,
      "y": 25,
      "z": 1,
      "name": "Rock_Stone"
    },
    {
      "x": -6,
      "y": 26,
      "z": 1,
      "name": "Rock_Stone"
    },
    {
      "x": -6,
      "y": 27,
      "z": 1,
      "name": "Rock_Stone"
    },
    {
      "x": -6,
      "y": 28,
      "z": 1,
      "name": "Rock_Stone"
    },
    {
      "x": -6,
      "y": 29,
      "z": 1,
      "name": "Rock_Stone"
    },
    {
      "x": -6,
      "y": 30,
      "z": 1,
      "name": "Rock_Stone"
    },
    {
      "x": -6,
      "y": 31,
      "z": 1,
      "name": "Rock_Stone_Mossy"
    },
    {
      "x": -6,
      "y": 32,
      "z": 1,
      "name": "Rock_Stone"
    },
    {
      "x": -6,
      "y": 33,
      "z": 1,
      "name": "Rock_Stone"
    },
    {
      "x": -6,
      "y": 34,
      "z": 1,
      "name": "Rock_Stone"
    },
    {
      "x": -6,
      "y": 35,
      "z": 1,
      "name": "Rock_Stone"
    },
    {
      "x": -6,
      "y": 36,
      "z": 1,
      "name": "Soil_Dirt"
    },
    {
      "x": -6,
      "y": 37,
      "z": 1,
      "name": "Soil_Dirt"
    },
    {
      "x": -6,
      "y": 38,
      "z": 1,
      "name": "Soil_Dirt"
    },
    {
      "x": -6,
      "y": 39,
      "z": 1,
      "name": "Soil_Dirt"
    },
    {
      "x": -6,
      "y": 40,
      "z": 1,
      "name": "Soil_Dirt"
    },
    {
      "x": -6,
      "y": 41,
      "z": 1,
      "name": "Soil_Grass"
    },
    {
      "x": -6,
      "y": 42,
      "z": 1,
      "name": "Plant_Grass_Sharp"
    },
    {
      "x": -6,
      "y": 52,
      "z": 1,
      "name": "Plant_Leaves_Aspen"
    },
    {
      "x": -6,
      "y": 53,
      "z": 1,
      "name": "Plant_Leaves_Aspen"
    },
    {
      "x": -6,
      "y": 54,
      "z": 1,
      "name": "Plant_Leaves_Aspen"
    },
    {
      "x": -6,
      "y": 19,
      "z": 2,
      "name": "Rock_Stone"
    },
    {
      "x": -6,
      "y": 20,
      "z": 2,
      "name": "Rock_Stone"
    },
    {
      "x": -6,
      "y": 21,
      "z": 2,
      "name": "Rock_Stone"
    },
    {
      "x": -6,
      "y": 22,
      "z": 2,
      "name": "Rock_Stone"
    },
    {
      "x": -6,
      "y": 23,
      "z": 2,
      "name": "Rock_Stone"
    },
    {
      "x": -6,
      "y": 24,
      "z": 2,
      "name": "Rock_Stone"
    },
    {
      "x": -6,
      "y": 25,
      "z": 2,
      "name": "Rock_Stone"
    },
    {
      "x": -6,
      "y": 26,
      "z": 2,
      "name": "Rock_Stone"
    },
    {
      "x": -6,
      "y": 27,
      "z": 2,
      "name": "Rock_Stone"
    },
    {
      "x": -6,
      "y": 28,
      "z": 2,
      "name": "Rock_Stone_Mossy"
    },
    {
      "x": -6,
      "y": 29,
      "z": 2,
      "name": "Rock_Stone_Mossy"
    },
    {
      "x": -6,
      "y": 30,
      "z": 2,
      "name": "Rock_Stone"
    },
    {
      "x": -6,
      "y": 31,
      "z": 2,
      "name": "Rock_Stone"
    },
    {
      "x": -6,
      "y": 32,
      "z": 2,
      "name": "Rock_Stone"
    },
    {
      "x": -6,
      "y": 33,
      "z": 2,
      "name": "Rock_Stone"
    },
    {
      "x": -6,
      "y": 34,
      "z": 2,
      "name": "Rock_Stone"
    },
    {
      "x": -6,
      "y": 35,
      "z": 2,
      "name": "Rock_Stone"
    },
    {
      "x": -6,
      "y": 36,
      "z": 2,
      "name": "Rock_Stone"
    },
    {
      "x": -6,
      "y": 37,
      "z": 2,
      "name": "Soil_Dirt"
    },
    {
      "x": -6,
      "y": 38,
      "z": 2,
      "name": "Soil_Dirt"
    },
    {
      "x": -6,
      "y": 39,
      "z": 2,
      "name": "Soil_Dirt"
    },
    {
      "x": -6,
      "y": 40,
      "z": 2,
      "name": "Soil_Dirt"
    },
    {
      "x": -6,
      "y": 41,
      "z": 2,
      "name": "Soil_Dirt"
    },
    {
      "x": -6,
      "y": 42,
      "z": 2,
      "name": "Soil_Dirt"
    },
    {
      "x": -6,
      "y": 43,
      "z": 2,
      "name": "Soil_Grass"
    },
    {
      "x": -6,
      "y": 51,
      "z": 2,
      "name": "Plant_Leaves_Aspen"
    },
    {
      "x": -6,
      "y": 52,
      "z": 2,
      "name": "Plant_Leaves_Aspen"
    },
    {
      "x": -6,
      "y": 53,
      "z": 2,
      "name": "Plant_Leaves_Aspen"
    },
    {
      "x": -6,
      "y": 54,
      "z": 2,
      "name": "Plant_Leaves_Aspen"
    },
    {
      "x": -6,
      "y": 55,
      "z": 2,
      "name": "Plant_Leaves_Aspen"
    },
    {
      "x": -6,
      "y": 57,
      "z": 2,
      "name": "Plant_Leaves_Aspen"
    },
    {
      "x": -6,
      "y": 20,
      "z": 3,
      "name": "Rock_Stone"
    },
    {
      "x": -6,
      "y": 21,
      "z": 3,
      "name": "Rock_Stone"
    },
    {
      "x": -6,
      "y": 22,
      "z": 3,
      "name": "Rock_Stone"
    },
    {
      "x": -6,
      "y": 23,
      "z": 3,
      "name": "Rock_Stone"
    },
    {
      "x": -6,
      "y": 24,
      "z": 3,
      "name": "Rock_Stone"
    },
    {
      "x": -6,
      "y": 25,
      "z": 3,
      "name": "Rock_Stone"
    },
    {
      "x": -6,
      "y": 26,
      "z": 3,
      "name": "Rock_Stone"
    },
    {
      "x": -6,
      "y": 27,
      "z": 3,
      "name": "Rock_Stone"
    },
    {
      "x": -6,
      "y": 28,
      "z": 3,
      "name": "Rock_Stone"
    },
    {
      "x": -6,
      "y": 29,
      "z": 3,
      "name": "Rock_Stone"
    },
    {
      "x": -6,
      "y": 30,
      "z": 3,
      "name": "Rock_Stone"
    },
    {
      "x": -6,
      "y": 31,
      "z": 3,
      "name": "Soil_Dirt"
    },
    {
      "x": -6,
      "y": 32,
      "z": 3,
      "name": "Soil_Dirt"
    },
    {
      "x": -6,
      "y": 33,
      "z": 3,
      "name": "Rock_Stone"
    },
    {
      "x": -6,
      "y": 34,
      "z": 3,
      "name": "Rock_Stone"
    },
    {
      "x": -6,
      "y": 35,
      "z": 3,
      "name": "Rock_Stone"
    },
    {
      "x": -6,
      "y": 36,
      "z": 3,
      "name": "Rock_Stone"
    },
    {
      "x": -6,
      "y": 37,
      "z": 3,
      "name": "Rock_Stone"
    },
    {
      "x": -6,
      "y": 38,
      "z": 3,
      "name": "Rock_Stone"
    },
    {
      "x": -6,
      "y": 39,
      "z": 3,
      "name": "Soil_Dirt"
    },
    {
      "x": -6,
      "y": 40,
      "z": 3,
      "name": "Soil_Dirt"
    },
    {
      "x": -6,
      "y": 41,
      "z": 3,
      "name": "Soil_Dirt"
    },
    {
      "x": -6,
      "y": 42,
      "z": 3,
      "name": "Soil_Dirt"
    },
    {
      "x": -6,
      "y": 43,
      "z": 3,
      "name": "Soil_Grass"
    },
    {
      "x": -6,
      "y": 52,
      "z": 3,
      "name": "Plant_Leaves_Aspen"
    },
    {
      "x": -6,
      "y": 53,
      "z": 3,
      "name": "Plant_Leaves_Aspen"
    },
    {
      "x": -6,
      "y": 20,
      "z": 4,
      "name": "Rock_Stone"
    },
    {
      "x": -6,
      "y": 21,
      "z": 4,
      "name": "Rock_Stone"
    },
    {
      "x": -6,
      "y": 22,
      "z": 4,
      "name": "Rock_Stone"
    },
    {
      "x": -6,
      "y": 23,
      "z": 4,
      "name": "Rock_Stone"
    },
    {
      "x": -6,
      "y": 24,
      "z": 4,
      "name": "Rock_Stone"
    },
    {
      "x": -6,
      "y": 25,
      "z": 4,
      "name": "Rock_Stone"
    },
    {
      "x": -6,
      "y": 26,
      "z": 4,
      "name": "Rock_Stone"
    },
    {
      "x": -6,
      "y": 27,
      "z": 4,
      "name": "Rock_Stone"
    },
    {
      "x": -6,
      "y": 28,
      "z": 4,
      "name": "Rock_Stone"
    },
    {
      "x": -6,
      "y": 29,
      "z": 4,
      "name": "Rock_Stone"
    },
    {
      "x": -6,
      "y": 30,
      "z": 4,
      "name": "Rock_Stone"
    },
    {
      "x": -6,
      "y": 31,
      "z": 4,
      "name": "Soil_Dirt"
    },
    {
      "x": -6,
      "y": 32,
      "z": 4,
      "name": "Soil_Dirt"
    },
    {
      "x": -6,
      "y": 33,
      "z": 4,
      "name": "Rock_Stone"
    },
    {
      "x": -6,
      "y": 34,
      "z": 4,
      "name": "Rock_Stone"
    },
    {
      "x": -6,
      "y": 35,
      "z": 4,
      "name": "Rock_Stone"
    },
    {
      "x": -6,
      "y": 36,
      "z": 4,
      "name": "Rock_Stone_Mossy"
    },
    {
      "x": -6,
      "y": 37,
      "z": 4,
      "name": "Rock_Stone"
    },
    {
      "x": -6,
      "y": 38,
      "z": 4,
      "name": "Rock_Stone"
    },
    {
      "x": -6,
      "y": 39,
      "z": 4,
      "name": "Rock_Stone"
    },
    {
      "x": -6,
      "y": 40,
      "z": 4,
      "name": "Soil_Dirt"
    },
    {
      "x": -6,
      "y": 41,
      "z": 4,
      "name": "Soil_Dirt"
    },
    {
      "x": -6,
      "y": 42,
      "z": 4,
      "name": "Soil_Dirt"
    },
    {
      "x": -6,
      "y": 43,
      "z": 4,
      "name": "Soil_Grass"
    },
    {
      "x": -6,
      "y": 25,
      "z": 5,
      "name": "Rock_Stone"
    },
    {
      "x": -6,
      "y": 26,
      "z": 5,
      "name": "Rock_Stone"
    },
    {
      "x": -6,
      "y": 27,
      "z": 5,
      "name": "Rock_Stone"
    },
    {
      "x": -6,
      "y": 28,
      "z": 5,
      "name": "Rock_Stone"
    },
    {
      "x": -6,
      "y": 29,
      "z": 5,
      "name": "Rock_Stone"
    },
    {
      "x": -6,
      "y": 30,
      "z": 5,
      "name": "Rock_Stone"
    },
    {
      "x": -6,
      "y": 31,
      "z": 5,
      "name": "Rock_Stone"
    },
    {
      "x": -6,
      "y": 32,
      "z": 5,
      "name": "Rock_Stone"
    },
    {
      "x": -6,
      "y": 33,
      "z": 5,
      "name": "Rock_Stone"
    },
    {
      "x": -6,
      "y": 34,
      "z": 5,
      "name": "Rock_Stone"
    },
    {
      "x": -6,
      "y": 35,
      "z": 5,
      "name": "Rock_Stone_Mossy"
    },
    {
      "x": -6,
      "y": 36,
      "z": 5,
      "name": "Rock_Stone_Mossy"
    },
    {
      "x": -6,
      "y": 37,
      "z": 5,
      "name": "Rock_Stone_Mossy"
    },
    {
      "x": -6,
      "y": 38,
      "z": 5,
      "name": "Rock_Stone_Mossy"
    },
    {
      "x": -6,
      "y": 39,
      "z": 5,
      "name": "Rock_Stone"
    },
    {
      "x": -6,
      "y": 40,
      "z": 5,
      "name": "Rock_Stone"
    },
    {
      "x": -6,
      "y": 41,
      "z": 5,
      "name": "Soil_Dirt"
    },
    {
      "x": -6,
      "y": 42,
      "z": 5,
      "name": "Soil_Dirt"
    },
    {
      "x": -6,
      "y": 43,
      "z": 5,
      "name": "Soil_Grass"
    },
    {
      "x": -6,
      "y": 44,
      "z": 5,
      "name": "Plant_Grass_Sharp"
    },
    {
      "x": -6,
      "y": 27,
      "z": 6,
      "name": "Rock_Stone"
    },
    {
      "x": -6,
      "y": 28,
      "z": 6,
      "name": "Rock_Stone"
    },
    {
      "x": -6,
      "y": 29,
      "z": 6,
      "name": "Rock_Stone"
    },
    {
      "x": -6,
      "y": 30,
      "z": 6,
      "name": "Rock_Stone"
    },
    {
      "x": -6,
      "y": 31,
      "z": 6,
      "name": "Soil_Dirt"
    },
    {
      "x": -6,
      "y": 32,
      "z": 6,
      "name": "Soil_Grass"
    },
    {
      "x": -6,
      "y": 33,
      "z": 6,
      "name": "Plant_Grass_Sharp"
    },
    {
      "x": -6,
      "y": 37,
      "z": 6,
      "name": "Rock_Stone_Mossy"
    },
    {
      "x": -6,
      "y": 38,
      "z": 6,
      "name": "Rock_Stone_Mossy"
    },
    {
      "x": -6,
      "y": 39,
      "z": 6,
      "name": "Rock_Stone_Mossy"
    },
    {
      "x": -6,
      "y": 40,
      "z": 6,
      "name": "Rock_Stone_Mossy"
    },
    {
      "x": -6,
      "y": 41,
      "z": 6,
      "name": "Soil_Dirt"
    },
    {
      "x": -6,
      "y": 42,
      "z": 6,
      "name": "Soil_Dirt"
    },
    {
      "x": -6,
      "y": 43,
      "z": 6,
      "name": "Soil_Grass"
    },
    {
      "x": -6,
      "y": 29,
      "z": 7,
      "name": "Rock_Stone"
    },
    {
      "x": -6,
      "y": 30,
      "z": 7,
      "name": "Soil_Dirt"
    },
    {
      "x": -6,
      "y": 31,
      "z": 7,
      "name": "Soil_Dirt"
    },
    {
      "x": -6,
      "y": 32,
      "z": 7,
      "name": "Soil_Grass"
    },
    {
      "x": -6,
      "y": 33,
      "z": 7,
      "name": "Plant_Grass_Sharp_Tall"
    },
    {
      "x": -6,
      "y": 34,
      "z": 7,
      "name": "Plant_Grass_Sharp_Tall",
      "filler": 1024
    },
    {
      "x": -6,
      "y": 30,
      "z": 8,
      "name": "Soil_Dirt"
    },
    {
      "x": -6,
      "y": 31,
      "z": 8,
      "name": "Soil_Dirt"
    },
    {
      "x": -6,
      "y": 32,
      "z": 8,
      "name": "Soil_Grass"
    },
    {
      "x": -5,
      "y": 25,
      "z": -2,
      "name": "Rock_Stone"
    },
    {
      "x": -5,
      "y": 26,
      "z": -2,
      "name": "Rock_Stone"
    },
    {
      "x": -5,
      "y": 27,
      "z": -2,
      "name": "Rock_Stone"
    },
    {
      "x": -5,
      "y": 28,
      "z": -2,
      "name": "Rock_Stone"
    },
    {
      "x": -5,
      "y": 29,
      "z": -2,
      "name": "Rock_Stone"
    },
    {
      "x": -5,
      "y": 30,
      "z": -2,
      "name": "Rock_Stone"
    },
    {
      "x": -5,
      "y": 31,
      "z": -2,
      "name": "Rock_Stone"
    },
    {
      "x": -5,
      "y": 32,
      "z": -2,
      "name": "Rock_Stone"
    },
    {
      "x": -5,
      "y": 33,
      "z": -2,
      "name": "Rock_Stone"
    },
    {
      "x": -5,
      "y": 34,
      "z": -2,
      "name": "Rock_Stone"
    },
    {
      "x": -5,
      "y": 35,
      "z": -2,
      "name": "Rock_Stone"
    },
    {
      "x": -5,
      "y": 36,
      "z": -2,
      "name": "Rock_Stone"
    },
    {
      "x": -5,
      "y": 37,
      "z": -2,
      "name": "Soil_Dirt"
    },
    {
      "x": -5,
      "y": 38,
      "z": -2,
      "name": "Soil_Grass"
    },
    {
      "x": -5,
      "y": 21,
      "z": -1,
      "name": "Rock_Stone"
    },
    {
      "x": -5,
      "y": 22,
      "z": -1,
      "name": "Rock_Stone"
    },
    {
      "x": -5,
      "y": 23,
      "z": -1,
      "name": "Rock_Stone"
    },
    {
      "x": -5,
      "y": 24,
      "z": -1,
      "name": "Rock_Stone"
    },
    {
      "x": -5,
      "y": 25,
      "z": -1,
      "name": "Rock_Stone"
    },
    {
      "x": -5,
      "y": 26,
      "z": -1,
      "name": "Rock_Stone"
    },
    {
      "x": -5,
      "y": 27,
      "z": -1,
      "name": "Rock_Stone"
    },
    {
      "x": -5,
      "y": 28,
      "z": -1,
      "name": "Rock_Stone"
    },
    {
      "x": -5,
      "y": 29,
      "z": -1,
      "name": "Rock_Stone"
    },
    {
      "x": -5,
      "y": 30,
      "z": -1,
      "name": "Rock_Stone"
    },
    {
      "x": -5,
      "y": 31,
      "z": -1,
      "name": "Rock_Stone"
    },
    {
      "x": -5,
      "y": 32,
      "z": -1,
      "name": "Rock_Stone"
    },
    {
      "x": -5,
      "y": 33,
      "z": -1,
      "name": "Rock_Stone"
    },
    {
      "x": -5,
      "y": 34,
      "z": -1,
      "name": "Rock_Stone"
    },
    {
      "x": -5,
      "y": 35,
      "z": -1,
      "name": "Rock_Stone"
    },
    {
      "x": -5,
      "y": 36,
      "z": -1,
      "name": "Soil_Dirt"
    },
    {
      "x": -5,
      "y": 37,
      "z": -1,
      "name": "Soil_Dirt"
    },
    {
      "x": -5,
      "y": 38,
      "z": -1,
      "name": "Soil_Dirt"
    },
    {
      "x": -5,
      "y": 39,
      "z": -1,
      "name": "Soil_Grass"
    },
    {
      "x": -5,
      "y": 52,
      "z": -1,
      "name": "Plant_Leaves_Aspen"
    },
    {
      "x": -5,
      "y": 53,
      "z": -1,
      "name": "Plant_Leaves_Aspen"
    },
    {
      "x": -5,
      "y": 19,
      "z": 0,
      "name": "Rock_Stone"
    },
    {
      "x": -5,
      "y": 20,
      "z": 0,
      "name": "Rock_Stone"
    },
    {
      "x": -5,
      "y": 21,
      "z": 0,
      "name": "Rock_Stone"
    },
    {
      "x": -5,
      "y": 22,
      "z": 0,
      "name": "Rock_Stone"
    },
    {
      "x": -5,
      "y": 23,
      "z": 0,
      "name": "Rock_Stone"
    },
    {
      "x": -5,
      "y": 24,
      "z": 0,
      "name": "Rock_Stone"
    },
    {
      "x": -5,
      "y": 25,
      "z": 0,
      "name": "Rock_Stone"
    },
    {
      "x": -5,
      "y": 26,
      "z": 0,
      "name": "Rock_Stone"
    },
    {
      "x": -5,
      "y": 27,
      "z": 0,
      "name": "Rock_Stone"
    },
    {
      "x": -5,
      "y": 28,
      "z": 0,
      "name": "Rock_Stone"
    },
    {
      "x": -5,
      "y": 29,
      "z": 0,
      "name": "Rock_Stone"
    },
    {
      "x": -5,
      "y": 30,
      "z": 0,
      "name": "Rock_Stone"
    },
    {
      "x": -5,
      "y": 31,
      "z": 0,
      "name": "Rock_Stone"
    },
    {
      "x": -5,
      "y": 32,
      "z": 0,
      "name": "Rock_Stone"
    },
    {
      "x": -5,
      "y": 33,
      "z": 0,
      "name": "Rock_Stone"
    },
    {
      "x": -5,
      "y": 34,
      "z": 0,
      "name": "Rock_Stone"
    },
    {
      "x": -5,
      "y": 35,
      "z": 0,
      "name": "Rock_Stone"
    },
    {
      "x": -5,
      "y": 36,
      "z": 0,
      "name": "Soil_Dirt"
    },
    {
      "x": -5,
      "y": 37,
      "z": 0,
      "name": "Soil_Dirt"
    },
    {
      "x": -5,
      "y": 38,
      "z": 0,
      "name": "Soil_Dirt"
    },
    {
      "x": -5,
      "y": 39,
      "z": 0,
      "name": "Soil_Dirt"
    },
    {
      "x": -5,
      "y": 40,
      "z": 0,
      "name": "Soil_Dirt"
    },
    {
      "x": -5,
      "y": 41,
      "z": 0,
      "name": "Soil_Dirt"
    },
    {
      "x": -5,
      "y": 42,
      "z": 0,
      "name": "Soil_Dirt"
    },
    {
      "x": -5,
      "y": 43,
      "z": 0,
      "name": "Soil_Grass"
    },
    {
      "x": -5,
      "y": 53,
      "z": 0,
      "name": "Plant_Leaves_Aspen"
    },
    {
      "x": -5,
      "y": 54,
      "z": 0,
      "name": "Plant_Leaves_Aspen"
    },
    {
      "x": -5,
      "y": 55,
      "z": 0,
      "name": "Plant_Leaves_Aspen"
    },
    {
      "x": -5,
      "y": 56,
      "z": 0,
      "name": "Plant_Leaves_Aspen"
    },
    {
      "x": -5,
      "y": 18,
      "z": 1,
      "name": "Rock_Stone"
    },
    {
      "x": -5,
      "y": 19,
      "z": 1,
      "name": "Rock_Stone"
    },
    {
      "x": -5,
      "y": 20,
      "z": 1,
      "name": "Rock_Stone"
    },
    {
      "x": -5,
      "y": 21,
      "z": 1,
      "name": "Rock_Stone"
    },
    {
      "x": -5,
      "y": 22,
      "z": 1,
      "name": "Rock_Stone"
    },
    {
      "x": -5,
      "y": 23,
      "z": 1,
      "name": "Rock_Stone"
    },
    {
      "x": -5,
      "y": 24,
      "z": 1,
      "name": "Rock_Stone"
    },
    {
      "x": -5,
      "y": 25,
      "z": 1,
      "name": "Rock_Stone"
    },
    {
      "x": -5,
      "y": 26,
      "z": 1,
      "name": "Rock_Stone"
    },
    {
      "x": -5,
      "y": 27,
      "z": 1,
      "name": "Rock_Stone"
    },
    {
      "x": -5,
      "y": 28,
      "z": 1,
      "name": "Rock_Stone"
    },
    {
      "x": -5,
      "y": 29,
      "z": 1,
      "name": "Rock_Stone"
    },
    {
      "x": -5,
      "y": 30,
      "z": 1,
      "name": "Rock_Stone"
    },
    {
      "x": -5,
      "y": 31,
      "z": 1,
      "name": "Rock_Stone"
    },
    {
      "x": -5,
      "y": 32,
      "z": 1,
      "name": "Rock_Stone"
    },
    {
      "x": -5,
      "y": 33,
      "z": 1,
      "name": "Rock_Stone"
    },
    {
      "x": -5,
      "y": 34,
      "z": 1,
      "name": "Rock_Stone"
    },
    {
      "x": -5,
      "y": 35,
      "z": 1,
      "name": "Rock_Stone"
    },
    {
      "x": -5,
      "y": 36,
      "z": 1,
      "name": "Soil_Dirt"
    },
    {
      "x": -5,
      "y": 37,
      "z": 1,
      "name": "Soil_Dirt"
    },
    {
      "x": -5,
      "y": 38,
      "z": 1,
      "name": "Soil_Dirt"
    },
    {
      "x": -5,
      "y": 39,
      "z": 1,
      "name": "Soil_Dirt"
    },
    {
      "x": -5,
      "y": 40,
      "z": 1,
      "name": "Soil_Dirt"
    },
    {
      "x": -5,
      "y": 41,
      "z": 1,
      "name": "Soil_Dirt"
    },
    {
      "x": -5,
      "y": 42,
      "z": 1,
      "name": "Soil_Dirt"
    },
    {
      "x": -5,
      "y": 43,
      "z": 1,
      "name": "Soil_Dirt"
    },
    {
      "x": -5,
      "y": 44,
      "z": 1,
      "name": "Soil_Grass"
    },
    {
      "x": -5,
      "y": 53,
      "z": 1,
      "name": "Plant_Leaves_Aspen"
    },
    {
      "x": -5,
      "y": 56,
      "z": 1,
      "name": "Plant_Leaves_Aspen"
    },
    {
      "x": -5,
      "y": 57,
      "z": 1,
      "name": "Plant_Leaves_Aspen"
    },
    {
      "x": -5,
      "y": 58,
      "z": 1,
      "name": "Plant_Leaves_Aspen"
    },
    {
      "x": -5,
      "y": 18,
      "z": 2,
      "name": "Rock_Stone"
    },
    {
      "x": -5,
      "y": 19,
      "z": 2,
      "name": "Rock_Stone"
    },
    {
      "x": -5,
      "y": 20,
      "z": 2,
      "name": "Rock_Stone"
    },
    {
      "x": -5,
      "y": 21,
      "z": 2,
      "name": "Rock_Stone"
    },
    {
      "x": -5,
      "y": 22,
      "z": 2,
      "name": "Rock_Stone"
    },
    {
      "x": -5,
      "y": 23,
      "z": 2,
      "name": "Rock_Stone"
    },
    {
      "x": -5,
      "y": 24,
      "z": 2,
      "name": "Rock_Stone"
    },
    {
      "x": -5,
      "y": 25,
      "z": 2,
      "name": "Rock_Stone"
    },
    {
      "x": -5,
      "y": 26,
      "z": 2,
      "name": "Rock_Stone"
    },
    {
      "x": -5,
      "y": 27,
      "z": 2,
      "name": "Rock_Stone"
    },
    {
      "x": -5,
      "y": 28,
      "z": 2,
      "name": "Rock_Stone"
    },
    {
      "x": -5,
      "y": 29,
      "z": 2,
      "name": "Rock_Stone"
    },
    {
      "x": -5,
      "y": 30,
      "z": 2,
      "name": "Rock_Stone"
    },
    {
      "x": -5,
      "y": 31,
      "z": 2,
      "name": "Rock_Stone"
    },
    {
      "x": -5,
      "y": 32,
      "z": 2,
      "name": "Rock_Stone"
    },
    {
      "x": -5,
      "y": 33,
      "z": 2,
      "name": "Rock_Stone"
    },
    {
      "x": -5,
      "y": 34,
      "z": 2,
      "name": "Rock_Stone"
    },
    {
      "x": -5,
      "y": 35,
      "z": 2,
      "name": "Rock_Stone"
    },
    {
      "x": -5,
      "y": 36,
      "z": 2,
      "name": "Rock_Stone"
    },
    {
      "x": -5,
      "y": 37,
      "z": 2,
      "name": "Soil_Dirt"
    },
    {
      "x": -5,
      "y": 38,
      "z": 2,
      "name": "Soil_Dirt"
    },
    {
      "x": -5,
      "y": 39,
      "z": 2,
      "name": "Rock_Stone"
    },
    {
      "x": -5,
      "y": 40,
      "z": 2,
      "name": "Soil_Dirt"
    },
    {
      "x": -5,
      "y": 41,
      "z": 2,
      "name": "Soil_Dirt"
    },
    {
      "x": -5,
      "y": 42,
      "z": 2,
      "name": "Soil_Dirt"
    },
    {
      "x": -5,
      "y": 43,
      "z": 2,
      "name": "Soil_Dirt"
    },
    {
      "x": -5,
      "y": 44,
      "z": 2,
      "name": "Soil_Grass"
    },
    {
      "x": -5,
      "y": 50,
      "z": 2,
      "name": "Plant_Leaves_Aspen"
    },
    {
      "x": -5,
      "y": 51,
      "z": 2,
      "name": "Plant_Leaves_Aspen"
    },
    {
      "x": -5,
      "y": 52,
      "z": 2,
      "name": "Wood_Aspen_Branch_Corner",
      "rotation": 3
    },
    {
      "x": -5,
      "y": 53,
      "z": 2,
      "name": "Wood_Aspen_Branch_Long"
    },
    {
      "x": -5,
      "y": 54,
      "z": 2,
      "name": "Plant_Leaves_Aspen"
    },
    {
      "x": -5,
      "y": 55,
      "z": 2,
      "name": "Plant_Leaves_Aspen"
    },
    {
      "x": -5,
      "y": 56,
      "z": 2,
      "name": "Plant_Leaves_Aspen"
    },
    {
      "x": -5,
      "y": 57,
      "z": 2,
      "name": "Plant_Leaves_Aspen"
    },
    {
      "x": -5,
      "y": 58,
      "z": 2,
      "name": "Plant_Leaves_Aspen"
    },
    {
      "x": -5,
      "y": 60,
      "z": 2,
      "name": "Plant_Leaves_Aspen"
    },
    {
      "x": -5,
      "y": 19,
      "z": 3,
      "name": "Rock_Stone"
    },
    {
      "x": -5,
      "y": 20,
      "z": 3,
      "name": "Rock_Stone"
    },
    {
      "x": -5,
      "y": 21,
      "z": 3,
      "name": "Rock_Stone"
    },
    {
      "x": -5,
      "y": 22,
      "z": 3,
      "name": "Rock_Stone"
    },
    {
      "x": -5,
      "y": 23,
      "z": 3,
      "name": "Rock_Stone"
    },
    {
      "x": -5,
      "y": 24,
      "z": 3,
      "name": "Rock_Stone"
    },
    {
      "x": -5,
      "y": 25,
      "z": 3,
      "name": "Rock_Stone"
    },
    {
      "x": -5,
      "y": 26,
      "z": 3,
      "name": "Rock_Stone"
    },
    {
      "x": -5,
      "y": 27,
      "z": 3,
      "name": "Rock_Stone"
    },
    {
      "x": -5,
      "y": 28,
      "z": 3,
      "name": "Rock_Stone"
    },
    {
      "x": -5,
      "y": 29,
      "z": 3,
      "name": "Rock_Stone"
    },
    {
      "x": -5,
      "y": 30,
      "z": 3,
      "name": "Rock_Stone"
    },
    {
      "x": -5,
      "y": 31,
      "z": 3,
      "name": "Rock_Stone"
    },
    {
      "x": -5,
      "y": 32,
      "z": 3,
      "name": "Rock_Stone"
    },
    {
      "x": -5,
      "y": 33,
      "z": 3,
      "name": "Rock_Stone"
    },
    {
      "x": -5,
      "y": 34,
      "z": 3,
      "name": "Rock_Stone"
    },
    {
      "x": -5,
      "y": 35,
      "z": 3,
      "name": "Rock_Stone"
    },
    {
      "x": -5,
      "y": 36,
      "z": 3,
      "name": "Rock_Stone"
    },
    {
      "x": -5,
      "y": 37,
      "z": 3,
      "name": "Rock_Stone"
    },
    {
      "x": -5,
      "y": 38,
      "z": 3,
      "name": "Rock_Stone"
    },
    {
      "x": -5,
      "y": 39,
      "z": 3,
      "name": "Rock_Stone"
    },
    {
      "x": -5,
      "y": 40,
      "z": 3,
      "name": "Soil_Dirt"
    },
    {
      "x": -5,
      "y": 41,
      "z": 3,
      "name": "Soil_Dirt"
    },
    {
      "x": -5,
      "y": 42,
      "z": 3,
      "name": "Soil_Dirt"
    },
    {
      "x": -5,
      "y": 43,
      "z": 3,
      "name": "Soil_Dirt"
    },
    {
      "x": -5,
      "y": 44,
      "z": 3,
      "name": "Soil_Grass"
    },
    {
      "x": -5,
      "y": 52,
      "z": 3,
      "name": "Plant_Leaves_Aspen"
    },
    {
      "x": -5,
      "y": 53,
      "z": 3,
      "name": "Plant_Leaves_Aspen"
    },
    {
      "x": -5,
      "y": 54,
      "z": 3,
      "name": "Plant_Leaves_Aspen"
    },
    {
      "x": -5,
      "y": 55,
      "z": 3,
      "name": "Plant_Leaves_Aspen"
    },
    {
      "x": -5,
      "y": 56,
      "z": 3,
      "name": "Plant_Leaves_Aspen"
    },
    {
      "x": -5,
      "y": 19,
      "z": 4,
      "name": "Rock_Stone"
    },
    {
      "x": -5,
      "y": 20,
      "z": 4,
      "name": "Rock_Stone"
    },
    {
      "x": -5,
      "y": 21,
      "z": 4,
      "name": "Rock_Stone"
    },
    {
      "x": -5,
      "y": 22,
      "z": 4,
      "name": "Rock_Stone"
    },
    {
      "x": -5,
      "y": 23,
      "z": 4,
      "name": "Rock_Stone"
    },
    {
      "x": -5,
      "y": 24,
      "z": 4,
      "name": "Rock_Stone"
    },
    {
      "x": -5,
      "y": 25,
      "z": 4,
      "name": "Rock_Stone"
    },
    {
      "x": -5,
      "y": 26,
      "z": 4,
      "name": "Rock_Stone"
    },
    {
      "x": -5,
      "y": 27,
      "z": 4,
      "name": "Rock_Stone"
    },
    {
      "x": -5,
      "y": 28,
      "z": 4,
      "name": "Rock_Stone"
    },
    {
      "x": -5,
      "y": 29,
      "z": 4,
      "name": "Rock_Stone"
    },
    {
      "x": -5,
      "y": 30,
      "z": 4,
      "name": "Rock_Stone"
    },
    {
      "x": -5,
      "y": 31,
      "z": 4,
      "name": "Rock_Stone"
    },
    {
      "x": -5,
      "y": 32,
      "z": 4,
      "name": "Rock_Stone"
    },
    {
      "x": -5,
      "y": 33,
      "z": 4,
      "name": "Rock_Stone"
    },
    {
      "x": -5,
      "y": 34,
      "z": 4,
      "name": "Rock_Stone"
    },
    {
      "x": -5,
      "y": 35,
      "z": 4,
      "name": "Rock_Stone"
    },
    {
      "x": -5,
      "y": 36,
      "z": 4,
      "name": "Rock_Stone"
    },
    {
      "x": -5,
      "y": 37,
      "z": 4,
      "name": "Rock_Stone"
    },
    {
      "x": -5,
      "y": 38,
      "z": 4,
      "name": "Rock_Stone"
    },
    {
      "x": -5,
      "y": 39,
      "z": 4,
      "name": "Rock_Stone"
    },
    {
      "x": -5,
      "y": 40,
      "z": 4,
      "name": "Rock_Stone"
    },
    {
      "x": -5,
      "y": 41,
      "z": 4,
      "name": "Rock_Stone"
    },
    {
      "x": -5,
      "y": 42,
      "z": 4,
      "name": "Rock_Stone"
    },
    {
      "x": -5,
      "y": 43,
      "z": 4,
      "name": "Soil_Grass"
    },
    {
      "x": -5,
      "y": 44,
      "z": 4,
      "name": "Plant_Bush"
    },
    {
      "x": -5,
      "y": 52,
      "z": 4,
      "name": "Plant_Leaves_Aspen"
    },
    {
      "x": -5,
      "y": 53,
      "z": 4,
      "name": "Plant_Leaves_Aspen"
    },
    {
      "x": -5,
      "y": 20,
      "z": 5,
      "name": "Rock_Stone"
    },
    {
      "x": -5,
      "y": 21,
      "z": 5,
      "name": "Rock_Stone"
    },
    {
      "x": -5,
      "y": 22,
      "z": 5,
      "name": "Rock_Stone"
    },
    {
      "x": -5,
      "y": 23,
      "z": 5,
      "name": "Rock_Stone"
    },
    {
      "x": -5,
      "y": 24,
      "z": 5,
      "name": "Rock_Stone"
    },
    {
      "x": -5,
      "y": 25,
      "z": 5,
      "name": "Rock_Stone"
    },
    {
      "x": -5,
      "y": 26,
      "z": 5,
      "name": "Rock_Stone"
    },
    {
      "x": -5,
      "y": 27,
      "z": 5,
      "name": "Rock_Stone"
    },
    {
      "x": -5,
      "y": 28,
      "z": 5,
      "name": "Rock_Stone"
    },
    {
      "x": -5,
      "y": 29,
      "z": 5,
      "name": "Rock_Stone"
    },
    {
      "x": -5,
      "y": 30,
      "z": 5,
      "name": "Rock_Stone"
    },
    {
      "x": -5,
      "y": 31,
      "z": 5,
      "name": "Rock_Stone"
    },
    {
      "x": -5,
      "y": 32,
      "z": 5,
      "name": "Rock_Stone"
    },
    {
      "x": -5,
      "y": 33,
      "z": 5,
      "name": "Rock_Stone"
    },
    {
      "x": -5,
      "y": 34,
      "z": 5,
      "name": "Rock_Stone"
    },
    {
      "x": -5,
      "y": 35,
      "z": 5,
      "name": "Rock_Stone_Mossy"
    },
    {
      "x": -5,
      "y": 36,
      "z": 5,
      "name": "Rock_Stone_Mossy"
    },
    {
      "x": -5,
      "y": 37,
      "z": 5,
      "name": "Rock_Stone"
    },
    {
      "x": -5,
      "y": 38,
      "z": 5,
      "name": "Rock_Stone"
    },
    {
      "x": -5,
      "y": 39,
      "z": 5,
      "name": "Rock_Stone"
    },
    {
      "x": -5,
      "y": 40,
      "z": 5,
      "name": "Rock_Stone"
    },
    {
      "x": -5,
      "y": 41,
      "z": 5,
      "name": "Rock_Stone_Mossy"
    },
    {
      "x": -5,
      "y": 42,
      "z": 5,
      "name": "Soil_Dirt"
    },
    {
      "x": -5,
      "y": 43,
      "z": 5,
      "name": "Soil_Grass"
    },
    {
      "x": -5,
      "y": 44,
      "z": 5,
      "name": "*Plant_Crop_Berry_Block_State_Definitions_StageFinal",
      "components": {
        "Components": {
          "FarmingBlock": {}
        }
      }
    },
    {
      "x": -5,
      "y": 23,
      "z": 6,
      "name": "Rock_Stone"
    },
    {
      "x": -5,
      "y": 24,
      "z": 6,
      "name": "Rock_Stone"
    },
    {
      "x": -5,
      "y": 25,
      "z": 6,
      "name": "Rock_Stone"
    },
    {
      "x": -5,
      "y": 26,
      "z": 6,
      "name": "Rock_Stone"
    },
    {
      "x": -5,
      "y": 27,
      "z": 6,
      "name": "Rock_Stone"
    },
    {
      "x": -5,
      "y": 28,
      "z": 6,
      "name": "Rock_Stone"
    },
    {
      "x": -5,
      "y": 29,
      "z": 6,
      "name": "Rock_Stone"
    },
    {
      "x": -5,
      "y": 30,
      "z": 6,
      "name": "Rock_Stone"
    },
    {
      "x": -5,
      "y": 31,
      "z": 6,
      "name": "Soil_Dirt"
    },
    {
      "x": -5,
      "y": 32,
      "z": 6,
      "name": "Soil_Grass"
    },
    {
      "x": -5,
      "y": 33,
      "z": 6,
      "name": "Plant_Grass_Sharp"
    },
    {
      "x": -5,
      "y": 35,
      "z": 6,
      "name": "Rock_Stone_Mossy"
    },
    {
      "x": -5,
      "y": 36,
      "z": 6,
      "name": "Rock_Stone_Mossy"
    },
    {
      "x": -5,
      "y": 37,
      "z": 6,
      "name": "Rock_Stone_Mossy"
    },
    {
      "x": -5,
      "y": 38,
      "z": 6,
      "name": "Rock_Stone_Mossy"
    },
    {
      "x": -5,
      "y": 39,
      "z": 6,
      "name": "Rock_Stone"
    },
    {
      "x": -5,
      "y": 40,
      "z": 6,
      "name": "Rock_Stone_Mossy"
    },
    {
      "x": -5,
      "y": 41,
      "z": 6,
      "name": "Rock_Stone_Mossy"
    },
    {
      "x": -5,
      "y": 42,
      "z": 6,
      "name": "Soil_Dirt"
    },
    {
      "x": -5,
      "y": 43,
      "z": 6,
      "name": "Soil_Grass"
    },
    {
      "x": -5,
      "y": 27,
      "z": 7,
      "name": "Rock_Stone"
    },
    {
      "x": -5,
      "y": 28,
      "z": 7,
      "name": "Rock_Stone"
    },
    {
      "x": -5,
      "y": 29,
      "z": 7,
      "name": "Rock_Stone"
    },
    {
      "x": -5,
      "y": 30,
      "z": 7,
      "name": "Soil_Dirt"
    },
    {
      "x": -5,
      "y": 31,
      "z": 7,
      "name": "Soil_Dirt"
    },
    {
      "x": -5,
      "y": 32,
      "z": 7,
      "name": "Soil_Grass"
    },
    {
      "x": -5,
      "y": 33,
      "z": 7,
      "name": "Plant_Grass_Sharp_Tall"
    },
    {
      "x": -5,
      "y": 34,
      "z": 7,
      "name": "Plant_Grass_Sharp_Tall",
      "filler": 1024
    },
    {
      "x": -5,
      "y": 30,
      "z": 8,
      "name": "Soil_Dirt"
    },
    {
      "x": -5,
      "y": 31,
      "z": 8,
      "name": "Soil_Dirt"
    },
    {
      "x": -5,
      "y": 32,
      "z": 8,
      "name": "Soil_Grass"
    },
    {
      "x": -4,
      "y": 26,
      "z": -3,
      "name": "Rock_Stone"
    },
    {
      "x": -4,
      "y": 27,
      "z": -3,
      "name": "Rock_Stone"
    },
    {
      "x": -4,
      "y": 28,
      "z": -3,
      "name": "Rock_Stone"
    },
    {
      "x": -4,
      "y": 29,
      "z": -3,
      "name": "Rock_Stone"
    },
    {
      "x": -4,
      "y": 30,
      "z": -3,
      "name": "Rock_Stone"
    },
    {
      "x": -4,
      "y": 22,
      "z": -2,
      "name": "Rock_Stone"
    },
    {
      "x": -4,
      "y": 23,
      "z": -2,
      "name": "Rock_Stone"
    },
    {
      "x": -4,
      "y": 24,
      "z": -2,
      "name": "Rock_Stone"
    },
    {
      "x": -4,
      "y": 25,
      "z": -2,
      "name": "Rock_Stone"
    },
    {
      "x": -4,
      "y": 26,
      "z": -2,
      "name": "Rock_Stone"
    },
    {
      "x": -4,
      "y": 27,
      "z": -2,
      "name": "Rock_Stone"
    },
    {
      "x": -4,
      "y": 28,
      "z": -2,
      "name": "Rock_Stone"
    },
    {
      "x": -4,
      "y": 29,
      "z": -2,
      "name": "Rock_Stone"
    },
    {
      "x": -4,
      "y": 30,
      "z": -2,
      "name": "Rock_Stone"
    },
    {
      "x": -4,
      "y": 31,
      "z": -2,
      "name": "Rock_Stone"
    },
    {
      "x": -4,
      "y": 32,
      "z": -2,
      "name": "Rock_Stone"
    },
    {
      "x": -4,
      "y": 33,
      "z": -2,
      "name": "Rock_Stone"
    },
    {
      "x": -4,
      "y": 34,
      "z": -2,
      "name": "Rock_Stone"
    },
    {
      "x": -4,
      "y": 35,
      "z": -2,
      "name": "Rock_Stone"
    },
    {
      "x": -4,
      "y": 36,
      "z": -2,
      "name": "Rock_Stone"
    },
    {
      "x": -4,
      "y": 37,
      "z": -2,
      "name": "Soil_Dirt"
    },
    {
      "x": -4,
      "y": 38,
      "z": -2,
      "name": "Soil_Grass"
    },
    {
      "x": -4,
      "y": 52,
      "z": -2,
      "name": "Plant_Leaves_Aspen"
    },
    {
      "x": -4,
      "y": 18,
      "z": -1,
      "name": "Rock_Stone"
    },
    {
      "x": -4,
      "y": 19,
      "z": -1,
      "name": "Rock_Stone"
    },
    {
      "x": -4,
      "y": 20,
      "z": -1,
      "name": "Rock_Stone"
    },
    {
      "x": -4,
      "y": 21,
      "z": -1,
      "name": "Rock_Stone"
    },
    {
      "x": -4,
      "y": 22,
      "z": -1,
      "name": "Rock_Stone"
    },
    {
      "x": -4,
      "y": 23,
      "z": -1,
      "name": "Rock_Stone"
    },
    {
      "x": -4,
      "y": 24,
      "z": -1,
      "name": "Rock_Stone"
    },
    {
      "x": -4,
      "y": 25,
      "z": -1,
      "name": "Rock_Stone"
    },
    {
      "x": -4,
      "y": 26,
      "z": -1,
      "name": "Rock_Stone"
    },
    {
      "x": -4,
      "y": 27,
      "z": -1,
      "name": "Rock_Stone"
    },
    {
      "x": -4,
      "y": 28,
      "z": -1,
      "name": "Rock_Stone"
    },
    {
      "x": -4,
      "y": 29,
      "z": -1,
      "name": "Rock_Stone"
    },
    {
      "x": -4,
      "y": 30,
      "z": -1,
      "name": "Rock_Stone"
    },
    {
      "x": -4,
      "y": 31,
      "z": -1,
      "name": "Rock_Stone"
    },
    {
      "x": -4,
      "y": 32,
      "z": -1,
      "name": "Rock_Stone"
    },
    {
      "x": -4,
      "y": 33,
      "z": -1,
      "name": "Rock_Stone"
    },
    {
      "x": -4,
      "y": 34,
      "z": -1,
      "name": "Rock_Stone"
    },
    {
      "x": -4,
      "y": 35,
      "z": -1,
      "name": "Rock_Stone"
    },
    {
      "x": -4,
      "y": 36,
      "z": -1,
      "name": "Rock_Stone"
    },
    {
      "x": -4,
      "y": 37,
      "z": -1,
      "name": "Soil_Dirt"
    },
    {
      "x": -4,
      "y": 38,
      "z": -1,
      "name": "Soil_Dirt"
    },
    {
      "x": -4,
      "y": 39,
      "z": -1,
      "name": "Soil_Dirt"
    },
    {
      "x": -4,
      "y": 40,
      "z": -1,
      "name": "Soil_Grass"
    },
    {
      "x": -4,
      "y": 51,
      "z": -1,
      "name": "Plant_Leaves_Aspen"
    },
    {
      "x": -4,
      "y": 52,
      "z": -1,
      "name": "Plant_Leaves_Aspen"
    },
    {
      "x": -4,
      "y": 53,
      "z": -1,
      "name": "Plant_Leaves_Aspen"
    },
    {
      "x": -4,
      "y": 54,
      "z": -1,
      "name": "Plant_Leaves_Aspen"
    },
    {
      "x": -4,
      "y": 55,
      "z": -1,
      "name": "Plant_Leaves_Aspen"
    },
    {
      "x": -4,
      "y": 18,
      "z": 0,
      "name": "Rock_Stone"
    },
    {
      "x": -4,
      "y": 19,
      "z": 0,
      "name": "Rock_Stone"
    },
    {
      "x": -4,
      "y": 20,
      "z": 0,
      "name": "Rock_Stone"
    },
    {
      "x": -4,
      "y": 21,
      "z": 0,
      "name": "Rock_Stone"
    },
    {
      "x": -4,
      "y": 22,
      "z": 0,
      "name": "Rock_Stone"
    },
    {
      "x": -4,
      "y": 23,
      "z": 0,
      "name": "Rock_Stone"
    },
    {
      "x": -4,
      "y": 24,
      "z": 0,
      "name": "Rock_Stone"
    },
    {
      "x": -4,
      "y": 25,
      "z": 0,
      "name": "Rock_Stone"
    },
    {
      "x": -4,
      "y": 26,
      "z": 0,
      "name": "Rock_Stone"
    },
    {
      "x": -4,
      "y": 27,
      "z": 0,
      "name": "Rock_Stone"
    },
    {
      "x": -4,
      "y": 28,
      "z": 0,
      "name": "Rock_Stone"
    },
    {
      "x": -4,
      "y": 29,
      "z": 0,
      "name": "Rock_Stone"
    },
    {
      "x": -4,
      "y": 30,
      "z": 0,
      "name": "Rock_Stone"
    },
    {
      "x": -4,
      "y": 31,
      "z": 0,
      "name": "Rock_Stone"
    },
    {
      "x": -4,
      "y": 32,
      "z": 0,
      "name": "Rock_Stone"
    },
    {
      "x": -4,
      "y": 33,
      "z": 0,
      "name": "Rock_Stone"
    },
    {
      "x": -4,
      "y": 34,
      "z": 0,
      "name": "Rock_Stone"
    },
    {
      "x": -4,
      "y": 35,
      "z": 0,
      "name": "Rock_Stone"
    },
    {
      "x": -4,
      "y": 36,
      "z": 0,
      "name": "Rock_Stone"
    },
    {
      "x": -4,
      "y": 37,
      "z": 0,
      "name": "Soil_Dirt"
    },
    {
      "x": -4,
      "y": 38,
      "z": 0,
      "name": "Soil_Dirt"
    },
    {
      "x": -4,
      "y": 39,
      "z": 0,
      "name": "Soil_Dirt"
    },
    {
      "x": -4,
      "y": 40,
      "z": 0,
      "name": "Soil_Dirt"
    },
    {
      "x": -4,
      "y": 41,
      "z": 0,
      "name": "Soil_Dirt"
    },
    {
      "x": -4,
      "y": 42,
      "z": 0,
      "name": "Soil_Dirt"
    },
    {
      "x": -4,
      "y": 43,
      "z": 0,
      "name": "Soil_Grass"
    },
    {
      "x": -4,
      "y": 18,
      "z": 1,
      "name": "Rock_Stone"
    },
    {
      "x": -4,
      "y": 19,
      "z": 1,
      "name": "Rock_Stone"
    },
    {
      "x": -4,
      "y": 20,
      "z": 1,
      "name": "Rock_Stone"
    },
    {
      "x": -4,
      "y": 21,
      "z": 1,
      "name": "Rock_Stone"
    },
    {
      "x": -4,
      "y": 22,
      "z": 1,
      "name": "Rock_Stone"
    },
    {
      "x": -4,
      "y": 23,
      "z": 1,
      "name": "Rock_Stone"
    },
    {
      "x": -4,
      "y": 24,
      "z": 1,
      "name": "Rock_Stone"
    },
    {
      "x": -4,
      "y": 25,
      "z": 1,
      "name": "Rock_Stone"
    },
    {
      "x": -4,
      "y": 26,
      "z": 1,
      "name": "Rock_Stone"
    },
    {
      "x": -4,
      "y": 27,
      "z": 1,
      "name": "Rock_Stone"
    },
    {
      "x": -4,
      "y": 28,
      "z": 1,
      "name": "Rock_Stone"
    },
    {
      "x": -4,
      "y": 29,
      "z": 1,
      "name": "Rock_Stone"
    },
    {
      "x": -4,
      "y": 30,
      "z": 1,
      "name": "Rock_Stone"
    },
    {
      "x": -4,
      "y": 31,
      "z": 1,
      "name": "Rock_Stone"
    },
    {
      "x": -4,
      "y": 32,
      "z": 1,
      "name": "Rock_Stone"
    },
    {
      "x": -4,
      "y": 33,
      "z": 1,
      "name": "Rock_Stone"
    },
    {
      "x": -4,
      "y": 34,
      "z": 1,
      "name": "Rock_Stone"
    },
    {
      "x": -4,
      "y": 35,
      "z": 1,
      "name": "Rock_Stone"
    },
    {
      "x": -4,
      "y": 36,
      "z": 1,
      "name": "Rock_Stone"
    },
    {
      "x": -4,
      "y": 37,
      "z": 1,
      "name": "Soil_Dirt"
    },
    {
      "x": -4,
      "y": 38,
      "z": 1,
      "name": "Soil_Dirt"
    },
    {
      "x": -4,
      "y": 39,
      "z": 1,
      "name": "Soil_Dirt"
    },
    {
      "x": -4,
      "y": 40,
      "z": 1,
      "name": "Soil_Dirt"
    },
    {
      "x": -4,
      "y": 41,
      "z": 1,
      "name": "Soil_Dirt"
    },
    {
      "x": -4,
      "y": 42,
      "z": 1,
      "name": "Soil_Dirt"
    },
    {
      "x": -4,
      "y": 43,
      "z": 1,
      "name": "Soil_Dirt"
    },
    {
      "x": -4,
      "y": 44,
      "z": 1,
      "name": "Soil_Grass"
    },
    {
      "x": -4,
      "y": 52,
      "z": 1,
      "name": "Wood_Aspen_Branch_Corner",
      "rotation": 2
    },
    {
      "x": -4,
      "y": 53,
      "z": 1,
      "name": "Wood_Aspen_Branch_Long"
    },
    {
      "x": -4,
      "y": 54,
      "z": 1,
      "name": "Plant_Leaves_Aspen"
    },
    {
      "x": -4,
      "y": 57,
      "z": 1,
      "name": "Plant_Leaves_Aspen"
    },
    {
      "x": -4,
      "y": 58,
      "z": 1,
      "name": "Plant_Leaves_Aspen"
    },
    {
      "x": -4,
      "y": 59,
      "z": 1,
      "name": "Plant_Leaves_Aspen"
    },
    {
      "x": -4,
      "y": 60,
      "z": 1,
      "name": "Plant_Leaves_Aspen"
    },
    {
      "x": -4,
      "y": 18,
      "z": 2,
      "name": "Rock_Stone"
    },
    {
      "x": -4,
      "y": 19,
      "z": 2,
      "name": "Rock_Stone"
    },
    {
      "x": -4,
      "y": 20,
      "z": 2,
      "name": "Rock_Stone"
    },
    {
      "x": -4,
      "y": 21,
      "z": 2,
      "name": "Rock_Stone"
    },
    {
      "x": -4,
      "y": 22,
      "z": 2,
      "name": "Rock_Stone"
    },
    {
      "x": -4,
      "y": 23,
      "z": 2,
      "name": "Rock_Stone"
    },
    {
      "x": -4,
      "y": 24,
      "z": 2,
      "name": "Rock_Stone"
    },
    {
      "x": -4,
      "y": 25,
      "z": 2,
      "name": "Rock_Stone"
    },
    {
      "x": -4,
      "y": 26,
      "z": 2,
      "name": "Rock_Stone"
    },
    {
      "x": -4,
      "y": 27,
      "z": 2,
      "name": "Rock_Stone"
    },
    {
      "x": -4,
      "y": 28,
      "z": 2,
      "name": "Rock_Stone"
    },
    {
      "x": -4,
      "y": 29,
      "z": 2,
      "name": "Rock_Stone"
    },
    {
      "x": -4,
      "y": 30,
      "z": 2,
      "name": "Rock_Stone"
    },
    {
      "x": -4,
      "y": 31,
      "z": 2,
      "name": "Rock_Stone"
    },
    {
      "x": -4,
      "y": 32,
      "z": 2,
      "name": "Rock_Stone"
    },
    {
      "x": -4,
      "y": 33,
      "z": 2,
      "name": "Rock_Stone"
    },
    {
      "x": -4,
      "y": 34,
      "z": 2,
      "name": "Rock_Stone"
    },
    {
      "x": -4,
      "y": 35,
      "z": 2,
      "name": "Rock_Stone"
    },
    {
      "x": -4,
      "y": 36,
      "z": 2,
      "name": "Rock_Stone"
    },
    {
      "x": -4,
      "y": 37,
      "z": 2,
      "name": "Rock_Stone"
    },
    {
      "x": -4,
      "y": 38,
      "z": 2,
      "name": "Rock_Stone"
    },
    {
      "x": -4,
      "y": 39,
      "z": 2,
      "name": "Rock_Stone"
    },
    {
      "x": -4,
      "y": 40,
      "z": 2,
      "name": "Soil_Dirt"
    },
    {
      "x": -4,
      "y": 41,
      "z": 2,
      "name": "Soil_Dirt"
    },
    {
      "x": -4,
      "y": 42,
      "z": 2,
      "name": "Rock_Stone"
    },
    {
      "x": -4,
      "y": 43,
      "z": 2,
      "name": "Soil_Dirt"
    },
    {
      "x": -4,
      "y": 44,
      "z": 2,
      "name": "Soil_Grass"
    },
    {
      "x": -4,
      "y": 52,
      "z": 2,
      "name": "Wood_Aspen_Trunk_Full"
    },
    {
      "x": -4,
      "y": 53,
      "z": 2,
      "name": "Wood_Aspen_Branch_Long"
    },
    {
      "x": -4,
      "y": 54,
      "z": 2,
      "name": "Wood_Aspen_Branch_Long"
    },
    {
      "x": -4,
      "y": 55,
      "z": 2,
      "name": "Wood_Aspen_Branch_Long"
    },
    {
      "x": -4,
      "y": 56,
      "z": 2,
      "name": "Wood_Aspen_Branch_Long"
    },
    {
      "x": -4,
      "y": 57,
      "z": 2,
      "name": "Plant_Leaves_Aspen"
    },
    {
      "x": -4,
      "y": 58,
      "z": 2,
      "name": "Plant_Leaves_Aspen"
    },
    {
      "x": -4,
      "y": 59,
      "z": 2,
      "name": "Plant_Leaves_Aspen"
    },
    {
      "x": -4,
      "y": 60,
      "z": 2,
      "name": "Plant_Leaves_Aspen"
    },
    {
      "x": -4,
      "y": 61,
      "z": 2,
      "name": "Plant_Leaves_Aspen"
    },
    {
      "x": -4,
      "y": 62,
      "z": 2,
      "name": "Plant_Leaves_Aspen"
    },
    {
      "x": -4,
      "y": 18,
      "z": 3,
      "name": "Rock_Stone"
    },
    {
      "x": -4,
      "y": 19,
      "z": 3,
      "name": "Rock_Stone"
    },
    {
      "x": -4,
      "y": 20,
      "z": 3,
      "name": "Rock_Stone"
    },
    {
      "x": -4,
      "y": 21,
      "z": 3,
      "name": "Rock_Stone"
    },
    {
      "x": -4,
      "y": 22,
      "z": 3,
      "name": "Rock_Stone"
    },
    {
      "x": -4,
      "y": 23,
      "z": 3,
      "name": "Rock_Stone"
    },
    {
      "x": -4,
      "y": 24,
      "z": 3,
      "name": "Rock_Stone"
    },
    {
      "x": -4,
      "y": 25,
      "z": 3,
      "name": "Rock_Stone"
    },
    {
      "x": -4,
      "y": 26,
      "z": 3,
      "name": "Rock_Stone"
    },
    {
      "x": -4,
      "y": 27,
      "z": 3,
      "name": "Rock_Stone"
    },
    {
      "x": -4,
      "y": 28,
      "z": 3,
      "name": "Rock_Stone"
    },
    {
      "x": -4,
      "y": 29,
      "z": 3,
      "name": "Rock_Stone"
    },
    {
      "x": -4,
      "y": 30,
      "z": 3,
      "name": "Rock_Stone"
    },
    {
      "x": -4,
      "y": 31,
      "z": 3,
      "name": "Rock_Stone"
    },
    {
      "x": -4,
      "y": 32,
      "z": 3,
      "name": "Rock_Stone"
    },
    {
      "x": -4,
      "y": 33,
      "z": 3,
      "name": "Rock_Stone"
    },
    {
      "x": -4,
      "y": 34,
      "z": 3,
      "name": "Rock_Stone"
    },
    {
      "x": -4,
      "y": 35,
      "z": 3,
      "name": "Rock_Stone"
    },
    {
      "x": -4,
      "y": 36,
      "z": 3,
      "name": "Rock_Stone"
    },
    {
      "x": -4,
      "y": 37,
      "z": 3,
      "name": "Rock_Stone"
    },
    {
      "x": -4,
      "y": 38,
      "z": 3,
      "name": "Rock_Stone"
    },
    {
      "x": -4,
      "y": 39,
      "z": 3,
      "name": "Rock_Stone"
    },
    {
      "x": -4,
      "y": 40,
      "z": 3,
      "name": "Rock_Stone"
    },
    {
      "x": -4,
      "y": 41,
      "z": 3,
      "name": "Rock_Stone"
    },
    {
      "x": -4,
      "y": 42,
      "z": 3,
      "name": "Rock_Stone"
    },
    {
      "x": -4,
      "y": 43,
      "z": 3,
      "name": "Soil_Dirt"
    },
    {
      "x": -4,
      "y": 44,
      "z": 3,
      "name": "Soil_Grass"
    },
    {
      "x": -4,
      "y": 56,
      "z": 3,
      "name": "Plant_Leaves_Aspen"
    },
    {
      "x": -4,
      "y": 57,
      "z": 3,
      "name": "Plant_Leaves_Aspen"
    },
    {
      "x": -4,
      "y": 58,
      "z": 3,
      "name": "Plant_Leaves_Aspen"
    },
    {
      "x": -4,
      "y": 60,
      "z": 3,
      "name": "Plant_Leaves_Aspen"
    },
    {
      "x": -4,
      "y": 19,
      "z": 4,
      "name": "Rock_Stone"
    },
    {
      "x": -4,
      "y": 20,
      "z": 4,
      "name": "Rock_Stone"
    },
    {
      "x": -4,
      "y": 21,
      "z": 4,
      "name": "Rock_Stone"
    },
    {
      "x": -4,
      "y": 22,
      "z": 4,
      "name": "Rock_Stone"
    },
    {
      "x": -4,
      "y": 23,
      "z": 4,
      "name": "Rock_Stone"
    },
    {
      "x": -4,
      "y": 24,
      "z": 4,
      "name": "Rock_Stone"
    },
    {
      "x": -4,
      "y": 25,
      "z": 4,
      "name": "Rock_Stone"
    },
    {
      "x": -4,
      "y": 26,
      "z": 4,
      "name": "Rock_Stone"
    },
    {
      "x": -4,
      "y": 27,
      "z": 4,
      "name": "Rock_Stone"
    },
    {
      "x": -4,
      "y": 28,
      "z": 4,
      "name": "Rock_Stone"
    },
    {
      "x": -4,
      "y": 29,
      "z": 4,
      "name": "Rock_Stone"
    },
    {
      "x": -4,
      "y": 30,
      "z": 4,
      "name": "Rock_Stone"
    },
    {
      "x": -4,
      "y": 31,
      "z": 4,
      "name": "Rock_Stone"
    },
    {
      "x": -4,
      "y": 32,
      "z": 4,
      "name": "Rock_Stone"
    },
    {
      "x": -4,
      "y": 33,
      "z": 4,
      "name": "Rock_Stone"
    },
    {
      "x": -4,
      "y": 34,
      "z": 4,
      "name": "Rock_Stone"
    },
    {
      "x": -4,
      "y": 35,
      "z": 4,
      "name": "Rock_Stone"
    },
    {
      "x": -4,
      "y": 36,
      "z": 4,
      "name": "Rock_Stone"
    },
    {
      "x": -4,
      "y": 37,
      "z": 4,
      "name": "Rock_Stone"
    },
    {
      "x": -4,
      "y": 38,
      "z": 4,
      "name": "Rock_Stone"
    },
    {
      "x": -4,
      "y": 39,
      "z": 4,
      "name": "Rock_Stone"
    },
    {
      "x": -4,
      "y": 40,
      "z": 4,
      "name": "Rock_Stone"
    },
    {
      "x": -4,
      "y": 41,
      "z": 4,
      "name": "Rock_Stone"
    },
    {
      "x": -4,
      "y": 42,
      "z": 4,
      "name": "Rock_Stone"
    },
    {
      "x": -4,
      "y": 43,
      "z": 4,
      "name": "Soil_Grass"
    },
    {
      "x": -4,
      "y": 51,
      "z": 4,
      "name": "Plant_Leaves_Aspen"
    },
    {
      "x": -4,
      "y": 52,
      "z": 4,
      "name": "Plant_Leaves_Aspen"
    },
    {
      "x": -4,
      "y": 53,
      "z": 4,
      "name": "Plant_Leaves_Aspen"
    },
    {
      "x": -4,
      "y": 19,
      "z": 5,
      "name": "Rock_Stone"
    },
    {
      "x": -4,
      "y": 20,
      "z": 5,
      "name": "Rock_Stone"
    },
    {
      "x": -4,
      "y": 21,
      "z": 5,
      "name": "Rock_Stone"
    },
    {
      "x": -4,
      "y": 22,
      "z": 5,
      "name": "Rock_Stone"
    },
    {
      "x": -4,
      "y": 23,
      "z": 5,
      "name": "Rock_Stone"
    },
    {
      "x": -4,
      "y": 24,
      "z": 5,
      "name": "Rock_Stone"
    },
    {
      "x": -4,
      "y": 25,
      "z": 5,
      "name": "Rock_Stone"
    },
    {
      "x": -4,
      "y": 26,
      "z": 5,
      "name": "Rock_Stone"
    },
    {
      "x": -4,
      "y": 27,
      "z": 5,
      "name": "Rock_Stone"
    },
    {
      "x": -4,
      "y": 28,
      "z": 5,
      "name": "Rock_Stone"
    },
    {
      "x": -4,
      "y": 29,
      "z": 5,
      "name": "Rock_Stone"
    },
    {
      "x": -4,
      "y": 30,
      "z": 5,
      "name": "Rock_Stone"
    },
    {
      "x": -4,
      "y": 31,
      "z": 5,
      "name": "Rock_Stone"
    },
    {
      "x": -4,
      "y": 32,
      "z": 5,
      "name": "Rock_Stone"
    },
    {
      "x": -4,
      "y": 33,
      "z": 5,
      "name": "Rock_Stone"
    },
    {
      "x": -4,
      "y": 34,
      "z": 5,
      "name": "Soil_Dirt"
    },
    {
      "x": -4,
      "y": 35,
      "z": 5,
      "name": "Rock_Stone"
    },
    {
      "x": -4,
      "y": 36,
      "z": 5,
      "name": "Rock_Stone"
    },
    {
      "x": -4,
      "y": 37,
      "z": 5,
      "name": "Rock_Stone"
    },
    {
      "x": -4,
      "y": 38,
      "z": 5,
      "name": "Rock_Stone"
    },
    {
      "x": -4,
      "y": 39,
      "z": 5,
      "name": "Rock_Stone"
    },
    {
      "x": -4,
      "y": 40,
      "z": 5,
      "name": "Rock_Stone"
    },
    {
      "x": -4,
      "y": 41,
      "z": 5,
      "name": "Rock_Stone"
    },
    {
      "x": -4,
      "y": 42,
      "z": 5,
      "name": "Soil_Dirt"
    },
    {
      "x": -4,
      "y": 43,
      "z": 5,
      "name": "Soil_Grass"
    },
    {
      "x": -4,
      "y": 44,
      "z": 5,
      "name": "*Plant_Crop_Berry_Block_State_Definitions_StageFinal",
      "components": {
        "Components": {
          "FarmingBlock": {}
        }
      }
    },
    {
      "x": -4,
      "y": 52,
      "z": 5,
      "name": "Plant_Leaves_Aspen"
    },
    {
      "x": -4,
      "y": 53,
      "z": 5,
      "name": "Plant_Leaves_Aspen"
    },
    {
      "x": -4,
      "y": 21,
      "z": 6,
      "name": "Rock_Stone"
    },
    {
      "x": -4,
      "y": 22,
      "z": 6,
      "name": "Rock_Stone"
    },
    {
      "x": -4,
      "y": 23,
      "z": 6,
      "name": "Rock_Stone"
    },
    {
      "x": -4,
      "y": 24,
      "z": 6,
      "name": "Rock_Stone"
    },
    {
      "x": -4,
      "y": 25,
      "z": 6,
      "name": "Rock_Stone"
    },
    {
      "x": -4,
      "y": 26,
      "z": 6,
      "name": "Rock_Stone"
    },
    {
      "x": -4,
      "y": 27,
      "z": 6,
      "name": "Rock_Stone"
    },
    {
      "x": -4,
      "y": 28,
      "z": 6,
      "name": "Rock_Stone"
    },
    {
      "x": -4,
      "y": 29,
      "z": 6,
      "name": "Rock_Stone"
    },
    {
      "x": -4,
      "y": 30,
      "z": 6,
      "name": "Rock_Stone"
    },
    {
      "x": -4,
      "y": 31,
      "z": 6,
      "name": "Soil_Dirt"
    },
    {
      "x": -4,
      "y": 32,
      "z": 6,
      "name": "Soil_Dirt"
    },
    {
      "x": -4,
      "y": 33,
      "z": 6,
      "name": "Soil_Dirt"
    },
    {
      "x": -4,
      "y": 34,
      "z": 6,
      "name": "Rock_Stone"
    },
    {
      "x": -4,
      "y": 35,
      "z": 6,
      "name": "Rock_Stone_Mossy"
    },
    {
      "x": -4,
      "y": 36,
      "z": 6,
      "name": "Rock_Stone"
    },
    {
      "x": -4,
      "y": 37,
      "z": 6,
      "name": "Rock_Stone"
    },
    {
      "x": -4,
      "y": 38,
      "z": 6,
      "name": "Rock_Stone"
    },
    {
      "x": -4,
      "y": 39,
      "z": 6,
      "name": "Rock_Stone"
    },
    {
      "x": -4,
      "y": 40,
      "z": 6,
      "name": "Rock_Stone"
    },
    {
      "x": -4,
      "y": 41,
      "z": 6,
      "name": "Rock_Stone_Mossy"
    },
    {
      "x": -4,
      "y": 42,
      "z": 6,
      "name": "Soil_Dirt"
    },
    {
      "x": -4,
      "y": 43,
      "z": 6,
      "name": "Soil_Grass"
    },
    {
      "x": -4,
      "y": 25,
      "z": 7,
      "name": "Rock_Stone"
    },
    {
      "x": -4,
      "y": 26,
      "z": 7,
      "name": "Rock_Stone"
    },
    {
      "x": -4,
      "y": 27,
      "z": 7,
      "name": "Rock_Stone"
    },
    {
      "x": -4,
      "y": 28,
      "z": 7,
      "name": "Rock_Stone"
    },
    {
      "x": -4,
      "y": 29,
      "z": 7,
      "name": "Rock_Stone"
    },
    {
      "x": -4,
      "y": 30,
      "z": 7,
      "name": "Soil_Dirt"
    },
    {
      "x": -4,
      "y": 31,
      "z": 7,
      "name": "Soil_Dirt"
    },
    {
      "x": -4,
      "y": 32,
      "z": 7,
      "name": "Soil_Dirt"
    },
    {
      "x": -4,
      "y": 33,
      "z": 7,
      "name": "Soil_Grass"
    },
    {
      "x": -4,
      "y": 29,
      "z": 8,
      "name": "Rock_Stone"
    },
    {
      "x": -4,
      "y": 30,
      "z": 8,
      "name": "Soil_Dirt"
    },
    {
      "x": -4,
      "y": 31,
      "z": 8,
      "name": "Soil_Dirt"
    },
    {
      "x": -4,
      "y": 32,
      "z": 8,
      "name": "Soil_Grass"
    },
    {
      "x": -3,
      "y": 23,
      "z": -3,
      "name": "Rock_Stone"
    },
    {
      "x": -3,
      "y": 24,
      "z": -3,
      "name": "Rock_Stone"
    },
    {
      "x": -3,
      "y": 25,
      "z": -3,
      "name": "Rock_Stone"
    },
    {
      "x": -3,
      "y": 26,
      "z": -3,
      "name": "Rock_Stone"
    },
    {
      "x": -3,
      "y": 27,
      "z": -3,
      "name": "Rock_Stone"
    },
    {
      "x": -3,
      "y": 28,
      "z": -3,
      "name": "Rock_Stone"
    },
    {
      "x": -3,
      "y": 29,
      "z": -3,
      "name": "Rock_Stone"
    },
    {
      "x": -3,
      "y": 30,
      "z": -3,
      "name": "Soil_Dirt"
    },
    {
      "x": -3,
      "y": 31,
      "z": -3,
      "name": "Soil_Grass"
    },
    {
      "x": -3,
      "y": 20,
      "z": -2,
      "name": "Rock_Stone"
    },
    {
      "x": -3,
      "y": 21,
      "z": -2,
      "name": "Rock_Stone"
    },
    {
      "x": -3,
      "y": 22,
      "z": -2,
      "name": "Rock_Stone"
    },
    {
      "x": -3,
      "y": 23,
      "z": -2,
      "name": "Rock_Stone"
    },
    {
      "x": -3,
      "y": 24,
      "z": -2,
      "name": "Rock_Stone"
    },
    {
      "x": -3,
      "y": 25,
      "z": -2,
      "name": "Rock_Stone"
    },
    {
      "x": -3,
      "y": 26,
      "z": -2,
      "name": "Rock_Stone"
    },
    {
      "x": -3,
      "y": 27,
      "z": -2,
      "name": "Rock_Stone"
    },
    {
      "x": -3,
      "y": 28,
      "z": -2,
      "name": "Rock_Stone"
    },
    {
      "x": -3,
      "y": 29,
      "z": -2,
      "name": "Rock_Stone"
    },
    {
      "x": -3,
      "y": 30,
      "z": -2,
      "name": "Rock_Stone"
    },
    {
      "x": -3,
      "y": 31,
      "z": -2,
      "name": "Rock_Stone"
    },
    {
      "x": -3,
      "y": 32,
      "z": -2,
      "name": "Rock_Stone"
    },
    {
      "x": -3,
      "y": 33,
      "z": -2,
      "name": "Rock_Stone"
    },
    {
      "x": -3,
      "y": 34,
      "z": -2,
      "name": "Rock_Stone"
    },
    {
      "x": -3,
      "y": 35,
      "z": -2,
      "name": "Rock_Stone"
    },
    {
      "x": -3,
      "y": 36,
      "z": -2,
      "name": "Soil_Dirt"
    },
    {
      "x": -3,
      "y": 37,
      "z": -2,
      "name": "Soil_Dirt"
    },
    {
      "x": -3,
      "y": 38,
      "z": -2,
      "name": "Soil_Grass"
    },
    {
      "x": -3,
      "y": 52,
      "z": -2,
      "name": "Plant_Leaves_Aspen"
    },
    {
      "x": -3,
      "y": 53,
      "z": -2,
      "name": "Plant_Leaves_Aspen"
    },
    {
      "x": -3,
      "y": 18,
      "z": -1,
      "name": "Rock_Stone"
    },
    {
      "x": -3,
      "y": 19,
      "z": -1,
      "name": "Rock_Stone"
    },
    {
      "x": -3,
      "y": 20,
      "z": -1,
      "name": "Rock_Stone"
    },
    {
      "x": -3,
      "y": 21,
      "z": -1,
      "name": "Rock_Stone"
    },
    {
      "x": -3,
      "y": 22,
      "z": -1,
      "name": "Rock_Stone"
    },
    {
      "x": -3,
      "y": 23,
      "z": -1,
      "name": "Rock_Stone"
    },
    {
      "x": -3,
      "y": 24,
      "z": -1,
      "name": "Rock_Stone"
    },
    {
      "x": -3,
      "y": 25,
      "z": -1,
      "name": "Rock_Stone"
    },
    {
      "x": -3,
      "y": 26,
      "z": -1,
      "name": "Rock_Stone"
    },
    {
      "x": -3,
      "y": 27,
      "z": -1,
      "name": "Rock_Stone"
    },
    {
      "x": -3,
      "y": 28,
      "z": -1,
      "name": "Rock_Stone"
    },
    {
      "x": -3,
      "y": 29,
      "z": -1,
      "name": "Rock_Stone"
    },
    {
      "x": -3,
      "y": 30,
      "z": -1,
      "name": "Rock_Stone"
    },
    {
      "x": -3,
      "y": 31,
      "z": -1,
      "name": "Rock_Stone"
    },
    {
      "x": -3,
      "y": 32,
      "z": -1,
      "name": "Rock_Stone"
    },
    {
      "x": -3,
      "y": 33,
      "z": -1,
      "name": "Rock_Stone"
    },
    {
      "x": -3,
      "y": 34,
      "z": -1,
      "name": "Rock_Stone"
    },
    {
      "x": -3,
      "y": 35,
      "z": -1,
      "name": "Rock_Stone"
    },
    {
      "x": -3,
      "y": 36,
      "z": -1,
      "name": "Soil_Dirt"
    },
    {
      "x": -3,
      "y": 37,
      "z": -1,
      "name": "Soil_Dirt"
    },
    {
      "x": -3,
      "y": 38,
      "z": -1,
      "name": "Soil_Dirt"
    },
    {
      "x": -3,
      "y": 39,
      "z": -1,
      "name": "Soil_Dirt"
    },
    {
      "x": -3,
      "y": 40,
      "z": -1,
      "name": "Soil_Grass"
    },
    {
      "x": -3,
      "y": 55,
      "z": -1,
      "name": "Plant_Leaves_Aspen"
    },
    {
      "x": -3,
      "y": 56,
      "z": -1,
      "name": "Plant_Leaves_Aspen"
    },
    {
      "x": -3,
      "y": 57,
      "z": -1,
      "name": "Plant_Leaves_Aspen"
    },
    {
      "x": -3,
      "y": 18,
      "z": 0,
      "name": "Rock_Stone"
    },
    {
      "x": -3,
      "y": 19,
      "z": 0,
      "name": "Rock_Stone"
    },
    {
      "x": -3,
      "y": 20,
      "z": 0,
      "name": "Rock_Stone"
    },
    {
      "x": -3,
      "y": 21,
      "z": 0,
      "name": "Rock_Stone"
    },
    {
      "x": -3,
      "y": 22,
      "z": 0,
      "name": "Rock_Stone"
    },
    {
      "x": -3,
      "y": 23,
      "z": 0,
      "name": "Rock_Stone"
    },
    {
      "x": -3,
      "y": 24,
      "z": 0,
      "name": "Rock_Stone"
    },
    {
      "x": -3,
      "y": 25,
      "z": 0,
      "name": "Rock_Stone"
    },
    {
      "x": -3,
      "y": 26,
      "z": 0,
      "name": "Rock_Stone"
    },
    {
      "x": -3,
      "y": 27,
      "z": 0,
      "name": "Rock_Stone"
    },
    {
      "x": -3,
      "y": 28,
      "z": 0,
      "name": "Rock_Stone"
    },
    {
      "x": -3,
      "y": 29,
      "z": 0,
      "name": "Rock_Stone"
    },
    {
      "x": -3,
      "y": 30,
      "z": 0,
      "name": "Rock_Stone"
    },
    {
      "x": -3,
      "y": 31,
      "z": 0,
      "name": "Rock_Stone"
    },
    {
      "x": -3,
      "y": 32,
      "z": 0,
      "name": "Rock_Stone"
    },
    {
      "x": -3,
      "y": 33,
      "z": 0,
      "name": "Rock_Stone"
    },
    {
      "x": -3,
      "y": 34,
      "z": 0,
      "name": "Rock_Stone"
    },
    {
      "x": -3,
      "y": 35,
      "z": 0,
      "name": "Rock_Stone"
    },
    {
      "x": -3,
      "y": 36,
      "z": 0,
      "name": "Rock_Stone"
    },
    {
      "x": -3,
      "y": 37,
      "z": 0,
      "name": "Soil_Dirt"
    },
    {
      "x": -3,
      "y": 38,
      "z": 0,
      "name": "Soil_Dirt"
    },
    {
      "x": -3,
      "y": 39,
      "z": 0,
      "name": "Soil_Dirt"
    },
    {
      "x": -3,
      "y": 40,
      "z": 0,
      "name": "Soil_Dirt"
    },
    {
      "x": -3,
      "y": 41,
      "z": 0,
      "name": "Soil_Dirt"
    },
    {
      "x": -3,
      "y": 42,
      "z": 0,
      "name": "Soil_Grass"
    },
    {
      "x": -3,
      "y": 58,
      "z": 0,
      "name": "Plant_Leaves_Aspen"
    },
    {
      "x": -3,
      "y": 59,
      "z": 0,
      "name": "Plant_Leaves_Aspen"
    },
    {
      "x": -3,
      "y": 60,
      "z": 0,
      "name": "Plant_Leaves_Aspen"
    },
    {
      "x": -3,
      "y": 18,
      "z": 1,
      "name": "Rock_Stone"
    },
    {
      "x": -3,
      "y": 19,
      "z": 1,
      "name": "Rock_Stone"
    },
    {
      "x": -3,
      "y": 20,
      "z": 1,
      "name": "Rock_Stone"
    },
    {
      "x": -3,
      "y": 21,
      "z": 1,
      "name": "Rock_Stone"
    },
    {
      "x": -3,
      "y": 22,
      "z": 1,
      "name": "Rock_Stone"
    },
    {
      "x": -3,
      "y": 23,
      "z": 1,
      "name": "Rock_Stone"
    },
    {
      "x": -3,
      "y": 24,
      "z": 1,
      "name": "Rock_Stone"
    },
    {
      "x": -3,
      "y": 25,
      "z": 1,
      "name": "Rock_Stone"
    },
    {
      "x": -3,
      "y": 26,
      "z": 1,
      "name": "Rock_Stone"
    },
    {
      "x": -3,
      "y": 27,
      "z": 1,
      "name": "Rock_Stone"
    },
    {
      "x": -3,
      "y": 28,
      "z": 1,
      "name": "Rock_Stone"
    },
    {
      "x": -3,
      "y": 29,
      "z": 1,
      "name": "Rock_Stone"
    },
    {
      "x": -3,
      "y": 30,
      "z": 1,
      "name": "Rock_Stone"
    },
    {
      "x": -3,
      "y": 31,
      "z": 1,
      "name": "Rock_Stone"
    },
    {
      "x": -3,
      "y": 32,
      "z": 1,
      "name": "Rock_Stone"
    },
    {
      "x": -3,
      "y": 33,
      "z": 1,
      "name": "Rock_Stone"
    },
    {
      "x": -3,
      "y": 34,
      "z": 1,
      "name": "Rock_Stone"
    },
    {
      "x": -3,
      "y": 35,
      "z": 1,
      "name": "Rock_Stone"
    },
    {
      "x": -3,
      "y": 36,
      "z": 1,
      "name": "Rock_Stone"
    },
    {
      "x": -3,
      "y": 37,
      "z": 1,
      "name": "Rock_Stone"
    },
    {
      "x": -3,
      "y": 38,
      "z": 1,
      "name": "Rock_Stone"
    },
    {
      "x": -3,
      "y": 39,
      "z": 1,
      "name": "Soil_Dirt"
    },
    {
      "x": -3,
      "y": 40,
      "z": 1,
      "name": "Soil_Dirt"
    },
    {
      "x": -3,
      "y": 41,
      "z": 1,
      "name": "Soil_Dirt"
    },
    {
      "x": -3,
      "y": 42,
      "z": 1,
      "name": "Soil_Dirt"
    },
    {
      "x": -3,
      "y": 43,
      "z": 1,
      "name": "Soil_Dirt"
    },
    {
      "x": -3,
      "y": 44,
      "z": 1,
      "name": "Soil_Grass"
    },
    {
      "x": -3,
      "y": 60,
      "z": 1,
      "name": "Plant_Leaves_Aspen"
    },
    {
      "x": -3,
      "y": 61,
      "z": 1,
      "name": "Plant_Leaves_Aspen"
    },
    {
      "x": -3,
      "y": 62,
      "z": 1,
      "name": "Plant_Leaves_Aspen"
    },
    {
      "x": -3,
      "y": 18,
      "z": 2,
      "name": "Rock_Stone"
    },
    {
      "x": -3,
      "y": 19,
      "z": 2,
      "name": "Rock_Stone"
    },
    {
      "x": -3,
      "y": 20,
      "z": 2,
      "name": "Rock_Stone"
    },
    {
      "x": -3,
      "y": 21,
      "z": 2,
      "name": "Rock_Stone"
    },
    {
      "x": -3,
      "y": 22,
      "z": 2,
      "name": "Rock_Stone"
    },
    {
      "x": -3,
      "y": 23,
      "z": 2,
      "name": "Rock_Stone"
    },
    {
      "x": -3,
      "y": 24,
      "z": 2,
      "name": "Rock_Stone"
    },
    {
      "x": -3,
      "y": 25,
      "z": 2,
      "name": "Rock_Stone"
    },
    {
      "x": -3,
      "y": 26,
      "z": 2,
      "name": "Rock_Stone"
    },
    {
      "x": -3,
      "y": 27,
      "z": 2,
      "name": "Rock_Stone"
    },
    {
      "x": -3,
      "y": 28,
      "z": 2,
      "name": "Rock_Stone"
    },
    {
      "x": -3,
      "y": 29,
      "z": 2,
      "name": "Rock_Stone"
    },
    {
      "x": -3,
      "y": 30,
      "z": 2,
      "name": "Rock_Stone"
    },
    {
      "x": -3,
      "y": 31,
      "z": 2,
      "name": "Rock_Stone"
    },
    {
      "x": -3,
      "y": 32,
      "z": 2,
      "name": "Rock_Stone"
    },
    {
      "x": -3,
      "y": 33,
      "z": 2,
      "name": "Rock_Stone"
    },
    {
      "x": -3,
      "y": 34,
      "z": 2,
      "name": "Rock_Stone"
    },
    {
      "x": -3,
      "y": 35,
      "z": 2,
      "name": "Rock_Stone"
    },
    {
      "x": -3,
      "y": 36,
      "z": 2,
      "name": "Rock_Stone"
    },
    {
      "x": -3,
      "y": 37,
      "z": 2,
      "name": "Rock_Stone"
    },
    {
      "x": -3,
      "y": 38,
      "z": 2,
      "name": "Rock_Stone"
    },
    {
      "x": -3,
      "y": 39,
      "z": 2,
      "name": "Rock_Stone"
    },
    {
      "x": -3,
      "y": 40,
      "z": 2,
      "name": "Rock_Stone"
    },
    {
      "x": -3,
      "y": 41,
      "z": 2,
      "name": "Soil_Dirt"
    },
    {
      "x": -3,
      "y": 42,
      "z": 2,
      "name": "Soil_Dirt"
    },
    {
      "x": -3,
      "y": 43,
      "z": 2,
      "name": "Soil_Dirt"
    },
    {
      "x": -3,
      "y": 44,
      "z": 2,
      "name": "Soil_Grass"
    },
    {
      "x": -3,
      "y": 50,
      "z": 2,
      "name": "Wood_Aspen_Branch_Short",
      "rotation": 3
    },
    {
      "x": -3,
      "y": 52,
      "z": 2,
      "name": "Wood_Aspen_Trunk_Full"
    },
    {
      "x": -3,
      "y": 60,
      "z": 2,
      "name": "Plant_Leaves_Aspen"
    },
    {
      "x": -3,
      "y": 61,
      "z": 2,
      "name": "Plant_Leaves_Aspen"
    },
    {
      "x": -3,
      "y": 62,
      "z": 2,
      "name": "Plant_Leaves_Aspen"
    },
    {
      "x": -3,
      "y": 63,
      "z": 2,
      "name": "Plant_Leaves_Aspen"
    },
    {
      "x": -3,
      "y": 18,
      "z": 3,
      "name": "Rock_Stone"
    },
    {
      "x": -3,
      "y": 19,
      "z": 3,
      "name": "Rock_Stone"
    },
    {
      "x": -3,
      "y": 20,
      "z": 3,
      "name": "Rock_Stone"
    },
    {
      "x": -3,
      "y": 21,
      "z": 3,
      "name": "Rock_Stone"
    },
    {
      "x": -3,
      "y": 22,
      "z": 3,
      "name": "Rock_Stone"
    },
    {
      "x": -3,
      "y": 23,
      "z": 3,
      "name": "Rock_Stone"
    },
    {
      "x": -3,
      "y": 24,
      "z": 3,
      "name": "Rock_Stone"
    },
    {
      "x": -3,
      "y": 25,
      "z": 3,
      "name": "Rock_Stone"
    },
    {
      "x": -3,
      "y": 26,
      "z": 3,
      "name": "Rock_Stone"
    },
    {
      "x": -3,
      "y": 27,
      "z": 3,
      "name": "Rock_Stone"
    },
    {
      "x": -3,
      "y": 28,
      "z": 3,
      "name": "Rock_Stone"
    },
    {
      "x": -3,
      "y": 29,
      "z": 3,
      "name": "Rock_Stone"
    },
    {
      "x": -3,
      "y": 30,
      "z": 3,
      "name": "Rock_Stone"
    },
    {
      "x": -3,
      "y": 31,
      "z": 3,
      "name": "Rock_Stone"
    },
    {
      "x": -3,
      "y": 32,
      "z": 3,
      "name": "Rock_Stone"
    },
    {
      "x": -3,
      "y": 33,
      "z": 3,
      "name": "Rock_Stone"
    },
    {
      "x": -3,
      "y": 34,
      "z": 3,
      "name": "Rock_Stone"
    },
    {
      "x": -3,
      "y": 35,
      "z": 3,
      "name": "Rock_Stone"
    },
    {
      "x": -3,
      "y": 36,
      "z": 3,
      "name": "Rock_Stone"
    },
    {
      "x": -3,
      "y": 37,
      "z": 3,
      "name": "Rock_Stone"
    },
    {
      "x": -3,
      "y": 38,
      "z": 3,
      "name": "Rock_Stone"
    },
    {
      "x": -3,
      "y": 39,
      "z": 3,
      "name": "Rock_Stone"
    },
    {
      "x": -3,
      "y": 40,
      "z": 3,
      "name": "Rock_Stone"
    },
    {
      "x": -3,
      "y": 41,
      "z": 3,
      "name": "Rock_Stone"
    },
    {
      "x": -3,
      "y": 42,
      "z": 3,
      "name": "Soil_Dirt"
    },
    {
      "x": -3,
      "y": 43,
      "z": 3,
      "name": "Soil_Grass"
    },
    {
      "x": -3,
      "y": 44,
      "z": 3,
      "name": "Plant_Grass_Sharp"
    },
    {
      "x": -3,
      "y": 53,
      "z": 3,
      "name": "Wood_Aspen_Branch_Corner",
      "rotation": 3
    },
    {
      "x": -3,
      "y": 54,
      "z": 3,
      "name": "Wood_Aspen_Branch_Long"
    },
    {
      "x": -3,
      "y": 55,
      "z": 3,
      "name": "Wood_Aspen_Branch_Long"
    },
    {
      "x": -3,
      "y": 56,
      "z": 3,
      "name": "Wood_Aspen_Branch_Long"
    },
    {
      "x": -3,
      "y": 57,
      "z": 3,
      "name": "Plant_Leaves_Aspen"
    },
    {
      "x": -3,
      "y": 58,
      "z": 3,
      "name": "Plant_Leaves_Aspen"
    },
    {
      "x": -3,
      "y": 60,
      "z": 3,
      "name": "Plant_Leaves_Aspen"
    },
    {
      "x": -3,
      "y": 61,
      "z": 3,
      "name": "Plant_Leaves_Aspen"
    },
    {
      "x": -3,
      "y": 62,
      "z": 3,
      "name": "Plant_Leaves_Aspen"
    },
    {
      "x": -3,
      "y": 18,
      "z": 4,
      "name": "Rock_Stone"
    },
    {
      "x": -3,
      "y": 19,
      "z": 4,
      "name": "Rock_Stone"
    },
    {
      "x": -3,
      "y": 20,
      "z": 4,
      "name": "Rock_Stone"
    },
    {
      "x": -3,
      "y": 21,
      "z": 4,
      "name": "Rock_Stone"
    },
    {
      "x": -3,
      "y": 22,
      "z": 4,
      "name": "Rock_Stone"
    },
    {
      "x": -3,
      "y": 23,
      "z": 4,
      "name": "Rock_Stone"
    },
    {
      "x": -3,
      "y": 24,
      "z": 4,
      "name": "Rock_Stone"
    },
    {
      "x": -3,
      "y": 25,
      "z": 4,
      "name": "Rock_Stone"
    },
    {
      "x": -3,
      "y": 26,
      "z": 4,
      "name": "Rock_Stone"
    },
    {
      "x": -3,
      "y": 27,
      "z": 4,
      "name": "Rock_Stone"
    },
    {
      "x": -3,
      "y": 28,
      "z": 4,
      "name": "Rock_Stone"
    },
    {
      "x": -3,
      "y": 29,
      "z": 4,
      "name": "Rock_Stone"
    },
    {
      "x": -3,
      "y": 30,
      "z": 4,
      "name": "Rock_Stone"
    },
    {
      "x": -3,
      "y": 31,
      "z": 4,
      "name": "Rock_Stone"
    },
    {
      "x": -3,
      "y": 32,
      "z": 4,
      "name": "Rock_Stone"
    },
    {
      "x": -3,
      "y": 33,
      "z": 4,
      "name": "Rock_Stone"
    },
    {
      "x": -3,
      "y": 34,
      "z": 4,
      "name": "Rock_Stone"
    },
    {
      "x": -3,
      "y": 35,
      "z": 4,
      "name": "Rock_Stone"
    },
    {
      "x": -3,
      "y": 36,
      "z": 4,
      "name": "Rock_Stone"
    },
    {
      "x": -3,
      "y": 37,
      "z": 4,
      "name": "Rock_Stone"
    },
    {
      "x": -3,
      "y": 38,
      "z": 4,
      "name": "Rock_Stone"
    },
    {
      "x": -3,
      "y": 39,
      "z": 4,
      "name": "Rock_Stone"
    },
    {
      "x": -3,
      "y": 40,
      "z": 4,
      "name": "Rock_Stone"
    },
    {
      "x": -3,
      "y": 41,
      "z": 4,
      "name": "Rock_Stone"
    },
    {
      "x": -3,
      "y": 42,
      "z": 4,
      "name": "Soil_Dirt"
    },
    {
      "x": -3,
      "y": 43,
      "z": 4,
      "name": "Soil_Grass"
    },
    {
      "x": -3,
      "y": 44,
      "z": 4,
      "name": "Plant_Grass_Sharp"
    },
    {
      "x": -3,
      "y": 55,
      "z": 4,
      "name": "Plant_Leaves_Aspen"
    },
    {
      "x": -3,
      "y": 56,
      "z": 4,
      "name": "Plant_Leaves_Aspen"
    },
    {
      "x": -3,
      "y": 60,
      "z": 4,
      "name": "Plant_Leaves_Aspen"
    },
    {
      "x": -3,
      "y": 19,
      "z": 5,
      "name": "Rock_Stone"
    },
    {
      "x": -3,
      "y": 20,
      "z": 5,
      "name": "Rock_Stone"
    },
    {
      "x": -3,
      "y": 21,
      "z": 5,
      "name": "Rock_Stone"
    },
    {
      "x": -3,
      "y": 22,
      "z": 5,
      "name": "Rock_Stone"
    },
    {
      "x": -3,
      "y": 23,
      "z": 5,
      "name": "Rock_Stone"
    },
    {
      "x": -3,
      "y": 24,
      "z": 5,
      "name": "Rock_Stone"
    },
    {
      "x": -3,
      "y": 25,
      "z": 5,
      "name": "Rock_Stone"
    },
    {
      "x": -3,
      "y": 26,
      "z": 5,
      "name": "Rock_Stone"
    },
    {
      "x": -3,
      "y": 27,
      "z": 5,
      "name": "Rock_Stone"
    },
    {
      "x": -3,
      "y": 28,
      "z": 5,
      "name": "Rock_Stone"
    },
    {
      "x": -3,
      "y": 29,
      "z": 5,
      "name": "Rock_Stone"
    },
    {
      "x": -3,
      "y": 30,
      "z": 5,
      "name": "Rock_Stone"
    },
    {
      "x": -3,
      "y": 31,
      "z": 5,
      "name": "Rock_Stone"
    },
    {
      "x": -3,
      "y": 32,
      "z": 5,
      "name": "Rock_Stone"
    },
    {
      "x": -3,
      "y": 33,
      "z": 5,
      "name": "Rock_Stone"
    },
    {
      "x": -3,
      "y": 34,
      "z": 5,
      "name": "Soil_Dirt"
    },
    {
      "x": -3,
      "y": 35,
      "z": 5,
      "name": "Rock_Stone"
    },
    {
      "x": -3,
      "y": 36,
      "z": 5,
      "name": "Rock_Stone"
    },
    {
      "x": -3,
      "y": 37,
      "z": 5,
      "name": "Rock_Stone"
    },
    {
      "x": -3,
      "y": 38,
      "z": 5,
      "name": "Rock_Stone"
    },
    {
      "x": -3,
      "y": 39,
      "z": 5,
      "name": "Rock_Stone"
    },
    {
      "x": -3,
      "y": 40,
      "z": 5,
      "name": "Rock_Stone"
    },
    {
      "x": -3,
      "y": 41,
      "z": 5,
      "name": "Rock_Stone"
    },
    {
      "x": -3,
      "y": 42,
      "z": 5,
      "name": "Soil_Dirt"
    },
    {
      "x": -3,
      "y": 43,
      "z": 5,
      "name": "Soil_Grass"
    },
    {
      "x": -3,
      "y": 51,
      "z": 5,
      "name": "Plant_Leaves_Aspen"
    },
    {
      "x": -3,
      "y": 52,
      "z": 5,
      "name": "Plant_Leaves_Aspen"
    },
    {
      "x": -3,
      "y": 53,
      "z": 5,
      "name": "Plant_Leaves_Aspen"
    },
    {
      "x": -3,
      "y": 55,
      "z": 5,
      "name": "Plant_Leaves_Aspen"
    },
    {
      "x": -3,
      "y": 20,
      "z": 6,
      "name": "Rock_Stone"
    },
    {
      "x": -3,
      "y": 21,
      "z": 6,
      "name": "Rock_Stone"
    },
    {
      "x": -3,
      "y": 22,
      "z": 6,
      "name": "Rock_Stone"
    },
    {
      "x": -3,
      "y": 23,
      "z": 6,
      "name": "Rock_Stone"
    },
    {
      "x": -3,
      "y": 24,
      "z": 6,
      "name": "Rock_Stone"
    },
    {
      "x": -3,
      "y": 25,
      "z": 6,
      "name": "Rock_Stone"
    },
    {
      "x": -3,
      "y": 26,
      "z": 6,
      "name": "Rock_Stone"
    },
    {
      "x": -3,
      "y": 27,
      "z": 6,
      "name": "Rock_Stone"
    },
    {
      "x": -3,
      "y": 28,
      "z": 6,
      "name": "Rock_Stone"
    },
    {
      "x": -3,
      "y": 29,
      "z": 6,
      "name": "Rock_Stone"
    },
    {
      "x": -3,
      "y": 30,
      "z": 6,
      "name": "Rock_Stone"
    },
    {
      "x": -3,
      "y": 31,
      "z": 6,
      "name": "Rock_Stone"
    },
    {
      "x": -3,
      "y": 32,
      "z": 6,
      "name": "Soil_Dirt"
    },
    {
      "x": -3,
      "y": 33,
      "z": 6,
      "name": "Soil_Dirt"
    },
    {
      "x": -3,
      "y": 34,
      "z": 6,
      "name": "Soil_Dirt"
    },
    {
      "x": -3,
      "y": 35,
      "z": 6,
      "name": "Soil_Dirt"
    },
    {
      "x": -3,
      "y": 36,
      "z": 6,
      "name": "Rock_Stone"
    },
    {
      "x": -3,
      "y": 37,
      "z": 6,
      "name": "Rock_Stone"
    },
    {
      "x": -3,
      "y": 38,
      "z": 6,
      "name": "Rock_Stone"
    },
    {
      "x": -3,
      "y": 39,
      "z": 6,
      "name": "Rock_Stone"
    },
    {
      "x": -3,
      "y": 40,
      "z": 6,
      "name": "Rock_Stone"
    },
    {
      "x": -3,
      "y": 41,
      "z": 6,
      "name": "Rock_Stone"
    },
    {
      "x": -3,
      "y": 42,
      "z": 6,
      "name": "Soil_Dirt"
    },
    {
      "x": -3,
      "y": 43,
      "z": 6,
      "name": "Soil_Grass"
    },
    {
      "x": -3,
      "y": 53,
      "z": 6,
      "name": "Plant_Leaves_Aspen"
    },
    {
      "x": -3,
      "y": 22,
      "z": 7,
      "name": "Rock_Stone"
    },
    {
      "x": -3,
      "y": 23,
      "z": 7,
      "name": "Rock_Stone"
    },
    {
      "x": -3,
      "y": 24,
      "z": 7,
      "name": "Rock_Stone"
    },
    {
      "x": -3,
      "y": 25,
      "z": 7,
      "name": "Rock_Stone"
    },
    {
      "x": -3,
      "y": 26,
      "z": 7,
      "name": "Rock_Stone"
    },
    {
      "x": -3,
      "y": 27,
      "z": 7,
      "name": "Rock_Stone"
    },
    {
      "x": -3,
      "y": 28,
      "z": 7,
      "name": "Rock_Stone"
    },
    {
      "x": -3,
      "y": 29,
      "z": 7,
      "name": "Rock_Stone_Mossy"
    },
    {
      "x": -3,
      "y": 30,
      "z": 7,
      "name": "Rock_Stone"
    },
    {
      "x": -3,
      "y": 31,
      "z": 7,
      "name": "Soil_Dirt"
    },
    {
      "x": -3,
      "y": 32,
      "z": 7,
      "name": "Soil_Dirt"
    },
    {
      "x": -3,
      "y": 33,
      "z": 7,
      "name": "Soil_Dirt"
    },
    {
      "x": -3,
      "y": 34,
      "z": 7,
      "name": "Soil_Dirt"
    },
    {
      "x": -3,
      "y": 35,
      "z": 7,
      "name": "Soil_Grass"
    },
    {
      "x": -3,
      "y": 29,
      "z": 8,
      "name": "Rock_Stone"
    },
    {
      "x": -3,
      "y": 30,
      "z": 8,
      "name": "Rock_Stone"
    },
    {
      "x": -3,
      "y": 31,
      "z": 8,
      "name": "Soil_Dirt"
    },
    {
      "x": -3,
      "y": 32,
      "z": 8,
      "name": "Soil_Grass"
    },
    {
      "x": -3,
      "y": 33,
      "z": 8,
      "name": "Plant_Grass_Sharp_Tall"
    },
    {
      "x": -3,
      "y": 34,
      "z": 8,
      "name": "Plant_Grass_Sharp_Tall",
      "filler": 1024
    },
    {
      "x": -2,
      "y": 22,
      "z": -3,
      "name": "Rock_Stone"
    },
    {
      "x": -2,
      "y": 23,
      "z": -3,
      "name": "Rock_Stone"
    },
    {
      "x": -2,
      "y": 24,
      "z": -3,
      "name": "Rock_Stone"
    },
    {
      "x": -2,
      "y": 25,
      "z": -3,
      "name": "Rock_Stone"
    },
    {
      "x": -2,
      "y": 26,
      "z": -3,
      "name": "Rock_Stone"
    },
    {
      "x": -2,
      "y": 27,
      "z": -3,
      "name": "Rock_Stone"
    },
    {
      "x": -2,
      "y": 28,
      "z": -3,
      "name": "Rock_Stone"
    },
    {
      "x": -2,
      "y": 29,
      "z": -3,
      "name": "Rock_Stone"
    },
    {
      "x": -2,
      "y": 30,
      "z": -3,
      "name": "Soil_Dirt"
    },
    {
      "x": -2,
      "y": 31,
      "z": -3,
      "name": "Soil_Grass"
    },
    {
      "x": -2,
      "y": 54,
      "z": -3,
      "name": "Plant_Leaves_Aspen"
    },
    {
      "x": -2,
      "y": 19,
      "z": -2,
      "name": "Rock_Stone"
    },
    {
      "x": -2,
      "y": 20,
      "z": -2,
      "name": "Rock_Stone"
    },
    {
      "x": -2,
      "y": 21,
      "z": -2,
      "name": "Rock_Stone"
    },
    {
      "x": -2,
      "y": 22,
      "z": -2,
      "name": "Rock_Stone"
    },
    {
      "x": -2,
      "y": 23,
      "z": -2,
      "name": "Rock_Stone"
    },
    {
      "x": -2,
      "y": 24,
      "z": -2,
      "name": "Rock_Stone"
    },
    {
      "x": -2,
      "y": 25,
      "z": -2,
      "name": "Rock_Stone"
    },
    {
      "x": -2,
      "y": 26,
      "z": -2,
      "name": "Rock_Stone"
    },
    {
      "x": -2,
      "y": 27,
      "z": -2,
      "name": "Rock_Stone"
    },
    {
      "x": -2,
      "y": 28,
      "z": -2,
      "name": "Rock_Stone"
    },
    {
      "x": -2,
      "y": 29,
      "z": -2,
      "name": "Rock_Stone"
    },
    {
      "x": -2,
      "y": 30,
      "z": -2,
      "name": "Rock_Stone"
    },
    {
      "x": -2,
      "y": 31,
      "z": -2,
      "name": "Rock_Stone"
    },
    {
      "x": -2,
      "y": 32,
      "z": -2,
      "name": "Rock_Stone"
    },
    {
      "x": -2,
      "y": 33,
      "z": -2,
      "name": "Rock_Stone"
    },
    {
      "x": -2,
      "y": 34,
      "z": -2,
      "name": "Rock_Stone"
    },
    {
      "x": -2,
      "y": 35,
      "z": -2,
      "name": "Rock_Stone"
    },
    {
      "x": -2,
      "y": 36,
      "z": -2,
      "name": "Soil_Dirt"
    },
    {
      "x": -2,
      "y": 37,
      "z": -2,
      "name": "Soil_Grass"
    },
    {
      "x": -2,
      "y": 52,
      "z": -2,
