{
  "version": 8,
  "blockIdVersion": 8,
  "anchorX": 2,
  "anchorY": 0,
  "anchorZ": 13,
  "blocks": [
    {
      "x": 0,
      "y": 0,
      "z": 0,
      "name": "Rock_Stone"
    },
    {
      "x": 0,
      "y": 1,
      "z": 0,
      "name": "Rock_Stone"
    },
    {
      "x": 0,
      "y": 2,
      "z": 0,
      "name": "Rock_Stone"
    },
    {
      "x": 0,
      "y": 3,
      "z": 0,
      "name": "Rock_Stone"
    },
    {
      "x": 0,
      "y": 4,
      "z": 0,
      "name": "Rock_Stone"
    },
    {
      "x": 0,
      "y": 5,
      "z": 0,
      "name": "Rock_Stone"
    },
    {
      "x": 0,
      "y": 6,
      "z": 0,
      "name": "Rock_Stone"
    },
    {
      "x": 0,
      "y": 7,
      "z": 0,
      "name": "Rock_Stone"
    },
    {
      "x": 0,
      "y": 8,
      "z": 0,
      "name": "Rock_Stone"
    },
    {
      "x": 0,
      "y": 9,
      "z": 0,
      "name": "Rock_Stone"
    },
    {
      "x": 0,
      "y": 0,
      "z": 1,
      "name": "Rock_Stone"
    },
    {
      "x": 0,
      "y": 1,
      "z": 1,
      "name": "Rock_Stone"
    },
    {
      "x": 0,
      "y": 2,
      "z": 1,
      "name": "Rock_Stone"
    },
    {
      "x": 0,
      "y": 3,
      "z": 1,
      "name": "Rock_Stone"
    },
    {
      "x": 0,
      "y": 4,
      "z": 1,
      "name": "Rock_Stone"
    },
    {
      "x": 0,
      "y": 5,
      "z": 1,
      "name": "Rock_Stone"
    },
    {
      "x": 0,
      "y": 6,
      "z": 1,
      "name": "Rock_Stone"
    },
    {
      "x": 0,
      "y": 7,
      "z": 1,
      "name": "Rock_Stone"
    },
    {
      "x": 0,
      "y": 8,
      "z": 1,
      "name": "Rock_Stone"
    },
    {
      "x": 0,
      "y": 9,
      "z": 1,
      "name": "Rock_Stone"
    },
    {
      "x": 0,
      "y": 0,
      "z": 2,
      "name": "Rock_Stone"
    },
    {
      "x": 0,
      "y": 1,
      "z": 2,
      "name": "Rock_Stone"
    },
    {
      "x": 0,
      "y": 2,
      "z": 2,
      "name": "Rock_Stone"
    },
    {
      "x": 0,
      "y": 3,
      "z": 2,
      "name": "Rock_Stone"
    },
    {
      "x": 0,
      "y": 4,
      "z": 2,
      "name": "Rock_Stone"
    },
    {
      "x": 0,
      "y": 5,
      "z": 2,
      "name": "Rock_Stone"
    },
    {
      "x": 0,
      "y": 6,
      "z": 2,
      "name": "Rock_Stone"
    },
    {
      "x": 0,
      "y": 7,
      "z": 2,
      "name": "Rock_Stone"
    },
    {
      "x": 0,
      "y": 8,
      "z": 2,
      "name": "Rock_Stone"
    },
    {
      "x": 0,
      "y": 9,
      "z": 2,
      "name": "Rock_Stone"
    },
    {
      "x": 0,
      "y": 0,
      "z": 3,
      "name": "Rock_Stone"
    },
    {
      "x": 0,
      "y": 1,
      "z": 3,
      "name": "Rock_Stone"
    },
    {
      "x": 0,
      "y": 2,
      "z": 3,
      "name": "Rock_Stone"
    },
    {
      "x": 0,
      "y": 3,
      "z": 3,
      "name": "Rock_Stone"
    },
    {
      "x": 0,
      "y": 4,
      "z": 3,
      "name": "Rock_Stone"
    },
    {
      "x": 0,
      "y": 5,
      "z": 3,
      "name": "Rock_Stone"
    },
    {
      "x": 0,
      "y": 6,
      "z": 3,
      "name": "Rock_Stone"
    },
    {
      "x": 0,
      "y": 7,
      "z": 3,
      "name": "Rock_Stone"
    },
    {
      "x": 0,
      "y": 8,
      "z": 3,
      "name": "Rock_Stone"
    },
    {
      "x": 0,
      "y": 9,
      "z": 3,
      "name": "Rock_Stone"
    },
    {
      "x": 0,
      "y": 0,
      "z": 4,
      "name": "Rock_Stone"
    },
    {
      "x": 0,
      "y": 1,
      "z": 4,
      "name": "Rock_Stone"
    },
    {
      "x": 0,
      "y": 2,
      "z": 4,
      "name": "Rock_Stone"
    },
    {
      "x": 0,
      "y": 3,
      "z": 4,
      "name": "Rock_Stone"
    },
    {
      "x": 0,
      "y": 4,
      "z": 4,
      "name": "Rock_Stone"
    },
    {
      "x": 0,
      "y": 5,
      "z": 4,
      "name": "Rock_Stone"
    },
    {
      "x": 0,
      "y": 6,
      "z": 4,
      "name": "Rock_Stone"
    },
    {
      "x": 0,
      "y": 7,
      "z": 4,
      "name": "Rock_Stone"
    },
    {
      "x": 0,
      "y": 8,
      "z": 4,
      "name": "Rock_Stone"
    },
    {
      "x": 0,
      "y": 9,
      "z": 4,
      "name": "Rock_Stone"
    },
    {
      "x": 0,
      "y": 0,
      "z": 5,
      "name": "Rock_Stone"
    },
    {
      "x": 0,
      "y": 1,
      "z": 5,
      "name": "Rock_Stone"
    },
    {
      "x": 0,
      "y": 2,
      "z": 5,
      "name": "Rock_Stone"
    },
    {
      "x": 0,
      "y": 3,
      "z": 5,
      "name": "Rock_Stone"
    },
    {
      "x": 0,
      "y": 4,
      "z": 5,
      "name": "Rock_Stone"
    },
    {
      "x": 0,
      "y": 5,
      "z": 5,
      "name": "Rock_Stone"
    },
    {
      "x": 0,
      "y": 6,
      "z": 5,
      "name": "Rock_Stone"
    },
    {
      "x": 0,
      "y": 7,
      "z": 5,
      "name": "Rock_Stone"
    },
    {
      "x": 0,
      "y": 8,
      "z": 5,
      "name": "Rock_Stone"
    },
    {
      "x": 0,
      "y": 9,
      "z": 5,
      "name": "Rock_Stone"
    },
    {
      "x": 0,
      "y": 0,
      "z": 6,
      "name": "Rock_Stone"
    },
    {
      "x": 0,
      "y": 1,
      "z": 6,
      "name": "Rock_Stone"
    },
    {
      "x": 0,
      "y": 2,
      "z": 6,
      "name": "Rock_Stone"
    },
    {
      "x": 0,
      "y": 3,
      "z": 6,
      "name": "Rock_Stone"
    },
    {
      "x": 0,
      "y": 4,
      "z": 6,
      "name": "Rock_Stone"
    },
    {
      "x": 0,
      "y": 5,
      "z": 6,
      "name": "Rock_Stone"
    },
    {
      "x": 0,
      "y": 6,
      "z": 6,
      "name": "Rock_Stone"
    },
    {
      "x": 0,
      "y": 7,
      "z": 6,
      "name": "Rock_Stone"
    },
    {
      "x": 0,
      "y": 8,
      "z": 6,
      "name": "Rock_Stone"
    },
    {
      "x": 0,
      "y": 9,
      "z": 6,
      "name": "Rock_Stone"
    },
    {
      "x": 0,
      "y": 0,
      "z": 7,
      "name": "Rock_Stone"
    },
    {
      "x": 0,
      "y": 1,
      "z": 7,
      "name": "Rock_Stone"
    },
    {
      "x": 0,
      "y": 2,
      "z": 7,
      "name": "Rock_Stone"
    },
    {
      "x": 0,
      "y": 3,
      "z": 7,
      "name": "Rock_Stone"
    },
    {
      "x": 0,
      "y": 4,
      "z": 7,
      "name": "Rock_Stone"
    },
    {
      "x": 0,
      "y": 5,
      "z": 7,
      "name": "Rock_Stone"
    },
    {
      "x": 0,
      "y": 6,
      "z": 7,
      "name": "Rock_Stone"
    },
    {
      "x": 0,
      "y": 7,
      "z": 7,
      "name": "Rock_Stone"
    },
    {
      "x": 0,
      "y": 8,
      "z": 7,
      "name": "Rock_Stone"
    },
    {
      "x": 0,
      "y": 9,
      "z": 7,
      "name": "Rock_Stone"
    },
    {
      "x": 0,
      "y": 0,
      "z": 8,
      "name": "Rock_Stone"
    },
    {
      "x": 0,
      "y": 1,
      "z": 8,
      "name": "Rock_Stone"
    },
    {
      "x": 0,
      "y": 2,
      "z": 8,
      "name": "Rock_Stone"
    },
    {
      "x": 0,
      "y": 3,
      "z": 8,
      "name": "Rock_Stone"
    },
    {
      "x": 0,
      "y": 4,
      "z": 8,
      "name": "Rock_Stone"
    },
    {
      "x": 0,
      "y": 5,
      "z": 8,
      "name": "Rock_Stone"
    },
    {
      "x": 0,
      "y": 6,
      "z": 8,
      "name": "Rock_Stone"
    },
    {
      "x": 0,
      "y": 7,
      "z": 8,
      "name": "Rock_Stone"
    },
    {
      "x": 0,
      "y": 8,
      "z": 8,
      "name": "Rock_Stone"
    },
    {
      "x": 0,
      "y": 9,
      "z": 8,
      "name": "Rock_Stone"
    },
    {
      "x": 0,
      "y": 0,
      "z": 9,
      "name": "Rock_Stone"
    },
    {
      "x": 0,
      "y": 1,
      "z": 9,
      "name": "Rock_Stone"
    },
    {
      "x": 0,
      "y": 2,
      "z": 9,
      "name": "Rock_Stone"
    },
    {
      "x": 0,
      "y": 3,
      "z": 9,
      "name": "Rock_Stone"
    },
    {
      "x": 0,
      "y": 4,
      "z": 9,
      "name": "Rock_Stone"
    },
    {
      "x": 0,
      "y": 5,
      "z": 9,
      "name": "Rock_Stone"
    },
    {
      "x": 0,
      "y": 6,
      "z": 9,
      "name": "Rock_Stone"
    },
    {
      "x": 0,
      "y": 7,
      "z": 9,
      "name": "Rock_Stone"
    },
    {
      "x": 0,
      "y": 8,
      "z": 9,
      "name": "Rock_Stone"
    },
    {
      "x": 0,
      "y": 9,
      "z": 9,
      "name": "Rock_Stone"
    },
    {
      "x": 0,
      "y": 0,
      "z": 10,
      "name": "Rock_Stone"
    },
    {
      "x": 0,
      "y": 1,
      "z": 10,
      "name": "Rock_Stone"
    },
    {
      "x": 0,
      "y": 2,
      "z": 10,
      "name": "Rock_Stone"
    },
    {
      "x": 0,
      "y": 3,
      "z": 10,
      "name": "Rock_Stone"
    },
    {
      "x": 0,
      "y": 4,
      "z": 10,
      "name": "Rock_Stone"
    },
    {
      "x": 0,
      "y": 5,
      "z": 10,
      "name": "Rock_Stone"
    },
    {
      "x": 0,
      "y": 6,
      "z": 10,
      "name": "Rock_Stone"
    },
    {
      "x": 0,
      "y": 7,
      "z": 10,
      "name": "Rock_Stone"
    },
    {
      "x": 0,
      "y": 8,
      "z": 10,
      "name": "Rock_Stone"
    },
    {
      "x": 0,
      "y": 9,
      "z": 10,
      "name": "Rock_Stone"
    },
    {
      "x": 0,
      "y": 0,
      "z": 11,
      "name": "Rock_Stone"
    },
    {
      "x": 0,
      "y": 1,
      "z": 11,
      "name": "Rock_Stone"
    },
    {
      "x": 0,
      "y": 2,
      "z": 11,
      "name": "Rock_Stone"
    },
    {
      "x": 0,
      "y": 3,
      "z": 11,
      "name": "Rock_Stone"
    },
    {
      "x": 0,
      "y": 4,
      "z": 11,
      "name": "Rock_Stone"
    },
    {
      "x": 0,
      "y": 5,
      "z": 11,
      "name": "Rock_Stone"
    },
    {
      "x": 0,
      "y": 6,
      "z": 11,
      "name": "Rock_Stone"
    },
    {
      "x": 0,
      "y": 7,
      "z": 11,
      "name": "Rock_Stone"
    },
    {
      "x": 0,
      "y": 8,
      "z": 11,
      "name": "Rock_Stone"
    },
    {
      "x": 0,
      "y": 9,
      "z": 11,
      "name": "Rock_Stone"
    },
    {
      "x": 0,
      "y": 0,
      "z": 12,
      "name": "Rock_Stone"
    },
    {
      "x": 0,
      "y": 1,
      "z": 12,
      "name": "Rock_Stone"
    },
    {
      "x": 0,
      "y": 2,
      "z": 12,
      "name": "Rock_Stone"
    },
    {
      "x": 0,
      "y": 3,
      "z": 12,
      "name": "Rock_Stone"
    },
    {
      "x": 0,
      "y": 4,
      "z": 12,
      "name": "Rock_Stone"
    },
    {
      "x": 0,
      "y": 5,
      "z": 12,
      "name": "Rock_Stone"
    },
    {
      "x": 0,
      "y": 6,
      "z": 12,
      "name": "Rock_Stone"
    },
    {
      "x": 0,
      "y": 7,
      "z": 12,
      "name": "Rock_Stone"
    },
    {
      "x": 0,
      "y": 8,
      "z": 12,
      "name": "Rock_Stone"
    },
    {
      "x": 0,
      "y": 9,
      "z": 12,
      "name": "Rock_Stone"
    },
    {
      "x": 1,
      "y": 0,
      "z": 0,
      "name": "Rock_Stone"
    },
    {
      "x": 1,
      "y": 9,
      "z": 0,
      "name": "Rock_Stone"
    },
    {
      "x": 1,
      "y": 0,
      "z": 1,
      "name": "Rock_Stone"
    },
    {
      "x": 1,
      "y": 9,
      "z": 1,
      "name": "Rock_Stone"
    },
    {
      "x": 1,
      "y": 0,
      "z": 2,
      "name": "Rock_Stone"
    },
    {
      "x": 1,
      "y": 9,
      "z": 2,
      "name": "Rock_Stone"
    },
    {
      "x": 1,
      "y": 0,
      "z": 3,
      "name": "Rock_Stone"
    },
    {
      "x": 1,
      "y": 9,
      "z": 3,
      "name": "Rock_Stone"
    },
    {
      "x": 1,
      "y": 0,
      "z": 4,
      "name": "Rock_Stone"
    },
    {
      "x": 1,
      "y": 9,
      "z": 4,
      "name": "Rock_Stone"
    },
    {
      "x": 1,
      "y": 0,
      "z": 5,
      "name": "Rock_Stone"
    },
    {
      "x": 1,
      "y": 9,
      "z": 5,
      "name": "Rock_Stone"
    },
    {
      "x": 1,
      "y": 0,
      "z": 6,
      "name": "Rock_Stone"
    },
    {
      "x": 1,
      "y": 9,
      "z": 6,
      "name": "Rock_Stone"
    },
    {
      "x": 1,
      "y": 0,
      "z": 7,
      "name": "Rock_Stone"
    },
    {
      "x": 1,
      "y": 9,
      "z": 7,
      "name": "Rock_Stone"
    },
    {
      "x": 1,
      "y": 0,
      "z": 8,
      "name": "Rock_Stone"
    },
    {
      "x": 1,
      "y": 9,
      "z": 8,
      "name": "Rock_Stone"
    },
    {
      "x": 1,
      "y": 0,
      "z": 9,
      "name": "Rock_Stone"
    },
    {
      "x": 1,
      "y": 9,
      "z": 9,
      "name": "Rock_Stone"
    },
    {
      "x": 1,
      "y": 0,
      "z": 10,
      "name": "Rock_Stone"
    },
    {
      "x": 1,
      "y": 9,
      "z": 10,
      "name": "Rock_Stone"
    },
    {
      "x": 1,
      "y": 0,
      "z": 11,
      "name": "Rock_Stone"
    },
    {
      "x": 1,
      "y": 9,
      "z": 11,
      "name": "Rock_Stone"
    },
    {
      "x": 1,
      "y": 0,
      "z": 12,
      "name": "Rock_Stone"
    },
    {
      "x": 1,
      "y": 9,
      "z": 12,
      "name": "Rock_Stone"
    },
    {
      "x": 2,
      "y": 0,
      "z": 0,
      "name": "Rock_Stone"
    },
    {
      "x": 2,
      "y": 9,
      "z": 0,
      "name": "Rock_Stone"
    },
    {
      "x": 2,
      "y": 0,
      "z": 1,
      "name": "Rock_Stone"
    },
    {
      "x": 2,
      "y": 9,
      "z": 1,
      "name": "Rock_Stone"
    },
    {
      "x": 2,
      "y": 0,
      "z": 2,
      "name": "Rock_Stone"
    },
    {
      "x": 2,
      "y": 9,
      "z": 2,
      "name": "Rock_Stone"
    },
    {
      "x": 2,
      "y": 0,
      "z": 3,
      "name": "Rock_Stone"
    },
    {
      "x": 2,
      "y": 9,
      "z": 3,
      "name": "Rock_Stone"
    },
    {
      "x": 2,
      "y": 0,
      "z": 4,
      "name": "Rock_Stone"
    },
    {
      "x": 2,
      "y": 9,
      "z": 4,
      "name": "Rock_Stone"
    },
    {
      "x": 2,
      "y": 0,
      "z": 5,
      "name": "Rock_Stone"
    },
    {
      "x": 2,
      "y": 9,
      "z": 5,
      "name": "Rock_Stone"
    },
    {
      "x": 2,
      "y": 0,
      "z": 6,
      "name": "Rock_Stone"
    },
    {
      "x": 2,
      "y": 9,
      "z": 6,
      "name": "Rock_Stone"
    },
    {
      "x": 2,
      "y": 0,
      "z": 7,
      "name": "Rock_Stone"
    },
    {
      "x": 2,
      "y": 9,
      "z": 7,
      "name": "Rock_Stone"
    },
    {
      "x": 2,
      "y": 0,
      "z": 8,
      "name": "Rock_Stone"
    },
    {
      "x": 2,
      "y": 9,
      "z": 8,
      "name": "Rock_Stone"
    },
    {
      "x": 2,
      "y": 0,
      "z": 9,
      "name": "Rock_Stone"
    },
    {
      "x": 2,
      "y": 9,
      "z": 9,
      "name": "Rock_Stone"
    },
    {
      "x": 2,
      "y": 0,
      "z": 10,
      "name": "Rock_Stone"
    },
    {
      "x": 2,
      "y": 9,
      "z": 10,
      "name": "Rock_Stone"
    },
    {
      "x": 2,
      "y": 0,
      "z": 11,
      "name": "Rock_Stone"
    },
    {
      "x": 2,
      "y": 9,
      "z": 11,
      "name": "Rock_Stone"
    },
    {
      "x": 2,
      "y": 0,
      "z": 12,
      "name": "Rock_Stone"
    },
    {
      "x": 2,
      "y": 9,
      "z": 12,
      "name": "Rock_Stone"
    },
    {
      "x": 2,
      "y": 0,
      "z": 13,
      "name": "Rock_Stone"
    },
    {
      "x": 3,
      "y": 0,
      "z": 0,
      "name": "Rock_Stone"
    },
    {
      "x": 3,
      "y": 9,
      "z": 0,
      "name": "Rock_Stone"
    },
    {
      "x": 3,
      "y": 0,
      "z": 1,
      "name": "Rock_Stone"
    },
    {
      "x": 3,
      "y": 9,
      "z": 1,
      "name": "Rock_Stone"
    },
    {
      "x": 3,
      "y": 0,
      "z": 2,
      "name": "Rock_Stone"
    },
    {
      "x": 3,
      "y": 9,
      "z": 2,
      "name": "Rock_Stone"
    },
    {
      "x": 3,
      "y": 0,
      "z": 3,
      "name": "Rock_Stone"
    },
    {
      "x": 3,
      "y": 9,
      "z": 3,
      "name": "Rock_Stone"
    },
    {
      "x": 3,
      "y": 0,
      "z": 4,
      "name": "Rock_Stone"
    },
    {
      "x": 3,
      "y": 9,
      "z": 4,
      "name": "Rock_Stone"
    },
    {
      "x": 3,
      "y": 0,
      "z": 5,
      "name": "Rock_Stone"
    },
    {
      "x": 3,
      "y": 9,
      "z": 5,
      "name": "Rock_Stone"
    },
    {
      "x": 3,
      "y": 0,
      "z": 6,
      "name": "Rock_Stone"
    },
    {
      "x": 3,
      "y": 9,
      "z": 6,
      "name": "Rock_Stone"
    },
    {
      "x": 3,
      "y": 0,
      "z": 7,
      "name": "Rock_Stone"
    },
    {
      "x": 3,
      "y": 9,
      "z": 7,
      "name": "Rock_Stone"
    },
    {
      "x": 3,
      "y": 0,
      "z": 8,
      "name": "Rock_Stone"
    },
    {
      "x": 3,
      "y": 9,
      "z": 8,
      "name": "Rock_Stone"
    },
    {
      "x": 3,
      "y": 0,
      "z": 9,
      "name": "Rock_Stone"
    },
    {
      "x": 3,
      "y": 9,
      "z": 9,
      "name": "Rock_Stone"
    },
    {
      "x": 3,
      "y": 0,
      "z": 10,
      "name": "Rock_Stone"
    },
    {
      "x": 3,
      "y": 9,
      "z": 10,
      "name": "Rock_Stone"
    },
    {
      "x": 3,
      "y": 0,
      "z": 11,
      "name": "Rock_Stone"
    },
    {
      "x": 3,
      "y": 9,
      "z": 11,
      "name": "Rock_Stone"
    },
    {
      "x": 3,
      "y": 0,
      "z": 12,
      "name": "Rock_Stone"
    },
    {
      "x": 3,
      "y": 9,
      "z": 12,
      "name": "Rock_Stone"
    },
    {
      "x": 4,
      "y": 0,
      "z": 0,
      "name": "Rock_Stone"
    },
    {
      "x": 4,
      "y": 1,
      "z": 0,
      "name": "Rock_Stone"
    },
    {
      "x": 4,
      "y": 2,
      "z": 0,
      "name": "Rock_Stone"
    },
    {
      "x": 4,
      "y": 3,
      "z": 0,
      "name": "Rock_Stone"
    },
    {
      "x": 4,
      "y": 4,
      "z": 0,
      "name": "Rock_Stone"
    },
    {
      "x": 4,
      "y": 5,
      "z": 0,
      "name": "Rock_Stone"
    },
    {
      "x": 4,
      "y": 6,
      "z": 0,
      "name": "Rock_Stone"
    },
    {
      "x": 4,
      "y": 7,
      "z": 0,
      "name": "Rock_Stone"
    },
    {
      "x": 4,
      "y": 8,
      "z": 0,
      "name": "Rock_Stone"
    },
    {
      "x": 4,
      "y": 9,
      "z": 0,
      "name": "Rock_Stone"
    },
    {
      "x": 4,
      "y": 0,
      "z": 1,
      "name": "Rock_Stone"
    },
    {
      "x": 4,
      "y": 1,
      "z": 1,
      "name": "Rock_Stone"
    },
    {
      "x": 4,
      "y": 2,
      "z": 1,
      "name": "Rock_Stone"
    },
    {
      "x": 4,
      "y": 3,
      "z": 1,
      "name": "Rock_Stone"
    },
    {
      "x": 4,
      "y": 4,
      "z": 1,
      "name": "Rock_Stone"
    },
    {
      "x": 4,
      "y": 5,
      "z": 1,
      "name": "Rock_Stone"
    },
    {
      "x": 4,
      "y": 6,
      "z": 1,
      "name": "Rock_Stone"
    },
    {
      "x": 4,
      "y": 7,
      "z": 1,
      "name": "Rock_Stone"
    },
    {
      "x": 4,
      "y": 8,
      "z": 1,
      "name": "Rock_Stone"
    },
    {
      "x": 4,
      "y": 9,
      "z": 1,
      "name": "Rock_Stone"
    },
    {
      "x": 4,
      "y": 0,
      "z": 2,
      "name": "Rock_Stone"
    },
    {
      "x": 4,
      "y": 1,
      "z": 2,
      "name": "Rock_Stone"
    },
    {
      "x": 4,
      "y": 2,
      "z": 2,
      "name": "Rock_Stone"
    },
    {
      "x": 4,
      "y": 3,
      "z": 2,
      "name": "Rock_Stone"
    },
    {
      "x": 4,
      "y": 4,
      "z": 2,
      "name": "Rock_Stone"
    },
    {
      "x": 4,
      "y": 5,
      "z": 2,
      "name": "Rock_Stone"
    },
    {
      "x": 4,
      "y": 6,
      "z": 2,
      "name": "Rock_Stone"
    },
    {
      "x": 4,
      "y": 7,
      "z": 2,
      "name": "Rock_Stone"
    },
    {
      "x": 4,
      "y": 8,
      "z": 2,
      "name": "Rock_Stone"
    },
    {
      "x": 4,
      "y": 9,
      "z": 2,
      "name": "Rock_Stone"
    },
    {
      "x": 4,
      "y": 0,
      "z": 3,
      "name": "Rock_Stone"
    },
    {
      "x": 4,
      "y": 1,
      "z": 3,
      "name": "Rock_Stone"
    },
    {
      "x": 4,
      "y": 2,
      "z": 3,
      "name": "Rock_Stone"
    },
    {
      "x": 4,
      "y": 3,
      "z": 3,
      "name": "Rock_Stone"
    },
    {
      "x": 4,
      "y": 4,
      "z": 3,
      "name": "Rock_Stone"
    },
    {
      "x": 4,
      "y": 5,
      "z": 3,
      "name": "Rock_Stone"
    },
    {
      "x": 4,
      "y": 6,
      "z": 3,
      "name": "Rock_Stone"
    },
    {
      "x": 4,
      "y": 7,
      "z": 3,
      "name": "Rock_Stone"
    },
    {
      "x": 4,
      "y": 8,
      "z": 3,
      "name": "Rock_Stone"
    },
    {
      "x": 4,
      "y": 9,
      "z": 3,
      "name": "Rock_Stone"
    },
    {
      "x": 4,
      "y": 0,
      "z": 4,
      "name": "Rock_Stone"
    },
    {
      "x": 4,
      "y": 1,
      "z": 4,
      "name": "Rock_Stone"
    },
    {
      "x": 4,
      "y": 2,
      "z": 4,
      "name": "Rock_Stone"
    },
    {
      "x": 4,
      "y": 3,
      "z": 4,
      "name": "Rock_Stone"
    },
    {
      "x": 4,
      "y": 4,
      "z": 4,
      "name": "Rock_Stone"
    },
    {
      "x": 4,
      "y": 5,
      "z": 4,
      "name": "Rock_Stone"
    },
    {
      "x": 4,
      "y": 6,
      "z": 4,
      "name": "Rock_Stone"
    },
    {
      "x": 4,
      "y": 7,
      "z": 4,
      "name": "Rock_Stone"
    },
    {
      "x": 4,
      "y": 8,
      "z": 4,
      "name": "Rock_Stone"
    },
    {
      "x": 4,
      "y": 9,
      "z": 4,
      "name": "Rock_Stone"
    },
    {
      "x": 4,
      "y": 0,
      "z": 5,
      "name": "Rock_Stone"
    },
    {
      "x": 4,
      "y": 1,
      "z": 5,
      "name": "Rock_Stone"
    },
    {
      "x": 4,
      "y": 2,
      "z": 5,
      "name": "Rock_Stone"
    },
    {
      "x": 4,
      "y": 3,
      "z": 5,
      "name": "Rock_Stone"
    },
    {
      "x": 4,
      "y": 4,
      "z": 5,
      "name": "Rock_Stone"
    },
    {
      "x": 4,
      "y": 5,
      "z": 5,
      "name": "Rock_Stone"
    },
    {
      "x": 4,
      "y": 6,
      "z": 5,
      "name": "Rock_Stone"
    },
    {
      "x": 4,
      "y": 7,
      "z": 5,
      "name": "Rock_Stone"
    },
    {
      "x": 4,
      "y": 8,
      "z": 5,
      "name": "Rock_Stone"
    },
    {
      "x": 4,
      "y": 9,
      "z": 5,
      "name": "Rock_Stone"
    },
    {
      "x": 4,
      "y": 0,
      "z": 6,
      "name": "Rock_Stone"
    },
    {
      "x": 4,
      "y": 1,
      "z": 6,
      "name": "Rock_Stone"
    },
    {
      "x": 4,
      "y": 2,
      "z": 6,
      "name": "Rock_Stone"
    },
    {
      "x": 4,
      "y": 3,
      "z": 6,
      "name": "Rock_Stone"
    },
    {
      "x": 4,
      "y": 4,
      "z": 6,
      "name": "Rock_Stone"
    },
    {
      "x": 4,
      "y": 5,
      "z": 6,
      "name": "Rock_Stone"
    },
    {
      "x": 4,
      "y": 6,
      "z": 6,
      "name": "Rock_Stone"
    },
    {
      "x": 4,
      "y": 7,
      "z": 6,
      "name": "Rock_Stone"
    },
    {
      "x": 4,
      "y": 8,
      "z": 6,
      "name": "Rock_Stone"
    },
    {
      "x": 4,
      "y": 9,
      "z": 6,
      "name": "Rock_Stone"
    },
    {
      "x": 4,
      "y": 0,
      "z": 7,
      "name": "Rock_Stone"
    },
    {
      "x": 4,
      "y": 1,
      "z": 7,
      "name": "Rock_Stone"
    },
    {
      "x": 4,
      "y": 2,
      "z": 7,
      "name": "Rock_Stone"
    },
    {
      "x": 4,
      "y": 3,
      "z": 7,
      "name": "Rock_Stone"
    },
    {
      "x": 4,
      "y": 4,
      "z": 7,
      "name": "Rock_Stone"
    },
    {
      "x": 4,
      "y": 5,
      "z": 7,
      "name": "Rock_Stone"
    },
    {
      "x": 4,
      "y": 6,
      "z": 7,
      "name": "Rock_Stone"
    },
    {
      "x": 4,
      "y": 7,
      "z": 7,
      "name": "Rock_Stone"
    },
    {
      "x": 4,
      "y": 8,
      "z": 7,
      "name": "Rock_Stone"
    },
    {
      "x": 4,
      "y": 9,
      "z": 7,
      "name": "Rock_Stone"
    },
    {
      "x": 4,
      "y": 0,
      "z": 8,
      "name": "Rock_Stone"
    },
    {
      "x": 4,
      "y": 1,
      "z": 8,
      "name": "Rock_Stone"
    },
    {
      "x": 4,
      "y": 2,
      "z": 8,
      "name": "Rock_Stone"
    },
    {
      "x": 4,
      "y": 3,
      "z": 8,
      "name": "Rock_Stone"
    },
    {
      "x": 4,
      "y": 4,
      "z": 8,
      "name": "Rock_Stone"
    },
    {
      "x": 4,
      "y": 5,
      "z": 8,
      "name": "Rock_Stone"
    },
    {
      "x": 4,
      "y": 6,
      "z": 8,
      "name": "Rock_Stone"
    },
    {
      "x": 4,
      "y": 7,
      "z": 8,
      "name": "Rock_Stone"
    },
    {
      "x": 4,
      "y": 8,
      "z": 8,
      "name": "Rock_Stone"
    },
    {
      "x": 4,
      "y": 9,
      "z": 8,
      "name": "Rock_Stone"
    },
    {
      "x": 4,
      "y": 0,
      "z": 9,
      "name": "Rock_Stone"
    },
    {
      "x": 4,
      "y": 1,
      "z": 9,
      "name": "Rock_Stone"
    },
    {
      "x": 4,
      "y": 2,
      "z": 9,
      "name": "Rock_Stone"
    },
    {
      "x": 4,
      "y": 3,
      "z": 9,
      "name": "Rock_Stone"
    },
    {
      "x": 4,
      "y": 4,
      "z": 9,
      "name": "Rock_Stone"
    },
    {
      "x": 4,
      "y": 5,
      "z": 9,
      "name": "Rock_Stone"
    },
    {
      "x": 4,
      "y": 6,
      "z": 9,
      "name": "Rock_Stone"
    },
    {
      "x": 4,
      "y": 7,
      "z": 9,
      "name": "Rock_Stone"
    },
    {
      "x": 4,
      "y": 8,
      "z": 9,
      "name": "Rock_Stone"
    },
    {
      "x": 4,
      "y": 9,
      "z": 9,
      "name": "Rock_Stone"
    },
    {
      "x": 4,
      "y": 0,
      "z": 10,
      "name": "Rock_Stone"
    },
    {
      "x": 4,
      "y": 1,
      "z": 10,
      "name": "Rock_Stone"
    },
    {
      "x": 4,
      "y": 2,
      "z": 10,
      "name": "Rock_Stone"
    },
    {
      "x": 4,
      "y": 3,
      "z": 10,
      "name": "Rock_Stone"
    },
    {
      "x": 4,
      "y": 4,
      "z": 10,
      "name": "Rock_Stone"
    },
    {
      "x": 4,
      "y": 5,
      "z": 10,
      "name": "Rock_Stone"
    },
    {
      "x": 4,
      "y": 6,
      "z": 10,
      "name": "Rock_Stone"
    },
    {
      "x": 4,
      "y": 7,
      "z": 10,
      "name": "Rock_Stone"
    },
    {
      "x": 4,
      "y": 8,
      "z": 10,
      "name": "Rock_Stone"
    },
    {
      "x": 4,
      "y": 9,
      "z": 10,
      "name": "Rock_Stone"
    },
    {
      "x": 4,
      "y": 0,
      "z": 11,
      "name": "Rock_Stone"
    },
    {
      "x": 4,
      "y": 1,
      "z": 11,
      "name": "Rock_Stone"
    },
    {
      "x": 4,
      "y": 2,
      "z": 11,
      "name": "Rock_Stone"
    },
    {
      "x": 4,
      "y": 3,
      "z": 11,
      "name": "Rock_Stone"
    },
    {
      "x": 4,
      "y": 4,
      "z": 11,
      "name": "Rock_Stone"
    },
    {
      "x": 4,
      "y": 5,
      "z": 11,
      "name": "Rock_Stone"
    },
    {
      "x": 4,
      "y": 6,
      "z": 11,
      "name": "Rock_Stone"
    },
    {
      "x": 4,
      "y": 7,
      "z": 11,
      "name": "Rock_Stone"
    },
    {
      "x": 4,
      "y": 8,
      "z": 11,
      "name": "Rock_Stone"
    },
    {
      "x": 4,
      "y": 9,
      "z": 11,
      "name": "Rock_Stone"
    },
    {
      "x": 4,
      "y": 0,
      "z": 12,
      "name": "Rock_Stone"
    },
    {
      "x": 4,
      "y": 1,
      "z": 12,
      "name": "Rock_Stone"
    },
    {
      "x": 4,
      "y": 2,
      "z": 12,
      "name": "Rock_Stone"
    },
    {
      "x": 4,
      "y": 3,
      "z": 12,
      "name": "Rock_Stone"
    },
    {
      "x": 4,
      "y": 4,
      "z": 12,
      "name": "Rock_Stone"
    },
    {
      "x": 4,
      "y": 5,
      "z": 12,
      "name": "Rock_Stone"
    },
    {
      "x": 4,
      "y": 6,
      "z": 12,
      "name": "Rock_Stone"
    },
    {
      "x": 4,
      "y": 7,
      "z": 12,
      "name": "Rock_Stone"
    },
    {
      "x": 4,
      "y": 8,
      "z": 12,
      "name": "Rock_Stone"
    },
    {
      "x": 4,
      "y": 9,
      "z": 12,
      "name": "Rock_Stone"
    }
  ]
}