{
  "version": 8,
  "blockIdVersion": 8,
  "anchorX": 1,
  "anchorY": 9,
  "anchorZ": 1,
  "blocks": [
    {
      "x": -7,
      "y": 8,
      "z": 0,
      "name": "Rock_Basalt_Cobble"
    },
    {
      "x": -7,
      "y": 9,
      "z": 0,
      "name": "Rock_Basalt_Brick"
    },
    {
      "x": -7,
      "y": 10,
      "z": 0,
      "name": "Rock_Basalt_Brick"
    },
    {
      "x": -7,
      "y": 11,
      "z": 0,
      "name": "Rock_Basalt_Brick"
    },
    {
      "x": -7,
      "y": 12,
      "z": 0,
      "name": "Rock_Basalt_Brick"
    },
    {
      "x": -7,
      "y": 13,
      "z": 0,
      "name": "Wood_Deadwood_Roof_Flat"
    },
    {
      "x": -7,
      "y": 6,
      "z": 1,
      "name": "Rock_Basalt_Cobble"
    },
    {
      "x": -7,
      "y": 7,
      "z": 1,
      "name": "Rock_Basalt_Cobble"
    },
    {
      "x": -7,
      "y": 8,
      "z": 1,
      "name": "Rock_Basalt_Cobble"
    },
    {
      "x": -7,
      "y": 9,
      "z": 1,
      "name": "Rock_Basalt_Brick"
    },
    {
      "x": -7,
      "y": 10,
      "z": 1,
      "name": "Rock_Basalt_Cobble"
    },
    {
      "x": -7,
      "y": 11,
      "z": 1,
      "name": "Rock_Basalt_Cobble"
    },
    {
      "x": -7,
      "y": 12,
      "z": 1,
      "name": "Rock_Basalt_Cobble"
    },
    {
      "x": -7,
      "y": 13,
      "z": 1,
      "name": "Wood_Deadwood_Roof_Flat"
    },
    {
      "x": -7,
      "y": 6,
      "z": 2,
      "name": "Rock_Basalt"
    },
    {
      "x": -7,
      "y": 7,
      "z": 2,
      "name": "Rock_Basalt_Cobble"
    },
    {
      "x": -7,
      "y": 8,
      "z": 2,
      "name": "Rock_Basalt_Cobble"
    },
    {
      "x": -7,
      "y": 9,
      "z": 2,
      "name": "Rock_Basalt_Brick"
    },
    {
      "x": -7,
      "y": 10,
      "z": 2,
      "name": "Rock_Basalt_Cobble"
    },
    {
      "x": -7,
      "y": 11,
      "z": 2,
      "name": "Rock_Basalt_Cobble"
    },
    {
      "x": -7,
      "y": 12,
      "z": 2,
      "name": "Rock_Basalt_Cobble"
    },
    {
      "x": -7,
      "y": 13,
      "z": 2,
      "name": "Wood_Deadwood_Roof_Flat"
    },
    {
      "x": -7,
      "y": 6,
      "z": 3,
      "name": "Rock_Basalt"
    },
    {
      "x": -7,
      "y": 7,
      "z": 3,
      "name": "Rock_Basalt_Cobble"
    },
    {
      "x": -7,
      "y": 8,
      "z": 3,
      "name": "Rock_Basalt_Cobble"
    },
    {
      "x": -7,
      "y": 9,
      "z": 3,
      "name": "Rock_Basalt_Brick"
    },
    {
      "x": -7,
      "y": 10,
      "z": 3,
      "name": "Rock_Basalt_Cobble"
    },
    {
      "x": -7,
      "y": 11,
      "z": 3,
      "name": "Rock_Basalt_Cobble"
    },
    {
      "x": -7,
      "y": 12,
      "z": 3,
      "name": "Rock_Basalt_Cobble"
    },
    {
      "x": -7,
      "y": 13,
      "z": 3,
      "name": "Wood_Deadwood_Roof_Flat"
    },
    {
      "x": -7,
      "y": 8,
      "z": 4,
      "name": "Rock_Basalt_Cobble"
    },
    {
      "x": -7,
      "y": 9,
      "z": 4,
      "name": "Rock_Basalt_Brick"
    },
    {
      "x": -7,
      "y": 10,
      "z": 4,
      "name": "Rock_Basalt_Brick"
    },
    {
      "x": -7,
      "y": 11,
      "z": 4,
      "name": "Rock_Basalt_Brick"
    },
    {
      "x": -7,
      "y": 12,
      "z": 4,
      "name": "Rock_Basalt_Brick"
    },
    {
      "x": -7,
      "y": 13,
      "z": 4,
      "name": "Wood_Deadwood_Roof_Flat"
    },
    {
      "x": -6,
      "y": 7,
      "z": 0,
      "name": "Rock_Basalt_Cobble"
    },
    {
      "x": -6,
      "y": 8,
      "z": 0,
      "name": "Rock_Basalt_Cobble"
    },
    {
      "x": -6,
      "y": 9,
      "z": 0,
      "name": "Rock_Basalt_Brick"
    },
    {
      "x": -6,
      "y": 10,
      "z": 0,
      "name": "Rock_Basalt_Cobble"
    },
    {
      "x": -6,
      "y": 11,
      "z": 0,
      "name": "Rock_Basalt_Cobble"
    },
    {
      "x": -6,
      "y": 12,
      "z": 0,
      "name": "Rock_Basalt_Cobble"
    },
    {
      "x": -6,
      "y": 13,
      "z": 0,
      "name": "Wood_Deadwood_Roof_Flat"
    },
    {
      "x": -6,
      "y": 6,
      "z": 1,
      "name": "Rock_Basalt_Cobble"
    },
    {
      "x": -6,
      "y": 7,
      "z": 1,
      "name": "Rock_Basalt_Cobble"
    },
    {
      "x": -6,
      "y": 8,
      "z": 1,
      "name": "Rock_Basalt_Cobble"
    },
    {
      "x": -6,
      "y": 9,
      "z": 1,
      "name": "Wood_Deadwood_Planks"
    },
    {
      "x": -6,
      "y": 10,
      "z": 1,
      "name": "Furniture_Ancient_Barrel"
    },
    {
      "x": -6,
      "y": 11,
      "z": 1,
      "name": "Empty"
    },
    {
      "x": -6,
      "y": 12,
      "z": 1,
      "name": "Empty"
    },
    {
      "x": -6,
      "y": 13,
      "z": 1,
      "name": "Wood_Deadwood_Roof_Flat"
    },
    {
      "x": -6,
      "y": 5,
      "z": 2,
      "name": "Rock_Basalt"
    },
    {
      "x": -6,
      "y": 6,
      "z": 2,
      "name": "Rock_Basalt_Cobble"
    },
    {
      "x": -6,
      "y": 7,
      "z": 2,
      "name": "Rock_Basalt_Cobble"
    },
    {
      "x": -6,
      "y": 8,
      "z": 2,
      "name": "Rock_Basalt_Cobble"
    },
    {
      "x": -6,
      "y": 9,
      "z": 2,
      "name": "Wood_Deadwood_Planks"
    },
    {
      "x": -6,
      "y": 10,
      "z": 2,
      "name": "Furniture_Ancient_Crate",
      "rotation": 1
    },
    {
      "x": -6,
      "y": 11,
      "z": 2,
      "name": "Furniture_Human_Ruins_Pot_Small"
    },
    {
      "x": -6,
      "y": 12,
      "z": 2,
      "name": "Empty"
    },
    {
      "x": -6,
      "y": 13,
      "z": 2,
      "name": "Wood_Deadwood_Roof_Flat"
    },
    {
      "x": -6,
      "y": 5,
      "z": 3,
      "name": "Rock_Basalt"
    },
    {
      "x": -6,
      "y": 6,
      "z": 3,
      "name": "Rock_Basalt_Cobble"
    },
    {
      "x": -6,
      "y": 7,
      "z": 3,
      "name": "Rock_Basalt_Cobble"
    },
    {
      "x": -6,
      "y": 8,
      "z": 3,
      "name": "Rock_Basalt_Cobble"
    },
    {
      "x": -6,
      "y": 9,
      "z": 3,
      "name": "Wood_Deadwood_Planks"
    },
    {
      "x": -6,
      "y": 10,
      "z": 3,
      "name": "Furniture_Ancient_Crate",
      "rotation": 1
    },
    {
      "x": -6,
      "y": 11,
      "z": 3,
      "name": "Furniture_Ancient_Crate",
      "rotation": 1
    },
    {
      "x": -6,
      "y": 12,
      "z": 3,
      "name": "Empty"
    },
    {
      "x": -6,
      "y": 13,
      "z": 3,
      "name": "Wood_Deadwood_Roof_Flat"
    },
    {
      "x": -6,
      "y": 5,
      "z": 4,
      "name": "Rock_Basalt"
    },
    {
      "x": -6,
      "y": 6,
      "z": 4,
      "name": "Rock_Basalt_Cobble"
    },
    {
      "x": -6,
      "y": 7,
      "z": 4,
      "name": "Rock_Basalt_Cobble"
    },
    {
      "x": -6,
      "y": 8,
      "z": 4,
      "name": "Rock_Basalt_Cobble"
    },
    {
      "x": -6,
      "y": 9,
      "z": 4,
      "name": "Rock_Basalt_Brick"
    },
    {
      "x": -6,
      "y": 10,
      "z": 4,
      "name": "Rock_Basalt_Cobble"
    },
    {
      "x": -6,
      "y": 11,
      "z": 4,
      "name": "Rock_Basalt_Cobble"
    },
    {
      "x": -6,
      "y": 12,
      "z": 4,
      "name": "Rock_Basalt_Cobble"
    },
    {
      "x": -6,
      "y": 13,
      "z": 4,
      "name": "Wood_Deadwood_Roof_Flat"
    },
    {
      "x": -5,
      "y": 7,
      "z": -5,
      "name": "Rock_Basalt_Cobble"
    },
    {
      "x": -5,
      "y": 8,
      "z": -5,
      "name": "Rock_Basalt_Cobble"
    },
    {
      "x": -5,
      "y": 9,
      "z": -5,
      "name": "Rock_Basalt_Cobble"
    },
    {
      "x": -5,
      "y": 10,
      "z": -5,
      "name": "Rock_Basalt_Cobble"
    },
    {
      "x": -5,
      "y": 6,
      "z": -4,
      "name": "Rock_Basalt_Cobble"
    },
    {
      "x": -5,
      "y": 7,
      "z": -4,
      "name": "Rock_Basalt_Cobble"
    },
    {
      "x": -5,
      "y": 8,
      "z": -4,
      "name": "Rock_Basalt_Cobble"
    },
    {
      "x": -5,
      "y": 9,
      "z": -4,
      "name": "Rock_Basalt_Cobble"
    },
    {
      "x": -5,
      "y": 10,
      "z": -4,
      "name": "Rock_Basalt_Cobble"
    },
    {
      "x": -5,
      "y": 7,
      "z": -3,
      "name": "Rock_Basalt_Cobble"
    },
    {
      "x": -5,
      "y": 8,
      "z": -3,
      "name": "Rock_Basalt_Cobble"
    },
    {
      "x": -5,
      "y": 9,
      "z": -3,
      "name": "Rock_Basalt_Cobble"
    },
    {
      "x": -5,
      "y": 10,
      "z": -3,
      "name": "Rock_Basalt_Cobble_Half",
      "rotation": 7
    },
    {
      "x": -5,
      "y": 8,
      "z": -2,
      "name": "Rock_Basalt_Cobble"
    },
    {
      "x": -5,
      "y": 9,
      "z": -2,
      "name": "Rock_Basalt_Cobble"
    },
    {
      "x": -5,
      "y": 7,
      "z": -1,
      "name": "Rock_Basalt_Cobble"
    },
    {
      "x": -5,
      "y": 8,
      "z": -1,
      "name": "Rock_Basalt_Cobble"
    },
    {
      "x": -5,
      "y": 9,
      "z": -1,
      "name": "Rock_Basalt_Cobble"
    },
    {
      "x": -5,
      "y": 10,
      "z": -1,
      "name": "Rock_Basalt_Cobble_Half",
      "rotation": 7
    },
    {
      "x": -5,
      "y": 6,
      "z": 0,
      "name": "Rock_Basalt_Cobble"
    },
    {
      "x": -5,
      "y": 7,
      "z": 0,
      "name": "Rock_Basalt_Cobble"
    },
    {
      "x": -5,
      "y": 8,
      "z": 0,
      "name": "Rock_Basalt_Cobble"
    },
    {
      "x": -5,
      "y": 9,
      "z": 0,
      "name": "Rock_Basalt_Brick"
    },
    {
      "x": -5,
      "y": 10,
      "z": 0,
      "name": "Rock_Basalt_Cobble"
    },
    {
      "x": -5,
      "y": 11,
      "z": 0,
      "name": "Rock_Basalt_Cobble"
    },
    {
      "x": -5,
      "y": 12,
      "z": 0,
      "name": "Rock_Basalt_Cobble"
    },
    {
      "x": -5,
      "y": 13,
      "z": 0,
      "name": "Wood_Deadwood_Roof_Flat"
    },
    {
      "x": -5,
      "y": 5,
      "z": 1,
      "name": "Rock_Basalt"
    },
    {
      "x": -5,
      "y": 6,
      "z": 1,
      "name": "Rock_Basalt_Cobble"
    },
    {
      "x": -5,
      "y": 7,
      "z": 1,
      "name": "Rock_Basalt_Cobble"
    },
    {
      "x": -5,
      "y": 8,
      "z": 1,
      "name": "Rock_Basalt_Cobble"
    },
    {
      "x": -5,
      "y": 9,
      "z": 1,
      "name": "Wood_Deadwood_Planks"
    },
    {
      "x": -5,
      "y": 10,
      "z": 1,
      "name": "Empty"
    },
    {
      "x": -5,
      "y": 11,
      "z": 1,
      "name": "Empty"
    },
    {
      "x": -5,
      "y": 12,
      "z": 1,
      "name": "Empty"
    },
    {
      "x": -5,
      "y": 13,
      "z": 1,
      "name": "Wood_Deadwood_Roof_Flat"
    },
    {
      "x": -5,
      "y": 4,
      "z": 2,
      "name": "Rock_Basalt"
    },
    {
      "x": -5,
      "y": 5,
      "z": 2,
      "name": "Rock_Basalt"
    },
    {
      "x": -5,
      "y": 6,
      "z": 2,
      "name": "Rock_Basalt_Cobble"
    },
    {
      "x": -5,
      "y": 7,
      "z": 2,
      "name": "Rock_Basalt_Cobble"
    },
    {
      "x": -5,
      "y": 8,
      "z": 2,
      "name": "Rock_Basalt_Cobble"
    },
    {
      "x": -5,
      "y": 9,
      "z": 2,
      "name": "Wood_Deadwood_Planks"
    },
    {
      "x": -5,
      "y": 10,
      "z": 2,
      "name": "Empty"
    },
    {
      "x": -5,
      "y": 11,
      "z": 2,
      "name": "Empty"
    },
    {
      "x": -5,
      "y": 12,
      "z": 2,
      "name": "Empty"
    },
    {
      "x": -5,
      "y": 13,
      "z": 2,
      "name": "Wood_Deadwood_Roof_Flat"
    },
    {
      "x": -5,
      "y": 3,
      "z": 3,
      "name": "Rock_Basalt"
    },
    {
      "x": -5,
      "y": 4,
      "z": 3,
      "name": "Rock_Basalt"
    },
    {
      "x": -5,
      "y": 5,
      "z": 3,
      "name": "Rock_Basalt"
    },
    {
      "x": -5,
      "y": 6,
      "z": 3,
      "name": "Rock_Basalt_Cobble"
    },
    {
      "x": -5,
      "y": 7,
      "z": 3,
      "name": "Rock_Basalt_Cobble"
    },
    {
      "x": -5,
      "y": 8,
      "z": 3,
      "name": "Rock_Basalt_Cobble"
    },
    {
      "x": -5,
      "y": 9,
      "z": 3,
      "name": "Wood_Deadwood_Planks"
    },
    {
      "x": -5,
      "y": 10,
      "z": 3,
      "name": "Furniture_Ancient_Barrel"
    },
    {
      "x": -5,
      "y": 11,
      "z": 3,
      "name": "Empty"
    },
    {
      "x": -5,
      "y": 12,
      "z": 3,
      "name": "Empty"
    },
    {
      "x": -5,
      "y": 13,
      "z": 3,
      "name": "Wood_Deadwood_Roof_Flat"
    },
    {
      "x": -5,
      "y": 5,
      "z": 4,
      "name": "Rock_Basalt"
    },
    {
      "x": -5,
      "y": 6,
      "z": 4,
      "name": "Rock_Basalt_Cobble"
    },
    {
      "x": -5,
      "y": 7,
      "z": 4,
      "name": "Rock_Basalt_Cobble"
    },
    {
      "x": -5,
      "y": 8,
      "z": 4,
      "name": "Rock_Basalt_Cobble"
    },
    {
      "x": -5,
      "y": 9,
      "z": 4,
      "name": "Rock_Basalt_Cobble"
    },
    {
      "x": -5,
      "y": 10,
      "z": 4,
      "name": "Rock_Basalt_Cobble"
    },
    {
      "x": -5,
      "y": 11,
      "z": 4,
      "name": "Rock_Basalt_Cobble"
    },
    {
      "x": -5,
      "y": 12,
      "z": 4,
      "name": "Rock_Basalt_Cobble"
    },
    {
      "x": -5,
      "y": 13,
      "z": 4,
      "name": "Wood_Deadwood_Roof_Flat"
    },
    {
      "x": -5,
      "y": 5,
      "z": 5,
      "name": "Rock_Basalt"
    },
    {
      "x": -5,
      "y": 6,
      "z": 5,
      "name": "Rock_Basalt_Cobble"
    },
    {
      "x": -5,
      "y": 7,
      "z": 5,
      "name": "Rock_Basalt_Cobble"
    },
    {
      "x": -5,
      "y": 8,
      "z": 5,
      "name": "Rock_Basalt_Cobble"
    },
    {
      "x": -5,
      "y": 9,
      "z": 5,
      "name": "Rock_Basalt_Brick"
    },
    {
      "x": -5,
      "y": 10,
      "z": 5,
      "name": "Rock_Basalt_Cobble"
    },
    {
      "x": -5,
      "y": 8,
      "z": 6,
      "name": "Rock_Basalt_Cobble"
    },
    {
      "x": -5,
      "y": 9,
      "z": 6,
      "name": "Rock_Basalt_Cobble"
    },
    {
      "x": -5,
      "y": 10,
      "z": 6,
      "name": "Rock_Basalt_Cobble_Half",
      "rotation": 7
    },
    {
      "x": -4,
      "y": 7,
      "z": -6,
      "name": "Rock_Basalt_Cobble"
    },
    {
      "x": -4,
      "y": 8,
      "z": -6,
      "name": "Rock_Basalt_Cobble"
    },
    {
      "x": -4,
      "y": 9,
      "z": -6,
      "name": "Rock_Basalt_Cobble"
    },
    {
      "x": -4,
      "y": 10,
      "z": -6,
      "name": "Rock_Basalt_Cobble"
    },
    {
      "x": -4,
      "y": 11,
      "z": -6,
      "name": "Wood_Deadwood_Planks_Half",
      "rotation": 6
    },
    {
      "x": -4,
      "y": 12,
      "z": -6,
      "name": "Rock_Basalt_Brick_Half",
      "rotation": 6
    },
    {
      "x": -4,
      "y": 13,
      "z": -6,
      "name": "Rock_Basalt_Brick_Half",
      "rotation": 6
    },
    {
      "x": -4,
      "y": 14,
      "z": -6,
      "name": "Rock_Basalt_Brick_Half",
      "rotation": 6
    },
    {
      "x": -4,
      "y": 15,
      "z": -6,
      "name": "Wood_Blackwood_Roof",
      "rotation": 3
    },
    {
      "x": -4,
      "y": 4,
      "z": -5,
      "name": "Rock_Basalt"
    },
    {
      "x": -4,
      "y": 5,
      "z": -5,
      "name": "Rock_Basalt"
    },
    {
      "x": -4,
      "y": 6,
      "z": -5,
      "name": "Rock_Basalt_Cobble"
    },
    {
      "x": -4,
      "y": 7,
      "z": -5,
      "name": "Rock_Basalt_Cobble"
    },
    {
      "x": -4,
      "y": 8,
      "z": -5,
      "name": "Rock_Basalt_Cobble"
    },
    {
      "x": -4,
      "y": 9,
      "z": -5,
      "name": "Rock_Basalt_Brick"
    },
    {
      "x": -4,
      "y": 10,
      "z": -5,
      "name": "Rock_Basalt_Cobble"
    },
    {
      "x": -4,
      "y": 11,
      "z": -5,
      "name": "Wood_Deadwood_Planks"
    },
    {
      "x": -4,
      "y": 12,
      "z": -5,
      "name": "Rock_Basalt_Brick"
    },
    {
      "x": -4,
      "y": 13,
      "z": -5,
      "name": "Rock_Basalt_Brick"
    },
    {
      "x": -4,
      "y": 14,
      "z": -5,
      "name": "Rock_Basalt_Brick"
    },
    {
      "x": -4,
      "y": 15,
      "z": -5,
      "name": "Wood_Blackwood_Roof",
      "rotation": 3
    },
    {
      "x": -4,
      "y": 3,
      "z": -4,
      "name": "Rock_Basalt"
    },
    {
      "x": -4,
      "y": 4,
      "z": -4,
      "name": "Rock_Basalt"
    },
    {
      "x": -4,
      "y": 5,
      "z": -4,
      "name": "Rock_Basalt"
    },
    {
      "x": -4,
      "y": 6,
      "z": -4,
      "name": "Rock_Basalt_Cobble"
    },
    {
      "x": -4,
      "y": 7,
      "z": -4,
      "name": "Rock_Basalt_Cobble"
    },
    {
      "x": -4,
      "y": 8,
      "z": -4,
      "name": "Rock_Basalt_Cobble"
    },
    {
      "x": -4,
      "y": 9,
      "z": -4,
      "name": "Rock_Basalt_Brick"
    },
    {
      "x": -4,
      "y": 10,
      "z": -4,
      "name": "Rock_Basalt_Cobble"
    },
    {
      "x": -4,
      "y": 11,
      "z": -4,
      "name": "Wood_Deadwood_Planks"
    },
    {
      "x": -4,
      "y": 12,
      "z": -4,
      "name": "Rock_Basalt_Brick"
    },
    {
      "x": -4,
      "y": 13,
      "z": -4,
      "name": "Rock_Basalt_Brick"
    },
    {
      "x": -4,
      "y": 14,
      "z": -4,
      "name": "Rock_Basalt_Brick"
    },
    {
      "x": -4,
      "y": 15,
      "z": -4,
      "name": "Wood_Blackwood_Roof",
      "rotation": 3
    },
    {
      "x": -4,
      "y": 4,
      "z": -3,
      "name": "Rock_Basalt"
    },
    {
      "x": -4,
      "y": 5,
      "z": -3,
      "name": "Rock_Basalt"
    },
    {
      "x": -4,
      "y": 6,
      "z": -3,
      "name": "Rock_Basalt_Cobble"
    },
    {
      "x": -4,
      "y": 7,
      "z": -3,
      "name": "Rock_Basalt_Cobble"
    },
    {
      "x": -4,
      "y": 8,
      "z": -3,
      "name": "Rock_Basalt_Cobble"
    },
    {
      "x": -4,
      "y": 9,
      "z": -3,
      "name": "Rock_Basalt_Brick"
    },
    {
      "x": -4,
      "y": 10,
      "z": -3,
      "name": "Rock_Basalt_Cobble"
    },
    {
      "x": -4,
      "y": 11,
      "z": -3,
      "name": "Wood_Deadwood_Planks"
    },
    {
      "x": -4,
      "y": 12,
      "z": -3,
      "name": "Rock_Basalt_Brick"
    },
    {
      "x": -4,
      "y": 7,
      "z": -2,
      "name": "Rock_Basalt_Cobble"
    },
    {
      "x": -4,
      "y": 8,
      "z": -2,
      "name": "Rock_Basalt_Cobble"
    },
    {
      "x": -4,
      "y": 9,
      "z": -2,
      "name": "Rock_Basalt_Brick"
    },
    {
      "x": -4,
      "y": 10,
      "z": -2,
      "name": "Rock_Basalt_Cobble"
    },
    {
      "x": -4,
      "y": 11,
      "z": -2,
      "name": "Wood_Deadwood_Planks"
    },
    {
      "x": -4,
      "y": 6,
      "z": -1,
      "name": "Rock_Basalt_Cobble"
    },
    {
      "x": -4,
      "y": 7,
      "z": -1,
      "name": "Rock_Basalt_Cobble"
    },
    {
      "x": -4,
      "y": 8,
      "z": -1,
      "name": "Rock_Basalt_Cobble"
    },
    {
      "x": -4,
      "y": 9,
      "z": -1,
      "name": "Rock_Basalt_Brick"
    },
    {
      "x": -4,
      "y": 10,
      "z": -1,
      "name": "Rock_Basalt_Cobble"
    },
    {
      "x": -4,
      "y": 11,
      "z": -1,
      "name": "Wood_Deadwood_Planks"
    },
    {
      "x": -4,
      "y": 12,
      "z": -1,
      "name": "Rock_Basalt_Brick"
    },
    {
      "x": -4,
      "y": 13,
      "z": -1,
      "name": "Rock_Basalt_Brick"
    },
    {
      "x": -4,
      "y": 6,
      "z": 0,
      "name": "Rock_Basalt_Cobble"
    },
    {
      "x": -4,
      "y": 7,
      "z": 0,
      "name": "Rock_Basalt_Cobble"
    },
    {
      "x": -4,
      "y": 8,
      "z": 0,
      "name": "Rock_Basalt_Cobble"
    },
    {
      "x": -4,
      "y": 9,
      "z": 0,
      "name": "Rock_Basalt_Brick"
    },
    {
      "x": -4,
      "y": 10,
      "z": 0,
      "name": "Rock_Basalt_Cobble"
    },
    {
      "x": -4,
      "y": 11,
      "z": 0,
      "name": "Wood_Deadwood_Planks"
    },
    {
      "x": -4,
      "y": 12,
      "z": 0,
      "name": "Rock_Basalt_Cobble"
    },
    {
      "x": -4,
      "y": 13,
      "z": 0,
      "name": "Rock_Basalt_Cobble"
    },
    {
      "x": -4,
      "y": 14,
      "z": 0,
      "name": "Rock_Basalt_Cobble"
    },
    {
      "x": -4,
      "y": 5,
      "z": 1,
      "name": "Rock_Basalt"
    },
    {
      "x": -4,
      "y": 6,
      "z": 1,
      "name": "Rock_Basalt_Cobble"
    },
    {
      "x": -4,
      "y": 7,
      "z": 1,
      "name": "Rock_Basalt_Cobble"
    },
    {
      "x": -4,
      "y": 8,
      "z": 1,
      "name": "Rock_Basalt_Cobble"
    },
    {
      "x": -4,
      "y": 9,
      "z": 1,
      "name": "Rock_Basalt_Brick"
    },
    {
      "x": -4,
      "y": 10,
      "z": 1,
      "name": "Empty"
    },
    {
      "x": -4,
      "y": 11,
      "z": 1,
      "name": "Empty"
    },
    {
      "x": -4,
      "y": 12,
      "z": 1,
      "name": "Wood_Deadwood_Planks_Half",
      "rotation": 8
    },
    {
      "x": -4,
      "y": 13,
      "z": 1,
      "name": "Rock_Basalt_Cobble"
    },
    {
      "x": -4,
      "y": 14,
      "z": 1,
      "name": "Rock_Basalt_Cobble"
    },
    {
      "x": -4,
      "y": 15,
      "z": 1,
      "name": "Wood_Blackwood_Roof",
      "rotation": 3
    },
    {
      "x": -4,
      "y": 3,
      "z": 2,
      "name": "Rock_Basalt"
    },
    {
      "x": -4,
      "y": 4,
      "z": 2,
      "name": "Rock_Basalt"
    },
    {
      "x": -4,
      "y": 5,
      "z": 2,
      "name": "Rock_Basalt"
    },
    {
      "x": -4,
      "y": 6,
      "z": 2,
      "name": "Rock_Basalt_Cobble"
    },
    {
      "x": -4,
      "y": 7,
      "z": 2,
      "name": "Rock_Basalt_Cobble"
    },
    {
      "x": -4,
      "y": 8,
      "z": 2,
      "name": "Rock_Basalt_Cobble"
    },
    {
      "x": -4,
      "y": 9,
      "z": 2,
      "name": "Rock_Basalt_Brick"
    },
    {
      "x": -4,
      "y": 10,
      "z": 2,
      "name": "Empty"
    },
    {
      "x": -4,
      "y": 11,
      "z": 2,
      "name": "Empty"
    },
    {
      "x": -4,
      "y": 12,
      "z": 2,
      "name": "Wood_Deadwood_Planks_Half",
      "rotation": 8
    },
    {
      "x": -4,
      "y": 13,
      "z": 2,
      "name": "Rock_Basalt_Brick"
    },
    {
      "x": -4,
      "y": 14,
      "z": 2,
      "name": "Rock_Basalt_Brick"
    },
    {
      "x": -4,
      "y": 15,
      "z": 2,
      "name": "Wood_Blackwood_Roof",
      "rotation": 3
    },
    {
      "x": -4,
      "y": 3,
      "z": 3,
      "name": "Rock_Basalt"
    },
    {
      "x": -4,
      "y": 4,
      "z": 3,
      "name": "Rock_Basalt"
    },
    {
      "x": -4,
      "y": 5,
      "z": 3,
      "name": "Rock_Basalt"
    },
    {
      "x": -4,
      "y": 6,
      "z": 3,
      "name": "Rock_Basalt_Cobble"
    },
    {
      "x": -4,
      "y": 7,
      "z": 3,
      "name": "Rock_Basalt_Cobble"
    },
    {
      "x": -4,
      "y": 8,
      "z": 3,
      "name": "Rock_Basalt_Cobble"
    },
    {
      "x": -4,
      "y": 9,
      "z": 3,
      "name": "Rock_Basalt_Brick"
    },
    {
      "x": -4,
      "y": 10,
      "z": 3,
      "name": "Empty"
    },
    {
      "x": -4,
      "y": 11,
      "z": 3,
      "name": "Empty"
    },
    {
      "x": -4,
      "y": 12,
      "z": 3,
      "name": "Wood_Deadwood_Planks_Half",
      "rotation": 8
    },
    {
      "x": -4,
      "y": 13,
      "z": 3,
      "name": "Rock_Basalt_Cobble"
    },
    {
      "x": -4,
      "y": 14,
      "z": 3,
      "name": "Rock_Basalt_Cobble"
    },
    {
      "x": -4,
      "y": 15,
      "z": 3,
      "name": "Wood_Blackwood_Roof",
      "rotation": 3
    },
    {
      "x": -4,
      "y": 2,
      "z": 4,
      "name": "Rock_Basalt"
    },
    {
      "x": -4,
      "y": 3,
      "z": 4,
      "name": "Rock_Basalt"
    },
    {
      "x": -4,
      "y": 4,
      "z": 4,
      "name": "Rock_Basalt"
    },
    {
      "x": -4,
      "y": 5,
      "z": 4,
      "name": "Rock_Basalt"
    },
    {
      "x": -4,
      "y": 6,
      "z": 4,
      "name": "Rock_Basalt_Cobble"
    },
    {
      "x": -4,
      "y": 7,
      "z": 4,
      "name": "Rock_Basalt_Cobble"
    },
    {
      "x": -4,
      "y": 8,
      "z": 4,
      "name": "Rock_Basalt_Cobble"
    },
    {
      "x": -4,
      "y": 9,
      "z": 4,
      "name": "Rock_Basalt_Brick"
    },
    {
      "x": -4,
      "y": 10,
      "z": 4,
      "name": "Rock_Basalt_Cobble"
    },
    {
      "x": -4,
      "y": 11,
      "z": 4,
      "name": "Wood_Deadwood_Planks"
    },
    {
      "x": -4,
      "y": 12,
      "z": 4,
      "name": "Rock_Basalt_Brick"
    },
    {
      "x": -4,
      "y": 13,
      "z": 4,
      "name": "Rock_Basalt_Brick"
    },
    {
      "x": -4,
      "y": 14,
      "z": 4,
      "name": "Rock_Basalt_Cobble"
    },
    {
      "x": -4,
      "y": 15,
      "z": 4,
      "name": "Wood_Blackwood_Roof",
      "rotation": 3
    },
    {
      "x": -4,
      "y": 3,
      "z": 5,
      "name": "Rock_Basalt"
    },
    {
      "x": -4,
      "y": 4,
      "z": 5,
      "name": "Rock_Basalt"
    },
    {
      "x": -4,
      "y": 5,
      "z": 5,
      "name": "Rock_Basalt"
    },
    {
      "x": -4,
      "y": 6,
      "z": 5,
      "name": "Rock_Basalt_Cobble"
    },
    {
      "x": -4,
      "y": 7,
      "z": 5,
      "name": "Rock_Basalt_Cobble"
    },
    {
      "x": -4,
      "y": 8,
      "z": 5,
      "name": "Rock_Basalt_Cobble"
    },
    {
      "x": -4,
      "y": 9,
      "z": 5,
      "name": "Rock_Basalt_Brick"
    },
    {
      "x": -4,
      "y": 10,
      "z": 5,
      "name": "Rock_Basalt_Cobble"
    },
    {
      "x": -4,
      "y": 11,
      "z": 5,
      "name": "Wood_Deadwood_Planks"
    },
    {
      "x": -4,
      "y": 12,
      "z": 5,
      "name": "Rock_Basalt_Brick"
    },
    {
      "x": -4,
      "y": 13,
      "z": 5,
      "name": "Rock_Basalt_Brick"
    },
    {
      "x": -4,
      "y": 14,
      "z": 5,
      "name": "Rock_Basalt_Brick"
    },
    {
      "x": -4,
      "y": 15,
      "z": 5,
      "name": "Wood_Blackwood_Roof",
      "rotation": 3
    },
    {
      "x": -4,
      "y": 5,
      "z": 6,
      "name": "Rock_Basalt"
    },
    {
      "x": -4,
      "y": 6,
      "z": 6,
      "name": "Rock_Basalt_Cobble"
    },
    {
      "x": -4,
      "y": 7,
      "z": 6,
      "name": "Rock_Basalt_Cobble"
    },
    {
      "x": -4,
      "y": 8,
      "z": 6,
      "name": "Rock_Basalt_Cobble"
    },
    {
      "x": -4,
      "y": 9,
      "z": 6,
      "name": "Rock_Basalt_Brick"
    },
    {
      "x": -4,
      "y": 10,
      "z": 6,
      "name": "Rock_Basalt_Cobble"
    },
    {
      "x": -4,
      "y": 11,
      "z": 6,
      "name": "Wood_Deadwood_Planks"
    },
    {
      "x": -4,
      "y": 12,
      "z": 6,
      "name": "Rock_Basalt_Brick"
    },
    {
      "x": -4,
      "y": 13,
      "z": 6,
      "name": "Rock_Basalt_Brick"
    },
    {
      "x": -4,
      "y": 14,
      "z": 6,
      "name": "Rock_Basalt_Brick"
    },
    {
      "x": -4,
      "y": 15,
      "z": 6,
      "name": "*Wood_Blackwood_Roof_State_Definitions_Corner_Right"
    },
    {
      "x": -4,
      "y": 7,
      "z": 7,
      "name": "Rock_Basalt_Cobble"
    },
    {
      "x": -4,
      "y": 8,
      "z": 7,
      "name": "Rock_Basalt_Cobble"
    },
    {
      "x": -4,
      "y": 9,
      "z": 7,
      "name": "Rock_Basalt_Cobble"
    },
    {
      "x": -4,
      "y": 10,
      "z": 7,
      "name": "Rock_Basalt_Cobble"
    },
    {
      "x": -3,
      "y": 5,
      "z": -6,
      "name": "Rock_Basalt"
    },
    {
      "x": -3,
      "y": 6,
      "z": -6,
      "name": "Rock_Basalt"
    },
    {
      "x": -3,
      "y": 7,
      "z": -6,
      "name": "Rock_Basalt_Cobble"
    },
    {
      "x": -3,
      "y": 8,
      "z": -6,
      "name": "Rock_Basalt_Cobble"
    },
    {
      "x": -3,
      "y": 9,
      "z": -6,
      "name": "Rock_Basalt_Cobble"
    },
    {
      "x": -3,
      "y": 10,
      "z": -6,
      "name": "Rock_Basalt_Cobble_Half",
      "rotation": 6
    },
    {
      "x": -3,
      "y": 11,
      "z": -6,
      "name": "Wood_Deadwood_Planks_Half",
      "rotation": 6
    },
    {
      "x": -3,
      "y": 14,
      "z": -6,
      "name": "Wood_Deadwood_Planks_Half",
      "rotation": 6
    },
    {
      "x": -3,
      "y": 15,
      "z": -6,
      "name": "Wood_Blackwood_Planks_Half",
      "rotation": 8
    },
    {
      "x": -3,
      "y": 16,
      "z": -6,
      "name": "Wood_Blackwood_Roof",
      "rotation": 3
    },
    {
      "x": -3,
      "y": 3,
      "z": -5,
      "name": "Rock_Basalt"
    },
    {
      "x": -3,
      "y": 4,
      "z": -5,
      "name": "Rock_Basalt"
    },
    {
      "x": -3,
      "y": 5,
      "z": -5,
      "name": "Rock_Basalt"
    },
    {
      "x": -3,
      "y": 6,
      "z": -5,
      "name": "Rock_Basalt_Cobble"
    },
    {
      "x": -3,
      "y": 7,
      "z": -5,
      "name": "Rock_Basalt_Cobble"
    },
    {
      "x": -3,
      "y": 8,
      "z": -5,
      "name": "Rock_Basalt_Cobble"
    },
    {
      "x": -3,
      "y": 9,
      "z": -5,
      "name": "Rock_Basalt_Brick"
    },
    {
      "x": -3,
      "y": 10,
      "z": -5,
      "name": "Rock_Basalt_Cobble"
    },
    {
      "x": -3,
      "y": 11,
      "z": -5,
      "name": "Wood_Deadwood_Planks"
    },
    {
      "x": -3,
      "y": 12,
      "z": -5,
      "name": "Wood_Deadwood_Decorative"
    },
    {
      "x": -3,
      "y": 13,
      "z": -5,
      "name": "Wood_Deadwood_Decorative"
    },
    {
      "x": -3,
      "y": 14,
      "z": -5,
      "name": "Wood_Deadwood_Ornate"
    },
    {
      "x": -3,
      "y": 15,
      "z": -5,
      "name": "Rock_Basalt_Brick"
    },
    {
      "x": -3,
      "y": 16,
      "z": -5,
      "name": "Wood_Blackwood_Roof",
      "rotation": 3
    },
    {
      "x": -3,
      "y": 1,
      "z": -4,
      "name": "Rock_Basalt"
    },
    {
      "x": -3,
      "y": 2,
      "z": -4,
      "name": "Rock_Basalt"
    },
    {
      "x": -3,
      "y": 3,
      "z": -4,
      "name": "Rock_Basalt"
    },
    {
      "x": -3,
      "y": 4,
      "z": -4,
      "name": "Rock_Basalt"
    },
    {
      "x": -3,
      "y": 5,
      "z": -4,
      "name": "Rock_Basalt"
    },
    {
      "x": -3,
      "y": 6,
      "z": -4,
      "name": "Rock_Basalt_Cobble"
    },
    {
      "x": -3,
      "y": 7,
      "z": -4,
      "name": "Rock_Basalt_Cobble"
    },
    {
      "x": -3,
      "y": 8,
      "z": -4,
      "name": "Rock_Basalt_Cobble"
    },
    {
      "x": -3,
      "y": 9,
      "z": -4,
      "name": "Wood_Deadwood_Planks"
    },
    {
      "x": -3,
      "y": 10,
      "z": -4,
      "name": "Empty"
    },
    {
      "x": -3,
      "y": 11,
      "z": -4,
      "name": "Empty"
    },
    {
      "x": -3,
      "y": 12,
      "z": -4,
      "name": "Empty"
    },
    {
      "x": -3,
      "y": 13,
      "z": -4,
      "name": "Empty"
    },
    {
      "x": -3,
      "y": 14,
      "z": -4,
      "name": "Empty"
    },
    {
      "x": -3,
      "y": 15,
      "z": -4,
      "name": "Empty"
    },
    {
      "x": -3,
      "y": 16,
      "z": -4,
      "name": "Wood_Blackwood_Roof_Hollow",
      "rotation": 3
    },
    {
      "x": -3,
      "y": 1,
      "z": -3,
      "name": "Rock_Basalt"
    },
    {
      "x": -3,
      "y": 2,
      "z": -3,
      "name": "Rock_Basalt"
    },
    {
      "x": -3,
      "y": 3,
      "z": -3,
      "name": "Rock_Basalt"
    },
    {
      "x": -3,
      "y": 4,
      "z": -3,
      "name": "Rock_Basalt"
    },
    {
      "x": -3,
      "y": 5,
      "z": -3,
      "name": "Rock_Basalt"
    },
    {
      "x": -3,
      "y": 6,
      "z": -3,
      "name": "Rock_Basalt_Cobble"
    },
    {
      "x": -3,
      "y": 7,
      "z": -3,
      "name": "Rock_Basalt_Cobble"
    },
    {
      "x": -3,
      "y": 8,
      "z": -3,
      "name": "Rock_Basalt_Cobble"
    },
    {
      "x": -3,
      "y": 9,
      "z": -3,
      "name": "Wood_Deadwood_Planks"
    },
    {
      "x": -3,
      "y": 10,
      "z": -3,
      "name": "Empty"
    },
    {
      "x": -3,
      "y": 11,
      "z": -3,
      "name": "Empty"
    },
    {
      "x": -3,
      "y": 12,
      "z": -3,
      "name": "Empty"
    },
    {
      "x": -3,
      "y": 13,
      "z": -3,
      "name": "Empty"
    },
    {
      "x": -3,
      "y": 14,
      "z": -3,
      "name": "Empty"
    },
    {
      "x": -3,
      "y": 15,
      "z": -3,
      "name": "Empty"
    },
    {
      "x": -3,
      "y": 16,
      "z": -3,
      "name": "Wood_Blackwood_Roof_Hollow",
      "rotation": 3
    },
    {
      "x": -3,
      "y": 1,
      "z": -2,
      "name": "Rock_Basalt"
    },
    {
      "x": -3,
      "y": 2,
      "z": -2,
      "name": "Rock_Basalt"
    },
    {
      "x": -3,
      "y": 3,
      "z": -2,
      "name": "Rock_Basalt"
    },
    {
      "x": -3,
      "y": 4,
      "z": -2,
      "name": "Rock_Basalt"
    },
    {
      "x": -3,
      "y": 5,
      "z": -2,
      "name": "Rock_Basalt"
    },
    {
      "x": -3,
      "y": 6,
      "z": -2,
      "name": "Rock_Basalt_Cobble"
    },
    {
      "x": -3,
      "y": 7,
      "z": -2,
      "name": "Rock_Basalt_Cobble"
    },
    {
      "x": -3,
      "y": 8,
      "z": -2,
      "name": "Rock_Basalt_Cobble"
    },
    {
      "x": -3,
      "y": 9,
      "z": -2,
      "name": "Wood_Deadwood_Planks"
    },
    {
      "x": -3,
      "y": 10,
      "z": -2,
      "name": "Empty"
    },
    {
      "x": -3,
      "y": 11,
      "z": -2,
      "name": "Empty"
    },
    {
      "x": -3,
      "y": 12,
      "z": -2,
      "name": "Empty"
    },
    {
      "x": -3,
      "y": 13,
      "z": -2,
      "name": "Empty"
    },
    {
      "x": -3,
      "y": 14,
      "z": -2,
      "name": "Empty"
    },
    {
      "x": -3,
      "y": 15,
      "z": -2,
      "name": "Empty"
    },
    {
      "x": -3,
      "y": 16,
      "z": -2,
      "name": "Wood_Blackwood_Roof_Hollow",
      "rotation": 3
    },
    {
      "x": -3,
      "y": 4,
      "z": -1,
      "name": "Rock_Basalt"
    },
    {
      "x": -3,
      "y": 5,
      "z": -1,
      "name": "Rock_Basalt"
    },
    {
      "x": -3,
      "y": 6,
      "z": -1,
      "name": "Rock_Basalt_Cobble"
    },
    {
      "x": -3,
      "y": 7,
      "z": -1,
      "name": "Rock_Basalt_Cobble"
    },
    {
      "x": -3,
      "y": 8,
      "z": -1,
      "name": "Rock_Basalt_Cobble"
    },
    {
      "x": -3,
      "y": 9,
      "z": -1,
      "name": "Wood_Deadwood_Planks"
    },
    {
      "x": -3,
      "y": 10,
      "z": -1,
      "name": "Empty"
    },
    {
      "x": -3,
      "y": 11,
      "z": -1,
      "name": "Empty"
    },
    {
      "x": -3,
      "y": 12,
      "z": -1,
      "name": "Empty"
    },
    {
      "x": -3,
      "y": 13,
      "z": -1,
      "name": "Empty"
    },
    {
      "x": -3,
      "y": 14,
      "z": -1,
      "name": "Empty"
    },
    {
      "x": -3,
      "y": 15,
      "z": -1,
      "name": "Empty"
    },
    {
      "x": -3,
      "y": 3,
      "z": 0,
      "name": "Rock_Basalt"
    },
    {
      "x": -3,
      "y": 4,
      "z": 0,
      "name": "Rock_Basalt"
    },
    {
      "x": -3,
      "y": 5,
      "z": 0,
      "name": "Rock_Basalt"
    },
    {
      "x": -3,
      "y": 6,
      "z": 0,
      "name": "Rock_Basalt_Cobble"
    },
    {
      "x": -3,
      "y": 7,
      "z": 0,
      "name": "Rock_Basalt_Cobble"
    },
    {
      "x": -3,
      "y": 8,
      "z": 0,
      "name": "Rock_Basalt_Cobble"
    },
    {
      "x": -3,
      "y": 9,
      "z": 0,
      "name": "Wood_Deadwood_Planks"
    },
    {
      "x": -3,
      "y": 10,
      "z": 0,
      "name": "Empty"
    },
    {
      "x": -3,
      "y": 11,
      "z": 0,
      "name": "Empty"
    },
    {
      "x": -3,
      "y": 12,
      "z": 0,
      "name": "Empty"
    },
    {
      "x": -3,
      "y": 13,
      "z": 0,
      "name": "Empty"
    },
    {
      "x": -3,
      "y": 14,
      "z": 0,
      "name": "Empty"
    },
    {
      "x": -3,
      "y": 15,
      "z": 0,
      "name": "Empty"
    },
    {
      "x": -3,
      "y": 16,
      "z": 0,
      "name": "Wood_Blackwood_Roof_Hollow",
      "rotation": 3
    },
    {
      "x": -3,
      "y": 2,
      "z": 1,
      "name": "Rock_Basalt"
    },
    {
      "x": -3,
      "y": 3,
      "z": 1,
      "name": "Rock_Basalt"
    },
    {
      "x": -3,
      "y": 4,
      "z": 1,
      "name": "Rock_Basalt"
    },
    {
      "x": -3,
      "y": 5,
      "z": 1,
      "name": "Rock_Basalt"
    },
    {
      "x": -3,
      "y": 6,
      "z": 1,
      "name": "Rock_Basalt_Cobble"
    },
    {
      "x": -3,
      "y": 7,
      "z": 1,
      "name": "Rock_Basalt_Cobble"
    },
    {
      "x": -3,
      "y": 8,
      "z": 1,
      "name": "Rock_Basalt_Cobble"
    },
    {
      "x": -3,
      "y": 9,
      "z": 1,
      "name": "Wood_Deadwood_Planks"
    },
    {
      "x": -3,
      "y": 10,
      "z": 1,
      "name": "Empty"
    },
    {
      "x": -3,
      "y": 11,
      "z": 1,
      "name": "Empty"
    },
    {
      "x": -3,
      "y": 12,
      "z": 1,
      "name": "Empty"
    },
    {
      "x": -3,
      "y": 13,
      "z": 1,
      "name": "Empty"
    },
    {
      "x": -3,
      "y": 14,
      "z": 1,
      "name": "Empty"
    },
    {
      "x": -3,
      "y": 15,
      "z": 1,
      "name": "Empty"
    },
    {
      "x": -3,
      "y": 16,
      "z": 1,
      "name": "Wood_Blackwood_Roof_Hollow",
      "rotation": 3
    },
    {
      "x": -3,
      "y": 2,
      "z": 2,
      "name": "Rock_Basalt"
    },
    {
      "x": -3,
      "y": 3,
      "z": 2,
      "name": "Rock_Basalt"
    },
    {
      "x": -3,
      "y": 4,
      "z": 2,
      "name": "Rock_Basalt"
    },
    {
      "x": -3,
      "y": 5,
      "z": 2,
      "name": "Rock_Basalt"
    },
    {
      "x": -3,
      "y": 6,
      "z": 2,
      "name": "Rock_Basalt_Cobble"
    },
    {
      "x": -3,
      "y": 7,
      "z": 2,
      "name": "Rock_Basalt_Cobble"
    },
    {
      "x": -3,
      "y": 8,
      "z": 2,
      "name": "Rock_Basalt_Cobble"
    },
    {
      "x": -3,
      "y": 9,
      "z": 2,
      "name": "Wood_Deadwood_Planks"
    },
    {
      "x": -3,
      "y": 10,
      "z": 2,
      "name": "Empty"
    },
    {
      "x": -3,
      "y": 11,
      "z": 2,
      "name": "Empty"
    },
    {
      "x": -3,
      "y": 12,
      "z": 2,
      "name": "Empty"
    },
    {
      "x": -3,
      "y": 13,
      "z": 2,
      "name": "Empty"
    },
    {
      "x": -3,
      "y": 14,
      "z": 2,
      "name": "Empty"
    },
    {
      "x": -3,
      "y": 15,
      "z": 2,
      "name": "Empty"
    },
    {
      "x": -3,
      "y": 16,
      "z": 2,
      "name": "Wood_Blackwood_Roof_Hollow",
      "rotation": 3
    },
    {
      "x": -3,
      "y": 1,
      "z": 3,
      "name": "Rock_Basalt"
    },
    {
      "x": -3,
      "y": 2,
      "z": 3,
      "name": "Rock_Basalt"
    },
    {
      "x": -3,
      "y": 3,
      "z": 3,
      "name": "Rock_Basalt"
    },
    {
      "x": -3,
      "y": 4,
      "z": 3,
      "name": "Rock_Basalt"
    },
    {
      "x": -3,
      "y": 5,
      "z": 3,
      "name": "Rock_Basalt"
    },
    {
      "x": -3,
      "y": 6,
      "z": 3,
      "name": "Rock_Basalt_Cobble"
    },
    {
      "x": -3,
      "y": 7,
      "z": 3,
      "name": "Rock_Basalt_Cobble"
    },
    {
      "x": -3,
      "y": 8,
      "z": 3,
      "name": "Rock_Basalt_Cobble"
    },
    {
      "x": -3,
      "y": 9,
      "z": 3,
      "name": "Wood_Deadwood_Planks"
    },
    {
      "x": -3,
      "y": 10,
      "z": 3,
      "name": "Empty"
    },
    {
      "x": -3,
      "y": 11,
      "z": 3,
      "name": "Empty"
    },
    {
      "x": -3,
      "y": 12,
      "z": 3,
      "name": "Empty"
    },
    {
      "x": -3,
      "y": 13,
      "z": 3,
      "name": "Wood_Deadwood_Planks_Half",
      "rotation": 8
    },
    {
      "x": -3,
      "y": 14,
      "z": 3,
      "name": "Empty"
    },
    {
      "x": -3,
      "y": 15,
      "z": 3,
      "name": "Empty"
    },
    {
      "x": -3,
      "y": 16,
      "z": 3,
      "name": "Wood_Blackwood_Roof_Hollow",
      "rotation": 3
    },
    {
      "x": -3,
      "y": 2,
      "z": 4,
      "name": "Rock_Basalt"
    },
    {
      "x": -3,
      "y": 3,
      "z": 4,
      "name": "Rock_Basalt"
    },
    {
      "x": -3,
      "y": 4,
      "z": 4,
      "name": "Rock_Basalt"
    },
    {
      "x": -3,
      "y": 5,
      "z": 4,
      "name": "Rock_Basalt"
    },
    {
      "x": -3,
      "y": 6,
      "z": 4,
      "name": "Rock_Basalt_Cobble"
    },
    {
      "x": -3,
      "y": 7,
      "z": 4,
      "name": "Rock_Basalt_Cobble"
    },
    {
      "x": -3,
      "y": 8,
      "z": 4,
      "name": "Rock_Basalt_Cobble"
    },
    {
      "x": -3,
      "y": 9,
      "z": 4,
      "name": "Wood_Deadwood_Planks"
    },
    {
      "x": -3,
      "y": 10,
      "z": 4,
      "name": "Plant_Hay_Bundle"
    },
    {
      "x": -3,
      "y": 11,
      "z": 4,
      "name": "Empty"
    },
    {
      "x": -3,
      "y": 12,
      "z": 4,
      "name": "Empty"
    },
    {
      "x": -3,
      "y": 13,
      "z": 4,
      "name": "Wood_Deadwood_Planks_Half",
      "rotation": 8
    },
    {
      "x": -3,
      "y": 14,
      "z": 4,
      "name": "Wood_Deadwood_Roof_Flat",
      "rotation": 1
    },
    {
      "x": -3,
      "y": 15,
      "z": 4,
      "name": "Empty"
    },
    {
      "x": -3,
      "y": 16,
      "z": 4,
      "name": "Wood_Blackwood_Roof_Hollow",
      "rotation": 3
    },
    {
      "x": -3,
      "y": 2,
      "z": 5,
      "name": "Rock_Basalt"
    },
    {
      "x": -3,
      "y": 3,
      "z": 5,
      "name": "Rock_Basalt"
    },
    {
      "x": -3,
      "y": 4,
      "z": 5,
      "name": "Rock_Basalt"
    },
    {
      "x": -3,
      "y": 5,
      "z": 5,
      "name": "Rock_Basalt"
    },
    {
      "x": -3,
      "y": 6,
      "z": 5,
      "name": "Rock_Basalt_Cobble"
    },
    {
      "x": -3,
      "y": 7,
      "z": 5,
      "name": "Rock_Basalt_Cobble"
    },
    {
      "x": -3,
      "y": 8,
      "z": 5,
      "name": "Rock_Basalt_Cobble"
    },
    {
      "x": -3,
      "y": 9,
      "z": 5,
      "name": "Wood_Deadwood_Planks"
    },
    {
      "x": -3,
      "y": 10,
      "z": 5,
      "name": "Ingredient_Hay"
    },
    {
      "x": -3,
      "y": 11,
      "z": 5,
      "name": "Empty"
    },
    {
      "x": -3,
      "y": 12,
      "z": 5,
      "name": "Empty"
    },
    {
      "x": -3,
      "y": 13,
      "z": 5,
      "name": "Wood_Deadwood_Planks_Half",
      "rotation": 8
    },
    {
      "x": -3,
      "y": 14,
      "z": 5,
      "name": "Ingredient_Hay"
    },
    {
      "x": -3,
      "y": 15,
      "z": 5,
      "name": "Empty"
    },
    {
      "x": -3,
      "y": 16,
      "z": 5,
      "name": "*Wood_Blackwood_Roof_State_Definitions_Corner_Right"
    },
    {
      "x": -3,
      "y": 3,
      "z": 6,
      "name": "Rock_Basalt"
    },
    {
      "x": -3,
      "y": 4,
      "z": 6,
      "name": "Rock_Basalt"
    },
    {
      "x": -3,
      "y": 5,
      "z": 6,
      "name": "Rock_Basalt"
    },
    {
      "x": -3,
      "y": 6,
      "z": 6,
      "name": "Rock_Basalt_Cobble"
    },
    {
      "x": -3,
      "y": 7,
      "z": 6,
      "name": "Rock_Basalt_Cobble"
    },
    {
      "x": -3,
      "y": 8,
      "z": 6,
      "name": "Rock_Basalt_Cobble"
    },
    {
      "x": -3,
      "y": 9,
      "z": 6,
      "name": "Rock_Basalt_Brick"
    },
    {
      "x": -3,
      "y": 10,
      "z": 6,
      "name": "Rock_Basalt_Cobble"
    },
    {
      "x": -3,
      "y": 11,
      "z": 6,
      "name": "Wood_Deadwood_Planks"
    },
    {
      "x": -3,
      "y": 12,
      "z": 6,
      "name": "Rock_Basalt_Brick"
    },
    {
      "x": -3,
      "y": 13,
      "z": 6,
      "name": "Rock_Basalt_Brick"
    },
    {
      "x": -3,
      "y": 14,
      "z": 6,
      "name": "Rock_Basalt_Cobble"
    },
    {
      "x": -3,
      "y": 15,
      "z": 6,
      "name": "Wood_Blackwood_Roof"
    },
    {
      "x": -3,
      "y": 4,
      "z": 7,
      "name": "Rock_Basalt"
    },
    {
      "x": -3,
      "y": 5,
      "z": 7,
      "name": "Rock_Basalt"
    },
    {
      "x": -3,
      "y": 6,
      "z": 7,
      "name": "Rock_Basalt_Cobble"
    },
    {
      "x": -3,
      "y": 7,
      "z": 7,
      "name": "Rock_Basalt_Cobble"
    },
    {
      "x": -3,
      "y": 8,
      "z": 7,
      "name": "Rock_Basalt_Cobble"
    },
    {
      "x": -3,
      "y": 9,
      "z": 7,
      "name": "Rock_Basalt_Cobble"
    },
    {
      "x": -3,
      "y": 10,
      "z": 7,
      "name": "Rock_Basalt_Cobble_Half",
      "rotation": 4
    },
    {
      "x": -2,
      "y": 3,
      "z": -6,
      "name": "Rock_Basalt"
    },
    {
      "x": -2,
      "y": 4,
      "z": -6,
      "name": "Rock_Basalt"
    },
    {
      "x": -2,
      "y": 5,
      "z": -6,
      "name": "Rock_Basalt"
    },
    {
      "x": -2,
      "y": 6,
      "z": -6,
      "name": "Rock_Basalt"
    },
    {
      "x": -2,
      "y": 7,
      "z": -6,
      "name": "Rock_Basalt_Cobble"
    },
    {
      "x": -2,
      "y": 8,
      "z": -6,
      "name": "Rock_Basalt_Cobble"
    },
    {
      "x": -2,
      "y": 9,
      "z": -6,
      "name": "Rock_Basalt_Cobble"
    },
    {
      "x": -2,
      "y": 14,
      "z": -6,
      "name": "Wood_Deadwood_Planks_Half",
      "rotation": 6
    },
    {
      "x": -2,
      "y": 16,
      "z": -6,
      "name": "Wood_Blackwood_Planks_Half",
      "rotation": 8
    },
    {
      "x": -2,
      "y": 17,
      "z": -6,
      "name": "Wood_Deadwood_Roof_Flat",
      "rotation": 1
    },
    {
      "x": -2,
      "y": 1,
      "z": -5,
      "name": "Rock_Basalt"
    },
    {
      "x": -2,
      "y": 2,
      "z": -5,
      "name": "Rock_Basalt"
    },
    {
      "x": -2,
      "y": 3,
      "z": -5,
      "name": "Rock_Basalt"
    },
    {
      "x": -2,
      "y": 4,
      "z": -5,
      "name": "Rock_Basalt"
    },
    {
      "x": -2,
      "y": 5,
      "z": -5,
      "name": "Rock_Basalt"
    },
    {
      "x": -2,
      "y": 6,
      "z": -5,
      "name": "Rock_Basalt_Cobble"
    },
    {
      "x": -2,
      "y": 7,
      "z": -5,
      "name": "Rock_Basalt_Cobble"
    },
    {
      "x": -2,
      "y": 8,
      "z": -5,
      "name": "Rock_Basalt_Cobble"
    },
    {
      "x": -2,
      "y": 9,
      "z": -5,
      "name": "Rock_Basalt_Brick"
    },
    {
      "x": -2,
      "y": 10,
      "z": -5,
      "name": "Empty"
    },
    {
      "x": -2,
      "y": 11,
      "z": -5,
      "name": "Empty"
    },
    {
      "x": -2,
      "y": 12,
      "z": -5,
      "name": "Wood_Deadwood_Planks_Half",
      "rotation": 5
    },
    {
      "x": -2,
      "y": 13,
      "z": -5,
      "name": "Wood_Deadwood_Decorative"
    },
    {
      "x": -2,
      "y": 14,
      "z": -5,
      "name": "Wood_Deadwood_Ornate"
    },
    {
      "x": -2,
      "y": 15,
      "z": -5,
      "name": "Wood_Deadwood_Ornate"
    },
    {
      "x": -2,
      "y": 16,
      "z": -5,
      "name": "Rock_Basalt_Brick"
    },
    {
      "x": -2,
      "y": 17,
      "z": -5,
      "name": "Wood_Deadwood_Roof_Flat",
      "rotation": 1
    },
    {
      "x": -2,
      "y": 0,
      "z": -4,
      "name": "Rock_Basalt"
    },
    {
      "x": -2,
      "y": 1,
      "z": -4,
      "name": "Rock_Basalt"
    },
    {
      "x": -2,
      "y": 2,
      "z": -4,
      "name": "Rock_Basalt"
    },
    {
      "x": -2,
      "y": 3,
      "z": -4,
      "name": "Rock_Basalt"
    },
    {
      "x": -2,
      "y": 4,
      "z": -4,
      "name": "Rock_Basalt"
    },
    {
      "x": -2,
      "y": 5,
      "z": -4,
      "name": "Rock_Basalt"
    },
    {
      "x": -2,
      "y": 6,
      "z": -4,
      "name": "Rock_Basalt_Cobble"
    },
    {
      "x": -2,
      "y": 7,
      "z": -4,
      "name": "Rock_Basalt_Cobble"
    },
    {
      "x": -2,
      "y": 8,
      "z": -4,
      "name": "Rock_Basalt_Cobble"
    },
    {
      "x": -2,
      "y": 9,
      "z": -4,
      "name": "Wood_Deadwood_Planks"
    },
    {
      "x": -2,
      "y": 10,
      "z": -4,
      "name": "Empty"
    },
    {
      "x": -2,
      "y": 11,
      "z": -4,
      "name": "Empty"
    },
    {
      "x": -2,
      "y": 12,
      "z": -4,
      "name": "Empty"
    },
    {
      "x": -2,
      "y": 13,
      "z": -4,
      "name": "Empty"
    },
    {
      "x": -2,
      "y": 14,
      "z": -4,
      "name": "Empty"
    },
    {
      "x": -2,
      "y": 15,
      "z": -4,
      "name": "Empty"
    },
    {
      "x": -2,
      "y": 16,
      "z": -4,
      "name": "Empty"
    },
    {
      "x": -2,
      "y": 17,
      "z": -4,
      "name": "Wood_Deadwood_Roof_Flat",
      "rotation": 1
    },
    {
      "x": -2,
      "y": 0,
      "z": -3,
      "name": "Rock_Basalt"
    },
    {
      "x": -2,
      "y": 1,
      "z": -3,
      "name": "Rock_Basalt"
    },
    {
      "x": -2,
      "y": 2,
      "z": -3,
      "name": "Rock_Basalt"
    },
    {
      "x": -2,
      "y": 3,
      "z": -3,
      "name": "Rock_Basalt"
    },
    {
      "x": -2,
      "y": 4,
      "z": -3,
      "name": "Rock_Basalt"
    },
    {
      "x": -2,
      "y": 5,
      "z": -3,
      "name": "Rock_Basalt"
    },
    {
      "x": -2,
      "y": 6,
      "z": -3,
      "name": "Rock_Basalt_Cobble"
    },
    {
      "x": -2,
      "y": 7,
      "z": -3,
      "name": "Rock_Basalt_Cobble"
    },
    {
      "x": -2,
      "y": 8,
      "z": -3,
      "name": "Rock_Basalt_Cobble"
    },
    {
      "x": -2,
      "y": 9,
      "z": -3,
      "name": "Wood_Deadwood_Planks"
    },
    {
      "x": -2,
      "y": 10,
      "z": -3,
      "name": "Empty"
    },
    {
      "x": -2,
      "y": 11,
      "z": -3,
      "name": "Empty"
    },
    {
      "x": -2,
      "y": 12,
      "z": -3,
      "name": "Empty"
    },
    {
      "x": -2,
      "y": 13,
      "z": -3,
      "name": "Empty"
    },
    {
      "x": -2,
      "y": 14,
      "z": -3,
      "name": "Empty"
    },
    {
      "x": -2,
      "y": 15,
      "z": -3,
      "name": "Empty"
    },
    {
      "x": -2,
      "y": 16,
      "z": -3,
      "name": "Empty"
    },
    {
      "x": -2,
      "y": 17,
      "z": -3,
      "name": "Wood_Deadwood_Roof_Flat",
      "rotation": 1
    },
    {
      "x": -2,
      "y": 1,
      "z": -2,
      "name": "Rock_Basalt"
    },
    {
      "x": -2,
      "y": 2,
      "z": -2,
      "name": "Rock_Basalt"
    },
    {
      "x": -2,
      "y": 3,
      "z": -2,
      "name": "Rock_Basalt"
    },
    {
      "x": -2,
      "y": 4,
      "z": -2,
      "name": "Rock_Basalt"
    },
    {
      "x": -2,
      "y": 5,
      "z": -2,
      "name": "Rock_Basalt"
    },
    {
      "x": -2,
      "y": 6,
      "z": -2,
      "name": "Rock_Basalt_Cobble"
    },
    {
      "x": -2,
      "y": 7,
      "z": -2,
      "name": "Rock_Basalt_Cobble"
    },
    {
      "x": -2,
      "y": 8,
      "z": -2,
      "name": "Rock_Basalt_Cobble"
    },
    {
      "x": -2,
      "y": 9,
      "z": -2,
      "name": "Wood_Deadwood_Planks"
    },
    {
      "x": -2,
      "y": 10,
      "z": -2,
      "name": "Empty"
    },
    {
      "x": -2,
      "y": 11,
      "z": -2,
      "name": "Empty"
    },
    {
      "x": -2,
      "y": 12,
      "z": -2,
      "name": "Empty"
    },
    {
      "x": -2,
      "y": 13,
      "z": -2,
      "name": "Empty"
    },
    {
      "x": -2,
      "y": 14,
      "z": -2,
      "name": "Empty"
    },
    {
      "x": -2,
      "y": 15,
      "z": -2,
      "name": "Empty"
    },
    {
      "x": -2,
      "y": 16,
      "z": -2,
      "name": "Empty"
    },
    {
      "x": -2,
      "y": 17,
      "z": -2,
      "name": "Wood_Deadwood_Roof_Flat",
      "rotation": 1
    },
    {
      "x": -2,
      "y": 1,
      "z": -1,
      "name": "Rock_Basalt"
    },
    {
      "x": -2,
      "y": 2,
      "z": -1,
      "name": "Rock_Basalt"
    },
    {
      "x": -2,
      "y": 3,
      "z": -1,
      "name": "Rock_Basalt"
    },
    {
      "x": -2,
      "y": 4,
      "z": -1,
      "name": "Rock_Basalt"
    },
    {
      "x": -2,
      "y": 5,
      "z": -1,
      "name": "Rock_Basalt"
    },
    {
      "x": -2,
      "y": 6,
      "z": -1,
      "name": "Rock_Basalt_Cobble"
    },
    {
      "x": -2,
      "y": 7,
      "z": -1,
      "name": "Rock_Basalt_Cobble"
    },
    {
      "x": -2,
      "y": 8,
      "z": -1,
      "name": "Rock_Basalt_Cobble"
    },
    {
      "x": -2,
      "y": 9,
      "z": -1,
      "name": "Wood_Deadwood_Planks"
    },
    {
      "x": -2,
      "y": 10,
      "z": -1,
      "name": "Empty"
    },
    {
      "x": -2,
      "y": 11,
      "z": -1,
      "name": "Empty"
    },
    {
      "x": -2,
      "y": 12,
      "z": -1,
      "name": "Empty"
    },
    {
      "x": -2,
      "y": 13,
      "z": -1,
      "name": "Empty"
    },
    {
      "x": -2,
      "y": 14,
      "z": -1,
      "name": "Empty"
    },
    {
      "x": -2,
      "y": 15,
      "z": -1,
      "name": "Empty"
    },
    {
      "x": -2,
      "y": 16,
      "z": -1,
      "name": "Empty"
    },
    {
      "x": -2,
      "y": 17,
      "z": -1,
      "name": "Wood_Deadwood_Roof_Flat",
      "rotation": 1
    },
    {
      "x": -2,
      "y": 2,
      "z": 0,
      "name": "Rock_Basalt"
    },
    {
      "x": -2,
      "y": 3,
      "z": 0,
      "name": "Rock_Basalt"
    },
    {
      "x": -2,
      "y": 4,
      "z": 0,
      "name": "Rock_Basalt"
    },
    {
      "x": -2,
      "y": 5,
      "z": 0,
      "name": "Rock_Basalt"
    },
    {
      "x": -2,
      "y": 6,
      "z": 0,
      "name": "Rock_Basalt_Cobble"
    },
    {
      "x": -2,
      "y": 7,
      "z": 0,
      "name": "Rock_Basalt_Cobble"
    },
    {
      "x": -2,
      "y": 8,
      "z": 0,
      "name": "Rock_Basalt_Cobble"
    },
    {
      "x": -2,
      "y": 9,
      "z": 0,
      "name": "Wood_Deadwood_Planks"
    },
    {
      "x": -2,
      "y": 10,
      "z": 0,
      "name": "Empty"
    },
    {
      "x": -2,
      "y": 11,
      "z": 0,
      "name": "Empty"
    },
    {
      "x": -2,
      "y": 12,
      "z": 0,
      "name": "Empty"
    },
    {
      "x": -2,
      "y": 13,
      "z": 0,
      "name": "Empty"
    },
    {
      "x": -2,
      "y": 14,
      "z": 0,
      "name": "Empty"
    },
    {
      "x": -2,
      "y": 15,
      "z": 0,
      "name": "Empty"
    },
    {
      "x": -2,
      "y": 16,
      "z": 0,
      "name": "Empty"
    },
    {
      "x": -2,
      "y": 17,
      "z": 0,
      "name": "Wood_Deadwood_Roof_Flat",
      "rotation": 1
    },
    {
      "x": -2,
      "y": 2,
      "z": 1,
      "name": "Rock_Basalt"
    },
    {
      "x": -2,
      "y": 3,
      "z": 1,
      "name": "Rock_Basalt"
    },
    {
      "x": -2,
      "y": 4,
      "z": 1,
      "name": "Rock_Basalt"
    },
    {
      "x": -2,
      "y": 5,
      "z": 1,
      "name": "Rock_Basalt"
    },
    {
      "x": -2,
      "y": 6,
      "z": 1,
      "name": "Rock_Basalt_Cobble"
    },
    {
      "x": -2,
      "y": 7,
      "z": 1,
      "name": "Rock_Basalt_Cobble"
    },
    {
      "x": -2,
      "y": 8,
      "z": 1,
      "name": "Rock_Basalt_Cobble"
    },
    {
      "x": -2,
      "y": 9,
      "z": 1,
      "name": "Wood_Deadwood_Planks"
    },
    {
      "x": -2,
      "y": 10,
      "z": 1,
      "name": "Empty"
    },
    {
      "x": -2,
      "y": 11,
      "z": 1,
      "name": "Empty"
    },
    {
      "x": -2,
      "y": 12,
      "z": 1,
      "name": "Empty"
    },
    {
      "x": -2,
      "y": 13,
      "z": 1,
      "name": "Empty"
    },
    {
      "x": -2,
      "y": 14,
      "z": 1,
      "name": "Empty"
    },
    {
      "x": -2,
      "y": 15,
      "z": 1,
      "name": "Empty"
    },
    {
      "x": -2,
      "y": 16,
      "z": 1,
      "name": "Empty"
    },
    {
      "x": -2,
      "y": 17,
      "z": 1,
      "name": "Wood_Deadwood_Roof_Flat",
      "rotation": 1
    },
    {
      "x": -2,
      "y": 1,
      "z": 2,
      "name": "Rock_Basalt"
    },
    {
      "x": -2,
      "y": 2,
      "z": 2,
      "name": "Rock_Basalt"
    },
    {
      "x": -2,
      "y": 3,
      "z": 2,
      "name": "Rock_Basalt"
    },
    {
      "x": -2,
      "y": 4,
      "z": 2,
      "name": "Rock_Basalt"
    },
    {
      "x": -2,
      "y": 5,
      "z": 2,
      "name": "Rock_Basalt"
    },
    {
      "x": -2,
      "y": 6,
      "z": 2,
      "name": "Rock_Basalt_Cobble"
    },
    {
      "x": -2,
      "y": 7,
      "z": 2,
      "name": "Rock_Basalt_Cobble"
    },
    {
      "x": -2,
      "y": 8,
      "z": 2,
      "name": "Rock_Basalt_Cobble"
    },
    {
      "x": -2,
      "y": 9,
      "z": 2,
      "name": "Wood_Deadwood_Planks"
    },
    {
      "x": -2,
      "y": 10,
      "z": 2,
      "name": "Empty"
    },
    {
      "x": -2,
      "y": 11,
      "z": 2,
      "name": "Empty"
    },
    {
      "x": -2,
      "y": 12,
      "z": 2,
      "name": "Empty"
    },
    {
      "x": -2,
      "y": 13,
      "z": 2,
      "name": "Empty"
    },
    {
      "x": -2,
      "y": 14,
      "z": 2,
      "name": "Empty"
    },
    {
      "x": -2,
      "y": 15,
      "z": 2,
      "name": "Empty"
    },
    {
      "x": -2,
      "y": 16,
      "z": 2,
      "name": "Empty"
    },
    {
      "x": -2,
      "y": 17,
      "z": 2,
      "name": "Wood_Deadwood_Roof_Flat",
      "rotation": 1
    },
    {
      "x": -2,
      "y": 0,
      "z": 3,
      "name": "Rock_Basalt"
    },
    {
      "x": -2,
      "y": 1,
      "z": 3,
      "name": "Rock_Basalt"
    },
    {
      "x": -2,
      "y": 2,
      "z": 3,
      "name": "Rock_Basalt"
    },
    {
      "x": -2,
      "y": 3,
      "z": 3,
      "name": "Rock_Basalt"
    },
    {
      "x": -2,
      "y": 4,
      "z": 3,
      "name": "Rock_Basalt"
    },
    {
      "x": -2,
      "y": 5,
      "z": 3,
      "name": "Rock_Basalt"
    },
    {
      "x": -2,
      "y": 6,
      "z": 3,
      "name": "Rock_Basalt_Cobble"
    },
    {
      "x": -2,
      "y": 7,
      "z": 3,
      "name": "Rock_Basalt_Cobble"
    },
    {
      "x": -2,
      "y": 8,
      "z": 3,
      "name": "Rock_Basalt_Cobble"
    },
    {
      "x": -2,
      "y": 9,
      "z": 3,
      "name": "Wood_Deadwood_Planks"
    },
    {
      "x": -2,
      "y": 10,
      "z": 3,
      "name": "Empty"
    },
    {
      "x": -2,
      "y": 11,
      "z": 3,
      "name": "Empty"
    },
    {
      "x": -2,
      "y": 12,
      "z": 3,
      "name": "Empty"
    },
    {
      "x": -2,
      "y": 13,
      "z": 3,
      "name": "Empty"
    },
    {
      "x": -2,
      "y": 14,
      "z": 3,
      "name": "Empty"
    },
    {
      "x": -2,
      "y": 15,
      "z": 3,
      "name": "Empty"
    },
    {
      "x": -2,
      "y": 16,
      "z": 3,
      "name": "Empty"
    },
    {
      "x": -2,
      "y": 17,
      "z": 3,
      "name": "Wood_Deadwood_Roof_Flat",
      "rotation": 1
    },
    {
      "x": -2,
      "y": 0,
      "z": 4,
      "name": "Rock_Basalt"
    },
    {
      "x": -2,
      "y": 1,
      "z": 4,
      "name": "Rock_Basalt"
    },
    {
      "x": -2,
      "y": 2,
      "z": 4,
      "name": "Rock_Basalt"
    },
    {
      "x": -2,
      "y": 3,
      "z": 4,
      "name": "Rock_Basalt"
    },
    {
      "x": -2,
      "y": 4,
      "z": 4,
      "name": "Rock_Basalt"
    },
    {
      "x": -2,
      "y": 5,
      "z": 4,
      "name": "Rock_Basalt"
    },
    {
      "x": -2,
      "y": 6,
      "z": 4,
      "name": "Rock_Basalt_Cobble"
    },
    {
      "x": -2,
      "y": 7,
      "z": 4,
      "name": "Rock_Basalt_Cobble"
    },
    {
      "x": -2,
      "y": 8,
      "z": 4,
      "name": "Rock_Basalt_Cobble"
    },
    {
      "x": -2,
      "y": 9,
      "z": 4,
      "name": "Wood_Deadwood_Planks"
    },
    {
      "x": -2,
      "y": 10,
      "z": 4,
      "name": "Empty"
    },
    {
      "x": -2,
      "y": 11,
      "z": 4,
      "name": "Empty"
    },
    {
      "x": -2,
      "y": 12,
      "z": 4,
      "name": "Empty"
    },
    {
      "x": -2,
      "y": 13,
      "z": 4,
      "name": "Wood_Deadwood_Planks_Half",
      "rotation": 8
    },
    {
      "x": -2,
      "y": 14,
      "z": 4,
      "name": "Empty"
    },
    {
      "x": -2,
      "y": 15,
      "z": 4,
      "name": "Empty"
    },
    {
      "x": -2,
      "y": 16,
      "z": 4,
      "name": "Empty"
    },
    {
      "x": -2,
      "y": 17,
      "z": 4,
      "name": "Wood_Deadwood_Roof_Flat"
    },
    {
      "x": -2,
      "y": 0,
      "z": 5,
      "name": "Rock_Basalt"
    },
    {
      "x": -2,
      "y": 1,
      "z": 5,
      "name": "Rock_Basalt"
    },
    {
      "x": -2,
      "y": 2,
      "z": 5,
      "name": "Rock_Basalt"
    },
    {
      "x": -2,
      "y": 3,
      "z": 5,
      "name": "Rock_Basalt"
    },
    {
      "x": -2,
      "y": 4,
      "z": 5,
      "name": "Rock_Basalt"
    },
    {
      "x": -2,
      "y": 5,
      "z": 5,
      "name": "Rock_Basalt"
    },
    {
      "x": -2,
      "y": 6,
      "z": 5,
      "name": "Rock_Basalt_Cobble"
    },
    {
      "x": -2,
      "y": 7,
      "z": 5,
      "name": "Rock_Basalt_Cobble"
    },
    {
      "x": -2,
      "y": 8,
      "z": 5,
      "name": "Rock_Basalt_Cobble"
    },
    {
      "x": -2,
      "y": 9,
      "z": 5,
      "name": "Wood_Deadwood_Planks"
    },
    {
      "x": -2,
      "y": 10,
      "z": 5,
      "name": "Wood_Deadwood_Roof_Flat"
    },
    {
      "x": -2,
      "y": 11,
      "z": 5,
      "name": "Empty"
    },
    {
      "x": -2,
      "y": 12,
      "z": 5,
      "name": "Empty"
    },
    {
      "x": -2,
      "y": 13,
      "z": 5,
      "name": "Wood_Deadwood_Planks_Half",
      "rotation": 8
    },
    {
      "x": -2,
      "y": 14,
      "z": 5,
      "name": "Wood_Deadwood_Roof_Flat"
    },
    {
      "x": -2,
      "y": 15,
      "z": 5,
      "name": "Empty"
    },
    {
      "x": -2,
      "y": 16,
      "z": 5,
      "name": "Wood_Blackwood_Roof_Hollow"
    },
    {
      "x": -2,
      "y": 2,
      "z": 6,
      "name": "Rock_Basalt"
    },
    {
      "x": -2,
      "y": 3,
      "z": 6,
      "name": "Rock_Basalt"
    },
    {
      "x": -2,
      "y": 4,
      "z": 6,
      "name": "Rock_Basalt"
    },
    {
      "x": -2,
      "y": 5,
      "z": 6,
      "name": "Rock_Basalt"
    },
    {
      "x": -2,
      "y": 6,
      "z": 6,
      "name": "Rock_Basalt_Cobble"
    },
    {
      "x": -2,
      "y": 7,
      "z": 6,
      "name": "Rock_Basalt_Cobble"
    },
    {
      "x": -2,
      "y": 8,
      "z": 6,
      "name": "Rock_Basalt_Cobble"
    },
    {
      "x": -2,
      "y": 9,
      "z": 6,
      "name": "Rock_Basalt_Brick"
    },
    {
      "x": -2,
      "y": 10,
      "z": 6,
      "name": "Rock_Basalt_Cobble"
    },
    {
      "x": -2,
      "y": 11,
      "z": 6,
      "name": "Wood_Deadwood_Planks"
    },
    {
      "x": -2,
      "y": 12,
      "z": 6,
      "name": "Rock_Basalt_Brick"
    },
    {
      "x": -2,
      "y": 13,
      "z": 6,
      "name": "Rock_Basalt_Cobble"
    },
    {
      "x": -2,
      "y": 14,
      "z": 6,
      "name": "Rock_Basalt_Cobble"
    },
    {
      "x": -2,
      "y": 15,
      "z": 6,
      "name": "Wood_Blackwood_Roof"
    },
    {
      "x": -2,
      "y": 3,
      "z": 7,
      "name": "Rock_Basalt"
    },
    {
      "x": -2,
      "y": 4,
      "z": 7,
      "name": "Rock_Basalt"
    },
    {
      "x": -2,
      "y": 5,
      "z": 7,
      "name": "Rock_Basalt"
    },
    {
      "x": -2,
      "y": 6,
      "z": 7,
      "name": "Rock_Basalt"
    },
    {
      "x": -2,
      "y": 7,
      "z": 7,
      "name": "Rock_Basalt_Cobble"
    },
    {
      "x": -2,
      "y": 8,
      "z": 7,
      "name": "Rock_Basalt_Cobble"
    },
    {
      "x": -2,
      "y": 9,
      "z": 7,
      "name": "Rock_Basalt_Cobble"
    },
    {
      "x": -1,
      "y": 3,
      "z": -6,
      "name": "Rock_Basalt"
    },
    {
      "x": -1,
      "y": 4,
      "z": -6,
      "name": "Rock_Basalt"
    },
    {
      "x": -1,
      "y": 5,
      "z": -6,
      "name": "Rock_Basalt"
    },
    {
      "x": -1,
      "y": 6,
      "z": -6,
      "name": "Rock_Basalt_Cobble"
    },
    {
      "x": -1,
      "y": 7,
      "z": -6,
      "name": "Rock_Basalt_Cobble"
    },
    {
      "x": -1,
      "y": 8,
      "z": -6,
      "name": "Rock_Basalt_Cobble"
    },
    {
      "x": -1,
      "y": 14,
      "z": -6,
      "name": "Wood_Deadwood_Planks_Half",
      "rotation": 6
    },
    {
      "x": -1,
      "y": 16,
      "z": -6,
      "name": "Wood_Blackwood_Planks_Half",
      "rotation": 8
    },
    {
      "x": -1,
      "y": 17,
      "z": -6,
      "name": "Wood_Deadwood_Roof_Flat",
      "rotation": 1
    },
    {
      "x": -1,
      "y": 1,
      "z": -5,
      "name": "Rock_Basalt"
    },
    {
      "x": -1,
      "y": 2,
      "z": -5,
      "name": "Rock_Basalt"
    },
    {
      "x": -1,
      "y": 3,
      "z": -5,
      "name": "Rock_Basalt"
    },
    {
      "x": -1,
      "y": 4,
      "z": -5,
      "name": "Rock_Basalt"
    },
    {
      "x": -1,
      "y": 5,
      "z": -5,
      "name": "Rock_Basalt"
    },
    {
      "x": -1,
      "y": 6,
      "z": -5,
      "name": "Rock_Basalt_Cobble"
    },
    {
      "x": -1,
      "y": 7,
      "z": -5,
      "name": "Rock_Basalt_Cobble"
    },
    {
      "x": -1,
      "y": 8,
      "z": -5,
      "name": "Rock_Basalt_Cobble"
    },
    {
      "x": -1,
      "y": 9,
      "z": -5,
      "name": "Rock_Basalt_Brick"
    },
    {
      "x": -1,
      "y": 10,
      "z": -5,
      "name": "Empty"
    },
    {
      "x": -1,
      "y": 11,
      "z": -5,
      "name": "Empty"
    },
    {
      "x": -1,
      "y": 12,
      "z": -5,
      "name": "Empty"
    },
    {
      "x": -1,
      "y": 13,
      "z": -5,
      "name": "Wood_Deadwood_Decorative"
    },
    {
      "x": -1,
      "y": 14,
      "z": -5,
      "name": "Wood_Deadwood_Ornate"
    },
    {
      "x": -1,
      "y": 15,
      "z": -5,
      "name": "Wood_Deadwood_Ornate"
    },
    {
      "x": -1,
      "y": 16,
      "z": -5,
      "name": "Rock_Basalt_Brick"
    },
    {
      "x": -1,
      "y": 17,
      "z": -5,
      "name": "Wood_Deadwood_Roof_Flat",
      "rotation": 1
    },
    {
      "x": -1,
      "y": 0,
      "z": -4,
      "name": "Rock_Basalt"
    },
    {
      "x": -1,
      "y": 1,
      "z": -4,
      "name": "Rock_Basalt"
    },
    {
      "x": -1,
      "y": 2,
      "z": -4,
      "name": "Rock_Basalt"
    },
    {
      "x": -1,
      "y": 3,
      "z": -4,
      "name": "Rock_Basalt"
    },
    {
      "x": -1,
      "y": 4,
      "z": -4,
      "name": "Rock_Basalt"
    },
    {
      "x": -1,
      "y": 5,
      "z": -4,
      "name": "Rock_Basalt"
    },
    {
      "x": -1,
      "y": 6,
      "z": -4,
      "name": "Rock_Basalt_Cobble"
    },
    {
      "x": -1,
      "y": 7,
      "z": -4,
      "name": "Rock_Basalt_Cobble"
    },
    {
      "x": -1,
      "y": 8,
      "z": -4,
      "name": "Rock_Basalt_Cobble"
    },
    {
      "x": -1,
      "y": 9,
      "z": -4,
      "name": "Wood_Deadwood_Planks"
    },
    {
      "x": -1,
      "y": 10,
      "z": -4,
      "name": "Empty"
    },
    {
      "x": -1,
      "y": 11,
      "z": -4,
      "name": "Empty"
    },
    {
      "x": -1,
      "y": 12,
      "z": -4,
      "name": "Empty"
    },
    {
      "x": -1,
      "y": 13,
      "z": -4,
      "name": "Empty"
    },
    {
      "x": -1,
      "y": 14,
      "z": -4,
      "name": "Empty"
    },
    {
      "x": -1,
      "y": 15,
      "z": -4,
      "name": "Empty"
    },
    {
      "x": -1,
      "y": 16,
      "z": -4,
      "name": "Empty"
    },
    {
      "x": -1,
      "y": 17,
      "z": -4,
      "name": "Wood_Deadwood_Roof_Flat",
      "rotation": 1
    },
    {
      "x": -1,
      "y": 0,
      "z": -3,
      "name": "Rock_Basalt"
    },
    {
      "x": -1,
      "y": 1,
      "z": -3,
      "name": "Rock_Basalt"
    },
    {
      "x": -1,
      "y": 2,
      "z": -3,
      "name": "Rock_Basalt"
    },
    {
      "x": -1,
      "y": 3,
      "z": -3,
      "name": "Rock_Basalt"
    },
    {
      "x": -1,
      "y": 4,
      "z": -3,
      "name": "Rock_Basalt"
    },
    {
      "x": -1,
      "y": 5,
      "z": -3,
      "name": "Rock_Basalt"
    },
    {
      "x": -1,
      "y": 6,
      "z": -3,
      "name": "Rock_Basalt_Cobble"
    },
    {
      "x": -1,
      "y": 7,
      "z": -3,
      "name": "Rock_Basalt_Cobble"
    },
    {
      "x": -1,
      "y": 8,
      "z": -3,
      "name": "Rock_Basalt_Cobble"
    },
    {
      "x": -1,
      "y": 9,
      "z": -3,
      "name": "Wood_Deadwood_Planks"
    },
    {
      "x": -1,
      "y": 10,
      "z": -3,
      "name": "Empty"
    },
    {
      "x": -1,
      "y": 11,
      "z": -3,
      "name": "Empty"
    },
    {
      "x": -1,
      "y": 12,
      "z": -3,
      "name": "Empty"
    },
    {
      "x": -1,
      "y": 13,
      "z": -3,
      "name": "Empty"
    },
    {
      "x": -1,
      "y": 14,
      "z": -3,
      "name": "Empty"
    },
    {
      "x": -1,
      "y": 15,
      "z": -3,
      "name": "Empty"
    },
    {
      "x": -1,
      "y": 16,
      "z": -3,
      "name": "Empty"
    },
    {
      "x": -1,
      "y": 17,
      "z": -3,
      "name": "Wood_Deadwood_Roof_Flat",
      "rotation": 1
    },
    {
      "x": -1,
      "y": 1,
      "z": -2,
      "name": "Rock_Basalt"
    },
    {
      "x": -1,
      "y": 2,
      "z": -2,
      "name": "Rock_Basalt"
    },
    {
      "x": -1,
      "y": 3,
      "z": -2,
      "name": "Rock_Basalt"
    },
    {
      "x": -1,
      "y": 4,
      "z": -2,
      "name": "Rock_Basalt"
    },
    {
      "x": -1,
      "y": 5,
      "z": -2,
      "name": "Rock_Basalt"
    },
    {
      "x": -1,
      "y": 6,
      "z": -2,
      "name": "Rock_Basalt_Cobble"
    },
    {
      "x": -1,
      "y": 7,
      "z": -2,
      "name": "Rock_Basalt_Cobble"
    },
    {
      "x": -1,
      "y": 8,
      "z": -2,
      "name": "Rock_Basalt_Cobble"
    },
    {
      "x": -1,
      "y": 9,
      "z": -2,
      "name": "Wood_Deadwood_Planks"
    },
    {
      "x": -1,
      "y": 10,
      "z": -2,
      "name": "Empty"
    },
    {
      "x": -1,
      "y": 11,
      "z": -2,
      "name": "Empty"
    },
    {
      "x": -1,
      "y": 12,
      "z": -2,
      "name": "Empty"
    },
    {
      "x": -1,
      "y": 13,
      "z": -2,
      "name": "Empty"
    },
    {
      "x": -1,
      "y": 14,
      "z": -2,
      "name": "Empty"
    },
    {
      "x": -1,
      "y": 15,
      "z": -2,
      "name": "Empty"
    },
    {
      "x": -1,
      "y": 16,
      "z": -2,
      "name": "Empty"
    },
    {
      "x": -1,
      "y": 17,
      "z": -2,
      "name": "Wood_Deadwood_Roof_Flat",
      "rotation": 1
    },
    {
      "x": -1,
      "y": 2,
      "z": -1,
      "name": "Rock_Basalt"
    },
    {
      "x": -1,
      "y": 3,
      "z": -1,
      "name": "Rock_Basalt"
    },
    {
      "x": -1,
      "y": 4,
      "z": -1,
      "name": "Rock_Basalt"
    },
    {
      "x": -1,
      "y": 5,
      "z": -1,
      "name": "Rock_Basalt"
    },
    {
      "x": -1,
      "y": 6,
      "z": -1,
      "name": "Rock_Basalt_Cobble"
    },
    {
      "x": -1,
      "y": 7,
      "z": -1,
      "name": "Rock_Basalt_Cobble"
    },
    {
      "x": -1,
      "y": 8,
      "z": -1,
      "name": "Rock_Basalt_Cobble"
    },
    {
      "x": -1,
      "y": 9,
      "z": -1,
      "name": "Wood_Deadwood_Planks"
    },
    {
      "x": -1,
      "y": 10,
      "z": -1,
      "name": "Empty"
    },
    {
      "x": -1,
      "y": 11,
      "z": -1,
      "name": "Empty"
    },
    {
      "x": -1,
      "y": 12,
      "z": -1,
      "name": "Empty"
    },
    {
      "x": -1,
      "y": 13,
      "z": -1,
      "name": "Empty"
    },
    {
      "x": -1,
      "y": 14,
      "z": -1,
      "name": "Empty"
    },
    {
      "x": -1,
      "y": 15,
      "z": -1,
      "name": "Empty"
    },
    {
      "x": -1,
      "y": 16,
      "z": -1,
      "name": "Empty"
    },
    {
      "x": -1,
      "y": 17,
      "z": -1,
      "name": "Wood_Deadwood_Roof_Flat",
      "rotation": 1
    },
    {
      "x": -1,
      "y": 2,
      "z": 0,
      "name": "Rock_Basalt"
    },
    {
      "x": -1,
      "y": 3,
      "z": 0,
      "name": "Rock_Basalt"
    },
    {
      "x": -1,
      "y": 4,
      "z": 0,
      "name": "Rock_Basalt"
    },
    {
      "x": -1,
      "y": 5,
      "z": 0,
      "name": "Rock_Basalt"
    },
    {
      "x": -1,
      "y": 6,
      "z": 0,
      "name": "Rock_Basalt_Cobble"
    },
    {
      "x": -1,
      "y": 7,
      "z": 0,
      "name": "Rock_Basalt_Cobble"
    },
    {
      "x": -1,
      "y": 8,
      "z": 0,
      "name": "Rock_Basalt_Cobble"
    },
    {
      "x": -1,
      "y": 9,
      "z": 0,
      "name": "Wood_Deadwood_Planks"
    },
    {
      "x": -1,
      "y": 10,
      "z": 0,
      "name": "Empty"
    },
    {
      "x": -1,
      "y": 11,
      "z": 0,
      "name": "Empty"
    },
    {
      "x": -1,
      "y": 12,
      "z": 0,
      "name": "Empty"
    },
    {
      "x": -1,
      "y": 13,
      "z": 0,
      "name": "Empty"
    },
    {
      "x": -1,
      "y": 14,
      "z": 0,
      "name": "Empty"
    },
    {
      "x": -1,
      "y": 15,
      "z": 0,
      "name": "Empty"
    },
    {
      "x": -1,
      "y": 16,
      "z": 0,
      "name": "Empty"
    },
    {
      "x": -1,
      "y": 17,
      "z": 0,
      "name": "Wood_Deadwood_Roof_Flat",
      "rotation": 1
    },
    {
      "x": -1,
      "y": 2,
      "z": 1,
      "name": "Rock_Basalt"
    },
    {
      "x": -1,
      "y": 3,
      "z": 1,
      "name": "Rock_Basalt"
    },
    {
      "x": -1,
      "y": 4,
      "z": 1,
      "name": "Rock_Basalt"
    },
    {
      "x": -1,
      "y": 5,
      "z": 1,
      "name": "Rock_Basalt"
    },
    {
      "x": -1,
      "y": 6,
      "z": 1,
      "name": "Rock_Basalt_Cobble"
    },
    {
      "x": -1,
      "y": 7,
      "z": 1,
      "name": "Rock_Basalt_Cobble"
    },
    {
      "x": -1,
      "y": 8,
      "z": 1,
      "name": "Rock_Basalt_Cobble"
    },
    {
      "x": -1,
      "y": 9,
      "z": 1,
      "name": "Wood_Deadwood_Planks"
    },
    {
      "x": -1,
      "y": 10,
      "z": 1,
      "name": "Empty"
    },
    {
      "x": -1,
      "y": 11,
      "z": 1,
      "name": "Empty"
    },
    {
      "x": -1,
      "y": 12,
      "z": 1,
      "name": "Empty"
    },
    {
      "x": -1,
      "y": 13,
      "z": 1,
      "name": "Empty"
    },
    {
      "x": -1,
      "y": 14,
      "z": 1,
      "name": "Empty"
    },
    {
      "x": -1,
      "y": 15,
      "z": 1,
      "name": "Empty"
    },
    {
      "x": -1,
      "y": 16,
      "z": 1,
      "name": "Empty"
    },
    {
      "x": -1,
      "y": 17,
      "z": 1,
      "name": "Wood_Deadwood_Roof_Flat",
      "rotation": 1
    },
    {
      "x": -1,
      "y": 0,
      "z": 2,
      "name": "Rock_Basalt"
    },
    {
      "x": -1,
      "y": 1,
      "z": 2,
      "name": "Rock_Basalt"
    },
    {
      "x": -1,
      "y": 2,
      "z": 2,
      "name": "Rock_Basalt"
    },
    {
      "x": -1,
      "y": 3,
      "z": 2,
      "name": "Rock_Basalt"
    },
    {
      "x": -1,
      "y": 4,
      "z": 2,
      "name": "Rock_Basalt"
    },
    {
      "x": -1,
      "y": 5,
      "z": 2,
      "name": "Rock_Basalt"
    },
    {
      "x": -1,
      "y": 6,
      "z": 2,
      "name": "Rock_Basalt_Cobble"
    },
    {
      "x": -1,
      "y": 7,
      "z": 2,
      "name": "Rock_Basalt_Cobble"
    },
    {
      "x": -1,
      "y": 8,
      "z": 2,
      "name": "Rock_Basalt_Cobble"
    },
    {
      "x": -1,
      "y": 9,
      "z": 2,
      "name": "Wood_Deadwood_Planks"
    },
    {
      "x": -1,
      "y": 10,
      "z": 2,
      "name": "Empty"
    },
    {
      "x": -1,
      "y": 11,
      "z": 2,
      "name": "Empty"
    },
    {
      "x": -1,
      "y": 12,
      "z": 2,
      "name": "Empty"
    },
    {
      "x": -1,
      "y": 13,
      "z": 2,
      "name": "Empty"
    },
    {
      "x": -1,
      "y": 14,
      "z": 2,
      "name": "Empty"
    },
    {
      "x": -1,
      "y": 15,
      "z": 2,
      "name": "Empty"
    },
    {
      "x": -1,
      "y": 16,
      "z": 2,
      "name": "Empty"
    },
    {
      "x": -1,
      "y": 17,
      "z": 2,
      "name": "Wood_Deadwood_Roof_Flat",
      "rotation": 1
    },
    {
      "x": -1,
      "y": 0,
      "z": 3,
      "name": "Rock_Basalt"
    },
    {
      "x": -1,
      "y": 1,
      "z": 3,
      "name": "Rock_Basalt"
    },
    {
      "x": -1,
      "y": 2,
      "z": 3,
      "name": "Rock_Basalt"
    },
    {
      "x": -1,
      "y": 3,
      "z": 3,
      "name": "Rock_Basalt"
    },
    {
      "x": -1,
      "y": 4,
      "z": 3,
      "name": "Rock_Basalt"
    },
    {
      "x": -1,
      "y": 5,
      "z": 3,
      "name": "Rock_Basalt"
    },
    {
      "x": -1,
      "y": 6,
      "z": 3,
      "name": "Rock_Basalt_Cobble"
    },
    {
      "x": -1,
      "y": 7,
      "z": 3,
      "name": "Rock_Basalt_Cobble"
    },
    {
      "x": -1,
      "y": 8,
      "z": 3,
      "name": "Rock_Basalt_Cobble"
    },
    {
      "x": -1,
      "y": 9,
      "z": 3,
      "name": "Wood_Deadwood_Planks"
    },
    {
      "x": -1,
      "y": 10,
      "z": 3,
      "name": "Empty"
    },
    {
      "x": -1,
      "y": 11,
      "z": 3,
      "name": "Empty"
    },
    {
      "x": -1,
      "y": 12,
      "z": 3,
      "name": "Empty"
    },
    {
      "x": -1,
      "y": 13,
      "z": 3,
      "name": "Empty"
    },
    {
      "x": -1,
      "y": 14,
      "z": 3,
      "name": "Empty"
    },
    {
      "x": -1,
      "y": 15,
      "z": 3,
      "name": "Empty"
    },
    {
      "x": -1,
      "y": 16,
      "z": 3,
      "name": "Empty"
    },
    {
      "x": -1,
      "y": 17,
      "z": 3,
      "name": "Wood_Deadwood_Roof_Flat"
    },
    {
      "x": -1,
      "y": 0,
      "z": 4,
      "name": "Rock_Basalt"
    },
    {
      "x": -1,
      "y": 1,
      "z": 4,
      "name": "Rock_Basalt"
    },
    {
      "x": -1,
      "y": 2,
      "z": 4,
      "name": "Rock_Basalt"
    },
    {
      "x": -1,
      "y": 3,
      "z": 4,
      "name": "Rock_Basalt"
    },
    {
      "x": -1,
      "y": 4,
      "z": 4,
      "name": "Rock_Basalt"
    },
    {
      "x": -1,
      "y": 5,
      "z": 4,
      "name": "Rock_Basalt"
    },
    {
      "x": -1,
      "y": 6,
      "z": 4,
      "name": "Rock_Basalt_Cobble"
    },
    {
      "x": -1,
      "y": 7,
      "z": 4,
      "name": "Rock_Basalt_Cobble"
    },
    {
      "x": -1,
      "y": 8,
      "z": 4,
      "name": "Rock_Basalt_Cobble"
    },
    {
      "x": -1,
      "y": 9,
      "z": 4,
      "name": "Wood_Deadwood_Planks"
    },
    {
      "x": -1,
      "y": 10,
      "z": 4,
      "name": "Empty"
    },
    {
      "x": -1,
      "y": 11,
      "z": 4,
      "name": "Empty"
    },
    {
      "x": -1,
      "y": 12,
      "z": 4,
      "name": "Empty"
    },
    {
      "x": -1,
      "y": 13,
      "z": 4,
      "name": "Empty"
    },
    {
      "x": -1,
      "y": 14,
      "z": 4,
      "name": "Empty"
    },
    {
      "x": -1,
      "y": 15,
      "z": 4,
      "name": "Empty"
    },
    {
      "x": -1,
      "y": 16,
      "z": 4,
      "name": "Empty"
    },
    {
      "x": -1,
      "y": 0,
      "z": 5,
      "name": "Rock_Basalt"
    },
    {
      "x": -1,
      "y": 1,
      "z": 5,
      "name": "Rock_Basalt"
    },
    {
      "x": -1,
      "y": 2,
      "z": 5,
      "name": "Rock_Basalt"
    },
    {
      "x": -1,
      "y": 3,
      "z": 5,
      "name": "Rock_Basalt"
    },
    {
      "x": -1,
      "y": 4,
      "z": 5,
      "name": "Rock_Basalt"
    },
    {
      "x": -1,
      "y": 5,
      "z": 5,
      "name": "Rock_Basalt"
    },
    {
      "x": -1,
      "y": 6,
      "z": 5,
      "name": "Rock_Basalt_Cobble"
    },
    {
      "x": -1,
      "y": 7,
      "z": 5,
      "name": "Rock_Basalt_Cobble"
    },
    {
      "x": -1,
      "y": 8,
      "z": 5,
      "name": "Rock_Basalt_Cobble"
    },
    {
      "x": -1,
      "y": 9,
      "z": 5,
      "name": "Wood_Deadwood_Planks"
    },
    {
      "x": -1,
      "y": 10,
      "z": 5,
      "name": "Empty"
    },
    {
      "x": -1,
      "y": 11,
      "z": 5,
      "name": "Empty"
    },
    {
      "x": -1,
      "y": 12,
      "z": 5,
      "name": "Empty"
    },
    {
      "x": -1,
      "y": 13,
      "z": 5,
      "name": "Empty"
    },
    {
      "x": -1,
      "y": 14,
      "z": 5,
      "name": "Empty"
    },
    {
      "x": -1,
      "y": 15,
      "z": 5,
      "name": "Empty"
    },
    {
      "x": -1,
      "y": 16,
      "z": 5,
      "name": "Wood_Blackwood_Roof_Hollow"
    },
    {
      "x": -1,
      "y": 1,
      "z": 6,
      "name": "Rock_Basalt"
    },
    {
      "x": -1,
      "y": 2,
      "z": 6,
      "name": "Rock_Basalt"
    },
    {
      "x": -1,
      "y": 3,
      "z": 6,
      "name": "Rock_Basalt"
    },
    {
      "x": -1,
      "y": 4,
      "z": 6,
      "name": "Rock_Basalt"
    },
    {
      "x": -1,
      "y": 5,
      "z": 6,
      "name": "Rock_Basalt"
    },
    {
      "x": -1,
      "y": 6,
      "z": 6,
      "name": "Rock_Basalt_Cobble"
    },
    {
      "x": -1,
      "y": 7,
      "z": 6,
      "name": "Rock_Basalt_Cobble"
    },
    {
      "x": -1,
      "y": 8,
      "z": 6,
      "name": "Rock_Basalt_Cobble"
    },
    {
      "x": -1,
      "y": 9,
      "z": 6,
      "name": "Rock_Basalt_Brick"
    },
    {
      "x": -1,
      "y": 10,
      "z": 6,
      "name": "Empty"
    },
    {
      "x": -1,
      "y": 11,
      "z": 6,
      "name": "Empty"
    },
    {
      "x": -1,
      "y": 12,
      "z": 6,
      "name": "Empty"
    },
    {
      "x": -1,
      "y": 13,
      "z": 6,
      "name": "Rock_Basalt_Cobble"
    },
    {
      "x": -1,
      "y": 14,
      "z": 6,
      "name": "Rock_Basalt_Cobble"
    },
    {
      "x": -1,
      "y": 15,
      "z": 6,
      "name": "Wood_Blackwood_Roof"
    },
    {
      "x": -1,
      "y": 3,
      "z": 7,
      "name": "Rock_Basalt"
    },
    {
      "x": -1,
      "y": 4,
      "z": 7,
      "name": "Rock_Basalt"
    },
    {
      "x": -1,
      "y": 5,
      "z": 7,
      "name": "Rock_Basalt"
    },
    {
      "x": -1,
      "y": 6,
      "z": 7,
      "name": "Rock_Basalt"
    },
    {
      "x": -1,
      "y": 7,
      "z": 7,
      "name": "Rock_Basalt_Cobble"
    },
    {
      "x": -1,
      "y": 8,
      "z": 7,
      "name": "Rock_Basalt_Cobble"
    },
    {
      "x": -1,
      "y": 9,
      "z": 7,
      "name": "Rock_Basalt_Cobble"
    },
    {
      "x": 0,
      "y": 6,
      "z": -6,
      "name": "Rock_Basalt_Cobble"
    },
    {
      "x": 0,
      "y": 7,
      "z": -6,
      "name": "Rock_Basalt_Cobble"
    },
    {
      "x": 0,
      "y": 8,
      "z": -6,
      "name": "Rock_Basalt_Cobble"
    },
    {
      "x": 0,
      "y": 14,
      "z": -6,
      "name": "Wood_Deadwood_Planks_Half",
      "rotation": 6
    },
    {
      "x": 0,
      "y": 16,
      "z": -6,
      "name": "Wood_Blackwood_Planks_Half",
      "rotation": 8
    },
    {
      "x": 0,
      "y": 17,
      "z": -6,
      "name": "Wood_Deadwood_Roof_Flat",
      "rotation": 1
    },
    {
      "x": 0,
      "y": 0,
      "z": -5,
      "name": "Rock_Basalt"
    },
    {
      "x": 0,
      "y": 1,
      "z": -5,
      "name": "Rock_Basalt"
    },
    {
      "x": 0,
      "y": 2,
      "z": -5,
      "name": "Rock_Basalt"
    },
    {
      "x": 0,
      "y": 3,
      "z": -5,
      "name": "Rock_Basalt"
    },
    {
      "x": 0,
      "y": 4,
      "z": -5,
      "name": "Rock_Basalt"
    },
    {
      "x": 0,
      "y": 5,
      "z": -5,
      "name": "Rock_Basalt"
    },
    {
      "x": 0,
      "y": 6,
      "z": -5,
      "name": "Rock_Basalt_Cobble"
    },
    {
      "x": 0,
      "y": 7,
      "z": -5,
      "name": "Rock_Basalt_Cobble"
    },
    {
      "x": 0,
      "y": 8,
      "z": -5,
      "name": "Rock_Basalt_Cobble"
    },
    {
      "x": 0,
      "y": 9,
      "z": -5,
      "name": "Rock_Basalt_Brick"
    },
    {
      "x": 0,
      "y": 10,
      "z": -5,
      "name": "Empty"
    },
    {
      "x": 0,
      "y": 11,
      "z": -5,
      "name": "Empty"
    },
    {
      "x": 0,
      "y": 12,
      "z": -5,
      "name": "Wood_Deadwood_Planks_Half",
      "rotation": 7
    },
    {
      "x": 0,
      "y": 13,
      "z": -5,
      "name": "Wood_Deadwood_Decorative"
    },
    {
      "x": 0,
      "y": 14,
      "z": -5,
      "name": "Wood_Deadwood_Ornate"
    },
    {
      "x": 0,
      "y": 15,
      "z": -5,
      "name": "Wood_Deadwood_Ornate"
    },
    {
      "x": 0,
      "y": 16,
      "z": -5,
      "name": "Rock_Basalt_Brick"
    },
    {
      "x": 0,
      "y": 17,
      "z": -5,
      "name": "Wood_Deadwood_Roof_Flat",
      "rotation": 1
    },
    {
      "x": 0,
      "y": 0,
      "z": -4,
      "name": "Rock_Basalt"
    },
    {
      "x": 0,
      "y": 1,
      "z": -4,
      "name": "Rock_Basalt"
    },
    {
      "x": 0,
      "y": 2,
      "z": -4,
      "name": "Rock_Basalt"
    },
    {
      "x": 0,
      "y": 3,
      "z": -4,
      "name": "Rock_Basalt"
    },
    {
      "x": 0,
      "y": 4,
      "z": -4,
      "name": "Rock_Basalt"
    },
    {
      "x": 0,
      "y": 5,
      "z": -4,
      "name": "Rock_Basalt"
    },
    {
      "x": 0,
      "y": 6,
      "z": -4,
      "name": "Rock_Basalt_Cobble"
    },
    {
      "x": 0,
      "y": 7,
      "z": -4,
      "name": "Rock_Basalt_Cobble"
    },
    {
      "x": 0,
      "y": 8,
      "z": -4,
      "name": "Rock_Basalt_Cobble"
    },
    {
      "x": 0,
      "y": 9,
      "z": -4,
      "name": "Wood_Deadwood_Planks"
    },
    {
      "x": 0,
      "y": 10,
      "z": -4,
      "name": "Empty"
    },
    {
      "x": 0,
      "y": 11,
      "z": -4,
      "name": "Empty"
    },
    {
      "x": 0,
      "y": 12,
      "z": -4,
      "name": "Empty"
    },
    {
      "x": 0,
      "y": 13,
      "z": -4,
      "name": "Wood_Deadwood_Planks_Half",
      "rotation": 8
    },
    {
      "x": 0,
      "y": 14,
      "z": -4,
      "name": "Furniture_Human_Ruins_Pot"
    },
    {
      "x": 0,
      "y": 15,
      "z": -4,
      "name": "Empty"
    },
    {
      "x": 0,
      "y": 16,
      "z": -4,
      "name": "Empty"
    },
    {
      "x": 0,
      "y": 17,
      "z": -4,
      "name": "Wood_Deadwood_Roof_Flat",
      "rotation": 1
    },
    {
      "x": 0,
      "y": 0,
      "z": -3,
      "name": "Rock_Basalt"
    },
    {
      "x": 0,
      "y": 1,
      "z": -3,
      "name": "Rock_Basalt"
    },
    {
      "x": 0,
      "y": 2,
      "z": -3,
      "name": "Rock_Basalt"
    },
    {
      "x": 0,
      "y": 3,
      "z": -3,
      "name": "Rock_Basalt"
    },
    {
      "x": 0,
      "y": 4,
      "z": -3,
      "name": "Rock_Basalt"
    },
    {
      "x": 0,
      "y": 5,
      "z": -3,
      "name": "Rock_Basalt"
    },
    {
      "x": 0,
      "y": 6,
      "z": -3,
      "name": "Rock_Basalt_Cobble"
    },
    {
      "x": 0,
      "y": 7,
      "z": -3,
      "name": "Rock_Basalt_Cobble"
    },
    {
      "x": 0,
      "y": 8,
      "z": -3,
      "name": "Rock_Basalt_Cobble"
    },
    {
      "x": 0,
      "y": 9,
      "z": -3,
      "name": "Wood_Deadwood_Planks"
    },
    {
      "x": 0,
      "y": 10,
      "z": -3,
      "name": "Empty"
    },
    {
      "x": 0,
      "y": 11,
      "z": -3,
      "name": "Empty"
    },
    {
      "x": 0,
      "y": 12,
      "z": -3,
      "name": "Empty"
    },
    {
      "x": 0,
      "y": 13,
      "z": -3,
      "name": "Wood_Deadwood_Planks_Half",
      "rotation": 8
    },
    {
      "x": 0,
      "y": 14,
      "z": -3,
      "name": "Empty"
    },
    {
      "x": 0,
      "y": 15,
      "z": -3,
      "name": "Empty"
    },
    {
      "x": 0,
      "y": 16,
      "z": -3,
      "name": "Empty"
    },
    {
      "x": 0,
      "y": 17,
      "z": -3,
      "name": "Wood_Deadwood_Roof_Flat",
      "rotation": 1
    },
    {
      "x": 0,
      "y": 1,
      "z": -2,
      "name": "Rock_Basalt"
    },
    {
      "x": 0,
      "y": 2,
      "z": -2,
      "name": "Rock_Basalt"
    },
    {
      "x": 0,
      "y": 3,
      "z": -2,
      "name": "Rock_Basalt"
    },
    {
      "x": 0,
      "y": 4,
      "z": -2,
      "name": "Rock_Basalt"
    },
    {
      "x": 0,
      "y": 5,
      "z": -2,
      "name": "Rock_Basalt"
    },
    {
      "x": 0,
      "y": 6,
      "z": -2,
      "name": "Rock_Basalt_Cobble"
    },
    {
      "x": 0,
      "y": 7,
      "z": -2,
      "name": "Rock_Basalt_Cobble"
    },
    {
      "x": 0,
      "y": 8,
      "z": -2,
      "name": "Rock_Basalt_Cobble"
    },
    {
      "x": 0,
      "y": 9,
      "z": -2,
      "name": "Wood_Deadwood_Planks"
    },
    {
      "x": 0,
      "y": 10,
      "z": -2,
      "name": "Empty"
    },
    {
      "x": 0,
      "y": 11,
      "z": -2,
      "name": "Empty"
    },
    {
      "x": 0,
      "y": 12,
      "z": -2,
      "name": "Empty"
    },
    {
      "x": 0,
      "y": 13,
      "z": -2,
      "name": "Wood_Deadwood_Planks_Half",
      "rotation": 8
    },
    {
      "x": 0,
      "y": 14,
      "z": -2,
      "name": "Empty"
    },
    {
      "x": 0,
      "y": 15,
      "z": -2,
      "name": "Empty"
    },
    {
      "x": 0,
      "y": 16,
      "z": -2,
      "name": "Empty"
    },
    {
      "x": 0,
      "y": 17,
      "z": -2,
      "name": "Wood_Deadwood_Roof_Flat",
      "rotation": 1
    },
    {
      "x": 0,
      "y": 2,
      "z": -1,
      "name": "Rock_Basalt"
    },
    {
      "x": 0,
      "y": 3,
      "z": -1,
      "name": "Rock_Basalt"
    },
    {
      "x": 0,
      "y": 4,
      "z": -1,
      "name": "Rock_Basalt"
    },
    {
      "x": 0,
      "y": 5,
      "z": -1,
      "name": "Rock_Basalt"
    },
    {
      "x": 0,
      "y": 6,
      "z": -1,
      "name": "Rock_Basalt_Cobble"
    },
    {
      "x": 0,
      "y": 7,
      "z": -1,
      "name": "Rock_Basalt_Cobble"
    },
    {
      "x": 0,
      "y": 8,
      "z": -1,
      "name": "Rock_Basalt_Cobble"
    },
    {
      "x": 0,
      "y": 9,
      "z": -1,
      "name": "Wood_Deadwood_Planks"
    },
    {
      "x": 0,
      "y": 10,
      "z": -1,
      "name": "Empty"
    },
    {
      "x": 0,
      "y": 11,
      "z": -1,
      "name": "Empty"
    },
    {
      "x": 0,
      "y": 12,
      "z": -1,
      "name": "Empty"
    },
    {
      "x": 0,
      "y": 13,
      "z": -1,
      "name": "Wood_Deadwood_Planks_Half",
      "rotation": 8
    },
    {
      "x": 0,
      "y": 14,
      "z": -1,
      "name": "Empty"
    },
    {
      "x": 0,
      "y": 15,
      "z": -1,
      "name": "Empty"
    },
    {
      "x": 0,
      "y": 16,
      "z": -1,
      "name": "Empty"
    },
    {
      "x": 0,
      "y": 17,
      "z": -1,
      "name": "Wood_Deadwood_Roof_Flat",
      "rotation": 1
    },
    {
      "x": 0,
      "y": 2,
      "z": 0,
      "name": "Rock_Basalt"
    },
    {
      "x": 0,
      "y": 3,
      "z": 0,
      "name": "Rock_Basalt"
    },
    {
      "x": 0,
      "y": 4,
      "z": 0,
      "name": "Rock_Basalt"
    },
    {
      "x": 0,
      "y": 5,
      "z": 0,
      "name": "Rock_Basalt"
    },
    {
      "x": 0,
      "y": 6,
      "z": 0,
      "name": "Rock_Basalt_Cobble"
    },
    {
      "x": 0,
      "y": 7,
      "z": 0,
      "name": "Rock_Basalt_Cobble"
    },
    {
      "x": 0,
      "y": 8,
      "z": 0,
      "name": "Rock_Basalt_Cobble"
    },
    {
      "x": 0,
      "y": 9,
      "z": 0,
      "name": "Wood_Deadwood_Planks"
    },
    {
      "x": 0,
      "y": 10,
      "z": 0,
      "name": "Empty"
    },
    {
      "x": 0,
      "y": 11,
      "z": 0,
      "name": "Empty"
    },
    {
      "x": 0,
      "y": 12,
      "z": 0,
      "name": "Empty"
    },
    {
      "x": 0,
      "y": 13,
      "z": 0,
      "name": "Empty"
    },
    {
      "x": 0,
      "y": 14,
      "z": 0,
      "name": "Empty"
    },
    {
      "x": 0,
      "y": 15,
      "z": 0,
      "name": "Empty"
    },
    {
      "x": 0,
      "y": 16,
      "z": 0,
      "name": "Empty"
    },
    {
      "x": 0,
      "y": 17,
      "z": 0,
      "name": "Wood_Deadwood_Roof_Flat",
      "rotation": 1
    },
    {
      "x": 0,
      "y": 1,
      "z": 1,
      "name": "Rock_Basalt"
    },
    {
      "x": 0,
      "y": 2,
      "z": 1,
      "name": "Rock_Basalt"
    },
    {
      "x": 0,
      "y": 3,
      "z": 1,
      "name": "Rock_Basalt"
    },
    {
      "x": 0,
      "y": 4,
      "z": 1,
      "name": "Rock_Basalt"
    },
    {
      "x": 0,
      "y": 5,
      "z": 1,
      "name": "Rock_Basalt"
    },
    {
      "x": 0,
      "y": 6,
      "z": 1,
      "name": "Rock_Basalt_Cobble"
    },
    {
      "x": 0,
      "y": 7,
      "z": 1,
      "name": "Rock_Basalt_Cobble"
    },
    {
      "x": 0,
      "y": 8,
      "z": 1,
      "name": "Rock_Basalt_Cobble"
    },
    {
      "x": 0,
      "y": 9,
      "z": 1,
      "name": "Wood_Deadwood_Planks"
    },
    {
      "x": 0,
      "y": 10,
      "z": 1,
      "name": "Empty"
    },
    {
      "x": 0,
      "y": 11,
      "z": 1,
      "name": "Empty"
    },
    {
      "x": 0,
      "y": 12,
      "z": 1,
      "name": "Empty"
    },
    {
      "x": 0,
      "y": 13,
      "z": 1,
      "name": "Empty"
    },
    {
      "x": 0,
      "y": 14,
      "z": 1,
      "name": "Empty"
    },
    {
      "x": 0,
      "y": 15,
      "z": 1,
      "name": "Empty"
    },
    {
      "x": 0,
      "y": 16,
      "z": 1,
      "name": "Empty"
    },
    {
      "x": 0,
      "y": 17,
      "z": 1,
      "name": "Wood_Deadwood_Roof_Flat",
      "rotation": 1
    },
    {
      "x": 0,
      "y": 0,
      "z": 2,
      "name": "Rock_Basalt"
    },
    {
      "x": 0,
      "y": 1,
      "z": 2,
      "name": "Rock_Basalt"
    },
    {
      "x": 0,
      "y": 2,
      "z": 2,
      "name": "Rock_Basalt"
    },
    {
      "x": 0,
      "y": 3,
      "z": 2,
      "name": "Rock_Basalt"
    },
    {
      "x": 0,
      "y": 4,
      "z": 2,
      "name": "Rock_Basalt"
    },
    {
      "x": 0,
      "y": 5,
      "z": 2,
      "name": "Rock_Basalt"
    },
    {
      "x": 0,
      "y": 6,
      "z": 2,
      "name": "Rock_Basalt_Cobble"
    },
    {
      "x": 0,
      "y": 7,
      "z": 2,
      "name": "Rock_Basalt_Cobble"
    },
    {
      "x": 0,
      "y": 8,
      "z": 2,
      "name": "Rock_Basalt_Cobble"
    },
    {
      "x": 0,
      "y": 9,
      "z": 2,
      "name": "Wood_Deadwood_Planks"
    },
    {
      "x": 0,
      "y": 10,
      "z": 2,
      "name": "Empty"
    },
    {
      "x": 0,
      "y": 11,
      "z": 2,
      "name": "Empty"
    },
    {
      "x": 0,
      "y": 12,
      "z": 2,
      "name": "Empty"
    },
    {
      "x": 0,
      "y": 13,
      "z": 2,
      "name": "Empty"
    },
    {
      "x": 0,
      "y": 14,
      "z": 2,
      "name": "Empty"
    },
    {
      "x": 0,
      "y": 15,
      "z": 2,
      "name": "Empty"
    },
    {
      "x": 0,
      "y": 16,
      "z": 2,
      "name": "Empty"
    },
    {
      "x": 0,
      "y": 17,
      "z": 2,
      "name": "Wood_Deadwood_Roof_Flat"
    },
    {
      "x": 0,
      "y": 0,
      "z": 3,
      "name": "Rock_Basalt"
    },
    {
      "x": 0,
      "y": 1,
      "z": 3,
      "name": "Rock_Basalt"
    },
    {
      "x": 0,
      "y": 2,
      "z": 3,
      "name": "Rock_Basalt"
    },
    {
      "x": 0,
      "y": 3,
      "z": 3,
      "name": "Rock_Basalt"
    },
    {
      "x": 0,
      "y": 4,
      "z": 3,
      "name": "Rock_Basalt"
    },
    {
      "x": 0,
      "y": 5,
      "z": 3,
      "name": "Rock_Basalt"
    },
    {
      "x": 0,
      "y": 6,
      "z": 3,
      "name": "Rock_Basalt_Cobble"
    },
    {
      "x": 0,
      "y": 7,
      "z": 3,
      "name": "Rock_Basalt_Cobble"
    },
    {
      "x": 0,
      "y": 8,
      "z": 3,
      "name": "Rock_Basalt_Cobble"
    },
    {
      "x": 0,
      "y": 9,
      "z": 3,
      "name": "Wood_Deadwood_Planks"
    },
    {
      "x": 0,
      "y": 10,
      "z": 3,
      "name": "Empty"
    },
    {
      "x": 0,
      "y": 11,
      "z": 3,
      "name": "Empty"
    },
    {
      "x": 0,
      "y": 12,
      "z": 3,
      "name": "Empty"
    },
    {
      "x": 0,
      "y": 13,
      "z": 3,
      "name": "Empty"
    },
    {
      "x": 0,
      "y": 14,
      "z": 3,
      "name": "Empty"
    },
    {
      "x": 0,
      "y": 15,
      "z": 3,
      "name": "Empty"
    },
    {
      "x": 0,
      "y": 16,
      "z": 3,
      "name": "Empty"
    },
    {
      "x": 0,
      "y": 17,
      "z": 3,
      "name": "Wood_Deadwood_Roof_Flat"
    },
    {
      "x": 0,
      "y": 0,
      "z": 4,
      "name": "Rock_Basalt"
    },
    {
      "x": 0,
      "y": 1,
      "z": 4,
      "name": "Rock_Basalt"
    },
    {
      "x": 0,
      "y": 2,
      "z": 4,
      "name": "Rock_Basalt"
    },
    {
      "x": 0,
      "y": 3,
      "z": 4,
      "name": "Rock_Basalt"
    },
    {
      "x": 0,
      "y": 4,
      "z": 4,
      "name": "Rock_Basalt"
    },
    {
      "x": 0,
      "y": 5,
      "z": 4,
      "name": "Rock_Basalt"
    },
    {
      "x": 0,
      "y": 6,
      "z": 4,
      "name": "Rock_Basalt_Cobble"
    },
    {
      "x": 0,
      "y": 7,
      "z": 4,
      "name": "Rock_Basalt_Cobble"
    },
    {
      "x": 0,
      "y": 8,
      "z": 4,
      "name": "Rock_Basalt_Cobble"
    },
    {
      "x": 0,
      "y": 9,
      "z": 4,
      "name": "Wood_Deadwood_Planks"
    },
    {
      "x": 0,
      "y": 10,
      "z": 4,
      "name": "Empty"
    },
    {
      "x": 0,
      "y": 11,
      "z": 4,
      "name": "Empty"
    },
    {
      "x": 0,
      "y": 12,
      "z": 4,
      "name": "Empty"
    },
    {
      "x": 0,
      "y": 13,
      "z": 4,
      "name": "Empty"
    },
    {
      "x": 0,
      "y": 14,
      "z": 4,
      "name": "Empty"
    },
    {
      "x": 0,
      "y": 15,
      "z": 4,
      "name": "Empty"
    },
    {
      "x": 0,
      "y": 16,
      "z": 4,
      "name": "Empty"
    },
    {
      "x": 0,
      "y": 17,
      "z": 4,
      "name": "Wood_Deadwood_Roof_Flat"
    },
    {
      "x": 0,
      "y": 0,
      "z": 5,
      "name": "Rock_Basalt"
    },
    {
      "x": 0,
      "y": 1,
      "z": 5,
      "name": "Rock_Basalt"
    },
    {
      "x": 0,
      "y": 2,
      "z": 5,
      "name": "Rock_Basalt"
    },
    {
      "x": 0,
      "y": 3,
      "z": 5,
      "name": "Rock_Basalt"
    },
    {
      "x": 0,
      "y": 4,
      "z": 5,
      "name": "Rock_Basalt"
    },
    {
      "x": 0,
      "y": 5,
      "z": 5,
      "name": "Rock_Basalt"
    },
    {
      "x": 0,
      "y": 6,
      "z": 5,
      "name": "Rock_Basalt_Cobble"
    },
    {
      "x": 0,
      "y": 7,
      "z": 5,
      "name": "Rock_Basalt_Cobble"
    },
    {
      "x": 0,
      "y": 8,
      "z": 5,
      "name": "Rock_Basalt_Cobble"
    },
    {
      "x": 0,
      "y": 9,
      "z": 5,
      "name": "Wood_Deadwood_Planks"
    },
    {
      "x": 0,
      "y": 10,
      "z": 5,
      "name": "Empty"
    },
    {
      "x": 0,
      "y": 11,
      "z": 5,
      "name": "Empty"
    },
    {
      "x": 0,
      "y": 12,
      "z": 5,
      "name": "Empty"
    },
    {
      "x": 0,
      "y": 13,
      "z": 5,
      "name": "Empty"
    },
    {
