{
  "version": 8,
  "blockIdVersion": 10,
  "anchorX": -3,
  "anchorY": 10,
  "anchorZ": -6,
  "blocks": [
    {
      "x": -11,
      "y": 19,
      "z": -8,
      "name": "Plant_Leaves_Jungle"
    },
    {
      "x": -11,
      "y": 20,
      "z": -8,
      "name": "Plant_Leaves_Jungle"
    },
    {
      "x": -11,
      "y": 20,
      "z": -7,
      "name": "Plant_Leaves_Jungle"
    },
    {
      "x": -11,
      "y": 21,
      "z": -7,
      "name": "Plant_Leaves_Jungle"
    },
    {
      "x": -11,
      "y": 18,
      "z": -6,
      "name": "Plant_Leaves_Jungle"
    },
    {
      "x": -11,
      "y": 19,
      "z": -6,
      "name": "Plant_Leaves_Jungle"
    },
    {
      "x": -11,
      "y": 20,
      "z": -6,
      "name": "Plant_Leaves_Jungle"
    },
    {
      "x": -11,
      "y": 21,
      "z": -6,
      "name": "Plant_Leaves_Jungle"
    },
    {
      "x": -11,
      "y": 20,
      "z": -5,
      "name": "Plant_Leaves_Jungle"
    },
    {
      "x": -10,
      "y": 20,
      "z": -9,
      "name": "Plant_Leaves_Jungle"
    },
    {
      "x": -10,
      "y": 20,
      "z": -8,
      "name": "Plant_Leaves_Jungle"
    },
    {
      "x": -10,
      "y": 21,
      "z": -8,
      "name": "Plant_Leaves_Jungle"
    },
    {
      "x": -10,
      "y": 22,
      "z": -8,
      "name": "Plant_Leaves_Jungle"
    },
    {
      "x": -10,
      "y": 21,
      "z": -7,
      "name": "Plant_Leaves_Jungle"
    },
    {
      "x": -10,
      "y": 22,
      "z": -7,
      "name": "Plant_Leaves_Jungle"
    },
    {
      "x": -10,
      "y": 22,
      "z": -6,
      "name": "Plant_Leaves_Jungle"
    },
    {
      "x": -10,
      "y": 20,
      "z": -5,
      "name": "Plant_Leaves_Jungle"
    },
    {
      "x": -10,
      "y": 20,
      "z": -4,
      "name": "Plant_Leaves_Jungle"
    },
    {
      "x": -10,
      "y": 21,
      "z": -4,
      "name": "Plant_Leaves_Jungle"
    },
    {
      "x": -9,
      "y": 20,
      "z": -10,
      "name": "Plant_Leaves_Jungle"
    },
    {
      "x": -9,
      "y": 21,
      "z": -9,
      "name": "Plant_Leaves_Jungle"
    },
    {
      "x": -9,
      "y": 22,
      "z": -9,
      "name": "Plant_Leaves_Jungle"
    },
    {
      "x": -9,
      "y": 23,
      "z": -8,
      "name": "Plant_Leaves_Jungle"
    },
    {
      "x": -9,
      "y": 20,
      "z": -7,
      "name": "Wood_Jungle_Branch_Corner",
      "rotation": 3
    },
    {
      "x": -9,
      "y": 21,
      "z": -7,
      "name": "Wood_Jungle_Branch_Long"
    },
    {
      "x": -9,
      "y": 22,
      "z": -7,
      "name": "Plant_Leaves_Jungle"
    },
    {
      "x": -9,
      "y": 23,
      "z": -7,
      "name": "Plant_Leaves_Jungle"
    },
    {
      "x": -9,
      "y": 22,
      "z": -6,
      "name": "Plant_Leaves_Jungle"
    },
    {
      "x": -9,
      "y": 23,
      "z": -6,
      "name": "Plant_Leaves_Jungle"
    },
    {
      "x": -9,
      "y": 20,
      "z": -5,
      "name": "Plant_Leaves_Jungle"
    },
    {
      "x": -9,
      "y": 22,
      "z": -5,
      "name": "Plant_Leaves_Jungle"
    },
    {
      "x": -9,
      "y": 19,
      "z": -4,
      "name": "Plant_Leaves_Jungle"
    },
    {
      "x": -9,
      "y": 20,
      "z": -4,
      "name": "Plant_Leaves_Jungle"
    },
    {
      "x": -9,
      "y": 21,
      "z": -4,
      "name": "Plant_Leaves_Jungle"
    },
    {
      "x": -9,
      "y": 22,
      "z": -4,
      "name": "Plant_Leaves_Jungle"
    },
    {
      "x": -9,
      "y": 19,
      "z": -3,
      "name": "Plant_Leaves_Jungle"
    },
    {
      "x": -9,
      "y": 20,
      "z": -3,
      "name": "Plant_Leaves_Jungle"
    },
    {
      "x": -9,
      "y": 21,
      "z": -3,
      "name": "Plant_Leaves_Jungle"
    },
    {
      "x": -8,
      "y": 18,
      "z": -10,
      "name": "Plant_Leaves_Jungle"
    },
    {
      "x": -8,
      "y": 19,
      "z": -10,
      "name": "Plant_Leaves_Jungle"
    },
    {
      "x": -8,
      "y": 20,
      "z": -10,
      "name": "Plant_Leaves_Jungle"
    },
    {
      "x": -8,
      "y": 21,
      "z": -10,
      "name": "Plant_Leaves_Jungle"
    },
    {
      "x": -8,
      "y": 21,
      "z": -9,
      "name": "Plant_Leaves_Jungle"
    },
    {
      "x": -8,
      "y": 22,
      "z": -9,
      "name": "Plant_Leaves_Jungle"
    },
    {
      "x": -8,
      "y": 23,
      "z": -9,
      "name": "Plant_Leaves_Jungle"
    },
    {
      "x": -8,
      "y": 23,
      "z": -8,
      "name": "Plant_Leaves_Jungle"
    },
    {
      "x": -8,
      "y": 20,
      "z": -7,
      "name": "Wood_Jungle_Branch_Long",
      "rotation": 5
    },
    {
      "x": -8,
      "y": 23,
      "z": -7,
      "name": "Plant_Leaves_Jungle"
    },
    {
      "x": -8,
      "y": 22,
      "z": -6,
      "name": "Plant_Leaves_Jungle"
    },
    {
      "x": -8,
      "y": 23,
      "z": -6,
      "name": "Plant_Leaves_Jungle"
    },
    {
      "x": -8,
      "y": 23,
      "z": -5,
      "name": "Plant_Leaves_Jungle"
    },
    {
      "x": -8,
      "y": 22,
      "z": -4,
      "name": "Plant_Leaves_Jungle"
    },
    {
      "x": -8,
      "y": 18,
      "z": -3,
      "name": "Plant_Leaves_Jungle"
    },
    {
      "x": -8,
      "y": 19,
      "z": -3,
      "name": "Plant_Leaves_Jungle"
    },
    {
      "x": -8,
      "y": 20,
      "z": -3,
      "name": "Plant_Leaves_Jungle"
    },
    {
      "x": -8,
      "y": 21,
      "z": -3,
      "name": "Plant_Leaves_Jungle"
    },
    {
      "x": -7,
      "y": 22,
      "z": -10,
      "name": "Plant_Leaves_Jungle"
    },
    {
      "x": -7,
      "y": 22,
      "z": -9,
      "name": "Plant_Leaves_Jungle"
    },
    {
      "x": -7,
      "y": 23,
      "z": -8,
      "name": "Plant_Leaves_Jungle"
    },
    {
      "x": -7,
      "y": 18,
      "z": -7,
      "name": "Wood_Jungle_Trunk_Full"
    },
    {
      "x": -7,
      "y": 19,
      "z": -7,
      "name": "Wood_Jungle_Trunk"
    },
    {
      "x": -7,
      "y": 20,
      "z": -7,
      "name": "Wood_Jungle_Trunk_Full"
    },
    {
      "x": -7,
      "y": 21,
      "z": -7,
      "name": "Wood_Jungle_Branch_Long"
    },
    {
      "x": -7,
      "y": 22,
      "z": -7,
      "name": "Wood_Jungle_Branch_Long"
    },
    {
      "x": -7,
      "y": 23,
      "z": -7,
      "name": "Plant_Leaves_Jungle"
    },
    {
      "x": -7,
      "y": 19,
      "z": -6,
      "name": "Wood_Jungle_Branch_Long",
      "rotation": 4
    },
    {
      "x": -7,
      "y": 19,
      "z": -5,
      "name": "Wood_Jungle_Branch_Long",
      "rotation": 4
    },
    {
      "x": -7,
      "y": 23,
      "z": -5,
      "name": "Plant_Leaves_Jungle"
    },
    {
      "x": -7,
      "y": 19,
      "z": -4,
      "name": "Wood_Jungle_Branch_Corner"
    },
    {
      "x": -7,
      "y": 20,
      "z": -4,
      "name": "Wood_Jungle_Branch_Long"
    },
    {
      "x": -7,
      "y": 21,
      "z": -4,
      "name": "Plant_Leaves_Jungle"
    },
    {
      "x": -7,
      "y": 22,
      "z": -4,
      "name": "Plant_Leaves_Jungle"
    },
    {
      "x": -7,
      "y": 19,
      "z": -3,
      "name": "Plant_Leaves_Jungle"
    },
    {
      "x": -7,
      "y": 20,
      "z": -3,
      "name": "Plant_Leaves_Jungle"
    },
    {
      "x": -7,
      "y": 21,
      "z": -3,
      "name": "Plant_Leaves_Jungle"
    },
    {
      "x": -7,
      "y": 22,
      "z": -3,
      "name": "Plant_Leaves_Jungle"
    },
    {
      "x": -7,
      "y": 16,
      "z": -1,
      "name": "Plant_Leaves_Jungle"
    },
    {
      "x": -7,
      "y": 17,
      "z": -1,
      "name": "Plant_Leaves_Jungle"
    },
    {
      "x": -7,
      "y": 18,
      "z": -1,
      "name": "Plant_Leaves_Jungle"
    },
    {
      "x": -7,
      "y": 19,
      "z": -1,
      "name": "Plant_Leaves_Jungle"
    },
    {
      "x": -7,
      "y": 20,
      "z": -1,
      "name": "Plant_Leaves_Jungle"
    },
    {
      "x": -7,
      "y": 15,
      "z": 0,
      "name": "Plant_Leaves_Jungle"
    },
    {
      "x": -7,
      "y": 16,
      "z": 0,
      "name": "Plant_Leaves_Jungle"
    },
    {
      "x": -7,
      "y": 18,
      "z": 0,
      "name": "Plant_Leaves_Jungle"
    },
    {
      "x": -7,
      "y": 17,
      "z": 1,
      "name": "Plant_Leaves_Jungle"
    },
    {
      "x": -7,
      "y": 18,
      "z": 1,
      "name": "Plant_Leaves_Jungle"
    },
    {
      "x": -7,
      "y": 19,
      "z": 1,
      "name": "Plant_Leaves_Jungle"
    },
    {
      "x": -6,
      "y": 18,
      "z": -12,
      "name": "Plant_Leaves_Jungle"
    },
    {
      "x": -6,
      "y": 19,
      "z": -12,
      "name": "Plant_Leaves_Jungle"
    },
    {
      "x": -6,
      "y": 20,
      "z": -12,
      "name": "Plant_Leaves_Jungle"
    },
    {
      "x": -6,
      "y": 17,
      "z": -11,
      "name": "Plant_Leaves_Jungle"
    },
    {
      "x": -6,
      "y": 18,
      "z": -11,
      "name": "Plant_Leaves_Jungle"
    },
    {
      "x": -6,
      "y": 19,
      "z": -11,
      "name": "Plant_Leaves_Jungle"
    },
    {
      "x": -6,
      "y": 20,
      "z": -11,
      "name": "Plant_Leaves_Jungle"
    },
    {
      "x": -6,
      "y": 18,
      "z": -10,
      "name": "Plant_Leaves_Jungle"
    },
    {
      "x": -6,
      "y": 19,
      "z": -10,
      "name": "Plant_Leaves_Jungle"
    },
    {
      "x": -6,
      "y": 20,
      "z": -10,
      "name": "Plant_Leaves_Jungle"
    },
    {
      "x": -6,
      "y": 21,
      "z": -10,
      "name": "Plant_Leaves_Jungle"
    },
    {
      "x": -6,
      "y": 18,
      "z": -9,
      "name": "Plant_Leaves_Jungle"
    },
    {
      "x": -6,
      "y": 20,
      "z": -9,
      "name": "Plant_Leaves_Jungle"
    },
    {
      "x": -6,
      "y": 22,
      "z": -9,
      "name": "Plant_Leaves_Jungle"
    },
    {
      "x": -6,
      "y": 19,
      "z": -8,
      "name": "Plant_Leaves_Jungle"
    },
    {
      "x": -6,
      "y": 18,
      "z": -7,
      "name": "Wood_Jungle_Trunk_Full"
    },
    {
      "x": -6,
      "y": 23,
      "z": -7,
      "name": "Plant_Leaves_Jungle"
    },
    {
      "x": -6,
      "y": 16,
      "z": -6,
      "name": "Wood_Jungle_Trunk_Full"
    },
    {
      "x": -6,
      "y": 17,
      "z": -6,
      "name": "Wood_Jungle_Trunk"
    },
    {
      "x": -6,
      "y": 18,
      "z": -6,
      "name": "Wood_Jungle_Trunk_Full"
    },
    {
      "x": -6,
      "y": 23,
      "z": -6,
      "name": "Plant_Leaves_Jungle"
    },
    {
      "x": -6,
      "y": 23,
      "z": -5,
      "name": "Plant_Leaves_Jungle"
    },
    {
      "x": -6,
      "y": 21,
      "z": -4,
      "name": "Plant_Leaves_Jungle"
    },
    {
      "x": -6,
      "y": 19,
      "z": -3,
      "name": "Plant_Leaves_Jungle"
    },
    {
      "x": -6,
      "y": 21,
      "z": -3,
      "name": "Plant_Leaves_Jungle"
    },
    {
      "x": -6,
      "y": 16,
      "z": -1,
      "name": "Plant_Leaves_Jungle"
    },
    {
      "x": -6,
      "y": 18,
      "z": -1,
      "name": "Plant_Leaves_Jungle"
    },
    {
      "x": -6,
      "y": 16,
      "z": 0,
      "name": "Plant_Leaves_Jungle"
    },
    {
      "x": -6,
      "y": 18,
      "z": 0,
      "name": "Plant_Leaves_Jungle"
    },
    {
      "x": -6,
      "y": 19,
      "z": 0,
      "name": "Plant_Leaves_Jungle"
    },
    {
      "x": -6,
      "y": 20,
      "z": 0,
      "name": "Plant_Leaves_Jungle"
    },
    {
      "x": -6,
      "y": 17,
      "z": 1,
      "name": "Plant_Leaves_Jungle"
    },
    {
      "x": -6,
      "y": 18,
      "z": 1,
      "name": "Plant_Leaves_Jungle"
    },
    {
      "x": -6,
      "y": 18,
      "z": 2,
      "name": "Plant_Leaves_Jungle"
    },
    {
      "x": -6,
      "y": 19,
      "z": 2,
      "name": "Plant_Leaves_Jungle"
    },
    {
      "x": -5,
      "y": 19,
      "z": -13,
      "name": "Plant_Leaves_Jungle"
    },
    {
      "x": -5,
      "y": 20,
      "z": -13,
      "name": "Plant_Leaves_Jungle"
    },
    {
      "x": -5,
      "y": 18,
      "z": -12,
      "name": "Plant_Leaves_Jungle"
    },
    {
      "x": -5,
      "y": 19,
      "z": -12,
      "name": "Plant_Leaves_Jungle"
    },
    {
      "x": -5,
      "y": 20,
      "z": -12,
      "name": "Plant_Leaves_Jungle"
    },
    {
      "x": -5,
      "y": 21,
      "z": -12,
      "name": "Plant_Leaves_Jungle"
    },
    {
      "x": -5,
      "y": 21,
      "z": -11,
      "name": "Plant_Leaves_Jungle"
    },
    {
      "x": -5,
      "y": 18,
      "z": -10,
      "name": "Wood_Jungle_Branch_Corner",
      "rotation": 3
    },
    {
      "x": -5,
      "y": 19,
      "z": -10,
      "name": "Wood_Jungle_Branch_Long"
    },
    {
      "x": -5,
      "y": 20,
      "z": -10,
      "name": "Plant_Leaves_Jungle"
    },
    {
      "x": -5,
      "y": 21,
      "z": -10,
      "name": "Plant_Leaves_Jungle"
    },
    {
      "x": -5,
      "y": 20,
      "z": -9,
      "name": "Plant_Leaves_Jungle"
    },
    {
      "x": -5,
      "y": 22,
      "z": -9,
      "name": "Plant_Leaves_Jungle"
    },
    {
      "x": -5,
      "y": 18,
      "z": -8,
      "name": "Plant_Leaves_Jungle"
    },
    {
      "x": -5,
      "y": 19,
      "z": -8,
      "name": "Plant_Leaves_Jungle"
    },
    {
      "x": -5,
      "y": 20,
      "z": -8,
      "name": "Plant_Leaves_Jungle"
    },
    {
      "x": -5,
      "y": 21,
      "z": -8,
      "name": "Plant_Leaves_Jungle"
    },
    {
      "x": -5,
      "y": 22,
      "z": -8,
      "name": "Plant_Leaves_Jungle"
    },
    {
      "x": -5,
      "y": 19,
      "z": -7,
      "name": "Plant_Leaves_Jungle"
    },
    {
      "x": -5,
      "y": 22,
      "z": -7,
      "name": "Plant_Leaves_Jungle"
    },
    {
      "x": -5,
      "y": 15,
      "z": -6,
      "name": "Wood_Jungle_Trunk_Full"
    },
    {
      "x": -5,
      "y": 16,
      "z": -6,
      "name": "Wood_Jungle_Trunk_Full"
    },
    {
      "x": -5,
      "y": 23,
      "z": -6,
      "name": "Plant_Leaves_Jungle"
    },
    {
      "x": -5,
      "y": 22,
      "z": -5,
      "name": "Plant_Leaves_Jungle"
    },
    {
      "x": -5,
      "y": 19,
      "z": -4,
      "name": "Plant_Leaves_Jungle"
    },
    {
      "x": -5,
      "y": 20,
      "z": -4,
      "name": "Plant_Leaves_Jungle"
    },
    {
      "x": -5,
      "y": 21,
      "z": -4,
      "name": "Plant_Leaves_Jungle"
    },
    {
      "x": -5,
      "y": 22,
      "z": -4,
      "name": "Plant_Leaves_Jungle"
    },
    {
      "x": -5,
      "y": 20,
      "z": -3,
      "name": "Plant_Leaves_Jungle"
    },
    {
      "x": -5,
      "y": 21,
      "z": -2,
      "name": "Plant_Leaves_Jungle"
    },
    {
      "x": -5,
      "y": 21,
      "z": -1,
      "name": "Plant_Leaves_Jungle"
    },
    {
      "x": -5,
      "y": 18,
      "z": 0,
      "name": "Wood_Jungle_Branch_Long",
      "rotation": 5
    },
    {
      "x": -5,
      "y": 19,
      "z": 0,
      "name": "Plant_Leaves_Jungle"
    },
    {
      "x": -5,
      "y": 20,
      "z": 0,
      "name": "Plant_Leaves_Jungle"
    },
    {
      "x": -5,
      "y": 21,
      "z": 0,
      "name": "Plant_Leaves_Jungle"
    },
    {
      "x": -5,
      "y": 18,
      "z": 1,
      "name": "Plant_Leaves_Jungle"
    },
    {
      "x": -5,
      "y": 21,
      "z": 1,
      "name": "Plant_Leaves_Jungle"
    },
    {
      "x": -5,
      "y": 16,
      "z": 2,
      "name": "Plant_Leaves_Jungle"
    },
    {
      "x": -5,
      "y": 17,
      "z": 2,
      "name": "Plant_Leaves_Jungle"
    },
    {
      "x": -5,
      "y": 18,
      "z": 2,
      "name": "Plant_Leaves_Jungle"
    },
    {
      "x": -5,
      "y": 19,
      "z": 2,
      "name": "Plant_Leaves_Jungle"
    },
    {
      "x": -5,
      "y": 20,
      "z": 2,
      "name": "Plant_Leaves_Jungle"
    },
    {
      "x": -5,
      "y": 19,
      "z": 3,
      "name": "Plant_Leaves_Jungle"
    },
    {
      "x": -4,
      "y": 19,
      "z": -14,
      "name": "Plant_Leaves_Jungle"
    },
    {
      "x": -4,
      "y": 19,
      "z": -13,
      "name": "Plant_Leaves_Jungle"
    },
    {
      "x": -4,
      "y": 19,
      "z": -12,
      "name": "Plant_Leaves_Jungle"
    },
    {
      "x": -4,
      "y": 21,
      "z": -12,
      "name": "Plant_Leaves_Jungle"
    },
    {
      "x": -4,
      "y": 22,
      "z": -11,
      "name": "Plant_Leaves_Jungle"
    },
    {
      "x": -4,
      "y": 18,
      "z": -10,
      "name": "Wood_Jungle_Branch_Long",
      "rotation": 5
    },
    {
      "x": -4,
      "y": 22,
      "z": -10,
      "name": "Plant_Leaves_Jungle"
    },
    {
      "x": -4,
      "y": 22,
      "z": -9,
      "name": "Plant_Leaves_Jungle"
    },
    {
      "x": -4,
      "y": 21,
      "z": -8,
      "name": "Plant_Leaves_Jungle"
    },
    {
      "x": -4,
      "y": 22,
      "z": -8,
      "name": "Plant_Leaves_Jungle"
    },
    {
      "x": -4,
      "y": 21,
      "z": -7,
      "name": "Plant_Leaves_Jungle"
    },
    {
      "x": -4,
      "y": 22,
      "z": -7,
      "name": "Plant_Leaves_Jungle"
    },
    {
      "x": -4,
      "y": 8,
      "z": -6,
      "name": "Wood_Jungle_Branch_Long"
    },
    {
      "x": -4,
      "y": 9,
      "z": -6,
      "name": "Wood_Jungle_Branch_Long"
    },
    {
      "x": -4,
      "y": 10,
      "z": -6,
      "name": "Wood_Jungle_Branch_Long"
    },
    {
      "x": -4,
      "y": 11,
      "z": -6,
      "name": "Wood_Jungle_Branch_Corner",
      "rotation": 9
    },
    {
      "x": -4,
      "y": 13,
      "z": -6,
      "name": "Wood_Jungle_Trunk_Full"
    },
    {
      "x": -4,
      "y": 14,
      "z": -6,
      "name": "Wood_Jungle_Trunk"
    },
    {
      "x": -4,
      "y": 15,
      "z": -6,
      "name": "Wood_Jungle_Trunk_Full"
    },
    {
      "x": -4,
      "y": 22,
      "z": -6,
      "name": "Plant_Leaves_Jungle"
    },
    {
      "x": -4,
      "y": 22,
      "z": -5,
      "name": "Plant_Leaves_Jungle"
    },
    {
      "x": -4,
      "y": 19,
      "z": -4,
      "name": "Plant_Leaves_Jungle"
    },
    {
      "x": -4,
      "y": 20,
      "z": -4,
      "name": "Plant_Leaves_Jungle"
    },
    {
      "x": -4,
      "y": 21,
      "z": -4,
      "name": "Plant_Leaves_Jungle"
    },
    {
      "x": -4,
      "y": 22,
      "z": -4,
      "name": "Plant_Leaves_Jungle"
    },
    {
      "x": -4,
      "y": 20,
      "z": -3,
      "name": "Plant_Leaves_Jungle"
    },
    {
      "x": -4,
      "y": 21,
      "z": -3,
      "name": "Plant_Leaves_Jungle"
    },
    {
      "x": -4,
      "y": 21,
      "z": -1,
      "name": "Plant_Leaves_Jungle"
    },
    {
      "x": -4,
      "y": 18,
      "z": 0,
      "name": "Wood_Jungle_Branch_Long",
      "rotation": 5
    },
    {
      "x": -4,
      "y": 21,
      "z": 0,
      "name": "Plant_Leaves_Jungle"
    },
    {
      "x": -4,
      "y": 19,
      "z": 3,
      "name": "Plant_Leaves_Jungle"
    },
    {
      "x": -4,
      "y": 20,
      "z": 3,
      "name": "Plant_Leaves_Jungle"
    },
    {
      "x": -4,
      "y": 19,
      "z": 4,
      "name": "Plant_Leaves_Jungle"
    },
    {
      "x": -3,
      "y": 17,
      "z": -14,
      "name": "Plant_Leaves_Jungle"
    },
    {
      "x": -3,
      "y": 18,
      "z": -14,
      "name": "Plant_Leaves_Jungle"
    },
    {
      "x": -3,
      "y": 19,
      "z": -14,
      "name": "Plant_Leaves_Jungle"
    },
    {
      "x": -3,
      "y": 20,
      "z": -14,
      "name": "Plant_Leaves_Jungle"
    },
    {
      "x": -3,
      "y": 21,
      "z": -13,
      "name": "Plant_Leaves_Jungle"
    },
    {
      "x": -3,
      "y": 21,
      "z": -12,
      "name": "Plant_Leaves_Jungle"
    },
    {
      "x": -3,
      "y": 22,
      "z": -12,
      "name": "Plant_Leaves_Jungle"
    },
    {
      "x": -3,
      "y": 21,
      "z": -11,
      "name": "Plant_Leaves_Jungle"
    },
    {
      "x": -3,
      "y": 22,
      "z": -11,
      "name": "Plant_Leaves_Jungle"
    },
    {
      "x": -3,
      "y": 18,
      "z": -10,
      "name": "Wood_Jungle_Branch_Long",
      "rotation": 5
    },
    {
      "x": -3,
      "y": 15,
      "z": -9,
      "name": "Wood_Jungle_Trunk_Full"
    },
    {
      "x": -3,
      "y": 16,
      "z": -9,
      "name": "Wood_Jungle_Trunk"
    },
    {
      "x": -3,
      "y": 17,
      "z": -9,
      "name": "Wood_Jungle_Trunk_Full"
    },
    {
      "x": -3,
      "y": 22,
      "z": -9,
      "name": "Plant_Leaves_Jungle"
    },
    {
      "x": -3,
      "y": 14,
      "z": -8,
      "name": "Wood_Jungle_Trunk_Full"
    },
    {
      "x": -3,
      "y": 15,
      "z": -8,
      "name": "Wood_Jungle_Trunk_Full"
    },
    {
      "x": -3,
      "y": 22,
      "z": -8,
      "name": "Plant_Leaves_Jungle"
    },
    {
      "x": -3,
      "y": 8,
      "z": -7,
      "name": "Wood_Jungle_Branch_Long"
    },
    {
      "x": -3,
      "y": 9,
      "z": -7,
      "name": "Wood_Jungle_Branch_Long"
    },
    {
      "x": -3,
      "y": 10,
      "z": -7,
      "name": "Wood_Jungle_Branch_Long"
    },
    {
      "x": -3,
      "y": 11,
      "z": -7,
      "name": "Wood_Jungle_Branch_Long"
    },
    {
      "x": -3,
      "y": 12,
      "z": -7,
      "name": "Wood_Jungle_Branch_Long"
    },
    {
      "x": -3,
      "y": 13,
      "z": -7,
      "name": "Wood_Jungle_Trunk_Full"
    },
    {
      "x": -3,
      "y": 14,
      "z": -7,
      "name": "Wood_Jungle_Trunk_Full"
    },
    {
      "x": -3,
      "y": 15,
      "z": -7,
      "name": "Wood_Jungle_Trunk_Full"
    },
    {
      "x": -3,
      "y": 21,
      "z": -7,
      "name": "Plant_Leaves_Jungle"
    },
    {
      "x": -3,
      "y": 8,
      "z": -6,
      "name": "Wood_Jungle_Trunk"
    },
    {
      "x": -3,
      "y": 9,
      "z": -6,
      "name": "Wood_Jungle_Trunk"
    },
    {
      "x": -3,
      "y": 10,
      "z": -6,
      "name": "Wood_Jungle_Branch_Long"
    },
    {
      "x": -3,
      "y": 11,
      "z": -6,
      "name": "Wood_Jungle_Trunk"
    },
    {
      "x": -3,
      "y": 12,
      "z": -6,
      "name": "Wood_Jungle_Trunk"
    },
    {
      "x": -3,
      "y": 13,
      "z": -6,
      "name": "Wood_Jungle_Trunk"
    },
    {
      "x": -3,
      "y": 14,
      "z": -6,
      "name": "Wood_Jungle_Trunk_Full"
    },
    {
      "x": -3,
      "y": 15,
      "z": -6,
      "name": "Wood_Jungle_Trunk_Full"
    },
    {
      "x": -3,
      "y": 24,
      "z": -6,
      "name": "Plant_Leaves_Jungle"
    },
    {
      "x": -3,
      "y": 14,
      "z": -5,
      "name": "Wood_Jungle_Trunk_Full"
    },
    {
      "x": -3,
      "y": 15,
      "z": -5,
      "name": "Wood_Jungle_Trunk"
    },
    {
      "x": -3,
      "y": 16,
      "z": -5,
      "name": "Wood_Jungle_Trunk_Full"
    },
    {
      "x": -3,
      "y": 16,
      "z": -4,
      "name": "Wood_Jungle_Trunk_Full"
    },
    {
      "x": -3,
      "y": 17,
      "z": -4,
      "name": "Wood_Jungle_Trunk_Full"
    },
    {
      "x": -3,
      "y": 22,
      "z": -4,
      "name": "Plant_Leaves_Jungle"
    },
    {
      "x": -3,
      "y": 23,
      "z": -4,
      "name": "Plant_Leaves_Jungle"
    },
    {
      "x": -3,
      "y": 17,
      "z": -3,
      "name": "Wood_Jungle_Trunk_Full"
    },
    {
      "x": -3,
      "y": 22,
      "z": -3,
      "name": "Plant_Leaves_Jungle"
    },
    {
      "x": -3,
      "y": 23,
      "z": -3,
      "name": "Plant_Leaves_Jungle"
    },
    {
      "x": -3,
      "y": 20,
      "z": -2,
      "name": "Plant_Leaves_Jungle"
    },
    {
      "x": -3,
      "y": 21,
      "z": -2,
      "name": "Plant_Leaves_Jungle"
    },
    {
      "x": -3,
      "y": 18,
      "z": 0,
      "name": "Wood_Jungle_Branch_Long",
      "rotation": 5
    },
    {
      "x": -3,
      "y": 21,
      "z": 0,
      "name": "Plant_Leaves_Jungle"
    },
    {
      "x": -3,
      "y": 21,
      "z": 2,
      "name": "Plant_Leaves_Jungle"
    },
    {
      "x": -3,
      "y": 17,
      "z": 3,
      "name": "Plant_Leaves_Jungle"
    },
    {
      "x": -3,
      "y": 18,
      "z": 3,
      "name": "Plant_Leaves_Jungle"
    },
    {
      "x": -3,
      "y": 19,
      "z": 3,
      "name": "Plant_Leaves_Jungle"
    },
    {
      "x": -3,
      "y": 18,
      "z": 4,
      "name": "Plant_Leaves_Jungle"
    },
    {
      "x": -3,
      "y": 19,
      "z": 4,
      "name": "Plant_Leaves_Jungle"
    },
    {
      "x": -2,
      "y": 19,
      "z": -14,
      "name": "Plant_Leaves_Jungle"
    },
    {
      "x": -2,
      "y": 20,
      "z": -14,
      "name": "Plant_Leaves_Jungle"
    },
    {
      "x": -2,
      "y": 20,
      "z": -13,
      "name": "Plant_Leaves_Jungle"
    },
    {
      "x": -2,
      "y": 21,
      "z": -13,
      "name": "Plant_Leaves_Jungle"
    },
    {
      "x": -2,
      "y": 19,
      "z": -12,
      "name": "Wood_Jungle_Branch_Corner",
      "rotation": 2
    },
    {
      "x": -2,
      "y": 20,
      "z": -12,
      "name": "Wood_Jungle_Branch_Long"
    },
    {
      "x": -2,
      "y": 21,
      "z": -12,
      "name": "Plant_Leaves_Jungle"
    },
    {
      "x": -2,
      "y": 22,
      "z": -12,
      "name": "Plant_Leaves_Jungle"
    },
    {
      "x": -2,
      "y": 19,
      "z": -11,
      "name": "Wood_Jungle_Branch_Long",
      "rotation": 4
    },
    {
      "x": -2,
      "y": 22,
      "z": -11,
      "name": "Plant_Leaves_Jungle"
    },
    {
      "x": -2,
      "y": 17,
      "z": -10,
      "name": "Wood_Jungle_Trunk_Full"
    },
    {
      "x": -2,
      "y": 18,
      "z": -10,
      "name": "Wood_Jungle_Trunk"
    },
    {
      "x": -2,
      "y": 19,
      "z": -10,
      "name": "Wood_Jungle_Trunk_Full"
    },
    {
      "x": -2,
      "y": 20,
      "z": -10,
      "name": "Wood_Jungle_Branch_Long"
    },
    {
      "x": -2,
      "y": 21,
      "z": -10,
      "name": "Wood_Jungle_Branch_Long"
    },
    {
      "x": -2,
      "y": 22,
      "z": -10,
      "name": "Plant_Leaves_Jungle"
    },
    {
      "x": -2,
      "y": 17,
      "z": -9,
      "name": "Wood_Jungle_Trunk_Full"
    },
    {
      "x": -2,
      "y": 22,
      "z": -9,
      "name": "Plant_Leaves_Jungle"
    },
    {
      "x": -2,
      "y": 8,
      "z": -8,
      "name": "Wood_Jungle_Branch_Long"
    },
    {
      "x": -2,
      "y": 9,
      "z": -8,
      "name": "Wood_Jungle_Branch_Long"
    },
    {
      "x": -2,
      "y": 10,
      "z": -8,
      "name": "Wood_Jungle_Branch_Corner",
      "rotation": 8
    },
    {
      "x": -2,
      "y": 21,
      "z": -8,
      "name": "Plant_Leaves_Jungle"
    },
    {
      "x": -2,
      "y": 24,
      "z": -8,
      "name": "Plant_Leaves_Jungle"
    },
    {
      "x": -2,
      "y": 8,
      "z": -7,
      "name": "Wood_Jungle_Trunk"
    },
    {
      "x": -2,
      "y": 9,
      "z": -7,
      "name": "Wood_Jungle_Trunk"
    },
    {
      "x": -2,
      "y": 10,
      "z": -7,
      "name": "Wood_Jungle_Trunk"
    },
    {
      "x": -2,
      "y": 11,
      "z": -7,
      "name": "Wood_Jungle_Trunk"
    },
    {
      "x": -2,
      "y": 12,
      "z": -7,
      "name": "Wood_Jungle_Trunk"
    },
    {
      "x": -2,
      "y": 13,
      "z": -7,
      "name": "Wood_Jungle_Trunk_Full"
    },
    {
      "x": -2,
      "y": 14,
      "z": -7,
      "name": "Wood_Jungle_Trunk_Full"
    },
    {
      "x": -2,
      "y": 15,
      "z": -7,
      "name": "Wood_Jungle_Trunk"
    },
    {
      "x": -2,
      "y": 21,
      "z": -7,
      "name": "Plant_Leaves_Jungle"
    },
    {
      "x": -2,
      "y": 8,
      "z": -6,
      "name": "Wood_Jungle_Trunk"
    },
    {
      "x": -2,
      "y": 9,
      "z": -6,
      "name": "Wood_Jungle_Trunk"
    },
    {
      "x": -2,
      "y": 10,
      "z": -6,
      "name": "Wood_Jungle_Trunk"
    },
    {
      "x": -2,
      "y": 11,
      "z": -6,
      "name": "Wood_Jungle_Trunk_Full"
    },
    {
      "x": -2,
      "y": 15,
      "z": -6,
      "name": "Wood_Jungle_Trunk_Full"
    },
    {
      "x": -2,
      "y": 16,
      "z": -6,
      "name": "Wood_Jungle_Trunk"
    },
    {
      "x": -2,
      "y": 17,
      "z": -6,
      "name": "Wood_Jungle_Trunk_Full"
    },
    {
      "x": -2,
      "y": 24,
      "z": -6,
      "name": "Plant_Leaves_Jungle"
    },
    {
      "x": -2,
      "y": 8,
      "z": -5,
      "name": "Wood_Jungle_Branch_Long"
    },
    {
      "x": -2,
      "y": 9,
      "z": -5,
      "name": "Wood_Jungle_Branch_Long"
    },
    {
      "x": -2,
      "y": 10,
      "z": -5,
      "name": "Wood_Jungle_Branch_Corner",
      "rotation": 10
    },
    {
      "x": -2,
      "y": 24,
      "z": -5,
      "name": "Plant_Leaves_Jungle"
    },
    {
      "x": -2,
      "y": 23,
      "z": -4,
      "name": "Plant_Leaves_Jungle"
    },
    {
      "x": -2,
      "y": 24,
      "z": -4,
      "name": "Plant_Leaves_Jungle"
    },
    {
      "x": -2,
      "y": 16,
      "z": -3,
      "name": "Wood_Jungle_Roots"
    },
    {
      "x": -2,
      "y": 17,
      "z": -3,
      "name": "Wood_Jungle_Trunk_Full"
    },
    {
      "x": -2,
      "y": 23,
      "z": -3,
      "name": "Plant_Leaves_Jungle"
    },
    {
      "x": -2,
      "y": 17,
      "z": -2,
      "name": "Wood_Jungle_Trunk_Full"
    },
    {
      "x": -2,
      "y": 18,
      "z": -2,
      "name": "Wood_Jungle_Trunk_Full"
    },
    {
      "x": -2,
      "y": 21,
      "z": -2,
      "name": "Plant_Leaves_Jungle"
    },
    {
      "x": -2,
      "y": 22,
      "z": -2,
      "name": "Plant_Leaves_Jungle"
    },
    {
      "x": -2,
      "y": 18,
      "z": -1,
      "name": "Wood_Jungle_Trunk_Full"
    },
    {
      "x": -2,
      "y": 19,
      "z": -1,
      "name": "Wood_Jungle_Branch_Long"
    },
    {
      "x": -2,
      "y": 20,
      "z": -1,
      "name": "Wood_Jungle_Branch_Long"
    },
    {
      "x": -2,
      "y": 21,
      "z": -1,
      "name": "Plant_Leaves_Jungle"
    },
    {
      "x": -2,
      "y": 18,
      "z": 0,
      "name": "Wood_Jungle_Trunk_Full"
    },
    {
      "x": -2,
      "y": 21,
      "z": 0,
      "name": "Plant_Leaves_Jungle"
    },
    {
      "x": -2,
      "y": 18,
      "z": 1,
      "name": "Wood_Jungle_Branch_Long",
      "rotation": 4
    },
    {
      "x": -2,
      "y": 21,
      "z": 1,
      "name": "Plant_Leaves_Jungle"
    },
    {
      "x": -2,
      "y": 18,
      "z": 2,
      "name": "Wood_Jungle_Branch_Corner"
    },
    {
      "x": -2,
      "y": 19,
      "z": 2,
      "name": "Wood_Jungle_Branch_Long"
    },
    {
      "x": -2,
      "y": 20,
      "z": 2,
      "name": "Plant_Leaves_Jungle"
    },
    {
      "x": -2,
      "y": 21,
      "z": 2,
      "name": "Plant_Leaves_Jungle"
    },
    {
      "x": -2,
      "y": 16,
      "z": 3,
      "name": "Plant_Leaves_Jungle"
    },
    {
      "x": -2,
      "y": 17,
      "z": 3,
      "name": "Plant_Leaves_Jungle"
    },
    {
      "x": -2,
      "y": 18,
      "z": 3,
      "name": "Plant_Leaves_Jungle"
    },
    {
      "x": -2,
      "y": 19,
      "z": 3,
      "name": "Plant_Leaves_Jungle"
    },
    {
      "x": -2,
      "y": 20,
      "z": 3,
      "name": "Plant_Leaves_Jungle"
    },
    {
      "x": -2,
      "y": 19,
      "z": 4,
      "name": "Plant_Leaves_Jungle"
    },
    {
      "x": -1,
      "y": 18,
      "z": -14,
      "name": "Plant_Leaves_Jungle"
    },
    {
      "x": -1,
      "y": 19,
      "z": -14,
      "name": "Plant_Leaves_Jungle"
    },
    {
      "x": -1,
      "y": 19,
      "z": -13,
      "name": "Plant_Leaves_Jungle"
    },
    {
      "x": -1,
      "y": 20,
      "z": -13,
      "name": "Plant_Leaves_Jungle"
    },
    {
      "x": -1,
      "y": 21,
      "z": -13,
      "name": "Plant_Leaves_Jungle"
    },
    {
      "x": -1,
      "y": 22,
      "z": -12,
      "name": "Plant_Leaves_Jungle"
    },
    {
      "x": -1,
      "y": 22,
      "z": -11,
      "name": "Plant_Leaves_Jungle"
    },
    {
      "x": -1,
      "y": 22,
      "z": -10,
      "name": "Plant_Leaves_Jungle"
    },
    {
      "x": -1,
      "y": 21,
      "z": -8,
      "name": "Plant_Leaves_Jungle"
    },
    {
      "x": -1,
      "y": 24,
      "z": -8,
      "name": "Plant_Leaves_Jungle"
    },
    {
      "x": -1,
      "y": 8,
      "z": -7,
      "name": "Wood_Jungle_Branch_Long"
    },
    {
      "x": -1,
      "y": 9,
      "z": -7,
      "name": "Wood_Jungle_Branch_Long"
    },
    {
      "x": -1,
      "y": 10,
      "z": -7,
      "name": "Wood_Jungle_Branch_Corner",
      "rotation": 11
    },
    {
      "x": -1,
      "y": 21,
      "z": -7,
      "name": "Plant_Leaves_Jungle"
    },
    {
      "x": -1,
      "y": 24,
      "z": -7,
      "name": "Plant_Leaves_Jungle"
    },
    {
      "x": -1,
      "y": 17,
      "z": -6,
      "name": "Wood_Jungle_Trunk_Full"
    },
    {
      "x": -1,
      "y": 24,
      "z": -6,
      "name": "Plant_Leaves_Jungle"
    },
    {
      "x": -1,
      "y": 17,
      "z": -5,
      "name": "Wood_Jungle_Trunk_Full"
    },
    {
      "x": -1,
      "y": 18,
      "z": -5,
      "name": "Wood_Jungle_Trunk"
    },
    {
      "x": -1,
      "y": 19,
      "z": -5,
      "name": "Wood_Jungle_Trunk"
    },
    {
      "x": -1,
      "y": 20,
      "z": -5,
      "name": "Wood_Jungle_Trunk"
    },
    {
      "x": -1,
      "y": 21,
      "z": -5,
      "name": "Wood_Jungle_Trunk_Full"
    },
    {
      "x": -1,
      "y": 22,
      "z": -5,
      "name": "Wood_Jungle_Branch_Long"
    },
    {
      "x": -1,
      "y": 23,
      "z": -5,
      "name": "Wood_Jungle_Branch_Long"
    },
    {
      "x": -1,
      "y": 24,
      "z": -5,
      "name": "Plant_Leaves_Jungle"
    },
    {
      "x": -1,
      "y": 20,
      "z": -4,
      "name": "Wood_Jungle_Branch_Long",
      "rotation": 4
    },
    {
      "x": -1,
      "y": 21,
      "z": -4,
      "name": "Plant_Leaves_Jungle"
    },
    {
      "x": -1,
      "y": 23,
      "z": -4,
      "name": "Plant_Leaves_Jungle"
    },
    {
      "x": -1,
      "y": 24,
      "z": -4,
      "name": "Plant_Leaves_Jungle"
    },
    {
      "x": -1,
      "y": 20,
      "z": -3,
      "name": "Wood_Jungle_Branch_Long",
      "rotation": 4
    },
    {
      "x": -1,
      "y": 21,
      "z": -3,
      "name": "Plant_Leaves_Jungle"
    },
    {
      "x": -1,
      "y": 22,
      "z": -3,
      "name": "Plant_Leaves_Jungle"
    },
    {
      "x": -1,
      "y": 23,
      "z": -3,
      "name": "Plant_Leaves_Jungle"
    },
    {
      "x": -1,
      "y": 24,
      "z": -3,
      "name": "Plant_Leaves_Jungle"
    },
    {
      "x": -1,
      "y": 20,
      "z": -2,
      "name": "Plant_Leaves_Jungle"
    },
    {
      "x": -1,
      "y": 21,
      "z": -2,
      "name": "Plant_Leaves_Jungle"
    },
    {
      "x": -1,
      "y": 22,
      "z": -2,
      "name": "Plant_Leaves_Jungle"
    },
    {
      "x": -1,
      "y": 23,
      "z": -2,
      "name": "Plant_Leaves_Jungle"
    },
    {
      "x": -1,
      "y": 18,
      "z": -1,
      "name": "Wood_Jungle_Branch_Long",
      "rotation": 5
    },
    {
      "x": -1,
      "y": 19,
      "z": -1,
      "name": "Plant_Leaves_Jungle"
    },
    {
      "x": -1,
      "y": 20,
      "z": -1,
      "name": "Plant_Leaves_Jungle"
    },
    {
      "x": -1,
      "y": 21,
      "z": -1,
      "name": "Plant_Leaves_Jungle"
    },
    {
      "x": -1,
      "y": 21,
      "z": 1,
      "name": "Plant_Leaves_Jungle"
    },
    {
      "x": -1,
      "y": 21,
      "z": 2,
      "name": "Plant_Leaves_Jungle"
    },
    {
      "x": -1,
      "y": 17,
      "z": 3,
      "name": "Plant_Leaves_Jungle"
    },
    {
      "x": -1,
      "y": 18,
      "z": 3,
      "name": "Plant_Leaves_Jungle"
    },
    {
      "x": -1,
      "y": 19,
      "z": 3,
      "name": "Plant_Leaves_Jungle"
    },
    {
      "x": -1,
      "y": 19,
      "z": 4,
      "name": "Plant_Leaves_Jungle"
    },
    {
      "x": 0,
      "y": 19,
      "z": -13,
      "name": "Plant_Leaves_Jungle"
    },
    {
      "x": 0,
      "y": 20,
      "z": -12,
      "name": "Plant_Leaves_Jungle"
    },
    {
      "x": 0,
      "y": 21,
      "z": -12,
      "name": "Plant_Leaves_Jungle"
    },
    {
      "x": 0,
      "y": 20,
      "z": -11,
      "name": "Plant_Leaves_Jungle"
    },
    {
      "x": 0,
      "y": 21,
      "z": -11,
      "name": "Plant_Leaves_Jungle"
    },
    {
      "x": 0,
      "y": 22,
      "z": -11,
      "name": "Plant_Leaves_Jungle"
    },
    {
      "x": 0,
      "y": 21,
      "z": -10,
      "name": "Plant_Leaves_Jungle"
    },
    {
      "x": 0,
      "y": 20,
      "z": -9,
      "name": "Plant_Leaves_Jungle"
    },
    {
      "x": 0,
      "y": 21,
      "z": -9,
      "name": "Plant_Leaves_Jungle"
    },
    {
      "x": 0,
      "y": 22,
      "z": -9,
      "name": "Plant_Leaves_Jungle"
    },
    {
      "x": 0,
      "y": 23,
      "z": -9,
      "name": "Plant_Leaves_Jungle"
    },
    {
      "x": 0,
      "y": 21,
      "z": -8,
      "name": "Plant_Leaves_Jungle"
    },
    {
      "x": 0,
      "y": 23,
      "z": -8,
      "name": "Plant_Leaves_Jungle"
    },
    {
      "x": 0,
      "y": 24,
      "z": -7,
      "name": "Plant_Leaves_Jungle"
    },
    {
      "x": 0,
      "y": 20,
      "z": -5,
      "name": "Plant_Leaves_Jungle"
    },
    {
      "x": 0,
      "y": 21,
      "z": -5,
      "name": "Wood_Jungle_Branch_Long",
      "rotation": 5
    },
    {
      "x": 0,
      "y": 24,
      "z": -5,
      "name": "Plant_Leaves_Jungle"
    },
    {
      "x": 0,
      "y": 20,
      "z": -4,
      "name": "Plant_Leaves_Jungle"
    },
    {
      "x": 0,
      "y": 21,
      "z": -4,
      "name": "Plant_Leaves_Jungle"
    },
    {
      "x": 0,
      "y": 20,
      "z": -3,
      "name": "Plant_Leaves_Jungle"
    },
    {
      "x": 0,
      "y": 23,
      "z": -3,
      "name": "Plant_Leaves_Jungle"
    },
    {
      "x": 0,
      "y": 20,
      "z": -2,
      "name": "Plant_Leaves_Jungle"
    },
    {
      "x": 0,
      "y": 21,
      "z": -2,
      "name": "Plant_Leaves_Jungle"
    },
    {
      "x": 0,
      "y": 22,
      "z": -2,
      "name": "Plant_Leaves_Jungle"
    },
    {
      "x": 0,
      "y": 18,
      "z": -1,
      "name": "Wood_Jungle_Branch_Long",
      "rotation": 5
    },
    {
      "x": 0,
      "y": 21,
      "z": -1,
      "name": "Plant_Leaves_Jungle"
    },
    {
      "x": 0,
      "y": 20,
      "z": 0,
      "name": "Plant_Leaves_Jungle"
    },
    {
      "x": 0,
      "y": 21,
      "z": 0,
      "name": "Plant_Leaves_Jungle"
    },
    {
      "x": 0,
      "y": 19,
      "z": 1,
      "name": "Plant_Leaves_Jungle"
    },
    {
      "x": 0,
      "y": 18,
      "z": 2,
      "name": "Plant_Leaves_Jungle"
    },
    {
      "x": 0,
      "y": 19,
      "z": 2,
      "name": "Plant_Leaves_Jungle"
    },
    {
      "x": 0,
      "y": 20,
      "z": 2,
      "name": "Plant_Leaves_Jungle"
    },
    {
      "x": 0,
      "y": 19,
      "z": 3,
      "name": "Plant_Leaves_Jungle"
    },
    {
      "x": 1,
      "y": 19,
      "z": -12,
      "name": "Plant_Leaves_Jungle"
    },
    {
      "x": 1,
      "y": 17,
      "z": -11,
      "name": "Plant_Leaves_Jungle"
    },
    {
      "x": 1,
      "y": 18,
      "z": -11,
      "name": "Plant_Leaves_Jungle"
    },
    {
      "x": 1,
      "y": 19,
      "z": -11,
      "name": "Plant_Leaves_Jungle"
    },
    {
      "x": 1,
      "y": 20,
      "z": -11,
      "name": "Plant_Leaves_Jungle"
    },
    {
      "x": 1,
      "y": 19,
      "z": -10,
      "name": "Plant_Leaves_Jungle"
    },
    {
      "x": 1,
      "y": 20,
      "z": -10,
      "name": "Plant_Leaves_Jungle"
    },
    {
      "x": 1,
      "y": 21,
      "z": -10,
      "name": "Plant_Leaves_Jungle"
    },
    {
      "x": 1,
      "y": 20,
      "z": -9,
      "name": "Plant_Leaves_Jungle"
    },
    {
      "x": 1,
      "y": 21,
      "z": -9,
      "name": "Plant_Leaves_Jungle"
    },
    {
      "x": 1,
      "y": 22,
      "z": -9,
      "name": "Plant_Leaves_Jungle"
    },
    {
      "x": 1,
      "y": 23,
      "z": -9,
      "name": "Plant_Leaves_Jungle"
    },
    {
      "x": 1,
      "y": 23,
      "z": -8,
      "name": "Plant_Leaves_Jungle"
    },
    {
      "x": 1,
      "y": 24,
      "z": -7,
      "name": "Plant_Leaves_Jungle"
    },
    {
      "x": 1,
      "y": 24,
      "z": -6,
      "name": "Plant_Leaves_Jungle"
    },
    {
      "x": 1,
      "y": 21,
      "z": -5,
      "name": "Wood_Jungle_Branch_Long",
      "rotation": 5
    },
    {
      "x": 1,
      "y": 24,
      "z": -5,
      "name": "Plant_Leaves_Jungle"
    },
    {
      "x": 1,
      "y": 18,
      "z": -4,
      "name": "Plant_Leaves_Jungle"
    },
    {
      "x": 1,
      "y": 24,
      "z": -4,
      "name": "Plant_Leaves_Jungle"
    },
    {
      "x": 1,
      "y": 18,
      "z": -3,
      "name": "Plant_Leaves_Jungle"
    },
    {
      "x": 1,
      "y": 19,
      "z": -3,
      "name": "Plant_Leaves_Jungle"
    },
    {
      "x": 1,
      "y": 23,
      "z": -3,
      "name": "Plant_Leaves_Jungle"
    },
    {
      "x": 1,
      "y": 19,
      "z": -2,
      "name": "Plant_Leaves_Jungle"
    },
    {
      "x": 1,
      "y": 20,
      "z": -2,
      "name": "Plant_Leaves_Jungle"
    },
    {
      "x": 1,
      "y": 22,
      "z": -2,
      "name": "Plant_Leaves_Jungle"
    },
    {
      "x": 1,
      "y": 23,
      "z": -2,
      "name": "Plant_Leaves_Jungle"
    },
    {
      "x": 1,
      "y": 18,
      "z": -1,
      "name": "Wood_Jungle_Branch_Corner",
      "rotation": 1
    },
    {
      "x": 1,
      "y": 19,
      "z": -1,
      "name": "Plant_Leaves_Jungle"
    },
    {
      "x": 1,
      "y": 20,
      "z": -1,
      "name": "Plant_Leaves_Jungle"
    },
    {
      "x": 1,
      "y": 21,
      "z": -1,
      "name": "Plant_Leaves_Jungle"
    },
    {
      "x": 1,
      "y": 19,
      "z": 0,
      "name": "Plant_Leaves_Jungle"
    },
    {
      "x": 1,
      "y": 20,
      "z": 0,
      "name": "Plant_Leaves_Jungle"
    },
    {
      "x": 1,
      "y": 20,
      "z": 1,
      "name": "Plant_Leaves_Jungle"
    },
    {
      "x": 1,
      "y": 17,
      "z": 2,
      "name": "Plant_Leaves_Jungle"
    },
    {
      "x": 1,
      "y": 18,
      "z": 2,
      "name": "Plant_Leaves_Jungle"
    },
    {
      "x": 1,
      "y": 19,
      "z": 2,
      "name": "Plant_Leaves_Jungle"
    },
    {
      "x": 1,
      "y": 18,
      "z": 3,
      "name": "Plant_Leaves_Jungle"
    },
    {
      "x": 1,
      "y": 19,
      "z": 3,
      "name": "Plant_Leaves_Jungle"
    },
    {
      "x": 2,
      "y": 21,
      "z": -9,
      "name": "Plant_Leaves_Jungle"
    },
    {
      "x": 2,
      "y": 22,
      "z": -9,
      "name": "Plant_Leaves_Jungle"
    },
    {
      "x": 2,
      "y": 21,
      "z": -8,
      "name": "Plant_Leaves_Jungle"
    },
    {
      "x": 2,
      "y": 22,
      "z": -8,
      "name": "Plant_Leaves_Jungle"
    },
    {
      "x": 2,
      "y": 23,
      "z": -8,
      "name": "Plant_Leaves_Jungle"
    },
    {
      "x": 2,
      "y": 23,
      "z": -7,
      "name": "Plant_Leaves_Jungle"
    },
    {
      "x": 2,
      "y": 23,
      "z": -6,
      "name": "Plant_Leaves_Jungle"
    },
    {
      "x": 2,
      "y": 24,
      "z": -6,
      "name": "Plant_Leaves_Jungle"
    },
    {
      "x": 2,
      "y": 21,
      "z": -5,
      "name": "Wood_Jungle_Branch_Corner",
      "rotation": 1
    },
    {
      "x": 2,
      "y": 22,
      "z": -5,
      "name": "Wood_Jungle_Branch_Long"
    },
    {
      "x": 2,
      "y": 23,
      "z": -5,
      "name": "Plant_Leaves_Jungle"
    },
    {
      "x": 2,
      "y": 21,
      "z": -4,
      "name": "Plant_Leaves_Jungle"
    },
    {
      "x": 2,
      "y": 23,
      "z": -4,
      "name": "Plant_Leaves_Jungle"
    },
    {
      "x": 2,
      "y": 18,
      "z": -3,
      "name": "Plant_Leaves_Jungle"
    },
    {
      "x": 2,
      "y": 20,
      "z": -3,
      "name": "Plant_Leaves_Jungle"
    },
    {
      "x": 2,
      "y": 21,
      "z": -3,
      "name": "Plant_Leaves_Jungle"
    },
    {
      "x": 2,
      "y": 22,
      "z": -3,
      "name": "Plant_Leaves_Jungle"
    },
    {
      "x": 2,
      "y": 18,
      "z": -2,
      "name": "Plant_Leaves_Jungle"
    },
    {
      "x": 2,
      "y": 19,
      "z": -2,
      "name": "Plant_Leaves_Jungle"
    },
    {
      "x": 2,
      "y": 20,
      "z": -2,
      "name": "Plant_Leaves_Jungle"
    },
    {
      "x": 2,
      "y": 16,
      "z": -1,
      "name": "Plant_Leaves_Jungle"
    },
    {
      "x": 2,
      "y": 18,
      "z": -1,
      "name": "Plant_Leaves_Jungle"
    },
    {
      "x": 2,
      "y": 19,
      "z": -1,
      "name": "Plant_Leaves_Jungle"
    },
    {
      "x": 2,
      "y": 16,
      "z": 0,
      "name": "Plant_Leaves_Jungle"
    },
    {
      "x": 2,
      "y": 17,
      "z": 0,
      "name": "Plant_Leaves_Jungle"
    },
    {
      "x": 2,
      "y": 18,
      "z": 0,
      "name": "Plant_Leaves_Jungle"
    },
    {
      "x": 2,
      "y": 19,
      "z": 0,
      "name": "Plant_Leaves_Jungle"
    },
    {
      "x": 2,
      "y": 20,
      "z": 0,
      "name": "Plant_Leaves_Jungle"
    },
    {
      "x": 2,
      "y": 16,
      "z": 1,
      "name": "Plant_Leaves_Jungle"
    },
    {
      "x": 2,
      "y": 17,
      "z": 1,
      "name": "Plant_Leaves_Jungle"
    },
    {
      "x": 2,
      "y": 18,
      "z": 1,
      "name": "Plant_Leaves_Jungle"
    },
    {
      "x": 2,
      "y": 19,
      "z": 1,
      "name": "Plant_Leaves_Jungle"
    },
    {
      "x": 2,
      "y": 18,
      "z": 2,
      "name": "Plant_Leaves_Jungle"
    },
    {
      "x": 3,
      "y": 20,
      "z": -9,
      "name": "Plant_Leaves_Jungle"
    },
    {
      "x": 3,
      "y": 21,
      "z": -9,
      "name": "Plant_Leaves_Jungle"
    },
    {
      "x": 3,
      "y": 21,
      "z": -8,
      "name": "Plant_Leaves_Jungle"
    },
    {
      "x": 3,
      "y": 22,
      "z": -8,
      "name": "Plant_Leaves_Jungle"
    },
    {
      "x": 3,
      "y": 23,
      "z": -8,
      "name": "Plant_Leaves_Jungle"
    },
    {
      "x": 3,
      "y": 22,
      "z": -7,
      "name": "Plant_Leaves_Jungle"
    },
    {
      "x": 3,
      "y": 23,
      "z": -7,
      "name": "Plant_Leaves_Jungle"
    },
    {
      "x": 3,
      "y": 22,
      "z": -6,
      "name": "Plant_Leaves_Jungle"
    },
    {
      "x": 3,
      "y": 23,
      "z": -6,
      "name": "Plant_Leaves_Jungle"
    },
    {
      "x": 3,
      "y": 22,
      "z": -5,
      "name": "Plant_Leaves_Jungle"
    },
    {
      "x": 3,
      "y": 23,
      "z": -5,
      "name": "Plant_Leaves_Jungle"
    },
    {
      "x": 3,
      "y": 21,
      "z": -4,
      "name": "Plant_Leaves_Jungle"
    },
    {
      "x": 3,
      "y": 22,
      "z": -4,
      "name": "Plant_Leaves_Jungle"
    },
    {
      "x": 3,
      "y": 17,
      "z": -3,
      "name": "Plant_Leaves_Jungle"
    },
    {
      "x": 3,
      "y": 18,
      "z": -3,
      "name": "Plant_Leaves_Jungle"
    },
    {
      "x": 3,
      "y": 20,
      "z": -3,
      "name": "Plant_Leaves_Jungle"
    },
    {
      "x": 3,
      "y": 21,
      "z": -3,
      "name": "Plant_Leaves_Jungle"
    },
    {
      "x": 3,
      "y": 15,
      "z": -2,
      "name": "Plant_Leaves_Jungle"
    },
    {
      "x": 3,
      "y": 16,
      "z": -2,
      "name": "Plant_Leaves_Jungle"
    },
    {
      "x": 3,
      "y": 17,
      "z": -2,
      "name": "Plant_Leaves_Jungle"
    },
    {
      "x": 3,
      "y": 18,
      "z": -2,
      "name": "Plant_Leaves_Jungle"
    },
    {
      "x": 3,
      "y": 15,
      "z": -1,
      "name": "Plant_Leaves_Jungle"
    },
    {
      "x": 3,
      "y": 16,
      "z": -1,
      "name": "Plant_Leaves_Jungle"
    },
    {
      "x": 3,
      "y": 17,
      "z": -1,
      "name": "Plant_Leaves_Jungle"
    },
    {
      "x": 3,
      "y": 18,
      "z": -1,
      "name": "Plant_Leaves_Jungle"
    },
    {
      "x": 3,
      "y": 18,
      "z": 0,
      "name": "Plant_Leaves_Jungle"
    },
    {
      "x": 3,
      "y": 19,
      "z": 0,
      "name": "Plant_Leaves_Jungle"
    },
    {
      "x": 4,
      "y": 21,
      "z": -8,
      "name": "Plant_Leaves_Jungle"
    },
    {
      "x": 4,
      "y": 20,
      "z": -7,
      "name": "Plant_Leaves_Jungle"
    },
    {
      "x": 4,
      "y": 21,
      "z": -7,
      "name": "Plant_Leaves_Jungle"
    },
    {
      "x": 4,
      "y": 22,
      "z": -7,
      "name": "Plant_Leaves_Jungle"
    },
    {
      "x": 4,
      "y": 20,
      "z": -6,
      "name": "Plant_Leaves_Jungle"
    },
    {
      "x": 4,
      "y": 21,
      "z": -6,
      "name": "Plant_Leaves_Jungle"
    },
    {
      "x": 4,
      "y": 22,
      "z": -6,
      "name": "Plant_Leaves_Jungle"
    },
    {
      "x": 4,
      "y": 19,
      "z": -5,
      "name": "Plant_Leaves_Jungle"
    },
    {
      "x": 4,
      "y": 20,
      "z": -5,
      "name": "Plant_Leaves_Jungle"
    },
    {
      "x": 4,
      "y": 21,
      "z": -5,
      "name": "Plant_Leaves_Jungle"
    },
    {
      "x": 4,
      "y": 22,
      "z": -5,
      "name": "Plant_Leaves_Jungle"
    },
    {
      "x": 4,
      "y": 21,
      "z": -4,
      "name": "Plant_Leaves_Jungle"
    },
    {
      "x": 4,
      "y": 22,
      "z": -4,
      "name": "Plant_Leaves_Jungle"
    }
  ]
}