{
  "version": 8,
  "blockIdVersion": 8,
  "anchorX": 1,
  "anchorY": 4,
  "anchorZ": -6,
  "blocks": [
    {
      "x": -6,
      "y": 6,
      "z": -5,
      "name": "Rock_Sandstone"
    },
    {
      "x": -6,
      "y": 7,
      "z": -5,
      "name": "Rock_Sandstone"
    },
    {
      "x": -6,
      "y": 8,
      "z": -5,
      "name": "Rock_Sandstone"
    },
    {
      "x": -6,
      "y": 9,
      "z": -5,
      "name": "Rock_Sandstone"
    },
    {
      "x": -6,
      "y": 10,
      "z": -5,
      "name": "Rock_Sandstone"
    },
    {
      "x": -6,
      "y": 11,
      "z": -5,
      "name": "Rock_Sandstone"
    },
    {
      "x": -6,
      "y": 12,
      "z": -5,
      "name": "Rock_Sandstone"
    },
    {
      "x": -6,
      "y": 13,
      "z": -5,
      "name": "Rock_Sandstone"
    },
    {
      "x": -6,
      "y": 4,
      "z": -4,
      "name": "Rock_Sandstone"
    },
    {
      "x": -6,
      "y": 5,
      "z": -4,
      "name": "Rock_Sandstone"
    },
    {
      "x": -6,
      "y": 6,
      "z": -4,
      "name": "Rock_Sandstone"
    },
    {
      "x": -6,
      "y": 7,
      "z": -4,
      "name": "Rock_Sandstone"
    },
    {
      "x": -6,
      "y": 8,
      "z": -4,
      "name": "Rock_Sandstone"
    },
    {
      "x": -6,
      "y": 9,
      "z": -4,
      "name": "Rock_Sandstone"
    },
    {
      "x": -6,
      "y": 10,
      "z": -4,
      "name": "Rock_Sandstone"
    },
    {
      "x": -6,
      "y": 11,
      "z": -4,
      "name": "Rock_Sandstone"
    },
    {
      "x": -6,
      "y": 12,
      "z": -4,
      "name": "Rock_Sandstone"
    },
    {
      "x": -6,
      "y": 13,
      "z": -4,
      "name": "Rock_Sandstone"
    },
    {
      "x": -6,
      "y": 4,
      "z": -3,
      "name": "Rock_Sandstone"
    },
    {
      "x": -6,
      "y": 5,
      "z": -3,
      "name": "Rock_Sandstone"
    },
    {
      "x": -6,
      "y": 6,
      "z": -3,
      "name": "Rock_Sandstone"
    },
    {
      "x": -6,
      "y": 7,
      "z": -3,
      "name": "Rock_Sandstone"
    },
    {
      "x": -6,
      "y": 8,
      "z": -3,
      "name": "Rock_Sandstone"
    },
    {
      "x": -6,
      "y": 9,
      "z": -3,
      "name": "Rock_Sandstone"
    },
    {
      "x": -6,
      "y": 10,
      "z": -3,
      "name": "Rock_Sandstone"
    },
    {
      "x": -6,
      "y": 11,
      "z": -3,
      "name": "Rock_Sandstone"
    },
    {
      "x": -6,
      "y": 12,
      "z": -3,
      "name": "Rock_Sandstone"
    },
    {
      "x": -6,
      "y": 13,
      "z": -3,
      "name": "Rock_Sandstone"
    },
    {
      "x": -6,
      "y": 14,
      "z": -3,
      "name": "Rock_Sandstone"
    },
    {
      "x": -6,
      "y": 4,
      "z": -2,
      "name": "Rock_Sandstone"
    },
    {
      "x": -6,
      "y": 5,
      "z": -2,
      "name": "Rock_Sandstone"
    },
    {
      "x": -6,
      "y": 6,
      "z": -2,
      "name": "Rock_Sandstone"
    },
    {
      "x": -6,
      "y": 7,
      "z": -2,
      "name": "Rock_Sandstone"
    },
    {
      "x": -6,
      "y": 8,
      "z": -2,
      "name": "Rock_Sandstone"
    },
    {
      "x": -6,
      "y": 9,
      "z": -2,
      "name": "Rock_Sandstone"
    },
    {
      "x": -6,
      "y": 10,
      "z": -2,
      "name": "Rock_Sandstone"
    },
    {
      "x": -6,
      "y": 11,
      "z": -2,
      "name": "Rock_Sandstone"
    },
    {
      "x": -6,
      "y": 12,
      "z": -2,
      "name": "Rock_Sandstone"
    },
    {
      "x": -6,
      "y": 13,
      "z": -2,
      "name": "Rock_Sandstone"
    },
    {
      "x": -6,
      "y": 14,
      "z": -2,
      "name": "Rock_Sandstone"
    },
    {
      "x": -6,
      "y": 3,
      "z": -1,
      "name": "Rock_Sandstone_Brick"
    },
    {
      "x": -6,
      "y": 4,
      "z": -1,
      "name": "Rock_Sandstone_Brick"
    },
    {
      "x": -6,
      "y": 5,
      "z": -1,
      "name": "Rock_Sandstone_Brick"
    },
    {
      "x": -6,
      "y": 6,
      "z": -1,
      "name": "Rock_Sandstone_Brick"
    },
    {
      "x": -6,
      "y": 7,
      "z": -1,
      "name": "Rock_Sandstone_Brick"
    },
    {
      "x": -6,
      "y": 8,
      "z": -1,
      "name": "Rock_Sandstone_Brick"
    },
    {
      "x": -6,
      "y": 9,
      "z": -1,
      "name": "Rock_Sandstone_Brick"
    },
    {
      "x": -6,
      "y": 10,
      "z": -1,
      "name": "Rock_Sandstone"
    },
    {
      "x": -6,
      "y": 11,
      "z": -1,
      "name": "Rock_Sandstone"
    },
    {
      "x": -6,
      "y": 12,
      "z": -1,
      "name": "Rock_Sandstone"
    },
    {
      "x": -6,
      "y": 13,
      "z": -1,
      "name": "Rock_Sandstone"
    },
    {
      "x": -6,
      "y": 14,
      "z": -1,
      "name": "Rock_Sandstone"
    },
    {
      "x": -6,
      "y": 3,
      "z": 0,
      "name": "Rock_Sandstone_Brick"
    },
    {
      "x": -6,
      "y": 4,
      "z": 0,
      "name": "Soil_Sand_White"
    },
    {
      "x": -6,
      "y": 5,
      "z": 0,
      "name": "Empty"
    },
    {
      "x": -6,
      "y": 6,
      "z": 0,
      "name": "Empty"
    },
    {
      "x": -6,
      "y": 7,
      "z": 0,
      "name": "Empty"
    },
    {
      "x": -6,
      "y": 8,
      "z": 0,
      "name": "Empty"
    },
    {
      "x": -6,
      "y": 9,
      "z": 0,
      "name": "Rock_Sandstone_Brick"
    },
    {
      "x": -6,
      "y": 10,
      "z": 0,
      "name": "Rock_Sandstone"
    },
    {
      "x": -6,
      "y": 11,
      "z": 0,
      "name": "Rock_Sandstone"
    },
    {
      "x": -6,
      "y": 12,
      "z": 0,
      "name": "Rock_Sandstone"
    },
    {
      "x": -6,
      "y": 13,
      "z": 0,
      "name": "Rock_Sandstone"
    },
    {
      "x": -6,
      "y": 14,
      "z": 0,
      "name": "Rock_Sandstone"
    },
    {
      "x": -6,
      "y": 3,
      "z": 1,
      "name": "Rock_Sandstone_Brick"
    },
    {
      "x": -6,
      "y": 4,
      "z": 1,
      "name": "Soil_Sand_White"
    },
    {
      "x": -6,
      "y": 5,
      "z": 1,
      "name": "Empty"
    },
    {
      "x": -6,
      "y": 6,
      "z": 1,
      "name": "Empty"
    },
    {
      "x": -6,
      "y": 7,
      "z": 1,
      "name": "Empty"
    },
    {
      "x": -6,
      "y": 8,
      "z": 1,
      "name": "Empty"
    },
    {
      "x": -6,
      "y": 9,
      "z": 1,
      "name": "Rock_Sandstone_Brick"
    },
    {
      "x": -6,
      "y": 10,
      "z": 1,
      "name": "Rock_Sandstone"
    },
    {
      "x": -6,
      "y": 11,
      "z": 1,
      "name": "Rock_Sandstone"
    },
    {
      "x": -6,
      "y": 12,
      "z": 1,
      "name": "Rock_Sandstone"
    },
    {
      "x": -6,
      "y": 13,
      "z": 1,
      "name": "Rock_Sandstone"
    },
    {
      "x": -6,
      "y": 14,
      "z": 1,
      "name": "Rock_Sandstone"
    },
    {
      "x": -6,
      "y": 3,
      "z": 2,
      "name": "Rock_Sandstone_Brick"
    },
    {
      "x": -6,
      "y": 4,
      "z": 2,
      "name": "Soil_Sand_White"
    },
    {
      "x": -6,
      "y": 5,
      "z": 2,
      "name": "Empty"
    },
    {
      "x": -6,
      "y": 6,
      "z": 2,
      "name": "Empty"
    },
    {
      "x": -6,
      "y": 7,
      "z": 2,
      "name": "Empty"
    },
    {
      "x": -6,
      "y": 8,
      "z": 2,
      "name": "Empty"
    },
    {
      "x": -6,
      "y": 9,
      "z": 2,
      "name": "Rock_Sandstone_Brick"
    },
    {
      "x": -6,
      "y": 10,
      "z": 2,
      "name": "Rock_Sandstone"
    },
    {
      "x": -6,
      "y": 11,
      "z": 2,
      "name": "Rock_Sandstone"
    },
    {
      "x": -6,
      "y": 12,
      "z": 2,
      "name": "Rock_Sandstone"
    },
    {
      "x": -6,
      "y": 13,
      "z": 2,
      "name": "Rock_Sandstone"
    },
    {
      "x": -6,
      "y": 14,
      "z": 2,
      "name": "Rock_Sandstone"
    },
    {
      "x": -6,
      "y": 3,
      "z": 3,
      "name": "Rock_Sandstone_Brick"
    },
    {
      "x": -6,
      "y": 4,
      "z": 3,
      "name": "Rock_Sandstone_Brick"
    },
    {
      "x": -6,
      "y": 5,
      "z": 3,
      "name": "Rock_Sandstone_Brick"
    },
    {
      "x": -6,
      "y": 6,
      "z": 3,
      "name": "Rock_Sandstone_Brick"
    },
    {
      "x": -6,
      "y": 7,
      "z": 3,
      "name": "Rock_Sandstone_Brick"
    },
    {
      "x": -6,
      "y": 8,
      "z": 3,
      "name": "Rock_Sandstone_Brick"
    },
    {
      "x": -6,
      "y": 9,
      "z": 3,
      "name": "Rock_Sandstone_Brick"
    },
    {
      "x": -6,
      "y": 10,
      "z": 3,
      "name": "Rock_Sandstone"
    },
    {
      "x": -6,
      "y": 11,
      "z": 3,
      "name": "Rock_Sandstone"
    },
    {
      "x": -6,
      "y": 12,
      "z": 3,
      "name": "Rock_Sandstone"
    },
    {
      "x": -6,
      "y": 13,
      "z": 3,
      "name": "Rock_Sandstone"
    },
    {
      "x": -6,
      "y": 14,
      "z": 3,
      "name": "Rock_Sandstone"
    },
    {
      "x": -6,
      "y": 4,
      "z": 4,
      "name": "Rock_Sandstone"
    },
    {
      "x": -6,
      "y": 5,
      "z": 4,
      "name": "Rock_Sandstone"
    },
    {
      "x": -6,
      "y": 6,
      "z": 4,
      "name": "Rock_Sandstone"
    },
    {
      "x": -6,
      "y": 7,
      "z": 4,
      "name": "Rock_Sandstone"
    },
    {
      "x": -6,
      "y": 8,
      "z": 4,
      "name": "Rock_Sandstone"
    },
    {
      "x": -6,
      "y": 9,
      "z": 4,
      "name": "Rock_Sandstone"
    },
    {
      "x": -6,
      "y": 10,
      "z": 4,
      "name": "Rock_Sandstone"
    },
    {
      "x": -6,
      "y": 11,
      "z": 4,
      "name": "Rock_Sandstone"
    },
    {
      "x": -6,
      "y": 12,
      "z": 4,
      "name": "Rock_Sandstone"
    },
    {
      "x": -6,
      "y": 13,
      "z": 4,
      "name": "Rock_Sandstone"
    },
    {
      "x": -6,
      "y": 14,
      "z": 4,
      "name": "Rock_Sandstone"
    },
    {
      "x": -6,
      "y": 4,
      "z": 5,
      "name": "Rock_Sandstone"
    },
    {
      "x": -6,
      "y": 5,
      "z": 5,
      "name": "Rock_Sandstone"
    },
    {
      "x": -6,
      "y": 6,
      "z": 5,
      "name": "Rock_Sandstone"
    },
    {
      "x": -6,
      "y": 7,
      "z": 5,
      "name": "Rock_Sandstone"
    },
    {
      "x": -6,
      "y": 8,
      "z": 5,
      "name": "Rock_Sandstone"
    },
    {
      "x": -6,
      "y": 9,
      "z": 5,
      "name": "Rock_Sandstone"
    },
    {
      "x": -6,
      "y": 10,
      "z": 5,
      "name": "Rock_Sandstone"
    },
    {
      "x": -6,
      "y": 11,
      "z": 5,
      "name": "Rock_Sandstone"
    },
    {
      "x": -6,
      "y": 12,
      "z": 5,
      "name": "Rock_Sandstone"
    },
    {
      "x": -6,
      "y": 13,
      "z": 5,
      "name": "Rock_Sandstone"
    },
    {
      "x": -6,
      "y": 4,
      "z": 6,
      "name": "Rock_Sandstone"
    },
    {
      "x": -6,
      "y": 5,
      "z": 6,
      "name": "Rock_Sandstone"
    },
    {
      "x": -6,
      "y": 6,
      "z": 6,
      "name": "Rock_Sandstone"
    },
    {
      "x": -6,
      "y": 7,
      "z": 6,
      "name": "Rock_Sandstone"
    },
    {
      "x": -6,
      "y": 8,
      "z": 6,
      "name": "Rock_Sandstone"
    },
    {
      "x": -6,
      "y": 9,
      "z": 6,
      "name": "Rock_Sandstone"
    },
    {
      "x": -6,
      "y": 10,
      "z": 6,
      "name": "Rock_Sandstone"
    },
    {
      "x": -6,
      "y": 11,
      "z": 6,
      "name": "Rock_Sandstone"
    },
    {
      "x": -6,
      "y": 12,
      "z": 6,
      "name": "Rock_Sandstone"
    },
    {
      "x": -6,
      "y": 13,
      "z": 6,
      "name": "Rock_Sandstone"
    },
    {
      "x": -6,
      "y": 6,
      "z": 7,
      "name": "Rock_Sandstone"
    },
    {
      "x": -6,
      "y": 7,
      "z": 7,
      "name": "Rock_Sandstone"
    },
    {
      "x": -6,
      "y": 8,
      "z": 7,
      "name": "Rock_Sandstone"
    },
    {
      "x": -6,
      "y": 9,
      "z": 7,
      "name": "Rock_Sandstone"
    },
    {
      "x": -6,
      "y": 10,
      "z": 7,
      "name": "Rock_Sandstone"
    },
    {
      "x": -6,
      "y": 11,
      "z": 7,
      "name": "Rock_Sandstone"
    },
    {
      "x": -6,
      "y": 12,
      "z": 7,
      "name": "Rock_Sandstone"
    },
    {
      "x": -5,
      "y": 4,
      "z": -6,
      "name": "Rock_Sandstone"
    },
    {
      "x": -5,
      "y": 5,
      "z": -6,
      "name": "Rock_Sandstone"
    },
    {
      "x": -5,
      "y": 6,
      "z": -6,
      "name": "Rock_Sandstone"
    },
    {
      "x": -5,
      "y": 7,
      "z": -6,
      "name": "Rock_Sandstone"
    },
    {
      "x": -5,
      "y": 8,
      "z": -6,
      "name": "Rock_Sandstone"
    },
    {
      "x": -5,
      "y": 9,
      "z": -6,
      "name": "Rock_Sandstone"
    },
    {
      "x": -5,
      "y": 10,
      "z": -6,
      "name": "Rock_Sandstone"
    },
    {
      "x": -5,
      "y": 11,
      "z": -6,
      "name": "Rock_Sandstone"
    },
    {
      "x": -5,
      "y": 3,
      "z": -5,
      "name": "Rock_Sandstone"
    },
    {
      "x": -5,
      "y": 4,
      "z": -5,
      "name": "Rock_Sandstone"
    },
    {
      "x": -5,
      "y": 5,
      "z": -5,
      "name": "Rock_Sandstone"
    },
    {
      "x": -5,
      "y": 6,
      "z": -5,
      "name": "Rock_Sandstone"
    },
    {
      "x": -5,
      "y": 7,
      "z": -5,
      "name": "Rock_Sandstone"
    },
    {
      "x": -5,
      "y": 8,
      "z": -5,
      "name": "Rock_Sandstone"
    },
    {
      "x": -5,
      "y": 9,
      "z": -5,
      "name": "Rock_Sandstone"
    },
    {
      "x": -5,
      "y": 10,
      "z": -5,
      "name": "Rock_Sandstone"
    },
    {
      "x": -5,
      "y": 11,
      "z": -5,
      "name": "Rock_Sandstone"
    },
    {
      "x": -5,
      "y": 12,
      "z": -5,
      "name": "Rock_Sandstone"
    },
    {
      "x": -5,
      "y": 13,
      "z": -5,
      "name": "Rock_Sandstone"
    },
    {
      "x": -5,
      "y": 14,
      "z": -5,
      "name": "Rock_Sandstone"
    },
    {
      "x": -5,
      "y": 3,
      "z": -4,
      "name": "Rock_Sandstone"
    },
    {
      "x": -5,
      "y": 4,
      "z": -4,
      "name": "Rock_Sandstone"
    },
    {
      "x": -5,
      "y": 5,
      "z": -4,
      "name": "Rock_Sandstone_Brick"
    },
    {
      "x": -5,
      "y": 6,
      "z": -4,
      "name": "Rock_Sandstone_Brick"
    },
    {
      "x": -5,
      "y": 7,
      "z": -4,
      "name": "Rock_Sandstone_Brick"
    },
    {
      "x": -5,
      "y": 8,
      "z": -4,
      "name": "Rock_Sandstone"
    },
    {
      "x": -5,
      "y": 9,
      "z": -4,
      "name": "Empty"
    },
    {
      "x": -5,
      "y": 10,
      "z": -4,
      "name": "Rock_Sandstone_Brick_Half"
    },
    {
      "x": -5,
      "y": 11,
      "z": -4,
      "name": "Rock_Sandstone_Brick_Ornate"
    },
    {
      "x": -5,
      "y": 12,
      "z": -4,
      "name": "Rock_Sandstone"
    },
    {
      "x": -5,
      "y": 13,
      "z": -4,
      "name": "Rock_Sandstone"
    },
    {
      "x": -5,
      "y": 14,
      "z": -4,
      "name": "Rock_Sandstone"
    },
    {
      "x": -5,
      "y": 3,
      "z": -3,
      "name": "Rock_Sandstone"
    },
    {
      "x": -5,
      "y": 4,
      "z": -3,
      "name": "Rock_Sandstone"
    },
    {
      "x": -5,
      "y": 5,
      "z": -3,
      "name": "Rock_Sandstone"
    },
    {
      "x": -5,
      "y": 6,
      "z": -3,
      "name": "Rock_Sandstone"
    },
    {
      "x": -5,
      "y": 7,
      "z": -3,
      "name": "Empty"
    },
    {
      "x": -5,
      "y": 8,
      "z": -3,
      "name": "Empty"
    },
    {
      "x": -5,
      "y": 9,
      "z": -3,
      "name": "Empty"
    },
    {
      "x": -5,
      "y": 10,
      "z": -3,
      "name": "Empty"
    },
    {
      "x": -5,
      "y": 11,
      "z": -3,
      "name": "Empty"
    },
    {
      "x": -5,
      "y": 12,
      "z": -3,
      "name": "Rock_Sandstone"
    },
    {
      "x": -5,
      "y": 13,
      "z": -3,
      "name": "Rock_Sandstone"
    },
    {
      "x": -5,
      "y": 14,
      "z": -3,
      "name": "Rock_Sandstone"
    },
    {
      "x": -5,
      "y": 3,
      "z": -2,
      "name": "Rock_Sandstone"
    },
    {
      "x": -5,
      "y": 4,
      "z": -2,
      "name": "Soil_Sand_White"
    },
    {
      "x": -5,
      "y": 5,
      "z": -2,
      "name": "Rock_Sandstone_Brick_Ornate"
    },
    {
      "x": -5,
      "y": 6,
      "z": -2,
      "name": "Rock_Sandstone_Brick_Pillar_Base"
    },
    {
      "x": -5,
      "y": 7,
      "z": -2,
      "name": "Rock_Sandstone_Brick_Pillar_Middle"
    },
    {
      "x": -5,
      "y": 8,
      "z": -2,
      "name": "Rock_Sandstone_Brick_Pillar_Middle"
    },
    {
      "x": -5,
      "y": 9,
      "z": -2,
      "name": "Rock_Sandstone_Brick_Pillar_Middle"
    },
    {
      "x": -5,
      "y": 10,
      "z": -2,
      "name": "Rock_Sandstone_Brick_Pillar_Middle"
    },
    {
      "x": -5,
      "y": 11,
      "z": -2,
      "name": "Rock_Sandstone_Brick_Pillar_Base",
      "rotation": 8
    },
    {
      "x": -5,
      "y": 12,
      "z": -2,
      "name": "Rock_Sandstone"
    },
    {
      "x": -5,
      "y": 13,
      "z": -2,
      "name": "Rock_Sandstone"
    },
    {
      "x": -5,
      "y": 14,
      "z": -2,
      "name": "Rock_Sandstone"
    },
    {
      "x": -5,
      "y": 3,
      "z": -1,
      "name": "Rock_Sandstone"
    },
    {
      "x": -5,
      "y": 4,
      "z": -1,
      "name": "Soil_Sand_White"
    },
    {
      "x": -5,
      "y": 5,
      "z": -1,
      "name": "Rock_Sandstone_Brick_Ornate"
    },
    {
      "x": -5,
      "y": 6,
      "z": -1,
      "name": "Rock_Sandstone_Brick_Pillar_Base"
    },
    {
      "x": -5,
      "y": 7,
      "z": -1,
      "name": "Rock_Sandstone_Brick_Pillar_Middle"
    },
    {
      "x": -5,
      "y": 8,
      "z": -1,
      "name": "Rock_Sandstone_Brick_Pillar_Middle"
    },
    {
      "x": -5,
      "y": 9,
      "z": -1,
      "name": "Rock_Sandstone_Brick_Pillar_Middle"
    },
    {
      "x": -5,
      "y": 10,
      "z": -1,
      "name": "Rock_Sandstone_Brick_Pillar_Base",
      "rotation": 8
    },
    {
      "x": -5,
      "y": 11,
      "z": -1,
      "name": "Rock_Sandstone"
    },
    {
      "x": -5,
      "y": 12,
      "z": -1,
      "name": "Rock_Sandstone"
    },
    {
      "x": -5,
      "y": 13,
      "z": -1,
      "name": "Rock_Sandstone"
    },
    {
      "x": -5,
      "y": 14,
      "z": -1,
      "name": "Rock_Sandstone"
    },
    {
      "x": -5,
      "y": 3,
      "z": 0,
      "name": "Rock_Sandstone"
    },
    {
      "x": -5,
      "y": 4,
      "z": 0,
      "name": "Soil_Sand_White"
    },
    {
      "x": -5,
      "y": 5,
      "z": 0,
      "name": "Empty"
    },
    {
      "x": -5,
      "y": 6,
      "z": 0,
      "name": "Empty"
    },
    {
      "x": -5,
      "y": 7,
      "z": 0,
      "name": "Empty"
    },
    {
      "x": -5,
      "y": 8,
      "z": 0,
      "name": "Empty"
    },
    {
      "x": -5,
      "y": 9,
      "z": 0,
      "name": "Empty"
    },
    {
      "x": -5,
      "y": 10,
      "z": 0,
      "name": "Empty"
    },
    {
      "x": -5,
      "y": 11,
      "z": 0,
      "name": "Rock_Sandstone"
    },
    {
      "x": -5,
      "y": 12,
      "z": 0,
      "name": "Rock_Sandstone"
    },
    {
      "x": -5,
      "y": 13,
      "z": 0,
      "name": "Rock_Sandstone"
    },
    {
      "x": -5,
      "y": 14,
      "z": 0,
      "name": "Rock_Sandstone"
    },
    {
      "x": -5,
      "y": 3,
      "z": 1,
      "name": "Rock_Sandstone"
    },
    {
      "x": -5,
      "y": 4,
      "z": 1,
      "name": "Soil_Sand_White"
    },
    {
      "x": -5,
      "y": 5,
      "z": 1,
      "name": "Empty"
    },
    {
      "x": -5,
      "y": 6,
      "z": 1,
      "name": "Empty"
    },
    {
      "x": -5,
      "y": 7,
      "z": 1,
      "name": "Empty"
    },
    {
      "x": -5,
      "y": 8,
      "z": 1,
      "name": "Empty"
    },
    {
      "x": -5,
      "y": 9,
      "z": 1,
      "name": "Empty"
    },
    {
      "x": -5,
      "y": 10,
      "z": 1,
      "name": "Rock_Sandstone"
    },
    {
      "x": -5,
      "y": 11,
      "z": 1,
      "name": "Rock_Sandstone"
    },
    {
      "x": -5,
      "y": 12,
      "z": 1,
      "name": "Rock_Sandstone"
    },
    {
      "x": -5,
      "y": 13,
      "z": 1,
      "name": "Rock_Sandstone"
    },
    {
      "x": -5,
      "y": 14,
      "z": 1,
      "name": "Rock_Sandstone"
    },
    {
      "x": -5,
      "y": 3,
      "z": 2,
      "name": "Rock_Sandstone"
    },
    {
      "x": -5,
      "y": 4,
      "z": 2,
      "name": "Soil_Sand_White"
    },
    {
      "x": -5,
      "y": 5,
      "z": 2,
      "name": "Empty"
    },
    {
      "x": -5,
      "y": 6,
      "z": 2,
      "name": "Empty"
    },
    {
      "x": -5,
      "y": 7,
      "z": 2,
      "name": "Empty"
    },
    {
      "x": -5,
      "y": 8,
      "z": 2,
      "name": "Empty"
    },
    {
      "x": -5,
      "y": 9,
      "z": 2,
      "name": "Rock_Sandstone"
    },
    {
      "x": -5,
      "y": 10,
      "z": 2,
      "name": "Rock_Sandstone"
    },
    {
      "x": -5,
      "y": 11,
      "z": 2,
      "name": "Rock_Sandstone"
    },
    {
      "x": -5,
      "y": 12,
      "z": 2,
      "name": "Rock_Sandstone"
    },
    {
      "x": -5,
      "y": 13,
      "z": 2,
      "name": "Rock_Sandstone"
    },
    {
      "x": -5,
      "y": 14,
      "z": 2,
      "name": "Rock_Sandstone"
    },
    {
      "x": -5,
      "y": 3,
      "z": 3,
      "name": "Rock_Sandstone"
    },
    {
      "x": -5,
      "y": 4,
      "z": 3,
      "name": "Soil_Sand_White"
    },
    {
      "x": -5,
      "y": 5,
      "z": 3,
      "name": "Rock_Sandstone_Brick_Ornate"
    },
    {
      "x": -5,
      "y": 6,
      "z": 3,
      "name": "Rock_Sandstone_Brick_Pillar_Base"
    },
    {
      "x": -5,
      "y": 7,
      "z": 3,
      "name": "Rock_Sandstone"
    },
    {
      "x": -5,
      "y": 8,
      "z": 3,
      "name": "Rock_Sandstone"
    },
    {
      "x": -5,
      "y": 9,
      "z": 3,
      "name": "Rock_Sandstone"
    },
    {
      "x": -5,
      "y": 10,
      "z": 3,
      "name": "Rock_Sandstone"
    },
    {
      "x": -5,
      "y": 11,
      "z": 3,
      "name": "Rock_Sandstone"
    },
    {
      "x": -5,
      "y": 12,
      "z": 3,
      "name": "Rock_Sandstone"
    },
    {
      "x": -5,
      "y": 13,
      "z": 3,
      "name": "Rock_Sandstone"
    },
    {
      "x": -5,
      "y": 14,
      "z": 3,
      "name": "Rock_Sandstone"
    },
    {
      "x": -5,
      "y": 3,
      "z": 4,
      "name": "Rock_Sandstone"
    },
    {
      "x": -5,
      "y": 4,
      "z": 4,
      "name": "Rock_Sandstone"
    },
    {
      "x": -5,
      "y": 5,
      "z": 4,
      "name": "Rock_Sandstone"
    },
    {
      "x": -5,
      "y": 6,
      "z": 4,
      "name": "Rock_Sandstone"
    },
    {
      "x": -5,
      "y": 7,
      "z": 4,
      "name": "Rock_Sandstone"
    },
    {
      "x": -5,
      "y": 8,
      "z": 4,
      "name": "Rock_Sandstone"
    },
    {
      "x": -5,
      "y": 9,
      "z": 4,
      "name": "Rock_Sandstone"
    },
    {
      "x": -5,
      "y": 10,
      "z": 4,
      "name": "Rock_Sandstone"
    },
    {
      "x": -5,
      "y": 11,
      "z": 4,
      "name": "Rock_Sandstone"
    },
    {
      "x": -5,
      "y": 12,
      "z": 4,
      "name": "Rock_Sandstone"
    },
    {
      "x": -5,
      "y": 13,
      "z": 4,
      "name": "Rock_Sandstone"
    },
    {
      "x": -5,
      "y": 14,
      "z": 4,
      "name": "Rock_Sandstone"
    },
    {
      "x": -5,
      "y": 3,
      "z": 5,
      "name": "Rock_Sandstone"
    },
    {
      "x": -5,
      "y": 4,
      "z": 5,
      "name": "Rock_Sandstone"
    },
    {
      "x": -5,
      "y": 5,
      "z": 5,
      "name": "Rock_Sandstone"
    },
    {
      "x": -5,
      "y": 6,
      "z": 5,
      "name": "Rock_Sandstone"
    },
    {
      "x": -5,
      "y": 7,
      "z": 5,
      "name": "Rock_Sandstone"
    },
    {
      "x": -5,
      "y": 8,
      "z": 5,
      "name": "Rock_Sandstone"
    },
    {
      "x": -5,
      "y": 9,
      "z": 5,
      "name": "Rock_Sandstone"
    },
    {
      "x": -5,
      "y": 10,
      "z": 5,
      "name": "Rock_Sandstone"
    },
    {
      "x": -5,
      "y": 11,
      "z": 5,
      "name": "Rock_Sandstone"
    },
    {
      "x": -5,
      "y": 12,
      "z": 5,
      "name": "Rock_Sandstone"
    },
    {
      "x": -5,
      "y": 13,
      "z": 5,
      "name": "Rock_Sandstone"
    },
    {
      "x": -5,
      "y": 14,
      "z": 5,
      "name": "Rock_Sandstone"
    },
    {
      "x": -5,
      "y": 3,
      "z": 6,
      "name": "Rock_Sandstone"
    },
    {
      "x": -5,
      "y": 4,
      "z": 6,
      "name": "Rock_Sandstone"
    },
    {
      "x": -5,
      "y": 5,
      "z": 6,
      "name": "Rock_Sandstone"
    },
    {
      "x": -5,
      "y": 6,
      "z": 6,
      "name": "Rock_Sandstone"
    },
    {
      "x": -5,
      "y": 7,
      "z": 6,
      "name": "Rock_Sandstone"
    },
    {
      "x": -5,
      "y": 8,
      "z": 6,
      "name": "Rock_Sandstone"
    },
    {
      "x": -5,
      "y": 9,
      "z": 6,
      "name": "Rock_Sandstone"
    },
    {
      "x": -5,
      "y": 10,
      "z": 6,
      "name": "Rock_Sandstone"
    },
    {
      "x": -5,
      "y": 11,
      "z": 6,
      "name": "Rock_Sandstone"
    },
    {
      "x": -5,
      "y": 12,
      "z": 6,
      "name": "Rock_Sandstone"
    },
    {
      "x": -5,
      "y": 13,
      "z": 6,
      "name": "Rock_Sandstone"
    },
    {
      "x": -5,
      "y": 14,
      "z": 6,
      "name": "Rock_Sandstone"
    },
    {
      "x": -5,
      "y": 3,
      "z": 7,
      "name": "Rock_Sandstone"
    },
    {
      "x": -5,
      "y": 4,
      "z": 7,
      "name": "Rock_Sandstone"
    },
    {
      "x": -5,
      "y": 5,
      "z": 7,
      "name": "Rock_Sandstone"
    },
    {
      "x": -5,
      "y": 6,
      "z": 7,
      "name": "Rock_Sandstone"
    },
    {
      "x": -5,
      "y": 7,
      "z": 7,
      "name": "Rock_Sandstone"
    },
    {
      "x": -5,
      "y": 8,
      "z": 7,
      "name": "Rock_Sandstone"
    },
    {
      "x": -5,
      "y": 9,
      "z": 7,
      "name": "Rock_Sandstone"
    },
    {
      "x": -5,
      "y": 10,
      "z": 7,
      "name": "Rock_Sandstone"
    },
    {
      "x": -5,
      "y": 11,
      "z": 7,
      "name": "Rock_Sandstone"
    },
    {
      "x": -5,
      "y": 12,
      "z": 7,
      "name": "Rock_Sandstone"
    },
    {
      "x": -5,
      "y": 13,
      "z": 7,
      "name": "Rock_Sandstone"
    },
    {
      "x": -5,
      "y": 5,
      "z": 8,
      "name": "Rock_Sandstone"
    },
    {
      "x": -5,
      "y": 6,
      "z": 8,
      "name": "Rock_Sandstone"
    },
    {
      "x": -5,
      "y": 7,
      "z": 8,
      "name": "Rock_Sandstone"
    },
    {
      "x": -5,
      "y": 8,
      "z": 8,
      "name": "Rock_Sandstone"
    },
    {
      "x": -5,
      "y": 9,
      "z": 8,
      "name": "Rock_Sandstone"
    },
    {
      "x": -5,
      "y": 10,
      "z": 8,
      "name": "Rock_Sandstone"
    },
    {
      "x": -4,
      "y": 4,
      "z": -6,
      "name": "Rock_Sandstone"
    },
    {
      "x": -4,
      "y": 5,
      "z": -6,
      "name": "Rock_Sandstone"
    },
    {
      "x": -4,
      "y": 6,
      "z": -6,
      "name": "Rock_Sandstone"
    },
    {
      "x": -4,
      "y": 7,
      "z": -6,
      "name": "Rock_Sandstone"
    },
    {
      "x": -4,
      "y": 8,
      "z": -6,
      "name": "Rock_Sandstone"
    },
    {
      "x": -4,
      "y": 9,
      "z": -6,
      "name": "Rock_Sandstone"
    },
    {
      "x": -4,
      "y": 10,
      "z": -6,
      "name": "Rock_Sandstone"
    },
    {
      "x": -4,
      "y": 11,
      "z": -6,
      "name": "Rock_Sandstone"
    },
    {
      "x": -4,
      "y": 12,
      "z": -6,
      "name": "Rock_Sandstone"
    },
    {
      "x": -4,
      "y": 13,
      "z": -6,
      "name": "Rock_Sandstone"
    },
    {
      "x": -4,
      "y": 3,
      "z": -5,
      "name": "Rock_Sandstone"
    },
    {
      "x": -4,
      "y": 4,
      "z": -5,
      "name": "Rock_Sandstone"
    },
    {
      "x": -4,
      "y": 5,
      "z": -5,
      "name": "Rock_Sandstone"
    },
    {
      "x": -4,
      "y": 6,
      "z": -5,
      "name": "Rock_Sandstone"
    },
    {
      "x": -4,
      "y": 7,
      "z": -5,
      "name": "Rock_Sandstone"
    },
    {
      "x": -4,
      "y": 8,
      "z": -5,
      "name": "Rock_Sandstone"
    },
    {
      "x": -4,
      "y": 9,
      "z": -5,
      "name": "Rock_Sandstone"
    },
    {
      "x": -4,
      "y": 10,
      "z": -5,
      "name": "Rock_Sandstone"
    },
    {
      "x": -4,
      "y": 11,
      "z": -5,
      "name": "Rock_Sandstone"
    },
    {
      "x": -4,
      "y": 12,
      "z": -5,
      "name": "Rock_Sandstone"
    },
    {
      "x": -4,
      "y": 13,
      "z": -5,
      "name": "Rock_Sandstone"
    },
    {
      "x": -4,
      "y": 14,
      "z": -5,
      "name": "Rock_Sandstone"
    },
    {
      "x": -4,
      "y": 3,
      "z": -4,
      "name": "Soil_Sand_White"
    },
    {
      "x": -4,
      "y": 4,
      "z": -4,
      "name": "Rock_Crystal_Yellow_Small"
    },
    {
      "x": -4,
      "y": 5,
      "z": -4,
      "name": "Empty"
    },
    {
      "x": -4,
      "y": 6,
      "z": -4,
      "name": "Empty"
    },
    {
      "x": -4,
      "y": 7,
      "z": -4,
      "name": "Rock_Sandstone_Brick"
    },
    {
      "x": -4,
      "y": 8,
      "z": -4,
      "name": "Rock_Sandstone_Brick"
    },
    {
      "x": -4,
      "y": 9,
      "z": -4,
      "name": "Rock_Sandstone_Brick"
    },
    {
      "x": -4,
      "y": 10,
      "z": -4,
      "name": "Rock_Sandstone_Brick"
    },
    {
      "x": -4,
      "y": 11,
      "z": -4,
      "name": "Rock_Sandstone_Brick_Ornate"
    },
    {
      "x": -4,
      "y": 12,
      "z": -4,
      "name": "Rock_Sandstone"
    },
    {
      "x": -4,
      "y": 13,
      "z": -4,
      "name": "Rock_Sandstone"
    },
    {
      "x": -4,
      "y": 14,
      "z": -4,
      "name": "Rock_Sandstone"
    },
    {
      "x": -4,
      "y": 3,
      "z": -3,
      "name": "Soil_Sand_White"
    },
    {
      "x": -4,
      "y": 4,
      "z": -3,
      "name": "Rock_Crystal_Yellow_Small"
    },
    {
      "x": -4,
      "y": 5,
      "z": -3,
      "name": "Empty"
    },
    {
      "x": -4,
      "y": 6,
      "z": -3,
      "name": "Empty"
    },
    {
      "x": -4,
      "y": 7,
      "z": -3,
      "name": "Empty"
    },
    {
      "x": -4,
      "y": 8,
      "z": -3,
      "name": "Empty"
    },
    {
      "x": -4,
      "y": 9,
      "z": -3,
      "name": "Empty"
    },
    {
      "x": -4,
      "y": 10,
      "z": -3,
      "name": "Empty"
    },
    {
      "x": -4,
      "y": 11,
      "z": -3,
      "name": "Empty"
    },
    {
      "x": -4,
      "y": 12,
      "z": -3,
      "name": "Rock_Sandstone"
    },
    {
      "x": -4,
      "y": 13,
      "z": -3,
      "name": "Rock_Sandstone"
    },
    {
      "x": -4,
      "y": 14,
      "z": -3,
      "name": "Rock_Sandstone"
    },
    {
      "x": -4,
      "y": 15,
      "z": -3,
      "name": "Rock_Sandstone"
    },
    {
      "x": -4,
      "y": 3,
      "z": -2,
      "name": "Rock_Sandstone"
    },
    {
      "x": -4,
      "y": 4,
      "z": -2,
      "name": "Soil_Sand_White"
    },
    {
      "x": -4,
      "y": 5,
      "z": -2,
      "name": "Rock_Sandstone_Brick_Ornate"
    },
    {
      "x": -4,
      "y": 6,
      "z": -2,
      "name": "Rock_Sandstone_Brick_Pillar_Base"
    },
    {
      "x": -4,
      "y": 7,
      "z": -2,
      "name": "Rock_Sandstone_Brick_Pillar_Middle"
    },
    {
      "x": -4,
      "y": 8,
      "z": -2,
      "name": "Rock_Sandstone_Brick_Pillar_Middle"
    },
    {
      "x": -4,
      "y": 9,
      "z": -2,
      "name": "Rock_Sandstone_Brick_Pillar_Middle"
    },
    {
      "x": -4,
      "y": 10,
      "z": -2,
      "name": "Rock_Sandstone_Brick_Pillar_Middle"
    },
    {
      "x": -4,
      "y": 11,
      "z": -2,
      "name": "Rock_Sandstone_Brick_Pillar_Middle"
    },
    {
      "x": -4,
      "y": 12,
      "z": -2,
      "name": "Rock_Sandstone_Brick_Pillar_Base",
      "rotation": 8
    },
    {
      "x": -4,
      "y": 13,
      "z": -2,
      "name": "Rock_Sandstone"
    },
    {
      "x": -4,
      "y": 14,
      "z": -2,
      "name": "Rock_Sandstone"
    },
    {
      "x": -4,
      "y": 15,
      "z": -2,
      "name": "Rock_Sandstone"
    },
    {
      "x": -4,
      "y": 3,
      "z": -1,
      "name": "Rock_Sandstone"
    },
    {
      "x": -4,
      "y": 4,
      "z": -1,
      "name": "Soil_Sand_White"
    },
    {
      "x": -4,
      "y": 5,
      "z": -1,
      "name": "Rock_Sandstone_Brick_Ornate"
    },
    {
      "x": -4,
      "y": 6,
      "z": -1,
      "name": "Rock_Sandstone_Brick_Pillar_Base"
    },
    {
      "x": -4,
      "y": 7,
      "z": -1,
      "name": "Rock_Sandstone_Brick_Pillar_Middle"
    },
    {
      "x": -4,
      "y": 8,
      "z": -1,
      "name": "Rock_Sandstone_Brick_Pillar_Middle"
    },
    {
      "x": -4,
      "y": 9,
      "z": -1,
      "name": "Rock_Sandstone_Brick_Pillar_Middle"
    },
    {
      "x": -4,
      "y": 10,
      "z": -1,
      "name": "Rock_Sandstone_Brick_Pillar_Middle"
    },
    {
      "x": -4,
      "y": 11,
      "z": -1,
      "name": "Rock_Sandstone_Brick_Pillar_Middle"
    },
    {
      "x": -4,
      "y": 12,
      "z": -1,
      "name": "Rock_Sandstone_Brick_Pillar_Base",
      "rotation": 8
    },
    {
      "x": -4,
      "y": 13,
      "z": -1,
      "name": "Rock_Sandstone"
    },
    {
      "x": -4,
      "y": 14,
      "z": -1,
      "name": "Rock_Sandstone"
    },
    {
      "x": -4,
      "y": 15,
      "z": -1,
      "name": "Rock_Sandstone"
    },
    {
      "x": -4,
      "y": 3,
      "z": 0,
      "name": "Rock_Sandstone"
    },
    {
      "x": -4,
      "y": 4,
      "z": 0,
      "name": "Soil_Sand_White"
    },
    {
      "x": -4,
      "y": 5,
      "z": 0,
      "name": "Empty"
    },
    {
      "x": -4,
      "y": 6,
      "z": 0,
      "name": "Empty"
    },
    {
      "x": -4,
      "y": 7,
      "z": 0,
      "name": "Empty"
    },
    {
      "x": -4,
      "y": 8,
      "z": 0,
      "name": "Empty"
    },
    {
      "x": -4,
      "y": 9,
      "z": 0,
      "name": "Empty"
    },
    {
      "x": -4,
      "y": 10,
      "z": 0,
      "name": "Empty"
    },
    {
      "x": -4,
      "y": 11,
      "z": 0,
      "name": "Empty"
    },
    {
      "x": -4,
      "y": 12,
      "z": 0,
      "name": "Empty"
    },
    {
      "x": -4,
      "y": 13,
      "z": 0,
      "name": "Rock_Sandstone"
    },
    {
      "x": -4,
      "y": 14,
      "z": 0,
      "name": "Rock_Sandstone"
    },
    {
      "x": -4,
      "y": 15,
      "z": 0,
      "name": "Rock_Sandstone"
    },
    {
      "x": -4,
      "y": 3,
      "z": 1,
      "name": "Rock_Sandstone"
    },
    {
      "x": -4,
      "y": 4,
      "z": 1,
      "name": "Soil_Sand_White"
    },
    {
      "x": -4,
      "y": 5,
      "z": 1,
      "name": "Empty"
    },
    {
      "x": -4,
      "y": 6,
      "z": 1,
      "name": "Empty"
    },
    {
      "x": -4,
      "y": 7,
      "z": 1,
      "name": "Empty"
    },
    {
      "x": -4,
      "y": 8,
      "z": 1,
      "name": "Empty"
    },
    {
      "x": -4,
      "y": 9,
      "z": 1,
      "name": "Empty"
    },
    {
      "x": -4,
      "y": 10,
      "z": 1,
      "name": "Empty"
    },
    {
      "x": -4,
      "y": 11,
      "z": 1,
      "name": "Empty"
    },
    {
      "x": -4,
      "y": 12,
      "z": 1,
      "name": "Empty"
    },
    {
      "x": -4,
      "y": 13,
      "z": 1,
      "name": "Rock_Sandstone"
    },
    {
      "x": -4,
      "y": 14,
      "z": 1,
      "name": "Rock_Sandstone"
    },
    {
      "x": -4,
      "y": 15,
      "z": 1,
      "name": "Rock_Sandstone"
    },
    {
      "x": -4,
      "y": 3,
      "z": 2,
      "name": "Rock_Sandstone"
    },
    {
      "x": -4,
      "y": 4,
      "z": 2,
      "name": "Soil_Sand_White"
    },
    {
      "x": -4,
      "y": 5,
      "z": 2,
      "name": "Empty"
    },
    {
      "x": -4,
      "y": 6,
      "z": 2,
      "name": "Empty"
    },
    {
      "x": -4,
      "y": 7,
      "z": 2,
      "name": "Empty"
    },
    {
      "x": -4,
      "y": 8,
      "z": 2,
      "name": "Empty"
    },
    {
      "x": -4,
      "y": 9,
      "z": 2,
      "name": "Empty"
    },
    {
      "x": -4,
      "y": 10,
      "z": 2,
      "name": "Empty"
    },
    {
      "x": -4,
      "y": 11,
      "z": 2,
      "name": "Empty"
    },
    {
      "x": -4,
      "y": 12,
      "z": 2,
      "name": "Empty"
    },
    {
      "x": -4,
      "y": 13,
      "z": 2,
      "name": "Rock_Sandstone"
    },
    {
      "x": -4,
      "y": 14,
      "z": 2,
      "name": "Rock_Sandstone"
    },
    {
      "x": -4,
      "y": 15,
      "z": 2,
      "name": "Rock_Sandstone"
    },
    {
      "x": -4,
      "y": 3,
      "z": 3,
      "name": "Rock_Sandstone"
    },
    {
      "x": -4,
      "y": 4,
      "z": 3,
      "name": "Soil_Sand_White"
    },
    {
      "x": -4,
      "y": 5,
      "z": 3,
      "name": "Rock_Sandstone_Brick_Ornate"
    },
    {
      "x": -4,
      "y": 6,
      "z": 3,
      "name": "Rock_Sandstone_Brick_Pillar_Base"
    },
    {
      "x": -4,
      "y": 7,
      "z": 3,
      "name": "Rock_Sandstone_Brick_Pillar_Middle"
    },
    {
      "x": -4,
      "y": 8,
      "z": 3,
      "name": "Rock_Sandstone_Brick_Pillar_Middle"
    },
    {
      "x": -4,
      "y": 9,
      "z": 3,
      "name": "Rock_Sandstone_Brick_Pillar_Middle"
    },
    {
      "x": -4,
      "y": 10,
      "z": 3,
      "name": "Rock_Sandstone_Brick_Pillar_Base",
      "rotation": 8
    },
    {
      "x": -4,
      "y": 11,
      "z": 3,
      "name": "Rock_Sandstone"
    },
    {
      "x": -4,
      "y": 12,
      "z": 3,
      "name": "Rock_Sandstone"
    },
    {
      "x": -4,
      "y": 13,
      "z": 3,
      "name": "Rock_Sandstone"
    },
    {
      "x": -4,
      "y": 14,
      "z": 3,
      "name": "Rock_Sandstone"
    },
    {
      "x": -4,
      "y": 15,
      "z": 3,
      "name": "Rock_Sandstone"
    },
    {
      "x": -4,
      "y": 3,
      "z": 4,
      "name": "Rock_Sandstone"
    },
    {
      "x": -4,
      "y": 4,
      "z": 4,
      "name": "Soil_Sand_White"
    },
    {
      "x": -4,
      "y": 5,
      "z": 4,
      "name": "Rock_Sandstone_Brick_Ornate"
    },
    {
      "x": -4,
      "y": 6,
      "z": 4,
      "name": "Rock_Sandstone_Brick_Pillar_Base"
    },
    {
      "x": -4,
      "y": 7,
      "z": 4,
      "name": "Rock_Sandstone_Brick_Pillar_Middle"
    },
    {
      "x": -4,
      "y": 8,
      "z": 4,
      "name": "Rock_Sandstone"
    },
    {
      "x": -4,
      "y": 9,
      "z": 4,
      "name": "Rock_Sandstone"
    },
    {
      "x": -4,
      "y": 10,
      "z": 4,
      "name": "Rock_Sandstone"
    },
    {
      "x": -4,
      "y": 11,
      "z": 4,
      "name": "Rock_Sandstone"
    },
    {
      "x": -4,
      "y": 12,
      "z": 4,
      "name": "Rock_Sandstone"
    },
    {
      "x": -4,
      "y": 13,
      "z": 4,
      "name": "Rock_Sandstone"
    },
    {
      "x": -4,
      "y": 14,
      "z": 4,
      "name": "Rock_Sandstone"
    },
    {
      "x": -4,
      "y": 15,
      "z": 4,
      "name": "Rock_Sandstone"
    },
    {
      "x": -4,
      "y": 3,
      "z": 5,
      "name": "Soil_Sand_White"
    },
    {
      "x": -4,
      "y": 4,
      "z": 5,
      "name": "Rock_Crystal_Yellow_Small"
    },
    {
      "x": -4,
      "y": 5,
      "z": 5,
      "name": "Empty"
    },
    {
      "x": -4,
      "y": 6,
      "z": 5,
      "name": "Empty"
    },
    {
      "x": -4,
      "y": 7,
      "z": 5,
      "name": "Empty"
    },
    {
      "x": -4,
      "y": 8,
      "z": 5,
      "name": "Rock_Sandstone"
    },
    {
      "x": -4,
      "y": 9,
      "z": 5,
      "name": "Rock_Sandstone"
    },
    {
      "x": -4,
      "y": 10,
      "z": 5,
      "name": "Rock_Sandstone"
    },
    {
      "x": -4,
      "y": 11,
      "z": 5,
      "name": "Rock_Sandstone"
    },
    {
      "x": -4,
      "y": 12,
      "z": 5,
      "name": "Rock_Sandstone"
    },
    {
      "x": -4,
      "y": 13,
      "z": 5,
      "name": "Rock_Sandstone"
    },
    {
      "x": -4,
      "y": 14,
      "z": 5,
      "name": "Rock_Sandstone"
    },
    {
      "x": -4,
      "y": 15,
      "z": 5,
      "name": "Rock_Sandstone"
    },
    {
      "x": -4,
      "y": 3,
      "z": 6,
      "name": "Rock_Sandstone"
    },
    {
      "x": -4,
      "y": 4,
      "z": 6,
      "name": "Rock_Sandstone"
    },
    {
      "x": -4,
      "y": 5,
      "z": 6,
      "name": "Rock_Sandstone"
    },
    {
      "x": -4,
      "y": 6,
      "z": 6,
      "name": "Rock_Sandstone"
    },
    {
      "x": -4,
      "y": 7,
      "z": 6,
      "name": "Rock_Sandstone"
    },
    {
      "x": -4,
      "y": 8,
      "z": 6,
      "name": "Rock_Sandstone"
    },
    {
      "x": -4,
      "y": 9,
      "z": 6,
      "name": "Rock_Sandstone"
    },
    {
      "x": -4,
      "y": 10,
      "z": 6,
      "name": "Rock_Sandstone"
    },
    {
      "x": -4,
      "y": 11,
      "z": 6,
      "name": "Rock_Sandstone"
    },
    {
      "x": -4,
      "y": 12,
      "z": 6,
      "name": "Rock_Sandstone"
    },
    {
      "x": -4,
      "y": 13,
      "z": 6,
      "name": "Rock_Sandstone"
    },
    {
      "x": -4,
      "y": 14,
      "z": 6,
      "name": "Rock_Sandstone"
    },
    {
      "x": -4,
      "y": 3,
      "z": 7,
      "name": "Rock_Sandstone"
    },
    {
      "x": -4,
      "y": 4,
      "z": 7,
      "name": "Rock_Sandstone"
    },
    {
      "x": -4,
      "y": 5,
      "z": 7,
      "name": "Rock_Sandstone"
    },
    {
      "x": -4,
      "y": 6,
      "z": 7,
      "name": "Rock_Sandstone"
    },
    {
      "x": -4,
      "y": 7,
      "z": 7,
      "name": "Rock_Sandstone"
    },
    {
      "x": -4,
      "y": 8,
      "z": 7,
      "name": "Rock_Sandstone"
    },
    {
      "x": -4,
      "y": 9,
      "z": 7,
      "name": "Rock_Sandstone"
    },
    {
      "x": -4,
      "y": 10,
      "z": 7,
      "name": "Rock_Sandstone"
    },
    {
      "x": -4,
      "y": 11,
      "z": 7,
      "name": "Rock_Sandstone"
    },
    {
      "x": -4,
      "y": 12,
      "z": 7,
      "name": "Rock_Sandstone"
    },
    {
      "x": -4,
      "y": 13,
      "z": 7,
      "name": "Rock_Sandstone"
    },
    {
      "x": -4,
      "y": 4,
      "z": 8,
      "name": "Rock_Sandstone"
    },
    {
      "x": -4,
      "y": 5,
      "z": 8,
      "name": "Rock_Sandstone"
    },
    {
      "x": -4,
      "y": 6,
      "z": 8,
      "name": "Rock_Sandstone"
    },
    {
      "x": -4,
      "y": 7,
      "z": 8,
      "name": "Rock_Sandstone"
    },
    {
      "x": -4,
      "y": 8,
      "z": 8,
      "name": "Rock_Sandstone"
    },
    {
      "x": -4,
      "y": 9,
      "z": 8,
      "name": "Rock_Sandstone"
    },
    {
      "x": -4,
      "y": 10,
      "z": 8,
      "name": "Rock_Sandstone"
    },
    {
      "x": -4,
      "y": 11,
      "z": 8,
      "name": "Rock_Sandstone"
    },
    {
      "x": -4,
      "y": 12,
      "z": 8,
      "name": "Rock_Sandstone"
    },
    {
      "x": -4,
      "y": 13,
      "z": 8,
      "name": "Rock_Sandstone"
    },
    {
      "x": -3,
      "y": 4,
      "z": -6,
      "name": "Rock_Sandstone"
    },
    {
      "x": -3,
      "y": 5,
      "z": -6,
      "name": "Rock_Sandstone"
    },
    {
      "x": -3,
      "y": 6,
      "z": -6,
      "name": "Rock_Sandstone"
    },
    {
      "x": -3,
      "y": 7,
      "z": -6,
      "name": "Rock_Sandstone"
    },
    {
      "x": -3,
      "y": 8,
      "z": -6,
      "name": "Rock_Sandstone"
    },
    {
      "x": -3,
      "y": 9,
      "z": -6,
      "name": "Rock_Sandstone"
    },
    {
      "x": -3,
      "y": 10,
      "z": -6,
      "name": "Rock_Sandstone"
    },
    {
      "x": -3,
      "y": 11,
      "z": -6,
      "name": "Rock_Sandstone"
    },
    {
      "x": -3,
      "y": 12,
      "z": -6,
      "name": "Rock_Sandstone"
    },
    {
      "x": -3,
      "y": 13,
      "z": -6,
      "name": "Rock_Sandstone"
    },
    {
      "x": -3,
      "y": 3,
      "z": -5,
      "name": "Rock_Sandstone"
    },
    {
      "x": -3,
      "y": 4,
      "z": -5,
      "name": "Rock_Sandstone"
    },
    {
      "x": -3,
      "y": 5,
      "z": -5,
      "name": "Rock_Sandstone"
    },
    {
      "x": -3,
      "y": 6,
      "z": -5,
      "name": "Rock_Sandstone"
    },
    {
      "x": -3,
      "y": 7,
      "z": -5,
      "name": "Rock_Sandstone"
    },
    {
      "x": -3,
      "y": 8,
      "z": -5,
      "name": "Rock_Sandstone"
    },
    {
      "x": -3,
      "y": 9,
      "z": -5,
      "name": "Rock_Sandstone_Brick"
    },
    {
      "x": -3,
      "y": 10,
      "z": -5,
      "name": "Rock_Sandstone_Brick"
    },
    {
      "x": -3,
      "y": 11,
      "z": -5,
      "name": "Rock_Sandstone_Brick_Ornate"
    },
    {
      "x": -3,
      "y": 12,
      "z": -5,
      "name": "Rock_Sandstone"
    },
    {
      "x": -3,
      "y": 13,
      "z": -5,
      "name": "Rock_Sandstone"
    },
    {
      "x": -3,
      "y": 14,
      "z": -5,
      "name": "Rock_Sandstone"
    },
    {
      "x": -3,
      "y": 3,
      "z": -4,
      "name": "Soil_Sand_White"
    },
    {
      "x": -3,
      "y": 4,
      "z": -4,
      "name": "Rock_Crystal_Yellow_Small"
    },
    {
      "x": -3,
      "y": 5,
      "z": -4,
      "name": "Empty"
    },
    {
      "x": -3,
      "y": 6,
      "z": -4,
      "name": "Empty"
    },
    {
      "x": -3,
      "y": 7,
      "z": -4,
      "name": "Empty"
    },
    {
      "x": -3,
      "y": 8,
      "z": -4,
      "name": "Empty"
    },
    {
      "x": -3,
      "y": 9,
      "z": -4,
      "name": "Rock_Sandstone_Brick_Half"
    },
    {
      "x": -3,
      "y": 10,
      "z": -4,
      "name": "Rock_Sandstone_Brick"
    },
    {
      "x": -3,
      "y": 11,
      "z": -4,
      "name": "Rock_Sandstone_Brick_Ornate"
    },
    {
      "x": -3,
      "y": 12,
      "z": -4,
      "name": "Rock_Sandstone"
    },
    {
      "x": -3,
      "y": 13,
      "z": -4,
      "name": "Rock_Sandstone"
    },
    {
      "x": -3,
      "y": 14,
      "z": -4,
      "name": "Rock_Sandstone"
    },
    {
      "x": -3,
      "y": 15,
      "z": -4,
      "name": "Rock_Sandstone"
    },
    {
      "x": -3,
      "y": 3,
      "z": -3,
      "name": "Rock_Sandstone"
    },
    {
      "x": -3,
      "y": 4,
      "z": -3,
      "name": "Soil_Sand_White"
    },
    {
      "x": -3,
      "y": 5,
      "z": -3,
      "name": "Rock_Sandstone_Brick_Half"
    },
    {
      "x": -3,
      "y": 6,
      "z": -3,
      "name": "Empty"
    },
    {
      "x": -3,
      "y": 7,
      "z": -3,
      "name": "Empty"
    },
    {
      "x": -3,
      "y": 8,
      "z": -3,
      "name": "Empty"
    },
    {
      "x": -3,
      "y": 9,
      "z": -3,
      "name": "Empty"
    },
    {
      "x": -3,
      "y": 10,
      "z": -3,
      "name": "Empty"
    },
    {
      "x": -3,
      "y": 11,
      "z": -3,
      "name": "Empty"
    },
    {
      "x": -3,
      "y": 12,
      "z": -3,
      "name": "Empty"
    },
    {
      "x": -3,
      "y": 13,
      "z": -3,
      "name": "Empty"
    },
    {
      "x": -3,
      "y": 14,
      "z": -3,
      "name": "Rock_Sandstone"
    },
    {
      "x": -3,
      "y": 15,
      "z": -3,
      "name": "Rock_Sandstone"
    },
    {
      "x": -3,
      "y": 3,
      "z": -2,
      "name": "Rock_Sandstone"
    },
    {
      "x": -3,
      "y": 4,
      "z": -2,
      "name": "Soil_Sand_White"
    },
    {
      "x": -3,
      "y": 5,
      "z": -2,
      "name": "Rock_Sandstone_Brick_Half"
    },
    {
      "x": -3,
      "y": 6,
      "z": -2,
      "name": "Empty"
    },
    {
      "x": -3,
      "y": 7,
      "z": -2,
      "name": "Empty"
    },
    {
      "x": -3,
      "y": 8,
      "z": -2,
      "name": "Empty"
    },
    {
      "x": -3,
      "y": 9,
      "z": -2,
      "name": "Empty"
    },
    {
      "x": -3,
      "y": 10,
      "z": -2,
      "name": "Empty"
    },
    {
      "x": -3,
      "y": 11,
      "z": -2,
      "name": "Empty"
    },
    {
      "x": -3,
      "y": 12,
      "z": -2,
      "name": "Empty"
    },
    {
      "x": -3,
      "y": 13,
      "z": -2,
      "name": "Empty"
    },
    {
      "x": -3,
      "y": 14,
      "z": -2,
      "name": "Rock_Sandstone"
    },
    {
      "x": -3,
      "y": 15,
      "z": -2,
      "name": "Rock_Sandstone"
    },
    {
      "x": -3,
      "y": 3,
      "z": -1,
      "name": "Rock_Sandstone"
    },
    {
      "x": -3,
      "y": 4,
      "z": -1,
      "name": "Soil_Sand_White"
    },
    {
      "x": -3,
      "y": 5,
      "z": -1,
      "name": "Empty"
    },
    {
      "x": -3,
      "y": 6,
      "z": -1,
      "name": "Empty"
    },
    {
      "x": -3,
      "y": 7,
      "z": -1,
      "name": "Empty"
    },
    {
      "x": -3,
      "y": 8,
      "z": -1,
      "name": "Empty"
    },
    {
      "x": -3,
      "y": 9,
      "z": -1,
      "name": "Empty"
    },
    {
      "x": -3,
      "y": 10,
      "z": -1,
      "name": "Empty"
    },
    {
      "x": -3,
      "y": 11,
      "z": -1,
      "name": "Empty"
    },
    {
      "x": -3,
      "y": 12,
      "z": -1,
      "name": "Empty"
    },
    {
      "x": -3,
      "y": 13,
      "z": -1,
      "name": "Empty"
    },
    {
      "x": -3,
      "y": 14,
      "z": -1,
      "name": "Rock_Sandstone"
    },
    {
      "x": -3,
      "y": 15,
      "z": -1,
      "name": "Rock_Sandstone"
    },
    {
      "x": -3,
      "y": 3,
      "z": 0,
      "name": "Rock_Sandstone"
    },
    {
      "x": -3,
      "y": 4,
      "z": 0,
      "name": "Soil_Sand_White"
    },
    {
      "x": -3,
      "y": 5,
      "z": 0,
      "name": "Empty"
    },
    {
      "x": -3,
      "y": 6,
      "z": 0,
      "name": "Empty"
    },
    {
      "x": -3,
      "y": 7,
      "z": 0,
      "name": "Empty"
    },
    {
      "x": -3,
      "y": 8,
      "z": 0,
      "name": "Empty"
    },
    {
      "x": -3,
      "y": 9,
      "z": 0,
      "name": "Empty"
    },
    {
      "x": -3,
      "y": 10,
      "z": 0,
      "name": "Empty"
    },
    {
      "x": -3,
      "y": 11,
      "z": 0,
      "name": "Empty"
    },
    {
      "x": -3,
      "y": 12,
      "z": 0,
      "name": "Empty"
    },
    {
      "x": -3,
      "y": 13,
      "z": 0,
      "name": "Empty"
    },
    {
      "x": -3,
      "y": 14,
      "z": 0,
      "name": "Rock_Sandstone"
    },
    {
      "x": -3,
      "y": 15,
      "z": 0,
      "name": "Rock_Sandstone"
    },
    {
      "x": -3,
      "y": 3,
      "z": 1,
      "name": "Rock_Sandstone"
    },
    {
      "x": -3,
      "y": 4,
      "z": 1,
      "name": "Soil_Sand_White"
    },
    {
      "x": -3,
      "y": 5,
      "z": 1,
      "name": "Empty"
    },
    {
      "x": -3,
      "y": 6,
      "z": 1,
      "name": "Empty"
    },
    {
      "x": -3,
      "y": 7,
      "z": 1,
      "name": "Empty"
    },
    {
      "x": -3,
      "y": 8,
      "z": 1,
      "name": "Empty"
    },
    {
      "x": -3,
      "y": 9,
      "z": 1,
      "name": "Empty"
    },
    {
      "x": -3,
      "y": 10,
      "z": 1,
      "name": "Empty"
    },
    {
      "x": -3,
      "y": 11,
      "z": 1,
      "name": "Empty"
    },
    {
      "x": -3,
      "y": 12,
      "z": 1,
      "name": "Empty"
    },
    {
      "x": -3,
      "y": 13,
      "z": 1,
      "name": "Rock_Sandstone"
    },
    {
      "x": -3,
      "y": 14,
      "z": 1,
      "name": "Rock_Sandstone"
    },
    {
      "x": -3,
      "y": 15,
      "z": 1,
      "name": "Rock_Sandstone"
    },
    {
      "x": -3,
      "y": 3,
      "z": 2,
      "name": "Rock_Sandstone"
    },
    {
      "x": -3,
      "y": 4,
      "z": 2,
      "name": "Soil_Sand_White"
    },
    {
      "x": -3,
      "y": 5,
      "z": 2,
      "name": "Empty"
    },
    {
      "x": -3,
      "y": 6,
      "z": 2,
      "name": "Empty"
    },
    {
      "x": -3,
      "y": 7,
      "z": 2,
      "name": "Empty"
    },
    {
      "x": -3,
      "y": 8,
      "z": 2,
      "name": "Empty"
    },
    {
      "x": -3,
      "y": 9,
      "z": 2,
      "name": "Empty"
    },
    {
      "x": -3,
      "y": 10,
      "z": 2,
      "name": "Empty"
    },
    {
      "x": -3,
      "y": 11,
      "z": 2,
      "name": "Empty"
    },
    {
      "x": -3,
      "y": 12,
      "z": 2,
      "name": "Empty"
    },
    {
      "x": -3,
      "y": 13,
      "z": 2,
      "name": "Rock_Sandstone"
    },
    {
      "x": -3,
      "y": 14,
      "z": 2,
      "name": "Rock_Sandstone"
    },
    {
      "x": -3,
      "y": 15,
      "z": 2,
      "name": "Rock_Sandstone"
    },
    {
      "x": -3,
      "y": 3,
      "z": 3,
      "name": "Rock_Sandstone"
    },
    {
      "x": -3,
      "y": 4,
      "z": 3,
      "name": "Soil_Sand_White"
    },
    {
      "x": -3,
      "y": 5,
      "z": 3,
      "name": "Empty"
    },
    {
      "x": -3,
      "y": 6,
      "z": 3,
      "name": "Empty"
    },
    {
      "x": -3,
      "y": 7,
      "z": 3,
      "name": "Empty"
    },
    {
      "x": -3,
      "y": 8,
      "z": 3,
      "name": "Empty"
    },
    {
      "x": -3,
      "y": 9,
      "z": 3,
      "name": "Empty"
    },
    {
      "x": -3,
      "y": 10,
      "z": 3,
      "name": "Empty"
    },
    {
      "x": -3,
      "y": 11,
      "z": 3,
      "name": "Empty"
    },
    {
      "x": -3,
      "y": 12,
      "z": 3,
      "name": "Empty"
    },
    {
      "x": -3,
      "y": 13,
      "z": 3,
      "name": "Rock_Sandstone"
    },
    {
      "x": -3,
      "y": 14,
      "z": 3,
      "name": "Rock_Sandstone"
    },
    {
      "x": -3,
      "y": 15,
      "z": 3,
      "name": "Rock_Sandstone"
    },
    {
      "x": -3,
      "y": 3,
      "z": 4,
      "name": "Rock_Sandstone"
    },
    {
      "x": -3,
      "y": 4,
      "z": 4,
      "name": "Soil_Sand_White"
    },
    {
      "x": -3,
      "y": 5,
      "z": 4,
      "name": "Rock_Sandstone_Brick_Half"
    },
    {
      "x": -3,
      "y": 6,
      "z": 4,
      "name": "Empty"
    },
    {
      "x": -3,
      "y": 7,
      "z": 4,
      "name": "Empty"
    },
    {
      "x": -3,
      "y": 8,
      "z": 4,
      "name": "Empty"
    },
    {
      "x": -3,
      "y": 9,
      "z": 4,
      "name": "Empty"
    },
    {
      "x": -3,
      "y": 10,
      "z": 4,
      "name": "Empty"
    },
    {
      "x": -3,
      "y": 11,
      "z": 4,
      "name": "Empty"
    },
    {
      "x": -3,
      "y": 12,
      "z": 4,
      "name": "Empty"
    },
    {
      "x": -3,
      "y": 13,
      "z": 4,
      "name": "Rock_Sandstone"
    },
    {
      "x": -3,
      "y": 14,
      "z": 4,
      "name": "Rock_Sandstone"
    },
    {
      "x": -3,
      "y": 15,
      "z": 4,
      "name": "Rock_Sandstone"
    },
    {
      "x": -3,
      "y": 3,
      "z": 5,
      "name": "Rock_Sandstone"
    },
    {
      "x": -3,
      "y": 4,
      "z": 5,
      "name": "Soil_Sand_White"
    },
    {
      "x": -3,
      "y": 5,
      "z": 5,
      "name": "Rock_Sandstone_Brick_Half"
    },
    {
      "x": -3,
      "y": 6,
      "z": 5,
      "name": "Empty"
    },
    {
      "x": -3,
      "y": 7,
      "z": 5,
      "name": "Empty"
    },
    {
      "x": -3,
      "y": 8,
      "z": 5,
      "name": "Empty"
    },
    {
      "x": -3,
      "y": 9,
      "z": 5,
      "name": "Empty"
    },
    {
      "x": -3,
      "y": 10,
      "z": 5,
      "name": "Empty"
    },
    {
      "x": -3,
      "y": 11,
      "z": 5,
      "name": "Empty"
    },
    {
      "x": -3,
      "y": 12,
      "z": 5,
      "name": "Empty"
    },
    {
      "x": -3,
      "y": 13,
      "z": 5,
      "name": "Rock_Sandstone"
    },
    {
      "x": -3,
      "y": 14,
      "z": 5,
      "name": "Rock_Sandstone"
    },
    {
      "x": -3,
      "y": 15,
      "z": 5,
      "name": "Rock_Sandstone"
    },
    {
      "x": -3,
      "y": 3,
      "z": 6,
      "name": "Soil_Sand_White"
    },
    {
      "x": -3,
      "y": 4,
      "z": 6,
      "name": "Rock_Crystal_Yellow_Small"
    },
    {
      "x": -3,
      "y": 5,
      "z": 6,
      "name": "Empty"
    },
    {
      "x": -3,
      "y": 6,
      "z": 6,
      "name": "Empty"
    },
    {
      "x": -3,
      "y": 7,
      "z": 6,
      "name": "Empty"
    },
    {
      "x": -3,
      "y": 8,
      "z": 6,
      "name": "Empty"
    },
    {
      "x": -3,
      "y": 9,
      "z": 6,
      "name": "Empty"
    },
    {
      "x": -3,
      "y": 10,
      "z": 6,
      "name": "Empty"
    },
    {
      "x": -3,
      "y": 11,
      "z": 6,
      "name": "Empty"
    },
    {
      "x": -3,
      "y": 12,
      "z": 6,
      "name": "Empty"
    },
    {
      "x": -3,
      "y": 13,
      "z": 6,
      "name": "Rock_Sandstone"
    },
    {
      "x": -3,
      "y": 14,
      "z": 6,
      "name": "Rock_Sandstone"
    },
    {
      "x": -3,
      "y": 15,
      "z": 6,
      "name": "Rock_Sandstone"
    },
    {
      "x": -3,
      "y": 3,
      "z": 7,
      "name": "Rock_Sandstone"
    },
    {
      "x": -3,
      "y": 4,
      "z": 7,
      "name": "Soil_Sand_White"
    },
    {
      "x": -3,
      "y": 5,
      "z": 7,
      "name": "Empty"
    },
    {
      "x": -3,
      "y": 6,
      "z": 7,
      "name": "Empty"
    },
    {
      "x": -3,
      "y": 7,
      "z": 7,
      "name": "Rock_Sandstone"
    },
    {
      "x": -3,
      "y": 8,
      "z": 7,
      "name": "Rock_Sandstone"
    },
    {
      "x": -3,
      "y": 9,
      "z": 7,
      "name": "Rock_Sandstone"
    },
    {
      "x": -3,
      "y": 10,
      "z": 7,
      "name": "Rock_Sandstone"
    },
    {
      "x": -3,
      "y": 11,
      "z": 7,
      "name": "Rock_Sandstone"
    },
    {
      "x": -3,
      "y": 12,
      "z": 7,
      "name": "Rock_Sandstone"
    },
    {
      "x": -3,
      "y": 13,
      "z": 7,
      "name": "Rock_Sandstone"
    },
    {
      "x": -3,
      "y": 14,
      "z": 7,
      "name": "Rock_Sandstone"
    },
    {
      "x": -3,
      "y": 4,
      "z": 8,
      "name": "Rock_Sandstone"
    },
    {
      "x": -3,
      "y": 5,
      "z": 8,
      "name": "Rock_Sandstone"
    },
    {
      "x": -3,
      "y": 6,
      "z": 8,
      "name": "Rock_Sandstone"
    },
    {
      "x": -3,
      "y": 7,
      "z": 8,
      "name": "Rock_Sandstone"
    },
    {
      "x": -3,
      "y": 8,
      "z": 8,
      "name": "Rock_Sandstone"
    },
    {
      "x": -3,
      "y": 9,
      "z": 8,
      "name": "Rock_Sandstone"
    },
    {
      "x": -3,
      "y": 10,
      "z": 8,
      "name": "Rock_Sandstone"
    },
    {
      "x": -3,
      "y": 11,
      "z": 8,
      "name": "Rock_Sandstone"
    },
    {
      "x": -3,
      "y": 12,
      "z": 8,
      "name": "Rock_Sandstone"
    },
    {
      "x": -3,
      "y": 13,
      "z": 8,
      "name": "Rock_Sandstone"
    },
    {
      "x": -2,
      "y": 4,
      "z": -6,
      "name": "Rock_Sandstone"
    },
    {
      "x": -2,
      "y": 5,
      "z": -6,
      "name": "Rock_Sandstone"
    },
    {
      "x": -2,
      "y": 6,
      "z": -6,
      "name": "Rock_Sandstone"
    },
    {
      "x": -2,
      "y": 7,
      "z": -6,
      "name": "Rock_Sandstone"
    },
    {
      "x": -2,
      "y": 8,
      "z": -6,
      "name": "Rock_Sandstone"
    },
    {
      "x": -2,
      "y": 9,
      "z": -6,
      "name": "Rock_Sandstone"
    },
    {
      "x": -2,
      "y": 10,
      "z": -6,
      "name": "Rock_Sandstone"
    },
    {
      "x": -2,
      "y": 11,
      "z": -6,
      "name": "Rock_Sandstone"
    },
    {
      "x": -2,
      "y": 12,
      "z": -6,
      "name": "Rock_Sandstone"
    },
    {
      "x": -2,
      "y": 13,
      "z": -6,
      "name": "Rock_Sandstone"
    },
    {
      "x": -2,
      "y": 14,
      "z": -6,
      "name": "Rock_Sandstone"
    },
    {
      "x": -2,
      "y": 3,
      "z": -5,
      "name": "Rock_Sandstone"
    },
    {
      "x": -2,
      "y": 4,
      "z": -5,
      "name": "Rock_Sandstone"
    },
    {
      "x": -2,
      "y": 5,
      "z": -5,
      "name": "Rock_Sandstone"
    },
    {
      "x": -2,
      "y": 6,
      "z": -5,
      "name": "Rock_Sandstone"
    },
    {
      "x": -2,
      "y": 7,
      "z": -5,
      "name": "Rock_Sandstone_Brick_Pillar_Middle"
    },
    {
      "x": -2,
      "y": 8,
      "z": -5,
      "name": "Rock_Sandstone_Brick_Pillar_Middle"
    },
    {
      "x": -2,
      "y": 9,
      "z": -5,
      "name": "Rock_Sandstone_Brick_Pillar_Middle"
    },
    {
      "x": -2,
      "y": 10,
      "z": -5,
      "name": "Rock_Sandstone_Brick_Pillar_Middle"
    },
    {
      "x": -2,
      "y": 11,
      "z": -5,
      "name": "Rock_Sandstone_Brick_Pillar_Base",
      "rotation": 8
    },
    {
      "x": -2,
      "y": 12,
      "z": -5,
      "name": "Rock_Sandstone"
    },
    {
      "x": -2,
      "y": 13,
      "z": -5,
      "name": "Rock_Sandstone"
    },
    {
      "x": -2,
      "y": 14,
      "z": -5,
      "name": "Rock_Sandstone"
    },
    {
      "x": -2,
      "y": 3,
      "z": -4,
      "name": "Rock_Sandstone"
    },
    {
      "x": -2,
      "y": 4,
      "z": -4,
      "name": "Soil_Sand_White"
    },
    {
      "x": -2,
      "y": 5,
      "z": -4,
      "name": "Rock_Sandstone_Brick_Ornate"
    },
    {
      "x": -2,
      "y": 6,
      "z": -4,
      "name": "Rock_Sandstone_Brick_Pillar_Base"
    },
    {
      "x": -2,
      "y": 7,
      "z": -4,
      "name": "Rock_Sandstone_Brick_Pillar_Middle"
    },
    {
      "x": -2,
      "y": 8,
      "z": -4,
      "name": "Rock_Sandstone_Brick_Pillar_Middle"
    },
    {
      "x": -2,
      "y": 9,
      "z": -4,
      "name": "Rock_Sandstone_Brick_Pillar_Middle"
    },
    {
      "x": -2,
      "y": 10,
      "z": -4,
      "name": "Rock_Sandstone_Brick_Pillar_Middle"
    },
    {
      "x": -2,
      "y": 11,
      "z": -4,
      "name": "Rock_Sandstone_Brick_Pillar_Middle"
    },
    {
      "x": -2,
      "y": 12,
      "z": -4,
      "name": "Rock_Sandstone_Brick_Pillar_Base",
      "rotation": 8
    },
    {
      "x": -2,
      "y": 13,
      "z": -4,
      "name": "Rock_Sandstone"
    },
    {
      "x": -2,
      "y": 14,
      "z": -4,
      "name": "Rock_Sandstone"
    },
    {
      "x": -2,
      "y": 15,
      "z": -4,
      "name": "Rock_Sandstone"
    },
    {
      "x": -2,
      "y": 3,
      "z": -3,
      "name": "Rock_Sandstone"
    },
    {
      "x": -2,
      "y": 4,
      "z": -3,
      "name": "Soil_Sand_White"
    },
    {
      "x": -2,
      "y": 5,
      "z": -3,
      "name": "Rock_Sandstone_Brick_Half"
    },
    {
      "x": -2,
      "y": 6,
      "z": -3,
      "name": "Empty"
    },
    {
      "x": -2,
      "y": 7,
      "z": -3,
      "name": "Empty"
    },
    {
      "x": -2,
      "y": 8,
      "z": -3,
      "name": "Empty"
    },
    {
      "x": -2,
      "y": 9,
      "z": -3,
      "name": "Empty"
    },
    {
      "x": -2,
      "y": 10,
      "z": -3,
      "name": "Empty"
    },
    {
      "x": -2,
      "y": 11,
      "z": -3,
      "name": "Empty"
    },
    {
      "x": -2,
      "y": 12,
      "z": -3,
      "name": "Empty"
    },
    {
      "x": -2,
      "y": 13,
      "z": -3,
      "name": "Empty"
    },
    {
      "x": -2,
      "y": 14,
      "z": -3,
      "name": "Rock_Sandstone"
    },
    {
      "x": -2,
      "y": 15,
      "z": -3,
      "name": "Rock_Sandstone"
    },
    {
      "x": -2,
      "y": 3,
      "z": -2,
      "name": "Rock_Sandstone"
    },
    {
      "x": -2,
      "y": 4,
      "z": -2,
      "name": "Soil_Sand_White"
    },
    {
      "x": -2,
      "y": 5,
      "z": -2,
      "name": "Empty"
    },
    {
      "x": -2,
      "y": 6,
      "z": -2,
      "name": "Empty"
    },
    {
      "x": -2,
      "y": 7,
      "z": -2,
      "name": "Empty"
    },
    {
      "x": -2,
      "y": 8,
      "z": -2,
      "name": "Empty"
    },
    {
      "x": -2,
      "y": 9,
      "z": -2,
      "name": "Empty"
    },
    {
      "x": -2,
      "y": 10,
      "z": -2,
      "name": "Empty"
    },
    {
      "x": -2,
      "y": 11,
      "z": -2,
      "name": "Empty"
    },
    {
      "x": -2,
      "y": 12,
      "z": -2,
      "name": "Empty"
    },
    {
      "x": -2,
      "y": 13,
      "z": -2,
      "name": "Empty"
    },
    {
      "x": -2,
      "y": 14,
      "z": -2,
      "name": "Rock_Sandstone"
    },
    {
      "x": -2,
      "y": 15,
      "z": -2,
      "name": "Rock_Sandstone"
    },
    {
      "x": -2,
      "y": 3,
      "z": -1,
      "name": "Rock_Sandstone"
    },
    {
      "x": -2,
      "y": 4,
      "z": -1,
      "name": "Soil_Sand_White"
    },
    {
      "x": -2,
      "y": 5,
      "z": -1,
      "name": "Empty"
    },
    {
      "x": -2,
      "y": 6,
      "z": -1,
      "name": "Empty"
    },
    {
      "x": -2,
      "y": 7,
      "z": -1,
      "name": "Empty"
    },
    {
      "x": -2,
      "y": 8,
      "z": -1,
      "name": "Empty"
    },
    {
      "x": -2,
      "y": 9,
      "z": -1,
      "name": "Empty"
    },
    {
      "x": -2,
      "y": 10,
      "z": -1,
      "name": "Empty"
    },
    {
      "x": -2,
      "y": 11,
      "z": -1,
      "name": "Empty"
    },
    {
      "x": -2,
      "y": 12,
      "z": -1,
      "name": "Empty"
    },
    {
      "x": -2,
      "y": 13,
      "z": -1,
      "name": "Empty"
    },
    {
      "x": -2,
      "y": 14,
      "z": -1,
      "name": "Rock_Sandstone"
    },
    {
      "x": -2,
      "y": 15,
      "z": -1,
      "name": "Rock_Sandstone"
    },
    {
      "x": -2,
      "y": 3,
      "z": 0,
      "name": "Rock_Sandstone"
    },
    {
      "x": -2,
      "y": 4,
      "z": 0,
      "name": "Soil_Sand_White"
    },
    {
      "x": -2,
      "y": 5,
      "z": 0,
      "name": "Empty"
    },
    {
      "x": -2,
      "y": 6,
      "z": 0,
      "name": "Empty"
    },
    {
      "x": -2,
      "y": 7,
      "z": 0,
      "name": "Empty"
    },
    {
      "x": -2,
      "y": 8,
      "z": 0,
      "name": "Empty"
    },
    {
      "x": -2,
      "y": 9,
      "z": 0,
      "name": "Empty"
    },
    {
      "x": -2,
      "y": 10,
      "z": 0,
      "name": "Empty"
    },
    {
      "x": -2,
      "y": 11,
      "z": 0,
      "name": "Empty"
    },
    {
      "x": -2,
      "y": 12,
      "z": 0,
      "name": "Empty"
    },
    {
      "x": -2,
      "y": 13,
      "z": 0,
      "name": "Empty"
    },
    {
      "x": -2,
      "y": 14,
      "z": 0,
      "name": "Rock_Sandstone"
    },
    {
      "x": -2,
      "y": 15,
      "z": 0,
      "name": "Rock_Sandstone"
    },
    {
      "x": -2,
      "y": 3,
      "z": 1,
      "name": "Rock_Sandstone"
    },
    {
      "x": -2,
      "y": 4,
      "z": 1,
      "name": "Soil_Sand_White"
    },
    {
      "x": -2,
      "y": 5,
      "z": 1,
      "name": "Empty"
    },
    {
      "x": -2,
      "y": 6,
      "z": 1,
      "name": "Empty"
    },
    {
      "x": -2,
      "y": 7,
      "z": 1,
      "name": "Empty"
    },
    {
      "x": -2,
      "y": 8,
      "z": 1,
      "name": "Empty"
    },
    {
      "x": -2,
      "y": 9,
      "z": 1,
      "name": "Empty"
    },
    {
      "x": -2,
      "y": 10,
      "z": 1,
      "name": "Empty"
    },
    {
      "x": -2,
      "y": 11,
      "z": 1,
      "name": "Empty"
    },
    {
      "x": -2,
      "y": 12,
      "z": 1,
      "name": "Empty"
    },
    {
      "x": -2,
      "y": 13,
      "z": 1,
      "name": "Empty"
    },
    {
      "x": -2,
      "y": 14,
      "z": 1,
      "name": "Rock_Sandstone"
    },
    {
      "x": -2,
      "y": 15,
      "z": 1,
      "name": "Rock_Sandstone"
    },
    {
      "x": -2,
      "y": 3,
      "z": 2,
      "name": "Rock_Sandstone"
    },
    {
      "x": -2,
      "y": 4,
      "z": 2,
      "name": "Soil_Sand_White"
    },
    {
      "x": -2,
      "y": 5,
      "z": 2,
      "name": "Empty"
    },
    {
      "x": -2,
      "y": 6,
      "z": 2,
      "name": "Empty"
    },
    {
      "x": -2,
      "y": 7,
      "z": 2,
      "name": "Empty"
    },
    {
      "x": -2,
      "y": 8,
      "z": 2,
      "name": "Empty"
    },
    {
      "x": -2,
      "y": 9,
      "z": 2,
      "name": "Empty"
    },
    {
      "x": -2,
      "y": 10,
      "z": 2,
      "name": "Empty"
    },
    {
      "x": -2,
      "y": 11,
      "z": 2,
      "name": "Empty"
    },
    {
      "x": -2,
      "y": 12,
      "z": 2,
      "name": "Empty"
    },
    {
      "x": -2,
      "y": 13,
      "z": 2,
      "name": "Rock_Sandstone"
    },
    {
      "x": -2,
      "y": 14,
      "z": 2,
      "name": "Rock_Sandstone"
    },
    {
      "x": -2,
      "y": 15,
      "z": 2,
      "name": "Rock_Sandstone"
    },
    {
      "x": -2,
      "y": 3,
      "z": 3,
      "name": "Rock_Sandstone"
    },
    {
      "x": -2,
      "y": 4,
      "z": 3,
      "name": "Soil_Sand_White"
    },
    {
      "x": -2,
      "y": 5,
      "z": 3,
      "name": "Empty"
    },
    {
      "x": -2,
      "y": 6,
      "z": 3,
      "name": "Empty"
    },
    {
      "x": -2,
      "y": 7,
      "z": 3,
      "name": "Empty"
    },
    {
      "x": -2,
      "y": 8,
      "z": 3,
      "name": "Empty"
    },
    {
      "x": -2,
      "y": 9,
      "z": 3,
      "name": "Empty"
    },
    {
      "x": -2,
      "y": 10,
      "z": 3,
      "name": "Empty"
    },
    {
      "x": -2,
      "y": 11,
      "z": 3,
      "name": "Empty"
    },
    {
      "x": -2,
      "y": 12,
      "z": 3,
      "name": "Empty"
    },
    {
      "x": -2,
      "y": 13,
      "z": 3,
      "name": "Rock_Sandstone"
    },
    {
      "x": -2,
      "y": 14,
      "z": 3,
      "name": "Rock_Sandstone"
    },
    {
      "x": -2,
      "y": 15,
      "z": 3,
      "name": "Rock_Sandstone"
    },
    {
      "x": -2,
      "y": 3,
      "z": 4,
      "name": "Rock_Sandstone"
    },
    {
      "x": -2,
      "y": 4,
      "z": 4,
      "name": "Soil_Sand_White"
    },
    {
      "x": -2,
      "y": 5,
      "z": 4,
      "name": "Empty"
    },
    {
      "x": -2,
      "y": 6,
      "z": 4,
      "name": "Empty"
    },
    {
      "x": -2,
      "y": 7,
      "z": 4,
      "name": "Empty"
    },
    {
      "x": -2,
      "y": 8,
      "z": 4,
      "name": "Empty"
    },
    {
      "x": -2,
      "y": 9,
      "z": 4,
      "name": "Empty"
    },
    {
      "x": -2,
      "y": 10,
      "z": 4,
      "name": "Empty"
    },
    {
      "x": -2,
      "y": 11,
      "z": 4,
      "name": "Empty"
    },
    {
      "x": -2,
      "y": 12,
      "z": 4,
      "name": "Empty"
    },
    {
      "x": -2,
      "y": 13,
      "z": 4,
      "name": "Rock_Sandstone"
    },
    {
      "x": -2,
      "y": 14,
      "z": 4,
      "name": "Rock_Sandstone"
    },
    {
      "x": -2,
      "y": 15,
      "z": 4,
      "name": "Rock_Sandstone"
    },
    {
      "x": -2,
      "y": 3,
      "z": 5,
      "name": "Rock_Sandstone"
    },
    {
      "x": -2,
      "y": 4,
      "z": 5,
      "name": "Soil_Sand_White"
    },
    {
      "x": -2,
      "y": 5,
      "z": 5,
      "name": "Rock_Sandstone_Brick_Half"
    },
    {
      "x": -2,
      "y": 6,
      "z": 5,
      "name": "Empty"
    },
    {
      "x": -2,
      "y": 7,
      "z": 5,
      "name": "Empty"
    },
    {
      "x": -2,
      "y": 8,
      "z": 5,
      "name": "Empty"
    },
    {
      "x": -2,
      "y": 9,
      "z": 5,
      "name": "Empty"
    },
    {
      "x": -2,
      "y": 10,
      "z": 5,
      "name": "Empty"
    },
    {
      "x": -2,
      "y": 11,
      "z": 5,
      "name": "Empty"
    },
    {
      "x": -2,
      "y": 12,
      "z": 5,
      "name": "Empty"
    },
    {
      "x": -2,
      "y": 13,
      "z": 5,
      "name": "Rock_Sandstone"
    },
    {
      "x": -2,
      "y": 14,
      "z": 5,
      "name": "Rock_Sandstone"
    },
    {
      "x": -2,
      "y": 15,
      "z": 5,
      "name": "Rock_Sandstone"
    },
    {
      "x": -2,
      "y": 3,
      "z": 6,
      "name": "Rock_Sandstone"
    },
    {
      "x": -2,
      "y": 4,
      "z": 6,
      "name": "Soil_Sand_White"
    },
    {
      "x": -2,
      "y": 5,
      "z": 6,
      "name": "Rock_Sandstone_Brick_Ornate"
    },
    {
      "x": -2,
      "y": 6,
      "z": 6,
      "name": "Rock_Sandstone_Brick_Pillar_Base"
    },
    {
      "x": -2,
      "y": 7,
      "z": 6,
      "name": "Rock_Sandstone_Brick_Pillar_Middle"
    },
    {
      "x": -2,
      "y": 8,
      "z": 6,
      "name": "Rock_Sandstone_Brick_Pillar_Middle"
    },
    {
      "x": -2,
      "y": 9,
      "z": 6,
      "name": "Rock_Sandstone_Brick_Pillar_Middle"
    },
    {
      "x": -2,
      "y": 10,
      "z": 6,
      "name": "Rock_Sandstone_Brick_Pillar_Middle"
    },
    {
      "x": -2,
      "y": 11,
      "z": 6,
      "name": "Rock_Sandstone_Brick_Pillar_Middle"
    },
    {
      "x": -2,
      "y": 12,
      "z": 6,
      "name": "Rock_Sandstone_Brick_Pillar_Base",
      "rotation": 8
    },
    {
      "x": -2,
      "y": 13,
      "z": 6,
      "name": "Rock_Sandstone"
    },
    {
      "x": -2,
      "y": 14,
      "z": 6,
      "name": "Rock_Sandstone"
    },
    {
      "x": -2,
      "y": 15,
      "z": 6,
      "name": "Rock_Sandstone"
    },
    {
      "x": -2,
      "y": 3,
      "z": 7,
      "name": "Rock_Sandstone"
    },
    {
      "x": -2,
      "y": 4,
      "z": 7,
      "name": "Soil_Sand_White"
    },
    {
      "x": -2,
      "y": 5,
      "z": 7,
      "name": "Rock_Sandstone_Brick_Ornate"
    },
    {
      "x": -2,
      "y": 6,
      "z": 7,
      "name": "Rock_Sandstone_Brick_Pillar_Base"
    },
    {
      "x": -2,
      "y": 7,
      "z": 7,
      "name": "Rock_Sandstone_Brick_Pillar_Middle"
    },
    {
      "x": -2,
      "y": 8,
      "z": 7,
      "name": "Rock_Sandstone_Brick_Pillar_Middle"
    },
    {
      "x": -2,
      "y": 9,
      "z": 7,
      "name": "Rock_Sandstone_Brick_Pillar_Base",
      "rotation": 8
    },
    {
      "x": -2,
      "y": 10,
      "z": 7,
      "name": "Rock_Sandstone"
    },
    {
      "x": -2,
      "y": 11,
      "z": 7,
      "name": "Rock_Sandstone"
    },
    {
      "x": -2,
      "y": 12,
      "z": 7,
      "name": "Rock_Sandstone"
    },
    {
      "x": -2,
      "y": 13,
      "z": 7,
      "name": "Rock_Sandstone"
    },
    {
      "x": -2,
      "y": 14,
      "z": 7,
      "name": "Rock_Sandstone"
    },
    {
      "x": -2,
      "y": 4,
      "z": 8,
      "name": "Rock_Sandstone"
    },
    {
      "x": -2,
      "y": 5,
      "z": 8,
      "name": "Rock_Sandstone"
    },
    {
      "x": -2,
      "y": 6,
      "z": 8,
      "name": "Rock_Sandstone"
    },
    {
      "x": -2,
      "y": 7,
      "z": 8,
      "name": "Rock_Sandstone"
    },
    {
      "x": -2,
      "y": 8,
      "z": 8,
      "name": "Rock_Sandstone"
    },
    {
      "x": -2,
      "y": 9,
      "z": 8,
      "name": "Rock_Sandstone"
    },
    {
      "x": -2,
      "y": 10,
      "z": 8,
      "name": "Rock_Sandstone"
    },
    {
      "x": -2,
      "y": 11,
      "z": 8,
      "name": "Rock_Sandstone"
    },
    {
      "x": -2,
      "y": 12,
      "z": 8,
      "name": "Rock_Sandstone"
    },
    {
      "x": -2,
      "y": 13,
      "z": 8,
      "name": "Rock_Sandstone"
    },
    {
      "x": -1,
      "y": 3,
      "z": -6,
      "name": "Rock_Sandstone_Brick"
    },
    {
      "x": -1,
      "y": 4,
      "z": -6,
      "name": "Rock_Sandstone_Brick"
    },
    {
      "x": -1,
      "y": 5,
      "z": -6,
      "name": "Rock_Sandstone_Brick"
    },
    {
      "x": -1,
      "y": 6,
      "z": -6,
      "name": "Rock_Sandstone_Brick"
    },
    {
      "x": -1,
      "y": 7,
      "z": -6,
      "name": "Rock_Sandstone_Brick"
    },
    {
      "x": -1,
      "y": 8,
      "z": -6,
      "name": "Rock_Sandstone_Brick"
    },
    {
      "x": -1,
      "y": 9,
      "z": -6,
      "name": "Rock_Sandstone_Brick"
    },
    {
      "x": -1,
      "y": 10,
      "z": -6,
      "name": "Rock_Sandstone"
    },
    {
      "x": -1,
      "y": 11,
      "z": -6,
      "name": "Rock_Sandstone"
    },
    {
      "x": -1,
      "y": 12,
      "z": -6,
      "name": "Rock_Sandstone"
    },
    {
      "x": -1,
      "y": 13,
      "z": -6,
      "name": "Rock_Sandstone"
    },
    {
      "x": -1,
      "y": 14,
      "z": -6,
      "name": "Rock_Sandstone"
    },
    {
      "x": -1,
      "y": 3,
      "z": -5,
      "name": "Rock_Sandstone"
    },
    {
      "x": -1,
      "y": 4,
      "z": -5,
      "name": "Soil_Sand_White"
    },
    {
      "x": -1,
      "y": 5,
      "z": -5,
      "name": "Rock_Sandstone_Brick_Ornate"
    },
    {
      "x": -1,
      "y": 6,
      "z": -5,
      "name": "Rock_Sandstone_Brick_Pillar_Base"
    },
    {
      "x": -1,
      "y": 7,
      "z": -5,
      "name": "Rock_Sandstone_Brick_Pillar_Middle"
    },
    {
      "x": -1,
      "y": 8,
      "z": -5,
      "name": "Rock_Sandstone_Brick_Pillar_Middle"
    },
    {
      "x": -1,
      "y": 9,
      "z": -5,
      "name": "Rock_Sandstone_Brick_Pillar_Middle"
    },
    {
      "x": -1,
      "y": 10,
      "z": -5,
      "name": "Rock_Sandstone_Brick_Pillar_Middle"
    },
    {
      "x": -1,
      "y": 11,
      "z": -5,
      "name": "Rock_Sandstone_Brick_Pillar_Middle"
    },
    {
      "x": -1,
      "y": 12,
      "z": -5,
      "name": "Rock_Sandstone_Brick_Pillar_Base",
      "rotation": 8
    },
    {
      "x": -1,
      "y": 13,
      "z": -5,
      "name": "Rock_Sandstone"
    },
    {
      "x": -1,
      "y": 14,
      "z": -5,
      "name": "Rock_Sandstone"
    },
    {
      "x": -1,
      "y": 3,
      "z": -4,
      "name": "Rock_Sandstone"
    },
    {
      "x": -1,
      "y": 4,
      "z": -4,
      "name": "Soil_Sand_White"
    },
    {
      "x": -1,
      "y": 5,
      "z": -4,
      "name": "Rock_Sandstone_Brick_Ornate"
    },
    {
      "x": -1,
      "y": 6,
      "z": -4,
      "name": "Rock_Sandstone_Brick_Pillar_Base"
    },
    {
      "x": -1,
      "y": 7,
      "z": -4,
      "name": "Rock_Sandstone_Brick_Pillar_Middle"
    },
    {
      "x": -1,
      "y": 8,
      "z": -4,
      "name": "Rock_Sandstone_Brick_Pillar_Middle"
    },
    {
      "x": -1,
      "y": 9,
      "z": -4,
      "name": "Rock_Sandstone_Brick_Pillar_Middle"
    },
    {
      "x": -1,
      "y": 10,
      "z": -4,
      "name": "Rock_Sandstone_Brick_Pillar_Middle"
    },
    {
      "x": -1,
      "y": 11,
      "z": -4,
      "name": "Rock_Sandstone_Brick_Pillar_Middle"
    },
    {
      "x": -1,
      "y": 12,
      "z": -4,
      "name": "Rock_Sandstone_Brick_Pillar_Base",
      "rotation": 8
    },
    {
      "x": -1,
      "y": 13,
      "z": -4,
      "name": "Rock_Sandstone"
    },
    {
      "x": -1,
      "y": 14,
      "z": -4,
      "name": "Rock_Sandstone"
    },
    {
      "x": -1,
      "y": 15,
      "z": -4,
      "name": "Rock_Sandstone"
    },
    {
      "x": -1,
      "y": 3,
      "z": -3,
      "name": "Rock_Sandstone"
    },
    {
      "x": -1,
      "y": 4,
      "z": -3,
      "name": "Soil_Sand_White"
    },
    {
      "x": -1,
      "y": 5,
      "z": -3,
      "name": "Empty"
    },
    {
      "x": -1,
      "y": 6,
      "z": -3,
      "name": "Empty"
    },
    {
      "x": -1,
      "y": 7,
      "z": -3,
      "name": "Empty"
    },
    {
      "x": -1,
      "y": 8,
      "z": -3,
      "name": "Empty"
    },
    {
      "x": -1,
      "y": 9,
      "z": -3,
      "name": "Empty"
    },
    {
      "x": -1,
      "y": 10,
      "z": -3,
      "name": "Empty"
    },
    {
      "x": -1,
      "y": 11,
      "z": -3,
      "name": "Empty"
    },
    {
      "x": -1,
      "y": 12,
      "z": -3,
      "name": "Empty"
    },
    {
      "x": -1,
      "y": 13,
      "z": -3,
      "name": "Empty"
    },
    {
      "x": -1,
      "y": 14,
      "z": -3,
      "name": "Rock_Sandstone"
    },
    {
      "x": -1,
      "y": 15,
      "z": -3,
      "name": "Rock_Sandstone"
    },
    {
      "x": -1,
      "y": 3,
      "z": -2,
      "name": "Rock_Sandstone"
    },
    {
      "x": -1,
      "y": 4,
      "z": -2,
      "name": "Soil_Sand_White"
    },
    {
      "x": -1,
      "y": 5,
      "z": -2,
      "name": "Empty"
    },
    {
      "x": -1,
      "y": 6,
      "z": -2,
      "name": "Empty"
    },
    {
      "x": -1,
      "y": 7,
      "z": -2,
      "name": "Empty"
    },
    {
      "x": -1,
      "y": 8,
      "z": -2,
      "name": "Empty"
    },
    {
      "x": -1,
      "y": 9,
      "z": -2,
      "name": "Empty"
    },
    {
      "x": -1,
      "y": 10,
      "z": -2,
      "name": "Empty"
    },
    {
      "x": -1,
      "y": 11,
      "z": -2,
      "name": "Empty"
    },
    {
      "x": -1,
      "y": 12,
      "z": -2,
      "name": "Empty"
    },
    {
      "x": -1,
      "y": 13,
      "z": -2,
      "name": "Empty"
    },
    {
      "x": -1,
      "y": 14,
      "z": -2,
      "name": "Rock_Sandstone"
    },
    {
      "x": -1,
      "y": 15,
      "z": -2,
      "name": "Rock_Sandstone"
    },
    {
      "x": -1,
      "y": 3,
      "z": -1,
      "name": "Empty"
    },
    {
      "x": -1,
      "y": 4,
      "z": -1,
      "name": "Rock_Sandstone_Brick"
    },
    {
      "x": -1,
      "y": 5,
      "z": -1,
      "name": "Empty"
    },
    {
      "x": -1,
      "y": 6,
      "z": -1,
      "name": "Empty"
    },
    {
      "x": -1,
      "y": 7,
      "z": -1,
      "name": "Empty"
    },
    {
      "x": -1,
      "y": 8,
      "z": -1,
      "name": "Empty"
    },
    {
      "x": -1,
      "y": 9,
      "z": -1,
      "name": "Empty"
    },
    {
      "x": -1,
      "y": 10,
      "z": -1,
      "name": "Empty"
    },
    {
      "x": -1,
      "y": 11,
      "z": -1,
      "name": "Empty"
    },
    {
      "x": -1,
      "y": 12,
      "z": -1,
      "name": "Empty"
    },
    {
      "x": -1,
      "y": 13,
      "z": -1,
      "name": "Empty"
    },
    {
      "x": -1,
      "y": 14,
      "z": -1,
      "name": "Rock_Sandstone"
    },
    {
      "x": -1,
      "y": 15,
      "z": -1,
      "name": "Rock_Sandstone"
    },
    {
      "x": -1,
      "y": 3,
      "z": 0,
      "name": "Empty"
    },
    {
      "x": -1,
      "y": 4,
      "z": 0,
      "name": "Rock_Sandstone_Brick"
    },
    {
      "x": -1,
      "y": 5,
      "z": 0,
      "name": "Empty"
    },
    {
      "x": -1,
      "y": 6,
      "z": 0,
      "name": "Empty"
    },
    {
      "x": -1,
      "y": 7,
      "z": 0,
      "name": "Empty"
    },
    {
      "x": -1,
      "y": 8,
      "z": 0,
      "name": "Empty"
    },
    {
      "x": -1,
      "y": 9,
      "z": 0,
      "name": "Empty"
    },
    {
      "x": -1,
      "y": 10,
      "z": 0,
      "name": "Empty"
    },
    {
      "x": -1,
      "y": 11,
      "z": 0,
      "name": "Empty"
    },
    {
      "x": -1,
      "y": 12,
      "z": 0,
      "name": "Empty"
    },
    {
      "x": -1,
      "y": 13,
      "z": 0,
      "name": "Empty"
    },
    {
      "x": -1,
      "y": 14,
      "z": 0,
      "name": "Rock_Sandstone"
    },
    {
      "x": -1,
      "y": 15,
      "z": 0,
      "name": "Rock_Sandstone"
    },
    {
      "x": -1,
      "y": 3,
      "z": 1,
      "name": "Empty"
    },
    {
      "x": -1,
      "y": 4,
      "z": 1,
      "name": "Rock_Sandstone_Brick"
    },
    {
      "x": -1,
      "y": 5,
      "z": 1,
      "name": "Rock_Sandstone_Brick_Half"
    },
    {
      "x": -1,
      "y": 6,
      "z": 1,
      "name": "Empty"
    },
    {
      "x": -1,
      "y": 7,
      "z": 1,
      "name": "Empty"
    },
    {
      "x": -1,
      "y": 8,
      "z": 1,
      "name": "Empty"
    },
    {
      "x": -1,
      "y": 9,
      "z": 1,
      "name": "Empty"
    },
    {
      "x": -1,
      "y": 10,
      "z": 1,
      "name": "Empty"
    },
    {
      "x": -1,
      "y": 11,
      "z": 1,
      "name": "Empty"
    },
    {
      "x": -1,
      "y": 12,
      "z": 1,
      "name": "Empty"
    },
    {
      "x": -1,
      "y": 13,
      "z": 1,
      "name": "Empty"
    },
    {
      "x": -1,
      "y": 14,
      "z": 1,
      "name": "Rock_Sandstone"
    },
    {
      "x": -1,
      "y": 15,
      "z": 1,
      "name": "Rock_Sandstone"
    },
    {
      "x": -1,
      "y": 3,
      "z": 2,
      "name": "Empty"
    },
    {
      "x": -1,
      "y": 4,
      "z": 2,
      "name": "Rock_Sandstone_Brick"
    },
    {
      "x": -1,
      "y": 5,
      "z": 2,
      "name": "Rock_Sandstone_Brick_Half"
    },
    {
      "x": -1,
      "y": 6,
      "z": 2,
      "name": "Empty"
    },
    {
      "x": -1,
      "y": 7,
      "z": 2,
      "name": "Empty"
    },
    {
      "x": -1,
      "y": 8,
      "z": 2,
      "name": "Empty"
    },
    {
      "x": -1,
      "y": 9,
      "z": 2,
      "name": "Empty"
    },
    {
      "x": -1,
      "y": 10,
      "z": 2,
      "name": "Empty"
    },
    {
      "x": -1,
      "y": 11,
      "z": 2,
      "name": "Empty"
    },
    {
      "x": -1,
      "y": 12,
      "z": 2,
      "name": "Empty"
    },
    {
      "x": -1,
      "y": 13,
      "z": 2,
      "name": "Rock_Sandstone"
    },
    {
      "x": -1,
      "y": 14,
      "z": 2,
      "name": "Rock_Sandstone"
    },
    {
      "x": -1,
      "y": 15,
      "z": 2,
      "name": "Rock_Sandstone"
    },
    {
      "x": -1,
      "y": 3,
      "z": 3,
      "name": "Empty"
    },
    {
      "x": -1,
      "y": 4,
      "z": 3,
      "name": "Rock_Sandstone_Brick"
    },
    {
      "x": -1,
      "y": 5,
      "z": 3,
      "name": "Rock_Sandstone_Brick_Half"
    },
    {
      "x": -1,
      "y": 6,
      "z": 3,
      "name": "Empty"
    },
    {
      "x": -1,
      "y": 7,
      "z": 3,
      "name": "Empty"
    },
    {
      "x": -1,
      "y": 8,
      "z": 3,
      "name": "Empty"
    },
    {
      "x": -1,
      "y": 9,
      "z": 3,
      "name": "Empty"
    },
    {
      "x": -1,
      "y": 10,
      "z": 3,
      "name": "Empty"
    },
    {
      "x": -1,
      "y": 11,
      "z": 3,
      "name": "Empty"
    },
    {
      "x": -1,
      "y": 12,
      "z": 3,
      "name": "Empty"
    },
    {
      "x": -1,
      "y": 13,
      "z": 3,
      "name": "Rock_Sandstone"
    },
    {
      "x": -1,
      "y": 14,
      "z": 3,
      "name": "Rock_Sandstone"
    },
    {
      "x": -1,
      "y": 15,
      "z": 3,
      "name": "Rock_Sandstone"
    },
    {
      "x": -1,
      "y": 3,
      "z": 4,
      "name": "Rock_Sandstone"
    },
    {
      "x": -1,
      "y": 4,
      "z": 4,
      "name": "Soil_Sand_White"
    },
    {
      "x": -1,
      "y": 5,
      "z": 4,
      "name": "Empty"
    },
    {
      "x": -1,
      "y": 6,
      "z": 4,
      "name": "Empty"
    },
    {
      "x": -1,
      "y": 7,
      "z": 4,
      "name": "Empty"
    },
    {
      "x": -1,
      "y": 8,
      "z": 4,
      "name": "Empty"
    },
    {
      "x": -1,
      "y": 9,
      "z": 4,
      "name": "Empty"
    },
    {
      "x": -1,
      "y": 10,
      "z": 4,
      "name": "Empty"
    },
    {
      "x": -1,
      "y": 11,
      "z": 4,
      "name": "Empty"
    },
    {
      "x": -1,
      "y": 12,
      "z": 4,
      "name": "Empty"
    },
    {
      "x": -1,
      "y": 13,
      "z": 4,
      "name": "Rock_Sandstone"
    },
    {
      "x": -1,
      "y": 14,
      "z": 4,
      "name": "Rock_Sandstone"
    },
    {
      "x": -1,
      "y": 15,
      "z": 4,
      "name": "Rock_Sandstone"
    },
    {
      "x": -1,
      "y": 3,
      "z": 5,
      "name": "Rock_Sandstone"
    },
    {
      "x": -1,
      "y": 4,
      "z": 5,
      "name": "Soil_Sand_White"
    },
    {
      "x": -1,
      "y": 5,
      "z": 5,
      "name": "Empty"
    },
    {
      "x": -1,
      "y": 6,
      "z": 5,
      "name": "Empty"
    },
    {
      "x": -1,
      "y": 7,
      "z": 5,
      "name": "Empty"
    },
    {
      "x": -1,
      "y": 8,
      "z": 5,
      "name": "Empty"
    },
    {
      "x": -1,
      "y": 9,
      "z": 5,
      "name": "Empty"
    },
    {
      "x": -1,
      "y": 10,
      "z": 5,
      "name": "Empty"
    },
    {
      "x": -1,
      "y": 11,
      "z": 5,
      "name": "Empty"
    },
    {
      "x": -1,
      "y": 12,
      "z": 5,
      "name": "Empty"
    },
    {
      "x": -1,
      "y": 13,
      "z": 5,
      "name": "Rock_Sandstone"
    },
    {
      "x": -1,
      "y": 14,
      "z": 5,
      "name": "Rock_Sandstone"
    },
    {
      "x": -1,
      "y": 15,
      "z": 5,
      "name": "Rock_Sandstone"
    },
    {
      "x": -1,
      "y": 3,
      "z": 6,
      "name": "Rock_Sandstone"
    },
    {
      "x": -1,
      "y": 4,
      "z": 6,
      "name": "Soil_Sand_White"
    },
    {
      "x": -1,
      "y": 5,
      "z": 6,
      "name": "Rock_Sandstone_Brick_Ornate"
    },
    {
      "x": -1,
      "y": 6,
      "z": 6,
      "name": "Rock_Sandstone_Brick_Pillar_Base"
    },
    {
      "x": -1,
      "y": 7,
      "z": 6,
      "name": "Rock_Sandstone_Brick_Pillar_Middle"
    },
    {
      "x": -1,
      "y": 8,
      "z": 6,
      "name": "Rock_Sandstone_Brick_Pillar_Middle"
    },
    {
      "x": -1,
      "y": 9,
      "z": 6,
      "name": "Rock_Sandstone_Brick_Pillar_Middle"
    },
    {
      "x": -1,
      "y": 10,
      "z": 6,
      "name": "Rock_Sandstone_Brick_Pillar_Middle"
    },
    {
      "x": -1,
      "y": 11,
      "z": 6,
      "name": "Rock_Sandstone_Brick_Pillar_Middle"
    },
    {
      "x": -1,
      "y": 12,
      "z": 6,
      "name": "Rock_Sandstone_Brick_Pillar_Base",
      "rotation": 8
    },
    {
      "x": -1,
      "y": 13,
      "z": 6,
      "name": "Rock_Sandstone"
    },
    {
      "x": -1,
      "y": 14,
      "z": 6,
      "name": "Rock_Sandstone"
    },
    {
      "x": -1,
      "y": 15,
      "z": 6,
      "name": "Rock_Sandstone"
    },
    {
      "x": -1,
      "y": 3,
      "z": 7,
      "name": "Rock_Sandstone"
    },
    {
      "x": -1,
      "y": 4,
      "z": 7,
      "name": "Soil_Sand_White"
    },
    {
      "x": -1,
      "y": 5,
      "z": 7,
      "name": "Rock_Sandstone_Brick_Ornate"
    },
    {
      "x": -1,
      "y": 6,
      "z": 7,
      "name": "Rock_Sandstone_Brick_Pillar_Base"
    },
    {
      "x": -1,
      "y": 7,
      "z": 7,
      "name": "Rock_Sandstone_Brick_Pillar_Middle"
    },
    {
      "x": -1,
      "y": 8,
      "z": 7,
      "name": "Rock_Sandstone_Brick_Pillar_Middle"
    },
    {
      "x": -1,
      "y": 9,
      "z": 7,
      "name": "Rock_Sandstone_Brick_Pillar_Middle"
    },
    {
      "x": -1,
      "y": 10,
      "z": 7,
      "name": "Rock_Sandstone_Brick_Pillar_Middle"
    },
    {
      "x": -1,
      "y": 11,
      "z": 7,
      "name": "Rock_Sandstone_Brick_Pillar_Middle"
    },
    {
      "x": -1,
      "y": 12,
      "z": 7,
      "name": "Rock_Sandstone_Brick_Pillar_Base",
      "rotation": 8
    },
    {
      "x": -1,
      "y": 13,
      "z": 7,
      "name": "Rock_Sandstone"
    },
    {
      "x": -1,
      "y": 14,
      "z": 7,
      "name": "Rock_Sandstone"
    },
    {
      "x": -1,
      "y": 4,
      "z": 8,
      "name": "Rock_Sandstone"
    },
    {
      "x": -1,
      "y": 5,
      "z": 8,
      "name": "Rock_Sandstone_Brick"
    },
    {
      "x": -1,
      "y": 6,
      "z": 8,
      "name": "Rock_Sandstone_Brick"
    },
    {
      "x": -1,
      "y": 7,
      "z": 8,
      "name": "Rock_Sandstone_Brick"
    },
    {
      "x": -1,
      "y": 8,
      "z": 8,
      "name": "Rock_Sandstone_Brick"
    },
    {
      "x": -1,
      "y": 9,
      "z": 8,
      "name": "Rock_Sandstone_Brick"
    },
    {
      "x": -1,
      "y": 10,
      "z": 8,
      "name": "Rock_Sandstone"
    },
    {
      "x": -1,
      "y": 11,
      "z": 8,
      "name": "Rock_Sandstone"
    },
    {
      "x": -1,
      "y": 12,
      "z": 8,
      "name": "Rock_Sandstone"
    },
    {
      "x": -1,
      "y": 13,
      "z": 8,
      "name": "Rock_Sandstone"
    },
    {
      "x": -1,
      "y": 14,
      "z": 8,
      "name": "Rock_Sandstone"
    },
    {
      "x": 0,
      "y": 3,
      "z": -6,
      "name": "Rock_Sandstone_Brick"
    },
    {
      "x": 0,
      "y": 4,
      "z": -6,
      "name": "Soil_Sand_White"
    },
    {
      "x": 0,
      "y": 5,
      "z": -6,
      "name": "Empty"
    },
    {
      "x": 0,
      "y": 6,
      "z": -6,
      "name": "Empty"
    },
    {
      "x": 0,
      "y": 7,
      "z": -6,
      "name": "Empty"
    },
    {
      "x": 0,
      "y": 8,
      "z": -6,
      "name": "Empty"
    },
    {
      "x": 0,
      "y": 9,
      "z": -6,
      "name": "Rock_Sandstone_Brick"
    },
    {
      "x": 0,
      "y": 10,
      "z": -6,
      "name": "Rock_Sandstone"
    },
    {
      "x": 0,
      "y": 11,
      "z": -6,
      "name": "Rock_Sandstone"
    },
    {
      "x": 0,
      "y": 12,
      "z": -6,
      "name": "Rock_Sandstone"
    },
    {
      "x": 0,
      "y": 13,
      "z": -6,
      "name": "Rock_Sandstone"
    },
    {
      "x": 0,
      "y": 14,
      "z": -6,
      "name": "Rock_Sandstone"
    },
    {
      "x": 0,
      "y": 3,
      "z": -5,
      "name": "Rock_Sandstone"
    },
    {
      "x": 0,
      "y": 4,
      "z": -5,
      "name": "Soil_Sand_White"
    },
    {
      "x": 0,
      "y": 5,
      "z": -5,
      "name": "Empty"
    },
    {
      "x": 0,
      "y": 6,
      "z": -5,
      "name": "Empty"
    },
    {
      "x": 0,
      "y": 7,
      "z": -5,
      "name": "Empty"
    },
    {
      "x": 0,
      "y": 8,
      "z": -5,
      "name": "Empty"
    },
    {
      "x": 0,
      "y": 9,
      "z": -5,
      "name": "Empty"
    },
    {
      "x": 0,
      "y": 10,
      "z": -5,
      "name": "Empty"
    },
    {
      "x": 0,
      "y": 11,
      "z": -5,
      "name": "Empty"
    },
    {
      "x": 0,
      "y": 12,
      "z": -5,
      "name": "Empty"
    },
    {
      "x": 0,
      "y": 13,
      "z": -5,
      "name": "Rock_Sandstone"
    },
    {
      "x": 0,
      "y": 14,
      "z": -5,
      "name": "Rock_Sandstone"
    },
    {
      "x": 0,
      "y": 3,
      "z": -4,
      "name": "Rock_Sandstone"
    },
    {
      "x": 0,
      "y": 4,
      "z": -4,
      "name": "Soil_Sand_White"
    },
    {
      "x": 0,
      "y": 5,
      "z": -4,
      "name": "Empty"
    },
    {
      "x": 0,
      "y": 6,
      "z": -4,
      "name": "Empty"
    },
    {
      "x": 0,
      "y": 7,
      "z": -4,
      "name": "Empty"
    },
    {
      "x": 0,
      "y": 8,
      "z": -4,
      "name": "Empty"
    },
    {
      "x": 0,
      "y": 9,
      "z": -4,
      "name": "Empty"
    },
    {
      "x": 0,
      "y": 10,
      "z": -4,
      "name": "Empty"
    },
    {
      "x": 0,
      "y": 11,
      "z": -4,
      "name": "Empty"
    },
    {
      "x": 0,
      "y": 12,
      "z": -4,
      "name": "Empty"
    },
    {
      "x": 0,
      "y": 13,
      "z": -4,
      "name": "Empty"
    },
    {
      "x": 0,
      "y": 14,
      "z": -4,
      "name": "Rock_Sandstone"
    },
    {
      "x": 0,
      "y": 15,
      "z": -4,
      "name": "Rock_Sandstone"
    },
    {
      "x": 0,
      "y": 3,
      "z": -3,
      "name": "Rock_Sandstone"
    },
    {
      "x": 0,
      "y": 4,
      "z": -3,
      "name": "Soil_Sand_White"
    },
    {
      "x": 0,
      "y": 5,
      "z": -3,
      "name": "Empty"
    },
    {
      "x": 0,
      "y": 6,
      "z": -3,
      "name": "Empty"
    },
    {
      "x": 0,
      "y": 7,
      "z": -3,
      "name": "Empty"
    },
    {
      "x": 0,
      "y": 8,
      "z": -3,
      "name": "Empty"
    },
    {
      "x": 0,
      "y": 9,
      "z": -3,
      "name": "Empty"
    },
    {
      "x": 0,
      "y": 10,
      "z": -3,
      "name": "Empty"
    },
    {
      "x": 0,
      "y": 11,
      "z": -3,
      "name": "Empty"
    },
    {
      "x": 0,
      "y": 12,
      "z": -3,
      "name": "Empty"
    },
    {
      "x": 0,
      "y": 13,
      "z": -3,
      "name": "Empty"
    },
    {
      "x": 0,
      "y": 14,
      "z": -3,
      "name": "Rock_Sandstone"
    },
    {
      "x": 0,
      "y": 15,
      "z": -3,
      "name": "Rock_Sandstone"
    },
    {
      "x": 0,
      "y": 3,
      "z": -2,
      "name": "Rock_Sandstone"
    },
    {
      "x": 0,
      "y": 4,
      "z": -2,
      "name": "Soil_Sand_White"
    },
    {
      "x": 0,
      "y": 5,
      "z": -2,
      "name": "Empty"
    },
    {
      "x": 0,
      "y": 6,
      "z": -2,
      "name": "Empty"
    },
    {
      "x": 0,
      "y": 7,
      "z": -2,
      "name": "Empty"
    },
    {
      "x": 0,
      "y": 8,
      "z": -2,
      "name": "Empty"
    },
    {
      "x": 0,
      "y": 9,
      "z": -2,
      "name": "Empty"
    },
    {
      "x": 0,
      "y": 10,
      "z": -2,
      "name": "Empty"
    },
    {
      "x": 0,
      "y": 11,
      "z": -2,
      "name": "Empty"
    },
    {
      "x": 0,
      "y": 12,
      "z": -2,
      "name": "Empty"
    },
    {
      "x": 0,
      "y": 13,
      "z": -2,
      "name": "Empty"
    },
    {
      "x": 0,
      "y": 14,
      "z": -2,
      "name": "Rock_Sandstone"
    },
    {
      "x": 0,
      "y": 15,
      "z": -2,
      "name": "Rock_Sandstone"
    },
    {
      "x": 0,
      "y": 3,
      "z": -1,
      "name": "Empty"
    },
    {
      "x": 0,
      "y": 4,
      "z": -1,
      "name": "Rock_Sandstone_Brick"
    },
    {
      "x": 0,
      "y": 5,
      "z": -1,
      "name": "Empty"
    },
    {
      "x": 0,
      "y": 6,
      "z": -1,
      "name": "Empty"
    },
    {
      "x": 0,
      "y": 7,
      "z": -1,
      "name": "Empty"
    },
    {
      "x": 0,
      "y": 8,
      "z": -1,
      "name": "Empty"
    },
    {
      "x": 0,
      "y": 9,
      "z": -1,
      "name": "Empty"
    },
    {
      "x": 0,
      "y": 10,
      "z": -1,
      "name": "Empty"
    },
    {
      "x": 0,
      "y": 11,
      "z": -1,
      "name": "Empty"
    },
    {
      "x": 0,
      "y": 12,
      "z": -1,
      "name": "Empty"
    },
    {
      "x": 0,
      "y": 13,
      "z": -1,
      "name": "Empty"
    },
    {
      "x": 0,
      "y": 14,
      "z": -1,
      "name": "Rock_Sandstone"
    },
    {
      "x": 0,
      "y": 15,
      "z": -1,
      "name": "Rock_Sandstone"
    },
    {
      "x": 0,
      "y": 3,
      "z": 0,
      "name": "Empty"
    },
    {
      "x": 0,
      "y": 4,
      "z": 0,
      "name": "Empty"
    },
    {
      "x": 0,
      "y": 5,
      "z": 0,
      "name": "Empty"
    },
    {
      "x": 0,
      "y": 6,
      "z": 0,
      "name": "Empty"
    },
    {
      "x": 0,
      "y": 7,
      "z": 0,
      "name": "Empty"
    },
    {
      "x": 0,
      "y": 8,
      "z": 0,
      "name": "Empty"
    },
    {
      "x": 0,
      "y": 9,
      "z": 0,
      "name": "Empty"
    },
    {
      "x": 0,
      "y": 10,
      "z": 0,
      "name": "Empty"
    },
    {
      "x": 0,
      "y": 11,
      "z": 0,
      "name": "Empty"
    },
    {
      "x": 0,
      "y": 12,
      "z": 0,
      "name": "Empty"
    },
    {
      "x": 0,
      "y": 13,
      "z": 0,
      "name": "Empty"
    },
    {
      "x": 0,
      "y": 14,
      "z": 0,
      "name": "Rock_Sandstone"
    },
    {
      "x": 0,
      "y": 15,
      "z": 0,
      "name": "Rock_Sandstone"
    },
    {
      "x": 0,
