{
  "version": 8,
  "blockIdVersion": 8,
  "anchorX": 0,
  "anchorY": 0,
  "anchorZ": 0,
  "blocks": [
    {
      "x": -3,
      "y": -1,
      "z": 0,
      "name": "Rock_Stone"
    },
    {
      "x": -3,
      "y": 0,
      "z": 0,
      "name": "Rock_Stone"
    },
    {
      "x": -3,
      "y": 1,
      "z": 0,
      "name": "Rock_Stone"
    },
    {
      "x": -3,
      "y": 2,
      "z": 0,
      "name": "Rock_Stone"
    },
    {
      "x": -3,
      "y": 3,
      "z": 0,
      "name": "Rock_Stone"
    },
    {
      "x": -3,
      "y": 4,
      "z": 0,
      "name": "Rock_Stone"
    },
    {
      "x": -3,
      "y": 5,
      "z": 0,
      "name": "Rock_Stone"
    },
    {
      "x": -3,
      "y": 6,
      "z": 0,
      "name": "Rock_Stone"
    },
    {
      "x": -3,
      "y": -1,
      "z": 1,
      "name": "Rock_Stone"
    },
    {
      "x": -3,
      "y": 0,
      "z": 1,
      "name": "Rock_Stone"
    },
    {
      "x": -3,
      "y": 1,
      "z": 1,
      "name": "Rock_Stone"
    },
    {
      "x": -3,
      "y": 2,
      "z": 1,
      "name": "Rock_Stone"
    },
    {
      "x": -3,
      "y": 3,
      "z": 1,
      "name": "Rock_Stone"
    },
    {
      "x": -3,
      "y": 4,
      "z": 1,
      "name": "Rock_Stone"
    },
    {
      "x": -3,
      "y": 5,
      "z": 1,
      "name": "Rock_Stone"
    },
    {
      "x": -3,
      "y": 6,
      "z": 1,
      "name": "Rock_Stone"
    },
    {
      "x": -3,
      "y": -1,
      "z": 2,
      "name": "Rock_Stone"
    },
    {
      "x": -3,
      "y": 0,
      "z": 2,
      "name": "Rock_Stone"
    },
    {
      "x": -3,
      "y": 1,
      "z": 2,
      "name": "Rock_Stone"
    },
    {
      "x": -3,
      "y": 2,
      "z": 2,
      "name": "Rock_Stone"
    },
    {
      "x": -3,
      "y": 3,
      "z": 2,
      "name": "Rock_Stone"
    },
    {
      "x": -3,
      "y": 4,
      "z": 2,
      "name": "Rock_Stone"
    },
    {
      "x": -3,
      "y": 5,
      "z": 2,
      "name": "Rock_Stone"
    },
    {
      "x": -3,
      "y": 6,
      "z": 2,
      "name": "Rock_Stone"
    },
    {
      "x": -3,
      "y": -1,
      "z": 3,
      "name": "Rock_Stone"
    },
    {
      "x": -3,
      "y": 0,
      "z": 3,
      "name": "Rock_Stone"
    },
    {
      "x": -3,
      "y": 1,
      "z": 3,
      "name": "Rock_Stone"
    },
    {
      "x": -3,
      "y": 2,
      "z": 3,
      "name": "Rock_Stone"
    },
    {
      "x": -3,
      "y": 3,
      "z": 3,
      "name": "Rock_Stone"
    },
    {
      "x": -3,
      "y": 4,
      "z": 3,
      "name": "Rock_Stone"
    },
    {
      "x": -3,
      "y": 5,
      "z": 3,
      "name": "Rock_Stone"
    },
    {
      "x": -3,
      "y": 6,
      "z": 3,
      "name": "Rock_Stone"
    },
    {
      "x": -3,
      "y": -1,
      "z": 4,
      "name": "Rock_Stone"
    },
    {
      "x": -3,
      "y": 0,
      "z": 4,
      "name": "Rock_Stone"
    },
    {
      "x": -3,
      "y": 1,
      "z": 4,
      "name": "Rock_Stone"
    },
    {
      "x": -3,
      "y": 2,
      "z": 4,
      "name": "Rock_Stone"
    },
    {
      "x": -3,
      "y": 3,
      "z": 4,
      "name": "Rock_Stone"
    },
    {
      "x": -3,
      "y": 4,
      "z": 4,
      "name": "Rock_Stone"
    },
    {
      "x": -3,
      "y": 5,
      "z": 4,
      "name": "Rock_Stone"
    },
    {
      "x": -3,
      "y": 6,
      "z": 4,
      "name": "Rock_Stone"
    },
    {
      "x": -3,
      "y": -1,
      "z": 5,
      "name": "Rock_Stone"
    },
    {
      "x": -3,
      "y": 0,
      "z": 5,
      "name": "Rock_Stone"
    },
    {
      "x": -3,
      "y": 1,
      "z": 5,
      "name": "Rock_Stone"
    },
    {
      "x": -3,
      "y": 2,
      "z": 5,
      "name": "Rock_Stone"
    },
    {
      "x": -3,
      "y": 3,
      "z": 5,
      "name": "Rock_Stone"
    },
    {
      "x": -3,
      "y": 4,
      "z": 5,
      "name": "Rock_Stone"
    },
    {
      "x": -3,
      "y": 5,
      "z": 5,
      "name": "Rock_Stone"
    },
    {
      "x": -3,
      "y": 6,
      "z": 5,
      "name": "Rock_Stone"
    },
    {
      "x": -3,
      "y": -1,
      "z": 6,
      "name": "Rock_Stone"
    },
    {
      "x": -3,
      "y": 0,
      "z": 6,
      "name": "Rock_Stone"
    },
    {
      "x": -3,
      "y": 1,
      "z": 6,
      "name": "Rock_Stone"
    },
    {
      "x": -3,
      "y": 2,
      "z": 6,
      "name": "Rock_Stone"
    },
    {
      "x": -3,
      "y": 3,
      "z": 6,
      "name": "Rock_Stone"
    },
    {
      "x": -3,
      "y": 4,
      "z": 6,
      "name": "Rock_Stone"
    },
    {
      "x": -3,
      "y": 5,
      "z": 6,
      "name": "Rock_Stone"
    },
    {
      "x": -3,
      "y": 6,
      "z": 6,
      "name": "Rock_Stone"
    },
    {
      "x": -3,
      "y": -1,
      "z": 7,
      "name": "Rock_Stone"
    },
    {
      "x": -3,
      "y": 0,
      "z": 7,
      "name": "Rock_Stone"
    },
    {
      "x": -3,
      "y": 1,
      "z": 7,
      "name": "Rock_Stone"
    },
    {
      "x": -3,
      "y": 2,
      "z": 7,
      "name": "Rock_Stone"
    },
    {
      "x": -3,
      "y": 3,
      "z": 7,
      "name": "Rock_Stone"
    },
    {
      "x": -3,
      "y": 4,
      "z": 7,
      "name": "Rock_Stone"
    },
    {
      "x": -3,
      "y": 5,
      "z": 7,
      "name": "Rock_Stone"
    },
    {
      "x": -3,
      "y": 6,
      "z": 7,
      "name": "Rock_Stone"
    },
    {
      "x": -2,
      "y": -1,
      "z": 0,
      "name": "Rock_Stone"
    },
    {
      "x": -2,
      "y": 0,
      "z": 0,
      "name": "Rock_Stone"
    },
    {
      "x": -2,
      "y": 1,
      "z": 0,
      "name": "Rock_Stone_Stalactite_Small"
    },
    {
      "x": -2,
      "y": 2,
      "z": 0,
      "name": "Empty"
    },
    {
      "x": -2,
      "y": 3,
      "z": 0,
      "name": "Empty"
    },
    {
      "x": -2,
      "y": 4,
      "z": 0,
      "name": "Rock_Stone_Stalactite_Large",
      "filler": 31744,
      "rotation": 8
    },
    {
      "x": -2,
      "y": 5,
      "z": 0,
      "name": "Rock_Stone_Stalactite_Large",
      "rotation": 8
    },
    {
      "x": -2,
      "y": 6,
      "z": 0,
      "name": "Rock_Stone"
    },
    {
      "x": -2,
      "y": -1,
      "z": 1,
      "name": "Rock_Stone"
    },
    {
      "x": -2,
      "y": 0,
      "z": 1,
      "name": "Rock_Stone"
    },
    {
      "x": -2,
      "y": 1,
      "z": 1,
      "name": "Rubble_Stone"
    },
    {
      "x": -2,
      "y": 2,
      "z": 1,
      "name": "Empty"
    },
    {
      "x": -2,
      "y": 3,
      "z": 1,
      "name": "Empty"
    },
    {
      "x": -2,
      "y": 4,
      "z": 1,
      "name": "Empty"
    },
    {
      "x": -2,
      "y": 5,
      "z": 1,
      "name": "Empty"
    },
    {
      "x": -2,
      "y": 6,
      "z": 1,
      "name": "Rock_Stone"
    },
    {
      "x": -2,
      "y": -1,
      "z": 2,
      "name": "Rock_Stone"
    },
    {
      "x": -2,
      "y": 0,
      "z": 2,
      "name": "Rock_Stone"
    },
    {
      "x": -2,
      "y": 1,
      "z": 2,
      "name": "Wood_Beech_Trunk"
    },
    {
      "x": -2,
      "y": 2,
      "z": 2,
      "name": "Wood_Beech_Trunk"
    },
    {
      "x": -2,
      "y": 3,
      "z": 2,
      "name": "Wood_Beech_Branch_Long"
    },
    {
      "x": -2,
      "y": 4,
      "z": 2,
      "name": "Wood_Beech_Branch_Long"
    },
    {
      "x": -2,
      "y": 5,
      "z": 2,
      "name": "Wood_Beech_Trunk",
      "rotation": 5
    },
    {
      "x": -2,
      "y": 6,
      "z": 2,
      "name": "Rock_Stone"
    },
    {
      "x": -2,
      "y": -1,
      "z": 3,
      "name": "Rock_Stone"
    },
    {
      "x": -2,
      "y": 0,
      "z": 3,
      "name": "Rock_Stone"
    },
    {
      "x": -2,
      "y": 1,
      "z": 3,
      "name": "Rock_Stone"
    },
    {
      "x": -2,
      "y": 2,
      "z": 3,
      "name": "Rock_Stone"
    },
    {
      "x": -2,
      "y": 3,
      "z": 3,
      "name": "Rock_Stone"
    },
    {
      "x": -2,
      "y": 4,
      "z": 3,
      "name": "Plant_Moss_Rug_Yellow"
    },
    {
      "x": -2,
      "y": 5,
      "z": 3,
      "name": "Empty"
    },
    {
      "x": -2,
      "y": 6,
      "z": 3,
      "name": "Rock_Stone"
    },
    {
      "x": -2,
      "y": -1,
      "z": 4,
      "name": "Rock_Stone"
    },
    {
      "x": -2,
      "y": 0,
      "z": 4,
      "name": "Rock_Stone"
    },
    {
      "x": -2,
      "y": 1,
      "z": 4,
      "name": "Rock_Stone"
    },
    {
      "x": -2,
      "y": 2,
      "z": 4,
      "name": "Rock_Stone"
    },
    {
      "x": -2,
      "y": 3,
      "z": 4,
      "name": "Rock_Stone"
    },
    {
      "x": -2,
      "y": 4,
      "z": 4,
      "name": "Plant_Moss_Rug_Yellow"
    },
    {
      "x": -2,
      "y": 5,
      "z": 4,
      "name": "Rock_Stone"
    },
    {
      "x": -2,
      "y": 6,
      "z": 4,
      "name": "Rock_Stone"
    },
    {
      "x": -2,
      "y": -1,
      "z": 5,
      "name": "Rock_Stone"
    },
    {
      "x": -2,
      "y": 0,
      "z": 5,
      "name": "Rock_Stone"
    },
    {
      "x": -2,
      "y": 1,
      "z": 5,
      "name": "Rock_Stone"
    },
    {
      "x": -2,
      "y": 2,
      "z": 5,
      "name": "Rock_Stone"
    },
    {
      "x": -2,
      "y": 3,
      "z": 5,
      "name": "Rock_Stone"
    },
    {
      "x": -2,
      "y": 4,
      "z": 5,
      "name": "Empty"
    },
    {
      "x": -2,
      "y": 5,
      "z": 5,
      "name": "Rock_Stone"
    },
    {
      "x": -2,
      "y": 6,
      "z": 5,
      "name": "Rock_Stone"
    },
    {
      "x": -2,
      "y": -1,
      "z": 6,
      "name": "Rock_Stone"
    },
    {
      "x": -2,
      "y": 0,
      "z": 6,
      "name": "Rock_Stone"
    },
    {
      "x": -2,
      "y": 1,
      "z": 6,
      "name": "Rock_Stone"
    },
    {
      "x": -2,
      "y": 2,
      "z": 6,
      "name": "Rock_Stone"
    },
    {
      "x": -2,
      "y": 3,
      "z": 6,
      "name": "Rock_Stone"
    },
    {
      "x": -2,
      "y": 4,
      "z": 6,
      "name": "Rock_Stone"
    },
    {
      "x": -2,
      "y": 5,
      "z": 6,
      "name": "Rock_Stone"
    },
    {
      "x": -2,
      "y": 6,
      "z": 6,
      "name": "Rock_Stone"
    },
    {
      "x": -2,
      "y": -1,
      "z": 7,
      "name": "Rock_Stone"
    },
    {
      "x": -2,
      "y": 0,
      "z": 7,
      "name": "Rock_Stone"
    },
    {
      "x": -2,
      "y": 1,
      "z": 7,
      "name": "Rock_Stone"
    },
    {
      "x": -2,
      "y": 2,
      "z": 7,
      "name": "Rock_Stone"
    },
    {
      "x": -2,
      "y": 3,
      "z": 7,
      "name": "Rock_Stone"
    },
    {
      "x": -2,
      "y": 4,
      "z": 7,
      "name": "Rock_Stone"
    },
    {
      "x": -2,
      "y": 5,
      "z": 7,
      "name": "Rock_Stone"
    },
    {
      "x": -2,
      "y": 6,
      "z": 7,
      "name": "Rock_Stone"
    },
    {
      "x": -1,
      "y": -1,
      "z": 0,
      "name": "Rock_Stone"
    },
    {
      "x": -1,
      "y": 0,
      "z": 0,
      "name": "Soil_Gravel"
    },
    {
      "x": -1,
      "y": 1,
      "z": 0,
      "name": "Empty"
    },
    {
      "x": -1,
      "y": 2,
      "z": 0,
      "name": "Empty"
    },
    {
      "x": -1,
      "y": 3,
      "z": 0,
      "name": "Empty"
    },
    {
      "x": -1,
      "y": 4,
      "z": 0,
      "name": "Empty"
    },
    {
      "x": -1,
      "y": 5,
      "z": 0,
      "name": "Empty"
    },
    {
      "x": -1,
      "y": 6,
      "z": 0,
      "name": "Rock_Stone"
    },
    {
      "x": -1,
      "y": -1,
      "z": 1,
      "name": "Rock_Stone"
    },
    {
      "x": -1,
      "y": 0,
      "z": 1,
      "name": "Rock_Stone"
    },
    {
      "x": -1,
      "y": 1,
      "z": 1,
      "name": "Empty"
    },
    {
      "x": -1,
      "y": 2,
      "z": 1,
      "name": "Empty"
    },
    {
      "x": -1,
      "y": 3,
      "z": 1,
      "name": "Empty"
    },
    {
      "x": -1,
      "y": 4,
      "z": 1,
      "name": "Empty"
    },
    {
      "x": -1,
      "y": 5,
      "z": 1,
      "name": "Empty"
    },
    {
      "x": -1,
      "y": 6,
      "z": 1,
      "name": "Rock_Stone"
    },
    {
      "x": -1,
      "y": -1,
      "z": 2,
      "name": "Rock_Stone"
    },
    {
      "x": -1,
      "y": 0,
      "z": 2,
      "name": "Rock_Stone"
    },
    {
      "x": -1,
      "y": 1,
      "z": 2,
      "name": "Furniture_Tavern_Barrel"
    },
    {
      "x": -1,
      "y": 2,
      "z": 2,
      "name": "Empty"
    },
    {
      "x": -1,
      "y": 3,
      "z": 2,
      "name": "Empty"
    },
    {
      "x": -1,
      "y": 4,
      "z": 2,
      "name": "Empty"
    },
    {
      "x": -1,
      "y": 5,
      "z": 2,
      "name": "Wood_Beech_Trunk",
      "rotation": 5
    },
    {
      "x": -1,
      "y": 6,
      "z": 2,
      "name": "Rock_Stone"
    },
    {
      "x": -1,
      "y": -1,
      "z": 3,
      "name": "Rock_Stone"
    },
    {
      "x": -1,
      "y": 0,
      "z": 3,
      "name": "Rock_Stone"
    },
    {
      "x": -1,
      "y": 1,
      "z": 3,
      "name": "Rock_Stone"
    },
    {
      "x": -1,
      "y": 2,
      "z": 3,
      "name": "Plant_Moss_Block_Yellow"
    },
    {
      "x": -1,
      "y": 3,
      "z": 3,
      "name": "Plant_Moss_Rug_Yellow"
    },
    {
      "x": -1,
      "y": 4,
      "z": 3,
      "name": "Empty"
    },
    {
      "x": -1,
      "y": 5,
      "z": 3,
      "name": "Empty"
    },
    {
      "x": -1,
      "y": 6,
      "z": 3,
      "name": "Rock_Stone"
    },
    {
      "x": -1,
      "y": -1,
      "z": 4,
      "name": "Rock_Stone"
    },
    {
      "x": -1,
      "y": 0,
      "z": 4,
      "name": "Rock_Stone"
    },
    {
      "x": -1,
      "y": 1,
      "z": 4,
      "name": "Rock_Stone"
    },
    {
      "x": -1,
      "y": 2,
      "z": 4,
      "name": "Rock_Stone"
    },
    {
      "x": -1,
      "y": 3,
      "z": 4,
      "name": "Plant_Moss_Block_Yellow"
    },
    {
      "x": -1,
      "y": 4,
      "z": 4,
      "name": "Plant_Moss_Rug_Yellow"
    },
    {
      "x": -1,
      "y": 5,
      "z": 4,
      "name": "Empty"
    },
    {
      "x": -1,
      "y": 6,
      "z": 4,
      "name": "Rock_Stone"
    },
    {
      "x": -1,
      "y": -1,
      "z": 5,
      "name": "Rock_Stone"
    },
    {
      "x": -1,
      "y": 0,
      "z": 5,
      "name": "Rock_Stone"
    },
    {
      "x": -1,
      "y": 1,
      "z": 5,
      "name": "Rock_Stone"
    },
    {
      "x": -1,
      "y": 2,
      "z": 5,
      "name": "Rock_Stone"
    },
    {
      "x": -1,
      "y": 3,
      "z": 5,
      "name": "Plant_Moss_Block_Yellow"
    },
    {
      "x": -1,
      "y": 4,
      "z": 5,
      "name": "Empty"
    },
    {
      "x": -1,
      "y": 5,
      "z": 5,
      "name": "Rock_Stone"
    },
    {
      "x": -1,
      "y": 6,
      "z": 5,
      "name": "Rock_Stone"
    },
    {
      "x": -1,
      "y": -1,
      "z": 6,
      "name": "Rock_Stone"
    },
    {
      "x": -1,
      "y": 0,
      "z": 6,
      "name": "Rock_Stone"
    },
    {
      "x": -1,
      "y": 1,
      "z": 6,
      "name": "Rock_Stone"
    },
    {
      "x": -1,
      "y": 2,
      "z": 6,
      "name": "Rock_Stone"
    },
    {
      "x": -1,
      "y": 3,
      "z": 6,
      "name": "Rock_Stone"
    },
    {
      "x": -1,
      "y": 4,
      "z": 6,
      "name": "Empty"
    },
    {
      "x": -1,
      "y": 5,
      "z": 6,
      "name": "Rock_Stone"
    },
    {
      "x": -1,
      "y": 6,
      "z": 6,
      "name": "Rock_Stone"
    },
    {
      "x": -1,
      "y": -1,
      "z": 7,
      "name": "Rock_Stone"
    },
    {
      "x": -1,
      "y": 0,
      "z": 7,
      "name": "Rock_Stone"
    },
    {
      "x": -1,
      "y": 1,
      "z": 7,
      "name": "Rock_Stone"
    },
    {
      "x": -1,
      "y": 2,
      "z": 7,
      "name": "Rock_Stone"
    },
    {
      "x": -1,
      "y": 3,
      "z": 7,
      "name": "Rock_Stone"
    },
    {
      "x": -1,
      "y": 4,
      "z": 7,
      "name": "Rock_Stone"
    },
    {
      "x": -1,
      "y": 5,
      "z": 7,
      "name": "Rock_Stone"
    },
    {
      "x": -1,
      "y": 6,
      "z": 7,
      "name": "Rock_Stone"
    },
    {
      "x": 0,
      "y": -1,
      "z": 0,
      "name": "Rock_Stone"
    },
    {
      "x": 0,
      "y": 0,
      "z": 0,
      "name": "Rock_Stone"
    },
    {
      "x": 0,
      "y": 1,
      "z": 0,
      "name": "Empty"
    },
    {
      "x": 0,
      "y": 2,
      "z": 0,
      "name": "Empty"
    },
    {
      "x": 0,
      "y": 3,
      "z": 0,
      "name": "Empty"
    },
    {
      "x": 0,
      "y": 4,
      "z": 0,
      "name": "Empty"
    },
    {
      "x": 0,
      "y": 5,
      "z": 0,
      "name": "Empty"
    },
    {
      "x": 0,
      "y": 6,
      "z": 0,
      "name": "Rock_Stone"
    },
    {
      "x": 0,
      "y": -1,
      "z": 1,
      "name": "Rock_Stone"
    },
    {
      "x": 0,
      "y": 0,
      "z": 1,
      "name": "Rock_Stone"
    },
    {
      "x": 0,
      "y": 1,
      "z": 1,
      "name": "Soil_Gravel"
    },
    {
      "x": 0,
      "y": 2,
      "z": 1,
      "name": "Empty"
    },
    {
      "x": 0,
      "y": 3,
      "z": 1,
      "name": "Empty"
    },
    {
      "x": 0,
      "y": 4,
      "z": 1,
      "name": "Empty"
    },
    {
      "x": 0,
      "y": 5,
      "z": 1,
      "name": "Empty"
    },
    {
      "x": 0,
      "y": 6,
      "z": 1,
      "name": "Rock_Stone"
    },
    {
      "x": 0,
      "y": -1,
      "z": 2,
      "name": "Rock_Stone"
    },
    {
      "x": 0,
      "y": 0,
      "z": 2,
      "name": "Rock_Stone"
    },
    {
      "x": 0,
      "y": 1,
      "z": 2,
      "name": "Rock_Stone"
    },
    {
      "x": 0,
      "y": 2,
      "z": 2,
      "name": "Empty"
    },
    {
      "x": 0,
      "y": 3,
      "z": 2,
      "name": "Empty"
    },
    {
      "x": 0,
      "y": 4,
      "z": 2,
      "name": "Wood_Softwood_Planks_Half",
      "rotation": 8
    },
    {
      "x": 0,
      "y": 5,
      "z": 2,
      "name": "Wood_Beech_Trunk",
      "rotation": 5
    },
    {
      "x": 0,
      "y": 6,
      "z": 2,
      "name": "Rock_Stone"
    },
    {
      "x": 0,
      "y": -1,
      "z": 3,
      "name": "Rock_Stone"
    },
    {
      "x": 0,
      "y": 0,
      "z": 3,
      "name": "Rock_Stone"
    },
    {
      "x": 0,
      "y": 1,
      "z": 3,
      "name": "Plant_Moss_Block_Yellow"
    },
    {
      "x": 0,
      "y": 2,
      "z": 3,
      "name": "Plant_Crop_Mushroom_Glowing_Red"
    },
    {
      "x": 0,
      "y": 3,
      "z": 3,
      "name": "Empty"
    },
    {
      "x": 0,
      "y": 4,
      "z": 3,
      "name": "Empty"
    },
    {
      "x": 0,
      "y": 5,
      "z": 3,
      "name": "Empty"
    },
    {
      "x": 0,
      "y": 6,
      "z": 3,
      "name": "Rock_Stone"
    },
    {
      "x": 0,
      "y": -1,
      "z": 4,
      "name": "Rock_Stone"
    },
    {
      "x": 0,
      "y": 0,
      "z": 4,
      "name": "Rock_Stone"
    },
    {
      "x": 0,
      "y": 1,
      "z": 4,
      "name": "Rock_Stone"
    },
    {
      "x": 0,
      "y": 2,
      "z": 4,
      "name": "Plant_Moss_Block_Yellow"
    },
    {
      "x": 0,
      "y": 3,
      "z": 4,
      "name": "Empty"
    },
    {
      "x": 0,
      "y": 4,
      "z": 4,
      "name": "Empty"
    },
    {
      "x": 0,
      "y": 5,
      "z": 4,
      "name": "Empty"
    },
    {
      "x": 0,
      "y": 6,
      "z": 4,
      "name": "Rock_Stone"
    },
    {
      "x": 0,
      "y": -1,
      "z": 5,
      "name": "Rock_Stone"
    },
    {
      "x": 0,
      "y": 0,
      "z": 5,
      "name": "Rock_Stone"
    },
    {
      "x": 0,
      "y": 1,
      "z": 5,
      "name": "Rock_Stone"
    },
    {
      "x": 0,
      "y": 2,
      "z": 5,
      "name": "Rock_Stone"
    },
    {
      "x": 0,
      "y": 3,
      "z": 5,
      "name": "Plant_Moss_Yellow"
    },
    {
      "x": 0,
      "y": 4,
      "z": 5,
      "name": "Empty"
    },
    {
      "x": 0,
      "y": 5,
      "z": 5,
      "name": "Rock_Stone"
    },
    {
      "x": 0,
      "y": 6,
      "z": 5,
      "name": "Rock_Stone"
    },
    {
      "x": 0,
      "y": -1,
      "z": 6,
      "name": "Rock_Stone"
    },
    {
      "x": 0,
      "y": 0,
      "z": 6,
      "name": "Rock_Stone"
    },
    {
      "x": 0,
      "y": 1,
      "z": 6,
      "name": "Rock_Stone"
    },
    {
      "x": 0,
      "y": 2,
      "z": 6,
      "name": "Rock_Stone"
    },
    {
      "x": 0,
      "y": 3,
      "z": 6,
      "name": "Empty"
    },
    {
      "x": 0,
      "y": 4,
      "z": 6,
      "name": "Empty"
    },
    {
      "x": 0,
      "y": 5,
      "z": 6,
      "name": "Rock_Stone"
    },
    {
      "x": 0,
      "y": 6,
      "z": 6,
      "name": "Rock_Stone"
    },
    {
      "x": 0,
      "y": -1,
      "z": 7,
      "name": "Rock_Stone"
    },
    {
      "x": 0,
      "y": 0,
      "z": 7,
      "name": "Rock_Stone"
    },
    {
      "x": 0,
      "y": 1,
      "z": 7,
      "name": "Rock_Stone"
    },
    {
      "x": 0,
      "y": 2,
      "z": 7,
      "name": "Rock_Stone"
    },
    {
      "x": 0,
      "y": 3,
      "z": 7,
      "name": "Rock_Stone"
    },
    {
      "x": 0,
      "y": 4,
      "z": 7,
      "name": "Rock_Stone"
    },
    {
      "x": 0,
      "y": 5,
      "z": 7,
      "name": "Rock_Stone"
    },
    {
      "x": 0,
      "y": 6,
      "z": 7,
      "name": "Rock_Stone"
    },
    {
      "x": 1,
      "y": -1,
      "z": 0,
      "name": "Rock_Stone"
    },
    {
      "x": 1,
      "y": 0,
      "z": 0,
      "name": "Rock_Stone"
    },
    {
      "x": 1,
      "y": 1,
      "z": 0,
      "name": "Rock_Stone"
    },
    {
      "x": 1,
      "y": 2,
      "z": 0,
      "name": "Empty"
    },
    {
      "x": 1,
      "y": 3,
      "z": 0,
      "name": "Empty"
    },
    {
      "x": 1,
      "y": 4,
      "z": 0,
      "name": "Empty"
    },
    {
      "x": 1,
      "y": 5,
      "z": 0,
      "name": "Empty"
    },
    {
      "x": 1,
      "y": 6,
      "z": 0,
      "name": "Rock_Stone"
    },
    {
      "x": 1,
      "y": -1,
      "z": 1,
      "name": "Rock_Stone"
    },
    {
      "x": 1,
      "y": 0,
      "z": 1,
      "name": "Rock_Stone"
    },
    {
      "x": 1,
      "y": 1,
      "z": 1,
      "name": "Rock_Stone"
    },
    {
      "x": 1,
      "y": 2,
      "z": 1,
      "name": "Rock_Stone"
    },
    {
      "x": 1,
      "y": 3,
      "z": 1,
      "name": "Plant_Moss_Rug_Yellow"
    },
    {
      "x": 1,
      "y": 4,
      "z": 1,
      "name": "Empty"
    },
    {
      "x": 1,
      "y": 5,
      "z": 1,
      "name": "Empty"
    },
    {
      "x": 1,
      "y": 6,
      "z": 1,
      "name": "Rock_Stone"
    },
    {
      "x": 1,
      "y": -1,
      "z": 2,
      "name": "Rock_Stone"
    },
    {
      "x": 1,
      "y": 0,
      "z": 2,
      "name": "Rock_Stone"
    },
    {
      "x": 1,
      "y": 1,
      "z": 2,
      "name": "Rock_Stone"
    },
    {
      "x": 1,
      "y": 2,
      "z": 2,
      "name": "Rock_Stone"
    },
    {
      "x": 1,
      "y": 3,
      "z": 2,
      "name": "Empty"
    },
    {
      "x": 1,
      "y": 4,
      "z": 2,
      "name": "Wood_Softwood_Planks_Half",
      "rotation": 8
    },
    {
      "x": 1,
      "y": 5,
      "z": 2,
      "name": "Wood_Beech_Trunk",
      "rotation": 5
    },
    {
      "x": 1,
      "y": 6,
      "z": 2,
      "name": "Rock_Stone"
    },
    {
      "x": 1,
      "y": -1,
      "z": 3,
      "name": "Rock_Stone"
    },
    {
      "x": 1,
      "y": 0,
      "z": 3,
      "name": "Rock_Stone"
    },
    {
      "x": 1,
      "y": 1,
      "z": 3,
      "name": "Rock_Stone"
    },
    {
      "x": 1,
      "y": 2,
      "z": 3,
      "name": "Empty"
    },
    {
      "x": 1,
      "y": 3,
      "z": 3,
      "name": "Empty"
    },
    {
      "x": 1,
      "y": 4,
      "z": 3,
      "name": "Empty"
    },
    {
      "x": 1,
      "y": 5,
      "z": 3,
      "name": "Empty"
    },
    {
      "x": 1,
      "y": 6,
      "z": 3,
      "name": "Rock_Stone"
    },
    {
      "x": 1,
      "y": -1,
      "z": 4,
      "name": "Rock_Stone"
    },
    {
      "x": 1,
      "y": 0,
      "z": 4,
      "name": "Rock_Stone"
    },
    {
      "x": 1,
      "y": 1,
      "z": 4,
      "name": "Rock_Stone"
    },
    {
      "x": 1,
      "y": 2,
      "z": 4,
      "name": "Plant_Moss_Yellow"
    },
    {
      "x": 1,
      "y": 3,
      "z": 4,
      "name": "Empty"
    },
    {
      "x": 1,
      "y": 4,
      "z": 4,
      "name": "Empty"
    },
    {
      "x": 1,
      "y": 5,
      "z": 4,
      "name": "Empty"
    },
    {
      "x": 1,
      "y": 6,
      "z": 4,
      "name": "Rock_Stone"
    },
    {
      "x": 1,
      "y": -1,
      "z": 5,
      "name": "Rock_Stone"
    },
    {
      "x": 1,
      "y": 0,
      "z": 5,
      "name": "Rock_Stone"
    },
    {
      "x": 1,
      "y": 1,
      "z": 5,
      "name": "Rock_Stone"
    },
    {
      "x": 1,
      "y": 2,
      "z": 5,
      "name": "Empty"
    },
    {
      "x": 1,
      "y": 3,
      "z": 5,
      "name": "Empty"
    },
    {
      "x": 1,
      "y": 4,
      "z": 5,
      "name": "Empty"
    },
    {
      "x": 1,
      "y": 5,
      "z": 5,
      "name": "Empty"
    },
    {
      "x": 1,
      "y": 6,
      "z": 5,
      "name": "Rock_Stone"
    },
    {
      "x": 1,
      "y": -1,
      "z": 6,
      "name": "Rock_Stone"
    },
    {
      "x": 1,
      "y": 0,
      "z": 6,
      "name": "Rock_Stone"
    },
    {
      "x": 1,
      "y": 1,
      "z": 6,
      "name": "Rock_Stone"
    },
    {
      "x": 1,
      "y": 2,
      "z": 6,
      "name": "Rubble_Stone_Medium"
    },
    {
      "x": 1,
      "y": 3,
      "z": 6,
      "name": "Empty"
    },
    {
      "x": 1,
      "y": 4,
      "z": 6,
      "name": "Empty"
    },
    {
      "x": 1,
      "y": 5,
      "z": 6,
      "name": "Empty"
    },
    {
      "x": 1,
      "y": 6,
      "z": 6,
      "name": "Rock_Stone"
    },
    {
      "x": 1,
      "y": -1,
      "z": 7,
      "name": "Rock_Stone"
    },
    {
      "x": 1,
      "y": 0,
      "z": 7,
      "name": "Rock_Stone"
    },
    {
      "x": 1,
      "y": 1,
      "z": 7,
      "name": "Rock_Stone"
    },
    {
      "x": 1,
      "y": 2,
      "z": 7,
      "name": "Rock_Stone"
    },
    {
      "x": 1,
      "y": 3,
      "z": 7,
      "name": "Rock_Stone"
    },
    {
      "x": 1,
      "y": 4,
      "z": 7,
      "name": "Rock_Stone"
    },
    {
      "x": 1,
      "y": 5,
      "z": 7,
      "name": "Rock_Stone"
    },
    {
      "x": 1,
      "y": 6,
      "z": 7,
      "name": "Rock_Stone"
    },
    {
      "x": 2,
      "y": -1,
      "z": 0,
      "name": "Rock_Stone"
    },
    {
      "x": 2,
      "y": 0,
      "z": 0,
      "name": "Rock_Stone"
    },
    {
      "x": 2,
      "y": 1,
      "z": 0,
      "name": "Rock_Stone"
    },
    {
      "x": 2,
      "y": 2,
      "z": 0,
      "name": "Rock_Stone"
    },
    {
      "x": 2,
      "y": 3,
      "z": 0,
      "name": "Empty"
    },
    {
      "x": 2,
      "y": 4,
      "z": 0,
      "name": "Empty"
    },
    {
      "x": 2,
      "y": 5,
      "z": 0,
      "name": "Empty"
    },
    {
      "x": 2,
      "y": 6,
      "z": 0,
      "name": "Rock_Stone"
    },
    {
      "x": 2,
      "y": -1,
      "z": 1,
      "name": "Rock_Stone"
    },
    {
      "x": 2,
      "y": 0,
      "z": 1,
      "name": "Rock_Stone"
    },
    {
      "x": 2,
      "y": 1,
      "z": 1,
      "name": "Rock_Stone"
    },
    {
      "x": 2,
      "y": 2,
      "z": 1,
      "name": "Rock_Stone"
    },
    {
      "x": 2,
      "y": 3,
      "z": 1,
      "name": "Plant_Moss_Rug_Yellow"
    },
    {
      "x": 2,
      "y": 4,
      "z": 1,
      "name": "Empty"
    },
    {
      "x": 2,
      "y": 5,
      "z": 1,
      "name": "Wood_Softwood_Planks_Half",
      "rotation": 6
    },
    {
      "x": 2,
      "y": 6,
      "z": 1,
      "name": "Rock_Stone"
    },
    {
      "x": 2,
      "y": -1,
      "z": 2,
      "name": "Rock_Stone"
    },
    {
      "x": 2,
      "y": 0,
      "z": 2,
      "name": "Rock_Stone"
    },
    {
      "x": 2,
      "y": 1,
      "z": 2,
      "name": "Wood_Beech_Trunk"
    },
    {
      "x": 2,
      "y": 2,
      "z": 2,
      "name": "Wood_Beech_Trunk"
    },
    {
      "x": 2,
      "y": 3,
      "z": 2,
      "name": "Wood_Beech_Trunk"
    },
    {
      "x": 2,
      "y": 4,
      "z": 2,
      "name": "Wood_Beech_Trunk"
    },
    {
      "x": 2,
      "y": 5,
      "z": 2,
      "name": "Wood_Beech_Trunk",
      "rotation": 5
    },
    {
      "x": 2,
      "y": 6,
      "z": 2,
      "name": "Rock_Stone"
    },
    {
      "x": 2,
      "y": -1,
      "z": 3,
      "name": "Rock_Stone"
    },
    {
      "x": 2,
      "y": 0,
      "z": 3,
      "name": "Rock_Stone"
    },
    {
      "x": 2,
      "y": 1,
      "z": 3,
      "name": "Rock_Stone"
    },
    {
      "x": 2,
      "y": 2,
      "z": 3,
      "name": "Block_Spawner_Block",
      "components": {
        "Components": {
          "BlockSpawner": {
            "BlockSpawnerId": "Zone1_Encounters_Tier2"
          }
        }
      },
      "rotation": 3
    },
    {
      "x": 2,
      "y": 3,
      "z": 3,
      "name": "Empty"
    },
    {
      "x": 2,
      "y": 4,
      "z": 3,
      "name": "Empty"
    },
    {
      "x": 2,
      "y": 5,
      "z": 3,
      "name": "Empty"
    },
    {
      "x": 2,
      "y": 6,
      "z": 3,
      "name": "Rock_Stone"
    },
    {
      "x": 2,
      "y": -1,
      "z": 4,
      "name": "Rock_Stone"
    },
    {
      "x": 2,
      "y": 0,
      "z": 4,
      "name": "Rock_Stone"
    },
    {
      "x": 2,
      "y": 1,
      "z": 4,
      "name": "Rock_Stone"
    },
    {
      "x": 2,
      "y": 2,
      "z": 4,
      "name": "Furniture_Ancient_Crate",
      "rotation": 2
    },
    {
      "x": 2,
      "y": 3,
      "z": 4,
      "name": "Empty"
    },
    {
      "x": 2,
      "y": 4,
      "z": 4,
      "name": "Empty"
    },
    {
      "x": 2,
      "y": 5,
      "z": 4,
      "name": "Rock_Stone"
    },
    {
      "x": 2,
      "y": 6,
      "z": 4,
      "name": "Rock_Stone"
    },
    {
      "x": 2,
      "y": -1,
      "z": 5,
      "name": "Rock_Stone"
    },
    {
      "x": 2,
      "y": 0,
      "z": 5,
      "name": "Rock_Stone"
    },
    {
      "x": 2,
      "y": 1,
      "z": 5,
      "name": "Rock_Stone"
    },
    {
      "x": 2,
      "y": 2,
      "z": 5,
      "name": "Furniture_Ancient_Crate",
      "rotation": 2
    },
    {
      "x": 2,
      "y": 3,
      "z": 5,
      "name": "Empty"
    },
    {
      "x": 2,
      "y": 4,
      "z": 5,
      "name": "Empty"
    },
    {
      "x": 2,
      "y": 5,
      "z": 5,
      "name": "Rock_Stone"
    },
    {
      "x": 2,
      "y": 6,
      "z": 5,
      "name": "Rock_Stone"
    },
    {
      "x": 2,
      "y": -1,
      "z": 6,
      "name": "Rock_Stone"
    },
    {
      "x": 2,
      "y": 0,
      "z": 6,
      "name": "Rock_Stone"
    },
    {
      "x": 2,
      "y": 1,
      "z": 6,
      "name": "Rock_Stone"
    },
    {
      "x": 2,
      "y": 2,
      "z": 6,
      "name": "Rock_Stone"
    },
    {
      "x": 2,
      "y": 3,
      "z": 6,
      "name": "Empty"
    },
    {
      "x": 2,
      "y": 4,
      "z": 6,
      "name": "Rock_Stone"
    },
    {
      "x": 2,
      "y": 5,
      "z": 6,
      "name": "Rock_Stone"
    },
    {
      "x": 2,
      "y": 6,
      "z": 6,
      "name": "Rock_Stone"
    },
    {
      "x": 2,
      "y": -1,
      "z": 7,
      "name": "Rock_Stone"
    },
    {
      "x": 2,
      "y": 0,
      "z": 7,
      "name": "Rock_Stone"
    },
    {
      "x": 2,
      "y": 1,
      "z": 7,
      "name": "Rock_Stone"
    },
    {
      "x": 2,
      "y": 2,
      "z": 7,
      "name": "Rock_Stone"
    },
    {
      "x": 2,
      "y": 3,
      "z": 7,
      "name": "Rock_Stone"
    },
    {
      "x": 2,
      "y": 4,
      "z": 7,
      "name": "Rock_Stone"
    },
    {
      "x": 2,
      "y": 5,
      "z": 7,
      "name": "Rock_Stone"
    },
    {
      "x": 2,
      "y": 6,
      "z": 7,
      "name": "Rock_Stone"
    },
    {
      "x": 3,
      "y": -1,
      "z": 0,
      "name": "Rock_Stone"
    },
    {
      "x": 3,
      "y": 0,
      "z": 0,
      "name": "Rock_Stone"
    },
    {
      "x": 3,
      "y": 1,
      "z": 0,
      "name": "Rock_Stone"
    },
    {
      "x": 3,
      "y": 2,
      "z": 0,
      "name": "Rock_Stone"
    },
    {
      "x": 3,
      "y": 3,
      "z": 0,
      "name": "Rock_Stone"
    },
    {
      "x": 3,
      "y": 4,
      "z": 0,
      "name": "Rock_Stone"
    },
    {
      "x": 3,
      "y": 5,
      "z": 0,
      "name": "Rock_Stone"
    },
    {
      "x": 3,
      "y": 6,
      "z": 0,
      "name": "Rock_Stone"
    },
    {
      "x": 3,
      "y": -1,
      "z": 1,
      "name": "Rock_Stone"
    },
    {
      "x": 3,
      "y": 0,
      "z": 1,
      "name": "Rock_Stone"
    },
    {
      "x": 3,
      "y": 1,
      "z": 1,
      "name": "Rock_Stone"
    },
    {
      "x": 3,
      "y": 2,
      "z": 1,
      "name": "Rock_Stone"
    },
    {
      "x": 3,
      "y": 3,
      "z": 1,
      "name": "Rock_Stone"
    },
    {
      "x": 3,
      "y": 4,
      "z": 1,
      "name": "Rock_Stone"
    },
    {
      "x": 3,
      "y": 5,
      "z": 1,
      "name": "Rock_Stone"
    },
    {
      "x": 3,
      "y": 6,
      "z": 1,
      "name": "Rock_Stone"
    },
    {
      "x": 3,
      "y": -1,
      "z": 2,
      "name": "Rock_Stone"
    },
    {
      "x": 3,
      "y": 0,
      "z": 2,
      "name": "Rock_Stone"
    },
    {
      "x": 3,
      "y": 1,
      "z": 2,
      "name": "Rock_Stone"
    },
    {
      "x": 3,
      "y": 2,
      "z": 2,
      "name": "Rock_Stone"
    },
    {
      "x": 3,
      "y": 3,
      "z": 2,
      "name": "Rock_Stone"
    },
    {
      "x": 3,
      "y": 4,
      "z": 2,
      "name": "Rock_Stone"
    },
    {
      "x": 3,
      "y": 5,
      "z": 2,
      "name": "Rock_Stone"
    },
    {
      "x": 3,
      "y": 6,
      "z": 2,
      "name": "Rock_Stone"
    },
    {
      "x": 3,
      "y": -1,
      "z": 3,
      "name": "Rock_Stone"
    },
    {
      "x": 3,
      "y": 0,
      "z": 3,
      "name": "Rock_Stone"
    },
    {
      "x": 3,
      "y": 1,
      "z": 3,
      "name": "Rock_Stone"
    },
    {
      "x": 3,
      "y": 2,
      "z": 3,
      "name": "Rock_Stone"
    },
    {
      "x": 3,
      "y": 3,
      "z": 3,
      "name": "Rock_Stone"
    },
    {
      "x": 3,
      "y": 4,
      "z": 3,
      "name": "Rock_Stone"
    },
    {
      "x": 3,
      "y": 5,
      "z": 3,
      "name": "Rock_Stone"
    },
    {
      "x": 3,
      "y": 6,
      "z": 3,
      "name": "Rock_Stone"
    },
    {
      "x": 3,
      "y": -1,
      "z": 4,
      "name": "Rock_Stone"
    },
    {
      "x": 3,
      "y": 0,
      "z": 4,
      "name": "Rock_Stone"
    },
    {
      "x": 3,
      "y": 1,
      "z": 4,
      "name": "Rock_Stone"
    },
    {
      "x": 3,
      "y": 2,
      "z": 4,
      "name": "Rock_Stone"
    },
    {
      "x": 3,
      "y": 3,
      "z": 4,
      "name": "Rock_Stone"
    },
    {
      "x": 3,
      "y": 4,
      "z": 4,
      "name": "Rock_Stone"
    },
    {
      "x": 3,
      "y": 5,
      "z": 4,
      "name": "Rock_Stone"
    },
    {
      "x": 3,
      "y": 6,
      "z": 4,
      "name": "Rock_Stone"
    },
    {
      "x": 3,
      "y": -1,
      "z": 5,
      "name": "Rock_Stone"
    },
    {
      "x": 3,
      "y": 0,
      "z": 5,
      "name": "Rock_Stone"
    },
    {
      "x": 3,
      "y": 1,
      "z": 5,
      "name": "Rock_Stone"
    },
    {
      "x": 3,
      "y": 2,
      "z": 5,
      "name": "Rock_Stone"
    },
    {
      "x": 3,
      "y": 3,
      "z": 5,
      "name": "Rock_Stone"
    },
    {
      "x": 3,
      "y": 4,
      "z": 5,
      "name": "Rock_Stone"
    },
    {
      "x": 3,
      "y": 5,
      "z": 5,
      "name": "Rock_Stone"
    },
    {
      "x": 3,
      "y": 6,
      "z": 5,
      "name": "Rock_Stone"
    },
    {
      "x": 3,
      "y": -1,
      "z": 6,
      "name": "Rock_Stone"
    },
    {
      "x": 3,
      "y": 0,
      "z": 6,
      "name": "Rock_Stone"
    },
    {
      "x": 3,
      "y": 1,
      "z": 6,
      "name": "Rock_Stone"
    },
    {
      "x": 3,
      "y": 2,
      "z": 6,
      "name": "Rock_Stone"
    },
    {
      "x": 3,
      "y": 3,
      "z": 6,
      "name": "Rock_Stone"
    },
    {
      "x": 3,
      "y": 4,
      "z": 6,
      "name": "Rock_Stone"
    },
    {
      "x": 3,
      "y": 5,
      "z": 6,
      "name": "Rock_Stone"
    },
    {
      "x": 3,
      "y": 6,
      "z": 6,
      "name": "Rock_Stone"
    },
    {
      "x": 3,
      "y": -1,
      "z": 7,
      "name": "Rock_Stone"
    },
    {
      "x": 3,
      "y": 0,
      "z": 7,
      "name": "Rock_Stone"
    },
    {
      "x": 3,
      "y": 1,
      "z": 7,
      "name": "Rock_Stone"
    },
    {
      "x": 3,
      "y": 2,
      "z": 7,
      "name": "Rock_Stone"
    },
    {
      "x": 3,
      "y": 3,
      "z": 7,
      "name": "Rock_Stone"
    },
    {
      "x": 3,
      "y": 4,
      "z": 7,
      "name": "Rock_Stone"
    },
    {
      "x": 3,
      "y": 5,
      "z": 7,
      "name": "Rock_Stone"
    },
    {
      "x": 3,
      "y": 6,
      "z": 7,
      "name": "Rock_Stone"
    }
  ]
}