{
  "version": 8,
  "blockIdVersion": 8,
  "anchorX": 4,
  "anchorY": 3,
  "anchorZ": 2,
  "blocks": [
    {
      "x": 0,
      "y": 1,
      "z": 1,
      "name": "Rock_Slate"
    },
    {
      "x": 0,
      "y": 2,
      "z": 1,
      "name": "Rock_Slate"
    },
    {
      "x": 0,
      "y": 3,
      "z": 1,
      "name": "Rock_Slate"
    },
    {
      "x": 1,
      "y": 2,
      "z": 0,
      "name": "Rock_Slate"
    },
    {
      "x": 1,
      "y": 3,
      "z": 0,
      "name": "Rock_Slate"
    },
    {
      "x": 1,
      "y": 4,
      "z": 0,
      "name": "Rock_Slate"
    },
    {
      "x": 1,
      "y": 1,
      "z": 1,
      "name": "Rock_Slate"
    },
    {
      "x": 1,
      "y": 2,
      "z": 1,
      "name": "Rock_Slate"
    },
    {
      "x": 1,
      "y": 3,
      "z": 1,
      "name": "Rock_Slate"
    },
    {
      "x": 2,
      "y": 8,
      "z": 2,
      "name": "Rock_Slate"
    },
    {
      "x": 2,
      "y": 9,
      "z": 2,
      "name": "Rock_Slate"
    },
    {
      "x": 2,
      "y": 10,
      "z": 2,
      "name": "Rock_Slate"
    },
    {
      "x": 2,
      "y": 11,
      "z": 2,
      "name": "Rock_Slate"
    },
    {
      "x": 2,
      "y": 7,
      "z": 3,
      "name": "Rock_Slate"
    },
    {
      "x": 2,
      "y": 8,
      "z": 3,
      "name": "Rock_Slate"
    },
    {
      "x": 2,
      "y": 9,
      "z": 3,
      "name": "Rock_Slate"
    },
    {
      "x": 2,
      "y": 10,
      "z": 3,
      "name": "Rock_Slate"
    },
    {
      "x": 2,
      "y": 11,
      "z": 3,
      "name": "Rock_Slate"
    },
    {
      "x": 2,
      "y": 12,
      "z": 3,
      "name": "Rock_Slate"
    },
    {
      "x": 2,
      "y": 7,
      "z": 4,
      "name": "Rock_Slate"
    },
    {
      "x": 2,
      "y": 8,
      "z": 4,
      "name": "Rock_Slate"
    },
    {
      "x": 2,
      "y": 9,
      "z": 4,
      "name": "Rock_Slate"
    },
    {
      "x": 2,
      "y": 10,
      "z": 4,
      "name": "Rock_Slate"
    },
    {
      "x": 2,
      "y": 11,
      "z": 4,
      "name": "Rock_Slate"
    },
    {
      "x": 2,
      "y": 12,
      "z": 4,
      "name": "Rock_Slate"
    },
    {
      "x": 2,
      "y": 10,
      "z": 5,
      "name": "Rock_Slate"
    },
    {
      "x": 2,
      "y": 11,
      "z": 5,
      "name": "Rock_Slate"
    },
    {
      "x": 3,
      "y": 1,
      "z": 1,
      "name": "Rock_Slate"
    },
    {
      "x": 3,
      "y": 2,
      "z": 1,
      "name": "Rock_Slate"
    },
    {
      "x": 3,
      "y": 3,
      "z": 1,
      "name": "Rock_Slate"
    },
    {
      "x": 3,
      "y": 4,
      "z": 1,
      "name": "Rock_Slate"
    },
    {
      "x": 3,
      "y": 5,
      "z": 1,
      "name": "Rock_Slate"
    },
    {
      "x": 3,
      "y": 6,
      "z": 1,
      "name": "Rock_Slate"
    },
    {
      "x": 3,
      "y": 7,
      "z": 1,
      "name": "Rock_Slate"
    },
    {
      "x": 3,
      "y": 8,
      "z": 1,
      "name": "Rock_Slate"
    },
    {
      "x": 3,
      "y": 0,
      "z": 2,
      "name": "Rock_Slate"
    },
    {
      "x": 3,
      "y": 1,
      "z": 2,
      "name": "Rock_Slate"
    },
    {
      "x": 3,
      "y": 2,
      "z": 2,
      "name": "Rock_Slate"
    },
    {
      "x": 3,
      "y": 3,
      "z": 2,
      "name": "Rock_Slate"
    },
    {
      "x": 3,
      "y": 4,
      "z": 2,
      "name": "Rock_Slate"
    },
    {
      "x": 3,
      "y": 5,
      "z": 2,
      "name": "Rock_Slate"
    },
    {
      "x": 3,
      "y": 6,
      "z": 2,
      "name": "Rock_Slate"
    },
    {
      "x": 3,
      "y": 7,
      "z": 2,
      "name": "Rock_Slate"
    },
    {
      "x": 3,
      "y": 8,
      "z": 2,
      "name": "Rock_Slate"
    },
    {
      "x": 3,
      "y": 9,
      "z": 2,
      "name": "Rock_Slate"
    },
    {
      "x": 3,
      "y": 10,
      "z": 2,
      "name": "Rock_Slate"
    },
    {
      "x": 3,
      "y": 11,
      "z": 2,
      "name": "Rock_Slate"
    },
    {
      "x": 3,
      "y": 12,
      "z": 2,
      "name": "Rock_Slate"
    },
    {
      "x": 3,
      "y": 0,
      "z": 3,
      "name": "Rock_Slate"
    },
    {
      "x": 3,
      "y": 1,
      "z": 3,
      "name": "Rock_Slate"
    },
    {
      "x": 3,
      "y": 2,
      "z": 3,
      "name": "Rock_Slate"
    },
    {
      "x": 3,
      "y": 3,
      "z": 3,
      "name": "Rock_Slate"
    },
    {
      "x": 3,
      "y": 4,
      "z": 3,
      "name": "Rock_Slate"
    },
    {
      "x": 3,
      "y": 5,
      "z": 3,
      "name": "Rock_Slate"
    },
    {
      "x": 3,
      "y": 6,
      "z": 3,
      "name": "Rock_Slate"
    },
    {
      "x": 3,
      "y": 7,
      "z": 3,
      "name": "Rock_Slate"
    },
    {
      "x": 3,
      "y": 8,
      "z": 3,
      "name": "Rock_Slate"
    },
    {
      "x": 3,
      "y": 9,
      "z": 3,
      "name": "Rock_Slate"
    },
    {
      "x": 3,
      "y": 10,
      "z": 3,
      "name": "Rock_Slate"
    },
    {
      "x": 3,
      "y": 11,
      "z": 3,
      "name": "Rock_Slate"
    },
    {
      "x": 3,
      "y": 12,
      "z": 3,
      "name": "Rock_Slate"
    },
    {
      "x": 3,
      "y": 2,
      "z": 4,
      "name": "Rock_Slate"
    },
    {
      "x": 3,
      "y": 3,
      "z": 4,
      "name": "Rock_Slate"
    },
    {
      "x": 3,
      "y": 4,
      "z": 4,
      "name": "Rock_Slate"
    },
    {
      "x": 3,
      "y": 5,
      "z": 4,
      "name": "Rock_Slate"
    },
    {
      "x": 3,
      "y": 6,
      "z": 4,
      "name": "Rock_Slate"
    },
    {
      "x": 3,
      "y": 7,
      "z": 4,
      "name": "Rock_Slate"
    },
    {
      "x": 3,
      "y": 8,
      "z": 4,
      "name": "Rock_Slate"
    },
    {
      "x": 3,
      "y": 9,
      "z": 4,
      "name": "Rock_Slate"
    },
    {
      "x": 3,
      "y": 10,
      "z": 4,
      "name": "Rock_Slate"
    },
    {
      "x": 3,
      "y": 11,
      "z": 4,
      "name": "Rock_Slate"
    },
    {
      "x": 3,
      "y": 12,
      "z": 4,
      "name": "Rock_Slate"
    },
    {
      "x": 3,
      "y": 9,
      "z": 5,
      "name": "Rock_Slate"
    },
    {
      "x": 3,
      "y": 10,
      "z": 5,
      "name": "Rock_Slate"
    },
    {
      "x": 3,
      "y": 11,
      "z": 5,
      "name": "Rock_Slate"
    },
    {
      "x": 3,
      "y": 12,
      "z": 5,
      "name": "Rock_Slate"
    },
    {
      "x": 4,
      "y": 0,
      "z": 1,
      "name": "Rock_Slate"
    },
    {
      "x": 4,
      "y": 1,
      "z": 1,
      "name": "Rock_Slate"
    },
    {
      "x": 4,
      "y": 2,
      "z": 1,
      "name": "Rock_Slate"
    },
    {
      "x": 4,
      "y": 3,
      "z": 1,
      "name": "Rock_Slate"
    },
    {
      "x": 4,
      "y": 4,
      "z": 1,
      "name": "Rock_Slate"
    },
    {
      "x": 4,
      "y": 5,
      "z": 1,
      "name": "Rock_Slate"
    },
    {
      "x": 4,
      "y": 6,
      "z": 1,
      "name": "Rock_Slate"
    },
    {
      "x": 4,
      "y": 7,
      "z": 1,
      "name": "Rock_Slate"
    },
    {
      "x": 4,
      "y": 8,
      "z": 1,
      "name": "Rock_Slate"
    },
    {
      "x": 4,
      "y": 9,
      "z": 1,
      "name": "Rock_Slate"
    },
    {
      "x": 4,
      "y": 10,
      "z": 1,
      "name": "Rock_Slate"
    },
    {
      "x": 4,
      "y": 0,
      "z": 2,
      "name": "Rock_Slate"
    },
    {
      "x": 4,
      "y": 1,
      "z": 2,
      "name": "Rock_Slate"
    },
    {
      "x": 4,
      "y": 2,
      "z": 2,
      "name": "Rock_Slate"
    },
    {
      "x": 4,
      "y": 3,
      "z": 2,
      "name": "Rock_Slate"
    },
    {
      "x": 4,
      "y": 4,
      "z": 2,
      "name": "Rock_Ice_Permafrost"
    },
    {
      "x": 4,
      "y": 5,
      "z": 2,
      "name": "Rock_Ice_Permafrost"
    },
    {
      "x": 4,
      "y": 6,
      "z": 2,
      "name": "Rock_Ice_Permafrost"
    },
    {
      "x": 4,
      "y": 7,
      "z": 2,
      "name": "Rock_Ice_Permafrost"
    },
    {
      "x": 4,
      "y": 8,
      "z": 2,
      "name": "Rock_Ice_Permafrost"
    },
    {
      "x": 4,
      "y": 9,
      "z": 2,
      "name": "Rock_Ice_Permafrost"
    },
    {
      "x": 4,
      "y": 10,
      "z": 2,
      "name": "Rock_Ice_Permafrost"
    },
    {
      "x": 4,
      "y": 11,
      "z": 2,
      "name": "Rock_Slate"
    },
    {
      "x": 4,
      "y": 12,
      "z": 2,
      "name": "Rock_Slate"
    },
    {
      "x": 4,
      "y": 0,
      "z": 3,
      "name": "Rock_Slate"
    },
    {
      "x": 4,
      "y": 1,
      "z": 3,
      "name": "Rock_Slate"
    },
    {
      "x": 4,
      "y": 2,
      "z": 3,
      "name": "Rock_Slate"
    },
    {
      "x": 4,
      "y": 3,
      "z": 3,
      "name": "Rock_Slate"
    },
    {
      "x": 4,
      "y": 4,
      "z": 3,
      "name": "Rock_Ice_Permafrost"
    },
    {
      "x": 4,
      "y": 5,
      "z": 3,
      "name": "Rock_Ice_Permafrost"
    },
    {
      "x": 4,
      "y": 6,
      "z": 3,
      "name": "Rock_Ice_Permafrost"
    },
    {
      "x": 4,
      "y": 7,
      "z": 3,
      "name": "Rock_Ice_Permafrost"
    },
    {
      "x": 4,
      "y": 8,
      "z": 3,
      "name": "Rock_Ice_Permafrost"
    },
    {
      "x": 4,
      "y": 9,
      "z": 3,
      "name": "Rock_Ice_Permafrost"
    },
    {
      "x": 4,
      "y": 10,
      "z": 3,
      "name": "Rock_Ice_Permafrost"
    },
    {
      "x": 4,
      "y": 11,
      "z": 3,
      "name": "Rock_Ice_Permafrost"
    },
    {
      "x": 4,
      "y": 12,
      "z": 3,
      "name": "Rock_Slate"
    },
    {
      "x": 4,
      "y": 0,
      "z": 4,
      "name": "Rock_Slate"
    },
    {
      "x": 4,
      "y": 1,
      "z": 4,
      "name": "Rock_Slate"
    },
    {
      "x": 4,
      "y": 2,
      "z": 4,
      "name": "Rock_Slate"
    },
    {
      "x": 4,
      "y": 3,
      "z": 4,
      "name": "Rock_Slate"
    },
    {
      "x": 4,
      "y": 4,
      "z": 4,
      "name": "Rock_Slate"
    },
    {
      "x": 4,
      "y": 5,
      "z": 4,
      "name": "Rock_Slate"
    },
    {
      "x": 4,
      "y": 6,
      "z": 4,
      "name": "Rock_Ice_Permafrost"
    },
    {
      "x": 4,
      "y": 7,
      "z": 4,
      "name": "Rock_Ice_Permafrost"
    },
    {
      "x": 4,
      "y": 8,
      "z": 4,
      "name": "Rock_Ice_Permafrost"
    },
    {
      "x": 4,
      "y": 9,
      "z": 4,
      "name": "Rock_Ice_Permafrost"
    },
    {
      "x": 4,
      "y": 10,
      "z": 4,
      "name": "Rock_Ice_Permafrost"
    },
    {
      "x": 4,
      "y": 11,
      "z": 4,
      "name": "Rock_Ice_Permafrost"
    },
    {
      "x": 4,
      "y": 12,
      "z": 4,
      "name": "Rock_Slate"
    },
    {
      "x": 4,
      "y": 6,
      "z": 5,
      "name": "Rock_Slate"
    },
    {
      "x": 4,
      "y": 7,
      "z": 5,
      "name": "Rock_Slate"
    },
    {
      "x": 4,
      "y": 8,
      "z": 5,
      "name": "Rock_Slate"
    },
    {
      "x": 4,
      "y": 9,
      "z": 5,
      "name": "Rock_Slate"
    },
    {
      "x": 4,
      "y": 10,
      "z": 5,
      "name": "Rock_Slate"
    },
    {
      "x": 4,
      "y": 11,
      "z": 5,
      "name": "Rock_Slate"
    },
    {
      "x": 4,
      "y": 12,
      "z": 5,
      "name": "Rock_Slate"
    },
    {
      "x": 5,
      "y": 0,
      "z": 1,
      "name": "Rock_Slate"
    },
    {
      "x": 5,
      "y": 1,
      "z": 1,
      "name": "Rock_Slate"
    },
    {
      "x": 5,
      "y": 2,
      "z": 1,
      "name": "Rock_Slate"
    },
    {
      "x": 5,
      "y": 3,
      "z": 1,
      "name": "Rock_Slate"
    },
    {
      "x": 5,
      "y": 4,
      "z": 1,
      "name": "Rock_Slate"
    },
    {
      "x": 5,
      "y": 5,
      "z": 1,
      "name": "Rock_Slate"
    },
    {
      "x": 5,
      "y": 6,
      "z": 1,
      "name": "Rock_Slate"
    },
    {
      "x": 5,
      "y": 7,
      "z": 1,
      "name": "Rock_Slate"
    },
    {
      "x": 5,
      "y": 8,
      "z": 1,
      "name": "Rock_Slate"
    },
    {
      "x": 5,
      "y": 9,
      "z": 1,
      "name": "Rock_Slate"
    },
    {
      "x": 5,
      "y": 10,
      "z": 1,
      "name": "Rock_Slate"
    },
    {
      "x": 5,
      "y": 0,
      "z": 2,
      "name": "Rock_Slate"
    },
    {
      "x": 5,
      "y": 1,
      "z": 2,
      "name": "Rock_Slate"
    },
    {
      "x": 5,
      "y": 2,
      "z": 2,
      "name": "Rock_Slate"
    },
    {
      "x": 5,
      "y": 3,
      "z": 2,
      "name": "Rock_Slate"
    },
    {
      "x": 5,
      "y": 4,
      "z": 2,
      "name": "Rock_Slate"
    },
    {
      "x": 5,
      "y": 5,
      "z": 2,
      "name": "Rock_Slate"
    },
    {
      "x": 5,
      "y": 6,
      "z": 2,
      "name": "Rock_Slate"
    },
    {
      "x": 5,
      "y": 7,
      "z": 2,
      "name": "Rock_Slate"
    },
    {
      "x": 5,
      "y": 8,
      "z": 2,
      "name": "Rock_Slate"
    },
    {
      "x": 5,
      "y": 9,
      "z": 2,
      "name": "Rock_Slate"
    },
    {
      "x": 5,
      "y": 10,
      "z": 2,
      "name": "Rock_Slate"
    },
    {
      "x": 5,
      "y": 11,
      "z": 2,
      "name": "Rock_Slate"
    },
    {
      "x": 5,
      "y": 12,
      "z": 2,
      "name": "Rock_Slate"
    },
    {
      "x": 5,
      "y": 0,
      "z": 3,
      "name": "Rock_Slate"
    },
    {
      "x": 5,
      "y": 1,
      "z": 3,
      "name": "Rock_Slate"
    },
    {
      "x": 5,
      "y": 2,
      "z": 3,
      "name": "Rock_Slate"
    },
    {
      "x": 5,
      "y": 3,
      "z": 3,
      "name": "Rock_Slate"
    },
    {
      "x": 5,
      "y": 4,
      "z": 3,
      "name": "Rock_Ice_Permafrost"
    },
    {
      "x": 5,
      "y": 5,
      "z": 3,
      "name": "Rock_Ice_Permafrost"
    },
    {
      "x": 5,
      "y": 6,
      "z": 3,
      "name": "Rock_Ice_Permafrost"
    },
    {
      "x": 5,
      "y": 7,
      "z": 3,
      "name": "Rock_Ice_Permafrost"
    },
    {
      "x": 5,
      "y": 8,
      "z": 3,
      "name": "Rock_Ice_Permafrost"
    },
    {
      "x": 5,
      "y": 9,
      "z": 3,
      "name": "Rock_Ice_Permafrost"
    },
    {
      "x": 5,
      "y": 10,
      "z": 3,
      "name": "Rock_Slate"
    },
    {
      "x": 5,
      "y": 11,
      "z": 3,
      "name": "Rock_Slate"
    },
    {
      "x": 5,
      "y": 12,
      "z": 3,
      "name": "Rock_Slate"
    },
    {
      "x": 5,
      "y": 0,
      "z": 4,
      "name": "Rock_Slate"
    },
    {
      "x": 5,
      "y": 1,
      "z": 4,
      "name": "Rock_Slate"
    },
    {
      "x": 5,
      "y": 2,
      "z": 4,
      "name": "Rock_Slate"
    },
    {
      "x": 5,
      "y": 3,
      "z": 4,
      "name": "Rock_Slate"
    },
    {
      "x": 5,
      "y": 4,
      "z": 4,
      "name": "Rock_Slate"
    },
    {
      "x": 5,
      "y": 5,
      "z": 4,
      "name": "Rock_Slate"
    },
    {
      "x": 5,
      "y": 6,
      "z": 4,
      "name": "Rock_Slate"
    },
    {
      "x": 5,
      "y": 7,
      "z": 4,
      "name": "Rock_Slate"
    },
    {
      "x": 5,
      "y": 8,
      "z": 4,
      "name": "Rock_Slate"
    },
    {
      "x": 5,
      "y": 9,
      "z": 4,
      "name": "Rock_Slate"
    },
    {
      "x": 5,
      "y": 10,
      "z": 4,
      "name": "Rock_Slate"
    },
    {
      "x": 5,
      "y": 11,
      "z": 4,
      "name": "Rock_Slate"
    },
    {
      "x": 5,
      "y": 12,
      "z": 4,
      "name": "Rock_Slate"
    },
    {
      "x": 5,
      "y": 6,
      "z": 5,
      "name": "Rock_Slate"
    },
    {
      "x": 5,
      "y": 7,
      "z": 5,
      "name": "Rock_Slate"
    },
    {
      "x": 5,
      "y": 8,
      "z": 5,
      "name": "Rock_Slate"
    },
    {
      "x": 5,
      "y": 9,
      "z": 5,
      "name": "Rock_Slate"
    },
    {
      "x": 5,
      "y": 10,
      "z": 5,
      "name": "Rock_Slate"
    },
    {
      "x": 5,
      "y": 11,
      "z": 5,
      "name": "Rock_Slate"
    },
    {
      "x": 6,
      "y": 0,
      "z": 1,
      "name": "Rock_Slate"
    },
    {
      "x": 6,
      "y": 1,
      "z": 1,
      "name": "Rock_Slate"
    },
    {
      "x": 6,
      "y": 2,
      "z": 1,
      "name": "Rock_Slate"
    },
    {
      "x": 6,
      "y": 3,
      "z": 1,
      "name": "Rock_Slate"
    },
    {
      "x": 6,
      "y": 4,
      "z": 1,
      "name": "Rock_Slate"
    },
    {
      "x": 6,
      "y": 5,
      "z": 1,
      "name": "Rock_Slate"
    },
    {
      "x": 6,
      "y": 6,
      "z": 1,
      "name": "Rock_Slate"
    },
    {
      "x": 6,
      "y": 7,
      "z": 1,
      "name": "Rock_Slate"
    },
    {
      "x": 6,
      "y": 0,
      "z": 2,
      "name": "Rock_Slate"
    },
    {
      "x": 6,
      "y": 1,
      "z": 2,
      "name": "Rock_Slate"
    },
    {
      "x": 6,
      "y": 2,
      "z": 2,
      "name": "Rock_Slate"
    },
    {
      "x": 6,
      "y": 3,
      "z": 2,
      "name": "Rock_Slate"
    },
    {
      "x": 6,
      "y": 4,
      "z": 2,
      "name": "Rock_Slate"
    },
    {
      "x": 6,
      "y": 5,
      "z": 2,
      "name": "Rock_Slate"
    },
    {
      "x": 6,
      "y": 6,
      "z": 2,
      "name": "Rock_Slate"
    },
    {
      "x": 6,
      "y": 7,
      "z": 2,
      "name": "Rock_Slate"
    },
    {
      "x": 6,
      "y": 8,
      "z": 2,
      "name": "Rock_Slate"
    },
    {
      "x": 6,
      "y": 9,
      "z": 2,
      "name": "Rock_Slate"
    },
    {
      "x": 6,
      "y": 0,
      "z": 3,
      "name": "Rock_Slate"
    },
    {
      "x": 6,
      "y": 1,
      "z": 3,
      "name": "Rock_Slate"
    },
    {
      "x": 6,
      "y": 2,
      "z": 3,
      "name": "Rock_Slate"
    },
    {
      "x": 6,
      "y": 3,
      "z": 3,
      "name": "Rock_Slate"
    },
    {
      "x": 6,
      "y": 4,
      "z": 3,
      "name": "Rock_Slate"
    },
    {
      "x": 6,
      "y": 5,
      "z": 3,
      "name": "Rock_Slate"
    },
    {
      "x": 6,
      "y": 6,
      "z": 3,
      "name": "Rock_Slate"
    },
    {
      "x": 6,
      "y": 7,
      "z": 3,
      "name": "Rock_Slate"
    },
    {
      "x": 6,
      "y": 8,
      "z": 3,
      "name": "Rock_Slate"
    },
    {
      "x": 6,
      "y": 9,
      "z": 3,
      "name": "Rock_Slate"
    },
    {
      "x": 6,
      "y": 1,
      "z": 4,
      "name": "Rock_Slate"
    },
    {
      "x": 6,
      "y": 2,
      "z": 4,
      "name": "Rock_Slate"
    },
    {
      "x": 6,
      "y": 3,
      "z": 4,
      "name": "Rock_Slate"
    },
    {
      "x": 6,
      "y": 4,
      "z": 4,
      "name": "Rock_Slate"
    },
    {
      "x": 6,
      "y": 5,
      "z": 4,
      "name": "Rock_Slate"
    },
    {
      "x": 6,
      "y": 6,
      "z": 4,
      "name": "Rock_Slate"
    },
    {
      "x": 6,
      "y": 7,
      "z": 4,
      "name": "Rock_Slate"
    },
    {
      "x": 6,
      "y": 8,
      "z": 4,
      "name": "Rock_Slate"
    },
    {
      "x": 7,
      "y": 1,
      "z": 2,
      "name": "Rock_Slate"
    },
    {
      "x": 7,
      "y": 2,
      "z": 2,
      "name": "Rock_Slate"
    },
    {
      "x": 7,
      "y": 3,
      "z": 2,
      "name": "Rock_Slate"
    },
    {
      "x": 7,
      "y": 4,
      "z": 2,
      "name": "Rock_Slate"
    },
    {
      "x": 7,
      "y": 0,
      "z": 3,
      "name": "Rock_Slate"
    },
    {
      "x": 7,
      "y": 1,
      "z": 3,
      "name": "Rock_Slate"
    },
    {
      "x": 7,
      "y": 2,
      "z": 3,
      "name": "Rock_Slate"
    },
    {
      "x": 7,
      "y": 3,
      "z": 3,
      "name": "Rock_Slate"
    }
  ]
}